{"channel": "book", "type": "snapshot", "data": [{"symbol": "BTC/USD", "bids": [{"price": 78980.2, "qty": 0.01758056}, {"price": 78980.0, "qty": 5.1e-05}, {"price": 78976.1, "qty": 5.1e-05}, {"price": 78972.1, "qty": 5.1e-05}, {"price": 78969.2, "qty": 5e-05}, {"price": 78968.2, "qty": 5.1e-05}, {"price": 78963.1, "qty": 0.04462285}, {"price": 78963.0, "qty": 5e-05}, {"price": 78961.9, "qty": 0.0003}, {"price": 78957.1, "qty": 0.11}, {"price": 78957.0, "qty": 0.02532642}, {"price": 78956.8, "qty": 5e-05}, {"price": 78956.2, "qty": 0.06331606}, {"price": 78955.0, "qty": 1.60263745}, {"price": 78954.3, "qty": 0.13109402}, {"price": 78950.6, "qty": 0.34780033}, {"price": 78950.5, "qty": 5e-05}, {"price": 78950.0, "qty": 0.20344794}, {"price": 78949.9, "qty": 0.63331298}, {"price": 78949.7, "qty": 0.25656326}, {"price": 78949.5, "qty": 0.53195441}, {"price": 78948.7, "qty": 0.4}, {"price": 78948.1, "qty": 0.122529}, {"price": 78945.4, "qty": 0.0171482}, {"price": 78944.9, "qty": 0.8995977}], "asks": [{"price": 78980.3, "qty": 7.32087043}, {"price": 78980.4, "qty": 0.53195441}, {"price": 78980.8, "qty": 0.02532642}, {"price": 78981.4, "qty": 0.37834565}, {"price": 78981.7, "qty": 0.63305827}, {"price": 78981.8, "qty": 0.12046386}, {"price": 78982.6, "qty": 0.03300708}, {"price": 78982.8, "qty": 0.06331606}, {"price": 78983.2, "qty": 0.00253218}, {"price": 78983.4, "qty": 0.34605902}, {"price": 78983.5, "qty": 0.02278956}, {"price": 78983.6, "qty": 0.4}, {"price": 78985.3, "qty": 0.40298465}, {"price": 78985.5, "qty": 0.63302766}, {"price": 78987.7, "qty": 0.009}, {"price": 78987.8, "qty": 5.1e-05}, {"price": 78988.0, "qty": 0.78889152}, {"price": 78988.1, "qty": 1.89975426}, {"price": 78988.2, "qty": 0.79787004}, {"price": 78988.9, "qty": 0.12257826}, {"price": 78989.6, "qty": 1.89898425}, {"price": 78989.9, "qty": 0.04924933}, {"price": 78991.7, "qty": 5.1e-05}, {"price": 78992.1, "qty": 0.000258}, {"price": 78992.2, "qty": 0.00881799}], "checksum": 1108567130, "timestamp": "2026-08-26T07:44:36.205375Z"}], "recv_ts_ns": 1787730276788103890}
{"channel": "book", "type": "update", "data": [{"symbol": "BTC/USD", "bids": [{"price": 78954.1, "qty": 0.63327886}], "asks": [], "checksum": 1108567130, "timestamp": "2026-08-26T07:44:36.268793Z"}], "recv_ts_ns": 1787730276788154571}
{"channel": "book", "type": "update", "data": [{"symbol": "BTC/USD", "bids": [{"price": 78949.9, "qty": 0.0}, {"price": 78944.9, "qty": 0.8995977}], "asks": [], "checksum": 1108567130, "timestamp": "2026-08-26T07:44:36.293352Z"}], "recv_ts_ns": 1787730276788172192}
{"channel": "book", "type": "update", "data": [{"symbol": "BTC/USD", "bids": [], "asks": [{"price": 78988.1, "qty": 0.0}, {"price": 78992.4, "qty": 1.90259847}, {"price": 78987.9, "qty": 1.89970652}], "checksum": 1108567130, "timestamp": "2026-08-26T07:44:36.352210Z"}], "recv_ts_ns": 1787730276788185956}
{"channel": "book", "type": "update", "data": [{"symbol": "BTC/USD", "bids": [], "asks": [{"price": 78985.3, "qty": 0.21401067}], "checksum": 1108567130, "timestamp": "2026-08-26T07:44:36.353339Z"}], "recv_ts_ns": 1787730276788202102}
{"channel": "book", "type": "update", "data": [{"symbol": "BTC/USD", "bids": [], "asks": [{"price": 78985.3, "qty": 0.0}, {"price": 78992.4, "qty": 1.90259847}], "checksum": 1108567130, "timestamp": "2026-08-26T07:44:36.353510Z"}], "recv_ts_ns": 1787730276788213966}
{"channel": "book", "type": "update", "data": [{"symbol": "BTC/USD", "bids": [], "asks": [{"price": 78987.8, "qty": 0.80259751}], "checksum": 1108567130, "timestamp": "2026-08-26T07:44:36.354882Z"}], "recv_ts_ns": 1787730276788225896}
{"channel": "book", "type": "update", "data": [{"symbol": "BTC/USD", "bids": [{"price": 78961.2, "qty": 0.63322171}], "asks": [], "checksum": 501314506, "timestamp": "2026-08-26T07:44:36.372452Z"}], "recv_ts_ns": 1787730276788235505}
{"channel": "book", "type": "update", "data": [{"symbol": "BTC/USD", "bids": [], "asks": [{"price": 78987.6, "qty": 0.08956015}], "checksum": 501314506, "timestamp": "2026-08-26T07:44:36.428099Z"}], "recv_ts_ns": 1787730276788245397}
{"channel": "book", "type": "update", "data": [{"symbol": "BTC/USD", "bids": [], "asks": [{"price": 78987.9, "qty": 0.0}, {"price": 78992.4, "qty": 1.90259847}, {"price": 78987.7, "qty": 1.90870097}], "checksum": 501314506, "timestamp": "2026-08-26T07:44:36.504493Z"}], "recv_ts_ns": 1787730276788256288}
{"channel": "book", "type": "update", "data": [{"symbol": "BTC/USD", "bids": [], "asks": [{"price": 78987.8, "qty": 5.1e-05}], "checksum": 501314506, "timestamp": "2026-08-26T07:44:36.505980Z"}], "recv_ts_ns": 1787730276788269791}
{"channel": "book", "type": "update", "data": [{"symbol": "BTC/USD", "bids": [], "asks": [{"price": 78987.5, "qty": 0.83198029}], "checksum": 501314506, "timestamp": "2026-08-26T07:44:36.507616Z"}], "recv_ts_ns": 1787730276788286153}
{"channel": "book", "type": "update", "data": [{"symbol": "BTC/USD", "bids": [{"price": 78945.4, "qty": 0.0}, {"price": 78944.9, "qty": 0.8995977}], "asks": [], "checksum": 501314506, "timestamp": "2026-08-26T07:44:36.530217Z"}], "recv_ts_ns": 1787730276788299164}
{"channel": "book", "type": "update", "data": [{"symbol": "BTC/USD", "bids": [{"price": 78961.9, "qty": 0.0}, {"price": 78944.8, "qty": 3.01367765}], "asks": [], "checksum": 3096917627, "timestamp": "2026-08-26T07:44:36.554853Z"}], "recv_ts_ns": 1787730276788316867}
{"channel": "book", "type": "update", "data": [{"symbol": "BTC/USD", "bids": [{"price": 78961.2, "qty": 0.0}, {"price": 78944.3, "qty": 5e-05}], "asks": [], "checksum": 3576803875, "timestamp": "2026-08-26T07:44:36.583978Z"}], "recv_ts_ns": 1787730276788328821}
{"channel": "book", "type": "update", "data": [{"symbol": "BTC/USD", "bids": [{"price": 78962.1, "qty": 0.63321483}], "asks": [], "checksum": 2921873707, "timestamp": "2026-08-26T07:44:36.585942Z"}], "recv_ts_ns": 1787730276788339246}
{"channel": "book", "type": "update", "data": [{"symbol": "BTC/USD", "bids": [{"price": 78959.6, "qty": 0.6332351}], "asks": [], "checksum": 3102439915, "timestamp": "2026-08-26T07:44:36.586257Z"}], "recv_ts_ns": 1787730276788349344}
{"channel": "book", "type": "update", "data": [{"symbol": "BTC/USD", "bids": [{"price": 78944.9, "qty": 2.79965533}], "asks": [], "checksum": 3102439915, "timestamp": "2026-08-26T07:44:36.586554Z"}], "recv_ts_ns": 1787730276788360799}
{"channel": "book", "type": "update", "data": [{"symbol": "BTC/USD", "bids": [], "asks": [{"price": 78987.7, "qty": 0.009}, {"price": 78987.9, "qty": 1.89970591}], "checksum": 3102439915, "timestamp": "2026-08-26T07:44:36.650644Z"}], "recv_ts_ns": 1787730276815330264}
{"channel": "book", "type": "update", "data": [{"symbol": "BTC/USD", "bids": [], "asks": [{"price": 78987.9, "qty": 0.0}, {"price": 78992.2, "qty": 0.00881799}, {"price": 78987.4, "qty": 1.89972957}], "checksum": 3102439915, "timestamp": "2026-08-26T07:44:36.656781Z"}], "recv_ts_ns": 1787730276815820397}
