{"recv_ts_ns": 1787746429749157700, "payload": "{\"channel\":\"l2_data\",\"timestamp\":\"2026-08-26T12:13:49.634135861Z\",\"sequence_num\":34,\"events\":[{\"type\":\"update\",\"product_id\":\"ATOM-USD\",\"updates\":[{\"side\":\"offer\",\"event_time\":\"2026-08-26T12:13:49.551528Z\",\"price_level\":\"1.5683\",\"new_quantity\":\"92.81\"}]}]}"}
{"recv_ts_ns": 1787746429807037775, "payload": "{\"channel\":\"l2_data\",\"timestamp\":\"2026-08-26T12:13:49.692902928Z\",\"sequence_num\":35,\"events\":[{\"type\":\"update\",\"product_id\":\"ATOM-USD\",\"updates\":[{\"side\":\"bid\",\"event_time\":\"2026-08-26T12:13:49.580634Z\",\"price_level\":\"1.5585\",\"new_quantity\":\"0\"},{\"side\":\"bid\",\"event_time\":\"2026-08-26T12:13:49.580634Z\",\"price_level\":\"1.5584\",\"new_quantity\":\"84.65\"},{\"side\":\"bid\",\"event_time\":\"2026-08-26T12:13:49.580634Z\",\"price_level\":\"1.5583\",\"new_quantity\":\"253.24\"},{\"side\":\"bid\",\"event_time\":\"2026-08-26T12:13:49.580634Z\",\"price_level\":\"1.5578\",\"new_quantity\":\"20.25\"},{\"side\":\"bid\",\"event_time\":\"2026-08-26T12:13:49.580634Z\",\"price_level\":\"1.5575\",\"new_quantity\":\"253.32\"},{\"side\":\"bid\",\"event_time\":\"2026-08-26T12:13:49.580634Z\",\"price_level\":\"1.5574\",\"new_quantity\":\"0\"},{\"side\":\"bid\",\"event_time\":\"2026-08-26T12:13:49.580634Z\",\"price_level\":\"1.5567\",\"new_quantity\":\"287.63\"},{\"side\":\"bid\",\"event_time\":\"2026-08-26T12:13:49.580634Z\",\"price_level\":\"1.5566\",\"new_quantity\":\"574.61\"},{\"side\":\"bid\",\"event_time\":\"2026-08-26T12:13:49.580634Z\",\"price_level\":\"1.5562\",\"new_quantity\":\"157.35\"},{\"side\":\"bid\",\"event_time\":\"2026-08-26T12:13:49.580634Z\",\"price_level\":\"1.5558\",\"new_quantity\":\"642.75\"},{\"side\":\"bid\",\"event_time\":\"2026-08-26T12:13:49.580634Z\",\"price_level\":\"1.555\",\"new_quantity\":\"0\"},{\"side\":\"bid\",\"event_time\":\"2026-08-26T12:13:49.580634Z\",\"price_level\":\"1.5539\",\"new_quantity\":\"0\"},{\"side\":\"bid\",\"event_time\":\"2026-08-26T12:13:49.580634Z\",\"price_level\":\"1.5467\",\"new_quantity\":\"0\"},{\"side\":\"bid\",\"event_time\":\"2026-08-26T12:13:49.580634Z\",\"price_level\":\"1.546\",\"new_quantity\":\"0\"},{\"side\":\"bid\",\"event_time\":\"2026-08-26T12:13:49.580634Z\",\"price_level\":\"1.5201\",\"new_quantity\":\"3134.53\"},{\"side\":\"offer\",\"event_time\":\"2026-08-26T12:13:49.580634Z\",\"price_level\":\"1.5594\",\"new_quantity\":\"194.54\"},{\"side\":\"offer\",\"event_time\":\"2026-08-26T12:13:49.580634Z\",\"price_level\":\"1.5595\",\"new_quantity\":\"325.87\"},{\"side\":\"offer\",\"event_time\":\"2026-08-26T12:13:49.580634Z\",\"price_level\":\"1.5596\",\"new_quantity\":\"80.14\"},{\"side\":\"offer\",\"event_time\":\"2026-08-26T12:13:49.580634Z\",\"price_level\":\"1.5597\",\"new_quantity\":\"0\"},{\"side\":\"offer\",\"event_time\":\"2026-08-26T12:13:49.580634Z\",\"price_level\":\"1.5606\",\"new_quantity\":\"1213.72\"},{\"side\":\"offer\",\"event_time\":\"2026-08-26T12:13:49.580634Z\",\"price_level\":\"1.5607\",\"new_quantity\":\"0\"},{\"side\":\"offer\",\"event_time\":\"2026-08-26T12:13:49.580634Z\",\"price_level\":\"1.5611\",\"new_quantity\":\"333.03\"},{\"side\":\"offer\",\"event_time\":\"2026-08-26T12:13:49.580634Z\",\"price_level\":\"1.5622\",\"new_quantity\":\"0\"},{\"side\":\"offer\",\"event_time\":\"2026-08-26T12:13:49.580634Z\",\"price_level\":\"1.5664\",\"new_quantity\":\"20.25\"},{\"side\":\"offer\",\"event_time\":\"2026-08-26T12:13:49.580634Z\",\"price_level\":\"1.5665\",\"new_quantity\":\"0\"},{\"side\":\"offer\",\"event_time\":\"2026-08-26T12:13:49.580634Z\",\"price_level\":\"1.5697\",\"new_quantity\":\"20.25\"}]}]}"}
{"recv_ts_ns": 1787746429867852769, "payload": "{\"channel\":\"l2_data\",\"timestamp\":\"2026-08-26T12:13:49.75290004Z\",\"sequence_num\":36,\"events\":[{\"type\":\"update\",\"product_id\":\"ATOM-USD\",\"updates\":[{\"side\":\"bid\",\"event_time\":\"2026-08-26T12:13:49.652927Z\",\"price_level\":\"1.5584\",\"new_quantity\":\"0\"},{\"side\":\"bid\",\"event_time\":\"2026-08-26T12:13:49.652927Z\",\"price_level\":\"1.5583\",\"new_quantity\":\"0\"},{\"side\":\"bid\",\"event_time\":\"2026-08-26T12:13:49.652927Z\",\"price_level\":\"1.5582\",\"new_quantity\":\"0\"},{\"side\":\"bid\",\"event_time\":\"2026-08-26T12:13:49.652927Z\",\"price_level\":\"1.5581\",\"new_quantity\":\"0\"},{\"side\":\"bid\",\"event_time\":\"2026-08-26T12:13:49.652927Z\",\"price_level\":\"1.558\",\"new_quantity\":\"20.25\"},{\"side\":\"bid\",\"event_time\":\"2026-08-26T12:13:49.652927Z\",\"price_level\":\"1.5579\",\"new_quantity\":\"0\"},{\"side\":\"bid\",\"event_time\":\"2026-08-26T12:13:49.652927Z\",\"price_level\":\"1.5578\",\"new_quantity\":\"0\"},{\"side\":\"bid\",\"event_time\":\"2026-08-26T12:13:49.652927Z\",\"price_level\":\"1.5577\",\"new_quantity\":\"92.81\"},{\"side\":\"bid\",\"event_time\":\"2026-08-26T12:13:49.652927Z\",\"price_level\":\"1.5576\",\"new_quantity\":\"0\"},{\"side\":\"bid\",\"event_time\":\"2026-08-26T12:13:49.652927Z\",\"price_level\":\"1.5575\",\"new_quantity\":\"92.81\"},{\"side\":\"bid\",\"event_time\":\"2026-08-26T12:13:49.652927Z\",\"price_level\":\"1.5574\",\"new_quantity\":\"20.25\"},{\"side\":\"bid\",\"event_time\":\"2026-08-26T12:13:49.652927Z\",\"price_level\":\"1.5573\",\"new_quantity\":\"0\"},{\"side\":\"bid\",\"event_time\":\"2026-08-26T12:13:49.652927Z\",\"price_level\":\"1.5572\",\"new_quantity\":\"92.81\"},{\"side\":\"bid\",\"event_time\":\"2026-08-26T12:13:49.652927Z\",\"price_level\":\"1.5571\",\"new_quantity\":\"0\"},{\"side\":\"bid\",\"event_time\":\"2026-08-26T12:13:49.652927Z\",\"price_level\":\"1.557\",\"new_quantity\":\"278.27\"},{\"side\":\"bid\",\"event_time\":\"2026-08-26T12:13:49.652927Z\",\"price_level\":\"1.5569\",\"new_quantity\":\"310.66\"},{\"side\":\"bid\",\"event_time\":\"2026-08-26T12:13:49.652927Z\",\"price_level\":\"1.5568\",\"new_quantity\":\"92.81\"},{\"side\":\"bid\",\"event_time\":\"2026-08-26T12:13:49.652927Z\",\"price_level\":\"1.5566\",\"new_quantity\":\"958.15\"},{\"side\":\"bid\",\"event_time\":\"2026-08-26T12:13:49.652927Z\",\"price_level\":\"1.5565\",\"new_quantity\":\"642.44\"},{\"side\":\"bid\",\"event_time\":\"2026-08-26T12:13:49.652927Z\",\"price_level\":\"1.5564\",\"new_quantity\":\"93.52\"},{\"side\":\"bid\",\"event_time\":\"2026-08-26T12:13:49.652927Z\",\"price_level\":\"1.5562\",\"new_quantity\":\"366.17\"},{\"side\":\"bid\",\"event_time\":\"2026-08-26T12:13:49.652927Z\",\"price_level\":\"1.556\",\"new_quantity\":\"92.81\"},{\"side\":\"bid\",\"event_time\":\"2026-08-26T12:13:49.652927Z\",\"price_level\":\"1.5559\",\"new_quantity\":\"403.97\"},{\"side\":\"bid\",\"event_time\":\"2026-08-26T12:13:49.652927Z\",\"price_level\":\"1.5556\",\"new_quantity\":\"477.6\"},{\"side\":\"bid\",\"event_time\":\"2026-08-26T12:13:49.652927Z\",\"price_level\":\"1.5555\",\"new_quantity\":\"2553.85\"},{\"side\":\"bid\",\"event_time\":\"2026-08-26T12:13:49.652927Z\",\"price_level\":\"1.5554\",\"new_quantity\":\"3412.01\"},{\"side\":\"bid\",\"event_time\":\"2026-08-26T12:13:49.652927Z\",\"price_level\":\"1.5553\",\"new_quantity\":\"1924.33\"},{\"side\":\"bid\",\"event_time\":\"2026-08-26T12:13:49.652927Z\",\"price_level\":\"1.5552\",\"new_quantity\":\"3158.33\"},{\"side\":\"bid\",\"event_time\":\"2026-08-26T12:13:49.652927Z\",\"price_level\":\"1.5547\",\"new_quantity\":\"5675.57\"},{\"side\":\"bid\",\"event_time\":\"2026-08-26T12:13:49.652927Z\",\"price_level\":\"1.5546\",\"new_quantity\":\"20.25\"},{\"side\":\"bid\",\"event_time\":\"2026-08-26T12:13:49.652927Z\",\"price_level\":\"1.5544\",\"new_quantity\":\"781.55\"},{\"side\":\"bid\",\"event_time\":\"2026-08-26T12:13:49.652927Z\",\"price_level\":\"1.5535\",\"new_quantity\":\"881.9\"},{\"side\":\"bid\",\"event_time\":\"2026-08-26T12:13:49.652927Z\",\"price_level\":\"1.5531\",\"new_quantity\":\"20.25\"},{\"side\":\"bid\",\"event_time\":\"2026-08-26T12:13:49.652927Z\",\"price_level\":\"1.552\",\"new_quantity\":\"1743.61\"},{\"side\":\"bid\",\"event_time\":\"2026-08-26T12:13:49.652927Z\",\"price_level\":\"1.5499\",\"new_quantity\":\"5900.45\"},{\"side\":\"bid\",\"event_time\":\"2026-08-26T12:13:49.652927Z\",\"price_level\":\"1.5483\",\"new_quantity\":\"0\"},{\"side\":\"bid\",\"event_time\":\"2026-08-26T12:13:49.652927Z\",\"price_level\":\"1.5479\",\"new_quantity\":\"20.25\"},{\"side\":\"bid\",\"event_time\":\"2026-08-26T12:13:49.652927Z\",\"price_level\":\"1.5467\",\"new_quantity\":\"0\"},{\"side\":\"bid\",\"event_time\":\"2026-08-26T12:13:49.652927Z\",\"price_level\":\"1.5418\",\"new_quantity\":\"5880.2\"},{\"side\":\"offer\",\"event_time\":\"2026-08-26T12:13:49.652927Z\",\"price_level\":\"1.5592\",\"new_quantity\":\"0\"},{\"side\":\"offer\",\"event_time\":\"2026-08-26T12:13:49.652927Z\",\"price_level\":\"1.5593\",\"new_quantity\":\"0\"},{\"side\":\"offer\",\"event_time\":\"2026-08-26T12:13:49.652927Z\",\"price_level\":\"1.5594\",\"new_quantity\":\"25.69\"},{\"side\":\"offer\",\"event_time\":\"2026-08-26T12:13:49.652927Z\",\"price_level\":\"1.5595\",\"new_quantity\":\"92.81\"},{\"side\":\"offer\",\"event_time\":\"2026-08-26T12:13:49.652927Z\",\"price_level\":\"1.5596\",\"new_quantity\":\"20.25\"},{\"side\":\"offer\",\"event_time\":\"2026-08-26T12:13:49.652927Z\",\"price_level\":\"1.5597\",\"new_quantity\":\"20.25\"},{\"side\":\"offer\",\"event_time\":\"2026-08-26T12:13:49.652927Z\",\"price_level\":\"1.56\",\"new_quantity\":\"0\"},{\"side\":\"offer\",\"event_time\":\"2026-08-26T12:13:49.652927Z\",\"price_level\":\"1.5601\",\"new_quantity\":\"92.81\"},{\"side\":\"offer\",\"event_time\":\"2026-08-26T12:13:49.652927Z\",\"price_level\":\"1.5602\",\"new_quantity\":\"450.57\"},{\"side\":\"offer\",\"event_time\":\"2026-08-26T12:13:49.652927Z\",\"price_level\":\"1.5603\",\"new_quantity\":\"818.39\"},{\"side\":\"offer\",\"event_time\":\"2026-08-26T12:13:49.652927Z\",\"price_level\":\"1.5604\",\"new_quantity\":\"307.99\"},{\"side\":\"offer\",\"event_time\":\"2026-08-26T12:13:49.652927Z\",\"price_level\":\"1.5605\",\"new_quantity\":\"1105.13\"},{\"side\":\"offer\",\"event_time\":\"2026-08-26T12:13:49.652927Z\",\"price_level\":\"1.5606\",\"new_quantity\":\"1042.06\"},{\"side\":\"offer\",\"event_time\":\"2026-08-26T12:13:49.652927Z\",\"price_level\":\"1.5609\",\"new_quantity\":\"320.33\"},{\"side\":\"offer\",\"event_time\":\"2026-08-26T12:13:49.652927Z\",\"price_level\":\"1.5611\",\"new_quantity\":\"92.81\"},{\"side\":\"offer\",\"event_time\":\"2026-08-26T12:13:49.652927Z\",\"price_level\":\"1.5614\",\"new_quantity\":\"0\"},{\"side\":\"offer\",\"event_time\":\"2026-08-26T12:13:49.652927Z\",\"price_level\":\"1.5616\",\"new_quantity\":\"5718.64\"},{\"side\":\"offer\",\"event_time\":\"2026-08-26T12:13:49.652927Z\",\"price_level\":\"1.5618\",\"new_quantity\":\"0\"},{\"side\":\"offer\",\"event_time\":\"2026-08-26T12:13:49.652927Z\",\"price_level\":\"1.562\",\"new_quantity\":\"0\"},{\"side\":\"offer\",\"event_time\":\"2026-08-26T12:13:49.652927Z\",\"price_level\":\"1.5644\",\"new_quantity\":\"20.25\"},{\"side\":\"offer\",\"event_time\":\"2026-08-26T12:13:49.652927Z\",\"price_level\":\"1.5645\",\"new_quantity\":\"20.25\"},{\"side\":\"offer\",\"event_time\":\"2026-08-26T12:13:49.652927Z\",\"price_level\":\"1.5647\",\"new_quantity\":\"92.81\"},{\"side\":\"offer\",\"event_time\":\"2026-08-26T12:13:49.652927Z\",\"price_level\":\"1.5648\",\"new_quantity\":\"13.53\"},{\"side\":\"offer\",\"event_time\":\"2026-08-26T12:13:49.652927Z\",\"price_level\":\"1.5663\",\"new_quantity\":\"0\"},{\"side\":\"offer\",\"event_time\":\"2026-08-26T12:13:49.652927Z\",\"price_level\":\"1.5664\",\"new_quantity\":\"0\"},{\"side\":\"offer\",\"event_time\":\"2026-08-26T12:13:49.652927Z\",\"price_level\":\"1.568\",\"new_quantity\":\"10\"},{\"side\":\"offer\",\"event_time\":\"2026-08-26T12:13:49.652927Z\",\"price_level\":\"1.5681\",\"new_quantity\":\"0\"},{\"side\":\"offer\",\"event_time\":\"2026-08-26T12:13:49.652927Z\",\"price_level\":\"1.5696\",\"new_quantity\":\"0.71\"},{\"side\":\"offer\",\"event_time\":\"2026-08-26T12:13:49.652927Z\",\"price_level\":\"1.5697\",\"new_quantity\":\"0\"}]}]}"}
{"recv_ts_ns": 1787746429913315929, "payload": "{\"channel\":\"l2_data\",\"timestamp\":\"2026-08-26T12:13:49.799008113Z\",\"sequence_num\":37,\"events\":[{\"type\":\"update\",\"product_id\":\"ATOM-USD\",\"updates\":[{\"side\":\"bid\",\"event_time\":\"2026-08-26T12:13:49.742748Z\",\"price_level\":\"1.558\",\"new_quantity\":\"0\"},{\"side\":\"bid\",\"event_time\":\"2026-08-26T12:13:49.742748Z\",\"price_level\":\"1.5577\",\"new_quantity\":\"92.81\"},{\"side\":\"bid\",\"event_time\":\"2026-08-26T12:13:49.742748Z\",\"price_level\":\"1.5576\",\"new_quantity\":\"0\"},{\"side\":\"bid\",\"event_time\":\"2026-08-26T12:13:49.742748Z\",\"price_level\":\"1.5575\",\"new_quantity\":\"0\"},{\"side\":\"bid\",\"event_time\":\"2026-08-26T12:13:49.742748Z\",\"price_level\":\"1.5574\",\"new_quantity\":\"20.25\"},{\"side\":\"bid\",\"event_time\":\"2026-08-26T12:13:49.742748Z\",\"price_level\":\"1.5573\",\"new_quantity\":\"0\"},{\"side\":\"bid\",\"event_time\":\"2026-08-26T12:13:49.742748Z\",\"price_level\":\"1.557\",\"new_quantity\":\"92.81\"},{\"side\":\"bid\",\"event_time\":\"2026-08-26T12:13:49.742748Z\",\"price_level\":\"1.5569\",\"new_quantity\":\"150.09\"},{\"side\":\"bid\",\"event_time\":\"2026-08-26T12:13:49.742748Z\",\"price_level\":\"1.5567\",\"new_quantity\":\"160.58\"},{\"side\":\"bid\",\"event_time\":\"2026-08-26T12:13:49.742748Z\",\"price_level\":\"1.5566\",\"new_quantity\":\"476.35\"},{\"side\":\"bid\",\"event_time\":\"2026-08-26T12:13:49.742748Z\",\"price_level\":\"1.5565\",\"new_quantity\":\"745.07\"},{\"side\":\"bid\",\"event_time\":\"2026-08-26T12:13:49.742748Z\",\"price_level\":\"1.5559\",\"new_quantity\":\"383.72\"},{\"side\":\"bid\",\"event_time\":\"2026-08-26T12:13:49.742748Z\",\"price_level\":\"1.555\",\"new_quantity\":\"643.07\"},{\"side\":\"bid\",\"event_time\":\"2026-08-26T12:13:49.742748Z\",\"price_level\":\"1.5547\",\"new_quantity\":\"0\"},{\"side\":\"bid\",\"event_time\":\"2026-08-26T12:13:49.742748Z\",\"price_level\":\"1.5545\",\"new_quantity\":\"5676.3\"},{\"side\":\"bid\",\"event_time\":\"2026-08-26T12:13:49.742748Z\",\"price_level\":\"1.5537\",\"new_quantity\":\"0\"},{\"side\":\"bid\",\"event_time\":\"2026-08-26T12:13:49.742748Z\",\"price_level\":\"1.5529\",\"new_quantity\":\"0\"},{\"side\":\"bid\",\"event_time\":\"2026-08-26T12:13:49.742748Z\",\"price_level\":\"1.5528\",\"new_quantity\":\"1787.83\"},{\"side\":\"bid\",\"event_time\":\"2026-08-26T12:13:49.742748Z\",\"price_level\":\"1.5522\",\"new_quantity\":\"0\"},{\"side\":\"bid\",\"event_time\":\"2026-08-26T12:13:49.742748Z\",\"price_level\":\"1.5513\",\"new_quantity\":\"284.63\"},{\"side\":\"bid\",\"event_time\":\"2026-08-26T12:13:49.742748Z\",\"price_level\":\"1.5491\",\"new_quantity\":\"4841.34\"},{\"side\":\"bid\",\"event_time\":\"2026-08-26T12:13:49.742748Z\",\"price_level\":\"1.5475\",\"new_quantity\":\"2351.16\"},{\"side\":\"bid\",\"event_time\":\"2026-08-26T12:13:49.742748Z\",\"price_level\":\"1.546\",\"new_quantity\":\"0\"},{\"side\":\"offer\",\"event_time\":\"2026-08-26T12:13:49.742748Z\",\"price_level\":\"1.5593\",\"new_quantity\":\"92.81\"},{\"side\":\"offer\",\"event_time\":\"2026-08-26T12:13:49.742748Z\",\"price_level\":\"1.5594\",\"new_quantity\":\"0\"},{\"side\":\"offer\",\"event_time\":\"2026-08-26T12:13:49.742748Z\",\"price_level\":\"1.5595\",\"new_quantity\":\"0\"},{\"side\":\"offer\",\"event_time\":\"2026-08-26T12:13:49.742748Z\",\"price_level\":\"1.5596\",\"new_quantity\":\"0\"},{\"side\":\"offer\",\"event_time\":\"2026-08-26T12:13:49.742748Z\",\"price_level\":\"1.5597\",\"new_quantity\":\"20.25\"},{\"side\":\"offer\",\"event_time\":\"2026-08-26T12:13:49.742748Z\",\"price_level\":\"1.5598\",\"new_quantity\":\"80.13\"},{\"side\":\"offer\",\"event_time\":\"2026-08-26T12:13:49.742748Z\",\"price_level\":\"1.5599\",\"new_quantity\":\"195.44\"},{\"side\":\"offer\",\"event_time\":\"2026-08-26T12:13:49.742748Z\",\"price_level\":\"1.5605\",\"new_quantity\":\"1002.46\"},{\"side\":\"offer\",\"event_time\":\"2026-08-26T12:13:49.742748Z\",\"price_level\":\"1.5607\",\"new_quantity\":\"240.28\"},{\"side\":\"offer\",\"event_time\":\"2026-08-26T12:13:49.742748Z\",\"price_level\":\"1.5611\",\"new_quantity\":\"92.81\"},{\"side\":\"offer\",\"event_time\":\"2026-08-26T12:13:49.742748Z\",\"price_level\":\"1.5614\",\"new_quantity\":\"5719.37\"},{\"side\":\"offer\",\"event_time\":\"2026-08-26T12:13:49.742748Z\",\"price_level\":\"1.5616\",\"new_quantity\":\"0\"},{\"side\":\"offer\",\"event_time\":\"2026-08-26T12:13:49.742748Z\",\"price_level\":\"1.5642\",\"new_quantity\":\"394.46\"},{\"side\":\"offer\",\"event_time\":\"2026-08-26T12:13:49.742748Z\",\"price_level\":\"1.5643\",\"new_quantity\":\"1921.06\"},{\"side\":\"offer\",\"event_time\":\"2026-08-26T12:13:49.742748Z\",\"price_level\":\"1.5644\",\"new_quantity\":\"0\"},{\"side\":\"offer\",\"event_time\":\"2026-08-26T12:13:49.742748Z\",\"price_level\":\"1.5645\",\"new_quantity\":\"0\"},{\"side\":\"offer\",\"event_time\":\"2026-08-26T12:13:49.742748Z\",\"price_level\":\"1.566\",\"new_quantity\":\"117.47\"},{\"side\":\"offer\",\"event_time\":\"2026-08-26T12:13:49.742748Z\",\"price_level\":\"1.5675\",\"new_quantity\":\"92.81\"},{\"side\":\"offer\",\"event_time\":\"2026-08-26T12:13:49.742748Z\",\"price_level\":\"1.5676\",\"new_quantity\":\"29.41\"},{\"side\":\"offer\",\"event_time\":\"2026-08-26T12:13:49.742748Z\",\"price_level\":\"1.5692\",\"new_quantity\":\"38.53\"}]}]}"}
{"recv_ts_ns": 1787746429974170054, "payload": "{\"channel\":\"l2_data\",\"timestamp\":\"2026-08-26T12:13:49.858872615Z\",\"sequence_num\":38,\"events\":[{\"type\":\"update\",\"product_id\":\"ATOM-USD\",\"updates\":[{\"side\":\"bid\",\"event_time\":\"2026-08-26T12:13:49.813016Z\",\"price_level\":\"1.5574\",\"new_quantity\":\"0\"},{\"side\":\"bid\",\"event_time\":\"2026-08-26T12:13:49.813016Z\",\"price_level\":\"1.5572\",\"new_quantity\":\"182.29\"},{\"side\":\"bid\",\"event_time\":\"2026-08-26T12:13:49.813016Z\",\"price_level\":\"1.5555\",\"new_quantity\":\"1222.19\"},{\"side\":\"bid\",\"event_time\":\"2026-08-26T12:13:49.813016Z\",\"price_level\":\"1.5554\",\"new_quantity\":\"1165.37\"},{\"side\":\"bid\",\"event_time\":\"2026-08-26T12:13:49.813016Z\",\"price_level\":\"1.5531\",\"new_quantity\":\"312.38\"},{\"side\":\"offer\",\"event_time\":\"2026-08-26T12:13:49.813016Z\",\"price_level\":\"1.5592\",\"new_quantity\":\"0\"}]}]}"}
{"recv_ts_ns": 1787746430002956960, "payload": "{\"channel\":\"heartbeats\",\"timestamp\":\"2026-08-26T12:13:49.887621303Z\",\"sequence_num\":39,\"events\":[{\"current_time\":\"2026-08-26 12:13:49.885211546 +0000 UTC m=+24611.287197579\",\"heartbeat_counter\":24611}]}"}
{"recv_ts_ns": 1787746430023340557, "payload": "{\"channel\":\"l2_data\",\"timestamp\":\"2026-08-26T12:13:49.909013545Z\",\"sequence_num\":40,\"events\":[{\"type\":\"update\",\"product_id\":\"ATOM-USD\",\"updates\":[{\"side\":\"bid\",\"event_time\":\"2026-08-26T12:13:49.836472Z\",\"price_level\":\"1.5553\",\"new_quantity\":\"2245.81\"},{\"side\":\"bid\",\"event_time\":\"2026-08-26T12:13:49.836472Z\",\"price_level\":\"1.55\",\"new_quantity\":\"1290.32\"}]}]}"}
{"recv_ts_ns": 1787746430098473965, "payload": "{\"channel\":\"l2_data\",\"timestamp\":\"2026-08-26T12:13:49.983102998Z\",\"sequence_num\":41,\"events\":[{\"type\":\"update\",\"product_id\":\"ATOM-USD\",\"updates\":[{\"side\":\"offer\",\"event_time\":\"2026-08-26T12:13:49.912085Z\",\"price_level\":\"1.5592\",\"new_quantity\":\"80.16\"}]}]}"}
{"recv_ts_ns": 1787746430176681439, "payload": "{\"channel\":\"l2_data\",\"timestamp\":\"2026-08-26T12:13:50.060781253Z\",\"sequence_num\":42,\"events\":[{\"type\":\"update\",\"product_id\":\"ATOM-USD\",\"updates\":[{\"side\":\"bid\",\"event_time\":\"2026-08-26T12:13:49.994353Z\",\"price_level\":\"1.5579\",\"new_quantity\":\"92.81\"},{\"side\":\"bid\",\"event_time\":\"2026-08-26T12:13:49.994353Z\",\"price_level\":\"1.5577\",\"new_quantity\":\"195.32\"},{\"side\":\"bid\",\"event_time\":\"2026-08-26T12:13:49.994353Z\",\"price_level\":\"1.5574\",\"new_quantity\":\"92.81\"},{\"side\":\"bid\",\"event_time\":\"2026-08-26T12:13:49.994353Z\",\"price_level\":\"1.5531\",\"new_quantity\":\"20.25\"},{\"side\":\"offer\",\"event_time\":\"2026-08-26T12:13:49.994353Z\",\"price_level\":\"1.5592\",\"new_quantity\":\"92.81\"},{\"side\":\"offer\",\"event_time\":\"2026-08-26T12:13:49.994353Z\",\"price_level\":\"1.5593\",\"new_quantity\":\"0\"},{\"side\":\"offer\",\"event_time\":\"2026-08-26T12:13:49.994353Z\",\"price_level\":\"1.5596\",\"new_quantity\":\"20.25\"},{\"side\":\"offer\",\"event_time\":\"2026-08-26T12:13:49.994353Z\",\"price_level\":\"1.5598\",\"new_quantity\":\"255.49\"},{\"side\":\"offer\",\"event_time\":\"2026-08-26T12:13:49.994353Z\",\"price_level\":\"1.5599\",\"new_quantity\":\"293.73\"},{\"side\":\"offer\",\"event_time\":\"2026-08-26T12:13:49.994353Z\",\"price_level\":\"1.5614\",\"new_quantity\":\"0\"},{\"side\":\"offer\",\"event_time\":\"2026-08-26T12:13:49.994353Z\",\"price_level\":\"1.5616\",\"new_quantity\":\"5718.64\"}]}]}"}
{"recv_ts_ns": 1787746430204482391, "payload": "{\"channel\":\"l2_data\",\"timestamp\":\"2026-08-26T12:13:50.088068676Z\",\"sequence_num\":43,\"events\":[{\"type\":\"update\",\"product_id\":\"ATOM-USD\",\"updates\":[{\"side\":\"bid\",\"event_time\":\"2026-08-26T12:13:50.018478Z\",\"price_level\":\"1.5574\",\"new_quantity\":\"113.06\"},{\"side\":\"bid\",\"event_time\":\"2026-08-26T12:13:50.018478Z\",\"price_level\":\"1.5558\",\"new_quantity\":\"663\"},{\"side\":\"bid\",\"event_time\":\"2026-08-26T12:13:50.018478Z\",\"price_level\":\"1.5462\",\"new_quantity\":\"20.25\"},{\"side\":\"offer\",\"event_time\":\"2026-08-26T12:13:50.018478Z\",\"price_level\":\"1.5602\",\"new_quantity\":\"497.5\"},{\"side\":\"offer\",\"event_time\":\"2026-08-26T12:13:50.018478Z\",\"price_level\":\"1.5608\",\"new_quantity\":\"92.81\"}]}]}"}
{"recv_ts_ns": 1787746430296725340, "payload": "{\"channel\":\"l2_data\",\"timestamp\":\"2026-08-26T12:13:50.182383389Z\",\"sequence_num\":44,\"events\":[{\"type\":\"update\",\"product_id\":\"ATOM-USD\",\"updates\":[{\"side\":\"bid\",\"event_time\":\"2026-08-26T12:13:50.154599Z\",\"price_level\":\"1.5574\",\"new_quantity\":\"92.81\"},{\"side\":\"bid\",\"event_time\":\"2026-08-26T12:13:50.154599Z\",\"price_level\":\"1.5462\",\"new_quantity\":\"0\"},{\"side\":\"offer\",\"event_time\":\"2026-08-26T12:13:50.154599Z\",\"price_level\":\"1.559\",\"new_quantity\":\"172.99\"},{\"side\":\"offer\",\"event_time\":\"2026-08-26T12:13:50.154599Z\",\"price_level\":\"1.5596\",\"new_quantity\":\"0\"},{\"side\":\"offer\",\"event_time\":\"2026-08-26T12:13:50.154599Z\",\"price_level\":\"1.5614\",\"new_quantity\":\"5719.37\"},{\"side\":\"offer\",\"event_time\":\"2026-08-26T12:13:50.154599Z\",\"price_level\":\"1.5616\",\"new_quantity\":\"0\"}]}]}"}
{"recv_ts_ns": 1787746430346849434, "payload": "{\"channel\":\"l2_data\",\"timestamp\":\"2026-08-26T12:13:50.232211074Z\",\"sequence_num\":45,\"events\":[{\"type\":\"update\",\"product_id\":\"ATOM-USD\",\"updates\":[{\"side\":\"bid\",\"event_time\":\"2026-08-26T12:13:50.17062Z\",\"price_level\":\"1.5577\",\"new_quantity\":\"160.48\"}]}]}"}
{"recv_ts_ns": 1787746430772978121, "payload": "{\"channel\":\"l2_data\",\"timestamp\":\"2026-08-26T12:13:50.657203658Z\",\"sequence_num\":46,\"events\":[{\"type\":\"update\",\"product_id\":\"ATOM-USD\",\"updates\":[{\"side\":\"bid\",\"event_time\":\"2026-08-26T12:13:50.59408Z\",\"price_level\":\"1.5573\",\"new_quantity\":\"20.25\"},{\"side\":\"bid\",\"event_time\":\"2026-08-26T12:13:50.59408Z\",\"price_level\":\"1.5461\",\"new_quantity\":\"20.25\"},{\"side\":\"offer\",\"event_time\":\"2026-08-26T12:13:50.59408Z\",\"price_level\":\"1.5596\",\"new_quantity\":\"20.25\"},{\"side\":\"offer\",\"event_time\":\"2026-08-26T12:13:50.59408Z\",\"price_level\":\"1.5676\",\"new_quantity\":\"49.66\"},{\"side\":\"offer\",\"event_time\":\"2026-08-26T12:13:50.59408Z\",\"price_level\":\"1.5692\",\"new_quantity\":\"58.78\"}]}]}"}
{"recv_ts_ns": 1787746430847209517, "payload": "{\"channel\":\"l2_data\",\"timestamp\":\"2026-08-26T12:13:50.732704217Z\",\"sequence_num\":47,\"events\":[{\"type\":\"update\",\"product_id\":\"ATOM-USD\",\"updates\":[{\"side\":\"bid\",\"event_time\":\"2026-08-26T12:13:50.686839Z\",\"price_level\":\"1.5579\",\"new_quantity\":\"92.81\"},{\"side\":\"bid\",\"event_time\":\"2026-08-26T12:13:50.686839Z\",\"price_level\":\"1.5578\",\"new_quantity\":\"160.47\"},{\"side\":\"bid\",\"event_time\":\"2026-08-26T12:13:50.686839Z\",\"price_level\":\"1.5577\",\"new_quantity\":\"0\"},{\"side\":\"bid\",\"event_time\":\"2026-08-26T12:13:50.686839Z\",\"price_level\":\"1.5575\",\"new_quantity\":\"20.25\"},{\"side\":\"bid\",\"event_time\":\"2026-08-26T12:13:50.686839Z\",\"price_level\":\"1.5574\",\"new_quantity\":\"126.65\"},{\"side\":\"bid\",\"event_time\":\"2026-08-26T12:13:50.686839Z\",\"price_level\":\"1.557\",\"new_quantity\":\"278.27\"},{\"side\":\"bid\",\"event_time\":\"2026-08-26T12:13:50.686839Z\",\"price_level\":\"1.5569\",\"new_quantity\":\"310.66\"},{\"side\":\"bid\",\"event_time\":\"2026-08-26T12:13:50.686839Z\",\"price_level\":\"1.5568\",\"new_quantity\":\"139.74\"},{\"side\":\"bid\",\"event_time\":\"2026-08-26T12:13:50.686839Z\",\"price_level\":\"1.5567\",\"new_quantity\":\"0\"},{\"side\":\"bid\",\"event_time\":\"2026-08-26T12:13:50.686839Z\",\"price_level\":\"1.5565\",\"new_quantity\":\"1184.44\"},{\"side\":\"bid\",\"event_time\":\"2026-08-26T12:13:50.686839Z\",\"price_level\":\"1.5564\",\"new_quantity\":\"735.96\"},{\"side\":\"bid\",\"event_time\":\"2026-08-26T12:13:50.686839Z\",\"price_level\":\"1.5558\",\"new_quantity\":\"642.75\"},{\"side\":\"bid\",\"event_time\":\"2026-08-26T12:13:50.686839Z\",\"price_level\":\"1.555\",\"new_quantity\":\"0\"},{\"side\":\"bid\",\"event_time\":\"2026-08-26T12:13:50.686839Z\",\"price_level\":\"1.5533\",\"new_quantity\":\"0\"},{\"side\":\"bid\",\"event_time\":\"2026-08-26T12:13:50.686839Z\",\"price_level\":\"1.5463\",\"new_quantity\":\"20.25\"},{\"side\":\"bid\",\"event_time\":\"2026-08-26T12:13:50.686839Z\",\"price_level\":\"1.5461\",\"new_quantity\":\"0\"},{\"side\":\"offer\",\"event_time\":\"2026-08-26T12:13:50.686839Z\",\"price_level\":\"1.559\",\"new_quantity\":\"0\"},{\"side\":\"offer\",\"event_time\":\"2026-08-26T12:13:50.686839Z\",\"price_level\":\"1.5592\",\"new_quantity\":\"172.98\"},{\"side\":\"offer\",\"event_time\":\"2026-08-26T12:13:50.686839Z\",\"price_level\":\"1.5596\",\"new_quantity\":\"0\"},{\"side\":\"offer\",\"event_time\":\"2026-08-26T12:13:50.686839Z\",\"price_level\":\"1.5597\",\"new_quantity\":\"0\"},{\"side\":\"offer\",\"event_time\":\"2026-08-26T12:13:50.686839Z\",\"price_level\":\"1.5612\",\"new_quantity\":\"5720.81\"},{\"side\":\"offer\",\"event_time\":\"2026-08-26T12:13:50.686839Z\",\"price_level\":\"1.5613\",\"new_quantity\":\"353.24\"},{\"side\":\"offer\",\"event_time\":\"2026-08-26T12:13:50.686839Z\",\"price_level\":\"1.5614\",\"new_quantity\":\"0\"},{\"side\":\"offer\",\"event_time\":\"2026-08-26T12:13:50.686839Z\",\"price_level\":\"1.5621\",\"new_quantity\":\"613.84\"},{\"side\":\"offer\",\"event_time\":\"2026-08-26T12:13:50.686839Z\",\"price_level\":\"1.5629\",\"new_quantity\":\"20.25\"},{\"side\":\"offer\",\"event_time\":\"2026-08-26T12:13:50.686839Z\",\"price_level\":\"1.5676\",\"new_quantity\":\"29.41\"},{\"side\":\"offer\",\"event_time\":\"2026-08-26T12:13:50.686839Z\",\"price_level\":\"1.5677\",\"new_quantity\":\"20.25\"},{\"side\":\"offer\",\"event_time\":\"2026-08-26T12:13:50.686839Z\",\"price_level\":\"1.5692\",\"new_quantity\":\"38.53\"},{\"side\":\"offer\",\"event_time\":\"2026-08-26T12:13:50.686839Z\",\"price_level\":\"1.5693\",\"new_quantity\":\"139.06\"},{\"side\":\"offer\",\"event_time\":\"2026-08-26T12:13:50.686839Z\",\"price_level\":\"1.5694\",\"new_quantity\":\"16.91\"}]}]}"}
{"recv_ts_ns": 1787746431002897217, "payload": "{\"channel\":\"heartbeats\",\"timestamp\":\"2026-08-26T12:13:50.88711061Z\",\"sequence_num\":48,\"events\":[{\"current_time\":\"2026-08-26 12:13:50.885192407 +0000 UTC m=+24612.287178438\",\"heartbeat_counter\":24612}]}"}
{"recv_ts_ns": 1787746431999083626, "payload": "{\"channel\":\"l2_data\",\"timestamp\":\"2026-08-26T12:13:51.883263081Z\",\"sequence_num\":49,\"events\":[{\"type\":\"update\",\"product_id\":\"ATOM-USD\",\"updates\":[{\"side\":\"bid\",\"event_time\":\"2026-08-26T12:13:51.859804Z\",\"price_level\":\"1.558\",\"new_quantity\":\"151.21\"},{\"side\":\"bid\",\"event_time\":\"2026-08-26T12:13:51.859804Z\",\"price_level\":\"1.5579\",\"new_quantity\":\"253.28\"},{\"side\":\"bid\",\"event_time\":\"2026-08-26T12:13:51.859804Z\",\"price_level\":\"1.5578\",\"new_quantity\":\"0\"},{\"side\":\"bid\",\"event_time\":\"2026-08-26T12:13:51.859804Z\",\"price_level\":\"1.5569\",\"new_quantity\":\"357.59\"},{\"side\":\"bid\",\"event_time\":\"2026-08-26T12:13:51.859804Z\",\"price_level\":\"1.5568\",\"new_quantity\":\"92.81\"},{\"side\":\"bid\",\"event_time\":\"2026-08-26T12:13:51.859804Z\",\"price_level\":\"1.5533\",\"new_quantity\":\"261.62\"},{\"side\":\"offer\",\"event_time\":\"2026-08-26T12:13:51.859804Z\",\"price_level\":\"1.5601\",\"new_quantity\":\"431.88\"},{\"side\":\"offer\",\"event_time\":\"2026-08-26T12:13:51.859804Z\",\"price_level\":\"1.5602\",\"new_quantity\":\"1018.53\"},{\"side\":\"offer\",\"event_time\":\"2026-08-26T12:13:51.859804Z\",\"price_level\":\"1.5605\",\"new_quantity\":\"670.31\"},{\"side\":\"offer\",\"event_time\":\"2026-08-26T12:13:51.859804Z\",\"price_level\":\"1.5606\",\"new_quantity\":\"664.48\"},{\"side\":\"offer\",\"event_time\":\"2026-08-26T12:13:51.859804Z\",\"price_level\":\"1.5612\",\"new_quantity\":\"0.71\"},{\"side\":\"offer\",\"event_time\":\"2026-08-26T12:13:51.859804Z\",\"price_level\":\"1.5614\",\"new_quantity\":\"5719.37\"}]}]}"}
{"recv_ts_ns": 1787746432005555935, "payload": "{\"channel\":\"heartbeats\",\"timestamp\":\"2026-08-26T12:13:51.890514877Z\",\"sequence_num\":50,\"events\":[{\"current_time\":\"2026-08-26 12:13:51.885448884 +0000 UTC m=+24613.287434916\",\"heartbeat_counter\":24613}]}"}
{"recv_ts_ns": 1787746432231857969, "payload": "{\"channel\":\"l2_data\",\"timestamp\":\"2026-08-26T12:13:52.117947164Z\",\"sequence_num\":51,\"events\":[{\"type\":\"update\",\"product_id\":\"ATOM-USD\",\"updates\":[{\"side\":\"bid\",\"event_time\":\"2026-08-26T12:13:52.045331Z\",\"price_level\":\"1.5241\",\"new_quantity\":\"0\"},{\"side\":\"bid\",\"event_time\":\"2026-08-26T12:13:52.045331Z\",\"price_level\":\"1.5157\",\"new_quantity\":\"0\"},{\"side\":\"bid\",\"event_time\":\"2026-08-26T12:13:52.045331Z\",\"price_level\":\"1.5073\",\"new_quantity\":\"0\"},{\"side\":\"offer\",\"event_time\":\"2026-08-26T12:13:52.045331Z\",\"price_level\":\"1.5606\",\"new_quantity\":\"521.03\"},{\"side\":\"offer\",\"event_time\":\"2026-08-26T12:13:52.045331Z\",\"price_level\":\"1.5614\",\"new_quantity\":\"0\"},{\"side\":\"offer\",\"event_time\":\"2026-08-26T12:13:52.045331Z\",\"price_level\":\"1.5616\",\"new_quantity\":\"5718.64\"}]}]}"}
{"recv_ts_ns": 1787746432339046972, "payload": "{\"channel\":\"l2_data\",\"timestamp\":\"2026-08-26T12:13:52.224629861Z\",\"sequence_num\":52,\"events\":[{\"type\":\"update\",\"product_id\":\"ATOM-USD\",\"updates\":[{\"side\":\"offer\",\"event_time\":\"2026-08-26T12:13:52.085158Z\",\"price_level\":\"1.5598\",\"new_quantity\":\"175.36\"}]}]}"}
{"recv_ts_ns": 1787746432356809537, "payload": "{\"channel\":\"l2_data\",\"timestamp\":\"2026-08-26T12:13:52.242788957Z\",\"sequence_num\":53,\"events\":[{\"type\":\"update\",\"product_id\":\"ATOM-USD\",\"updates\":[{\"side\":\"offer\",\"event_time\":\"2026-08-26T12:13:52.109496Z\",\"price_level\":\"1.5602\",\"new_quantity\":\"1098.65\"}]}]}"}
{"recv_ts_ns": 1787746432435714338, "payload": "{\"channel\":\"l2_data\",\"timestamp\":\"2026-08-26T12:13:52.320836049Z\",\"sequence_num\":54,\"events\":[{\"type\":\"update\",\"product_id\":\"ATOM-USD\",\"updates\":[{\"side\":\"bid\",\"event_time\":\"2026-08-26T12:13:52.249847Z\",\"price_level\":\"1.556\",\"new_quantity\":\"0\"}]}]}"}
{"recv_ts_ns": 1787746432465586705, "payload": "{\"channel\":\"l2_data\",\"timestamp\":\"2026-08-26T12:13:52.351274987Z\",\"sequence_num\":55,\"events\":[{\"type\":\"update\",\"product_id\":\"ATOM-USD\",\"updates\":[{\"side\":\"bid\",\"event_time\":\"2026-08-26T12:13:52.263861Z\",\"price_level\":\"1.5581\",\"new_quantity\":\"92.81\"},{\"side\":\"bid\",\"event_time\":\"2026-08-26T12:13:52.263861Z\",\"price_level\":\"1.5576\",\"new_quantity\":\"20.25\"},{\"side\":\"bid\",\"event_time\":\"2026-08-26T12:13:52.263861Z\",\"price_level\":\"1.5573\",\"new_quantity\":\"0\"},{\"side\":\"bid\",\"event_time\":\"2026-08-26T12:13:52.263861Z\",\"price_level\":\"1.548\",\"new_quantity\":\"20.97\"},{\"side\":\"bid\",\"event_time\":\"2026-08-26T12:13:52.263861Z\",\"price_level\":\"1.5479\",\"new_quantity\":\"0\"},{\"side\":\"bid\",\"event_time\":\"2026-08-26T12:13:52.263861Z\",\"price_level\":\"1.5463\",\"new_quantity\":\"0\"}]}]}"}
{"recv_ts_ns": 1787746432848773593, "payload": "{\"channel\":\"l2_data\",\"timestamp\":\"2026-08-26T12:13:52.733353841Z\",\"sequence_num\":56,\"events\":[{\"type\":\"update\",\"product_id\":\"ATOM-USD\",\"updates\":[{\"side\":\"bid\",\"event_time\":\"2026-08-26T12:13:52.683837Z\",\"price_level\":\"1.5305\",\"new_quantity\":\"17.71\"},{\"side\":\"bid\",\"event_time\":\"2026-08-26T12:13:52.683837Z\",\"price_level\":\"1.5237\",\"new_quantity\":\"22.24\"},{\"side\":\"bid\",\"event_time\":\"2026-08-26T12:13:52.683837Z\",\"price_level\":\"1.5169\",\"new_quantity\":\"26.81\"}]}]}"}
{"recv_ts_ns": 1787746433004710183, "payload": "{\"channel\":\"heartbeats\",\"timestamp\":\"2026-08-26T12:13:52.889485204Z\",\"sequence_num\":57,\"events\":[{\"current_time\":\"2026-08-26 12:13:52.88530432 +0000 UTC m=+24614.287290351\",\"heartbeat_counter\":24614}]}"}
{"recv_ts_ns": 1787746433047380022, "payload": "{\"channel\":\"l2_data\",\"timestamp\":\"2026-08-26T12:13:52.932148427Z\",\"sequence_num\":58,\"events\":[{\"type\":\"update\",\"product_id\":\"ATOM-USD\",\"updates\":[{\"side\":\"bid\",\"event_time\":\"2026-08-26T12:13:52.918725Z\",\"price_level\":\"1.5581\",\"new_quantity\":\"0\"}]}]}"}
{"recv_ts_ns": 1787746433096679974, "payload": "{\"channel\":\"l2_data\",\"timestamp\":\"2026-08-26T12:13:52.982357592Z\",\"sequence_num\":59,\"events\":[{\"type\":\"update\",\"product_id\":\"ATOM-USD\",\"updates\":[{\"side\":\"bid\",\"event_time\":\"2026-08-26T12:13:52.930223Z\",\"price_level\":\"1.5576\",\"new_quantity\":\"0\"},{\"side\":\"bid\",\"event_time\":\"2026-08-26T12:13:52.930223Z\",\"price_level\":\"1.5533\",\"new_quantity\":\"0\"},{\"side\":\"bid\",\"event_time\":\"2026-08-26T12:13:52.930223Z\",\"price_level\":\"1.5464\",\"new_quantity\":\"20.25\"}]}]}"}
{"recv_ts_ns": 1787746433146568547, "payload": "{\"channel\":\"l2_data\",\"timestamp\":\"2026-08-26T12:13:53.032092139Z\",\"sequence_num\":60,\"events\":[{\"type\":\"update\",\"product_id\":\"ATOM-USD\",\"updates\":[{\"side\":\"bid\",\"event_time\":\"2026-08-26T12:13:52.986209Z\",\"price_level\":\"1.5334\",\"new_quantity\":\"0\"}]}]}"}
{"recv_ts_ns": 1787746433349028473, "payload": "{\"channel\":\"l2_data\",\"timestamp\":\"2026-08-26T12:13:53.232641724Z\",\"sequence_num\":61,\"events\":[{\"type\":\"update\",\"product_id\":\"ATOM-USD\",\"updates\":[{\"side\":\"bid\",\"event_time\":\"2026-08-26T12:13:53.214365Z\",\"price_level\":\"1.5333\",\"new_quantity\":\"772.37\"}]}]}"}
{"recv_ts_ns": 1787746434003724905, "payload": "{\"channel\":\"heartbeats\",\"timestamp\":\"2026-08-26T12:13:53.888689569Z\",\"sequence_num\":62,\"events\":[{\"current_time\":\"2026-08-26 12:13:53.885669727 +0000 UTC m=+24615.287655758\",\"heartbeat_counter\":24615}]}"}
{"recv_ts_ns": 1787746434504149319, "payload": "{\"channel\":\"l2_data\",\"timestamp\":\"2026-08-26T12:13:54.382170069Z\",\"sequence_num\":63,\"events\":[{\"type\":\"update\",\"product_id\":\"ATOM-USD\",\"updates\":[{\"side\":\"bid\",\"event_time\":\"2026-08-26T12:13:54.350129Z\",\"price_level\":\"1.5236\",\"new_quantity\":\"17.77\"},{\"side\":\"bid\",\"event_time\":\"2026-08-26T12:13:54.350129Z\",\"price_level\":\"1.515\",\"new_quantity\":\"24.84\"},{\"side\":\"bid\",\"event_time\":\"2026-08-26T12:13:54.350129Z\",\"price_level\":\"1.5065\",\"new_quantity\":\"26.96\"}]}]}"}
{"recv_ts_ns": 1787746434596116532, "payload": "{\"channel\":\"l2_data\",\"timestamp\":\"2026-08-26T12:13:54.482090935Z\",\"sequence_num\":64,\"events\":[{\"type\":\"update\",\"product_id\":\"ATOM-USD\",\"updates\":[{\"side\":\"bid\",\"event_time\":\"2026-08-26T12:13:54.451033Z\",\"price_level\":\"1.5559\",\"new_quantity\":\"403.97\"}]}]}"}
{"recv_ts_ns": 1787746434649398335, "payload": "{\"channel\":\"l2_data\",\"timestamp\":\"2026-08-26T12:13:54.532944354Z\",\"sequence_num\":65,\"events\":[{\"type\":\"update\",\"product_id\":\"ATOM-USD\",\"updates\":[{\"side\":\"offer\",\"event_time\":\"2026-08-26T12:13:54.46499Z\",\"price_level\":\"1.5597\",\"new_quantity\":\"20.25\"}]}]}"}
{"recv_ts_ns": 1787746434719221201, "payload": "{\"channel\":\"l2_data\",\"timestamp\":\"2026-08-26T12:13:54.604413995Z\",\"sequence_num\":66,\"events\":[{\"type\":\"update\",\"product_id\":\"ATOM-USD\",\"updates\":[{\"side\":\"bid\",\"event_time\":\"2026-08-26T12:13:54.545628Z\",\"price_level\":\"1.558\",\"new_quantity\":\"0\"}]}]}"}
{"recv_ts_ns": 1787746434804687294, "payload": "{\"channel\":\"l2_data\",\"timestamp\":\"2026-08-26T12:13:54.685423523Z\",\"sequence_num\":67,\"events\":[{\"type\":\"update\",\"product_id\":\"ATOM-USD\",\"updates\":[{\"side\":\"bid\",\"event_time\":\"2026-08-26T12:13:54.594808Z\",\"price_level\":\"1.5579\",\"new_quantity\":\"160.47\"},{\"side\":\"bid\",\"event_time\":\"2026-08-26T12:13:54.594808Z\",\"price_level\":\"1.5575\",\"new_quantity\":\"0\"},{\"side\":\"bid\",\"event_time\":\"2026-08-26T12:13:54.594808Z\",\"price_level\":\"1.5572\",\"new_quantity\":\"202.54\"},{\"side\":\"bid\",\"event_time\":\"2026-08-26T12:13:54.594808Z\",\"price_level\":\"1.557\",\"new_quantity\":\"325.2\"},{\"side\":\"bid\",\"event_time\":\"2026-08-26T12:13:54.594808Z\",\"price_level\":\"1.5569\",\"new_quantity\":\"310.66\"},{\"side\":\"bid\",\"event_time\":\"2026-08-26T12:13:54.594808Z\",\"price_level\":\"1.5565\",\"new_quantity\":\"1081.81\"},{\"side\":\"bid\",\"event_time\":\"2026-08-26T12:13:54.594808Z\",\"price_level\":\"1.5464\",\"new_quantity\":\"0\"},{\"side\":\"offer\",\"event_time\":\"2026-08-26T12:13:54.594808Z\",\"price_level\":\"1.5591\",\"new_quantity\":\"320.47\"},{\"side\":\"offer\",\"event_time\":\"2026-08-26T12:13:54.594808Z\",\"price_level\":\"1.5596\",\"new_quantity\":\"20.25\"},{\"side\":\"offer\",\"event_time\":\"2026-08-26T12:13:54.594808Z\",\"price_level\":\"1.5601\",\"new_quantity\":\"478.81\"},{\"side\":\"offer\",\"event_time\":\"2026-08-26T12:13:54.594808Z\",\"price_level\":\"1.5602\",\"new_quantity\":\"971.6\"},{\"side\":\"offer\",\"event_time\":\"2026-08-26T12:13:54.594808Z\",\"price_level\":\"1.5614\",\"new_quantity\":\"5719.37\"},{\"side\":\"offer\",\"event_time\":\"2026-08-26T12:13:54.594808Z\",\"price_level\":\"1.5616\",\"new_quantity\":\"0\"},{\"side\":\"offer\",\"event_time\":\"2026-08-26T12:13:54.594808Z\",\"price_level\":\"1.5642\",\"new_quantity\":\"374.21\"},{\"side\":\"offer\",\"event_time\":\"2026-08-26T12:13:54.594808Z\",\"price_level\":\"1.5676\",\"new_quantity\":\"49.66\"},{\"side\":\"offer\",\"event_time\":\"2026-08-26T12:13:54.594808Z\",\"price_level\":\"1.5677\",\"new_quantity\":\"0\"},{\"side\":\"offer\",\"event_time\":\"2026-08-26T12:13:54.594808Z\",\"price_level\":\"1.5693\",\"new_quantity\":\"118.81\"}]}]}"}
{"recv_ts_ns": 1787746434878932025, "payload": "{\"channel\":\"l2_data\",\"timestamp\":\"2026-08-26T12:13:54.76174765Z\",\"sequence_num\":68,\"events\":[{\"type\":\"update\",\"product_id\":\"ATOM-USD\",\"updates\":[{\"side\":\"bid\",\"event_time\":\"2026-08-26T12:13:54.62193Z\",\"price_level\":\"1.5579\",\"new_quantity\":\"0\"},{\"side\":\"bid\",\"event_time\":\"2026-08-26T12:13:54.62193Z\",\"price_level\":\"1.5574\",\"new_quantity\":\"33.84\"},{\"side\":\"bid\",\"event_time\":\"2026-08-26T12:13:54.62193Z\",\"price_level\":\"1.557\",\"new_quantity\":\"278.27\"},{\"side\":\"bid\",\"event_time\":\"2026-08-26T12:13:54.62193Z\",\"price_level\":\"1.556\",\"new_quantity\":\"92.81\"},{\"side\":\"offer\",\"event_time\":\"2026-08-26T12:13:54.62193Z\",\"price_level\":\"1.5592\",\"new_quantity\":\"113.06\"},{\"side\":\"offer\",\"event_time\":\"2026-08-26T12:13:54.62193Z\",\"price_level\":\"1.5597\",\"new_quantity\":\"0\"},{\"side\":\"offer\",\"event_time\":\"2026-08-26T12:13:54.62193Z\",\"price_level\":\"1.5601\",\"new_quantity\":\"478.81\"},{\"side\":\"offer\",\"event_time\":\"2026-08-26T12:13:54.62193Z\",\"price_level\":\"1.5657\",\"new_quantity\":\"20.25\"},{\"side\":\"offer\",\"event_time\":\"2026-08-26T12:13:54.62193Z\",\"price_level\":\"1.5676\",\"new_quantity\":\"29.41\"}]}]}"}
{"recv_ts_ns": 1787746434971928532, "payload": "{\"channel\":\"l2_data\",\"timestamp\":\"2026-08-26T12:13:54.854919755Z\",\"sequence_num\":69,\"events\":[{\"type\":\"update\",\"product_id\":\"ATOM-USD\",\"updates\":[{\"side\":\"bid\",\"event_time\":\"2026-08-26T12:13:54.687763Z\",\"price_level\":\"1.5573\",\"new_quantity\":\"92.81\"},{\"side\":\"bid\",\"event_time\":\"2026-08-26T12:13:54.687763Z\",\"price_level\":\"1.5572\",\"new_quantity\":\"89.48\"},{\"side\":\"bid\",\"event_time\":\"2026-08-26T12:13:54.687763Z\",\"price_level\":\"1.5571\",\"new_quantity\":\"0\"},{\"side\":\"bid\",\"event_time\":\"2026-08-26T12:13:54.687763Z\",\"price_level\":\"1.5569\",\"new_quantity\":\"150.09\"},{\"side\":\"bid\",\"event_time\":\"2026-08-26T12:13:54.687763Z\",\"price_level\":\"1.5568\",\"new_quantity\":\"113.06\"},{\"side\":\"bid\",\"event_time\":\"2026-08-26T12:13:54.687763Z\",\"price_level\":\"1.5565\",\"new_quantity\":\"439.37\"},{\"side\":\"bid\",\"event_time\":\"2026-08-26T12:13:54.687763Z\",\"price_level\":\"1.5558\",\"new_quantity\":\"735.56\"},{\"side\":\"bid\",\"event_time\":\"2026-08-26T12:13:54.687763Z\",\"price_level\":\"1.5553\",\"new_quantity\":\"1924.33\"},{\"side\":\"bid\",\"event_time\":\"2026-08-26T12:13:54.687763Z\",\"price_level\":\"1.5552\",\"new_quantity\":\"989.13\"},{\"side\":\"bid\",\"event_time\":\"2026-08-26T12:13:54.687763Z\",\"price_level\":\"1.555\",\"new_quantity\":\"321.54\"},{\"side\":\"bid\",\"event_time\":\"2026-08-26T12:13:54.687763Z\",\"price_level\":\"1.5533\",\"new_quantity\":\"267.07\"},{\"side\":\"bid\",\"event_time\":\"2026-08-26T12:13:54.687763Z\",\"price_level\":\"1.548\",\"new_quantity\":\"0.72\"},{\"side\":\"bid\",\"event_time\":\"2026-08-26T12:13:54.687763Z\",\"price_level\":\"1.5475\",\"new_quantity\":\"2351.16\"},{\"side\":\"bid\",\"event_time\":\"2026-08-26T12:13:54.687763Z\",\"price_level\":\"1.5474\",\"new_quantity\":\"0\"},{\"side\":\"offer\",\"event_time\":\"2026-08-26T12:13:54.687763Z\",\"price_level\":\"1.559\",\"new_quantity\":\"191.32\"},{\"side\":\"offer\",\"event_time\":\"2026-08-26T12:13:54.687763Z\",\"price_level\":\"1.5591\",\"new_quantity\":\"340.72\"},{\"side\":\"offer\",\"event_time\":\"2026-08-26T12:13:54.687763Z\",\"price_level\":\"1.5592\",\"new_quantity\":\"92.81\"},{\"side\":\"offer\",\"event_time\":\"2026-08-26T12:13:54.687763Z\",\"price_level\":\"1.5596\",\"new_quantity\":\"0\"},{\"side\":\"offer\",\"event_time\":\"2026-08-26T12:13:54.687763Z\",\"price_level\":\"1.56\",\"new_quantity\":\"131.26\"},{\"side\":\"offer\",\"event_time\":\"2026-08-26T12:13:54.687763Z\",\"price_level\":\"1.5655\",\"new_quantity\":\"113.06\"},{\"side\":\"offer\",\"event_time\":\"2026-08-26T12:13:54.687763Z\",\"price_level\":\"1.5656\",\"new_quantity\":\"1941.31\"},{\"side\":\"offer\",\"event_time\":\"2026-08-26T12:13:54.687763Z\",\"price_level\":\"1.5657\",\"new_quantity\":\"0\"},{\"side\":\"offer\",\"event_time\":\"2026-08-26T12:13:54.687763Z\",\"price_level\":\"1.566\",\"new_quantity\":\"97.22\"}]}]}"}
{"recv_ts_ns": 1787746435007912117, "payload": "{\"channel\":\"heartbeats\",\"timestamp\":\"2026-08-26T12:13:54.885368492Z\",\"sequence_num\":70,\"events\":[{\"current_time\":\"2026-08-26 12:13:54.885186717 +0000 UTC m=+24616.287172748\",\"heartbeat_counter\":24616}]}"}
{"recv_ts_ns": 1787746435014911354, "payload": "{\"channel\":\"l2_data\",\"timestamp\":\"2026-08-26T12:13:54.90055677Z\",\"sequence_num\":71,\"events\":[{\"type\":\"update\",\"product_id\":\"ATOM-USD\",\"updates\":[{\"side\":\"bid\",\"event_time\":\"2026-08-26T12:13:54.720824Z\",\"price_level\":\"1.5574\",\"new_quantity\":\"126.65\"},{\"side\":\"bid\",\"event_time\":\"2026-08-26T12:13:54.720824Z\",\"price_level\":\"1.5573\",\"new_quantity\":\"0\"},{\"side\":\"bid\",\"event_time\":\"2026-08-26T12:13:54.720824Z\",\"price_level\":\"1.557\",\"new_quantity\":\"92.81\"},{\"side\":\"bid\",\"event_time\":\"2026-08-26T12:13:54.720824Z\",\"price_level\":\"1.5569\",\"new_quantity\":\"170.34\"},{\"side\":\"bid\",\"event_time\":\"2026-08-26T12:13:54.720824Z\",\"price_level\":\"1.5568\",\"new_quantity\":\"92.81\"},{\"side\":\"bid\",\"event_time\":\"2026-08-26T12:13:54.720824Z\",\"price_level\":\"1.5559\",\"new_quantity\":\"383.72\"},{\"side\":\"bid\",\"event_time\":\"2026-08-26T12:13:54.720824Z\",\"price_level\":\"1.5553\",\"new_quantity\":\"1944.58\"},{\"side\":\"offer\",\"event_time\":\"2026-08-26T12:13:54.720824Z\",\"price_level\":\"1.5591\",\"new_quantity\":\"320.47\"},{\"side\":\"offer\",\"event_time\":\"2026-08-26T12:13:54.720824Z\",\"price_level\":\"1.56\",\"new_quantity\":\"0\"},{\"side\":\"offer\",\"event_time\":\"2026-08-26T12:13:54.720824Z\",\"price_level\":\"1.5607\",\"new_quantity\":\"260.53\"},{\"side\":\"offer\",\"event_time\":\"2026-08-26T12:13:54.720824Z\",\"price_level\":\"1.5656\",\"new_quantity\":\"1921.06\"},{\"side\":\"offer\",\"event_time\":\"2026-08-26T12:13:54.720824Z\",\"price_level\":\"1.5671\",\"new_quantity\":\"2506.14\"}]}]}"}
{"recv_ts_ns": 1787746435079733233, "payload": "{\"channel\":\"l2_data\",\"timestamp\":\"2026-08-26T12:13:54.949521458Z\",\"sequence_num\":72,\"events\":[{\"type\":\"update\",\"product_id\":\"ATOM-USD\",\"updates\":[{\"side\":\"bid\",\"event_time\":\"2026-08-26T12:13:54.781097Z\",\"price_level\":\"1.5574\",\"new_quantity\":\"126.65\"},{\"side\":\"bid\",\"event_time\":\"2026-08-26T12:13:54.781097Z\",\"price_level\":\"1.5572\",\"new_quantity\":\"92.81\"},{\"side\":\"bid\",\"event_time\":\"2026-08-26T12:13:54.781097Z\",\"price_level\":\"1.5569\",\"new_quantity\":\"237.33\"},{\"side\":\"bid\",\"event_time\":\"2026-08-26T12:13:54.781097Z\",\"price_level\":\"1.5567\",\"new_quantity\":\"20.25\"},{\"side\":\"bid\",\"event_time\":\"2026-08-26T12:13:54.781097Z\",\"price_level\":\"1.5566\",\"new_quantity\":\"92.81\"},{\"side\":\"bid\",\"event_time\":\"2026-08-26T12:13:54.781097Z\",\"price_level\":\"1.5565\",\"new_quantity\":\"439.37\"},{\"side\":\"bid\",\"event_time\":\"2026-08-26T12:13:54.781097Z\",\"price_level\":\"1.5564\",\"new_quantity\":\"93.52\"},{\"side\":\"bid\",\"event_time\":\"2026-08-26T12:13:54.781097Z\",\"price_level\":\"1.5561\",\"new_quantity\":\"0\"},{\"side\":\"bid\",\"event_time\":\"2026-08-26T12:13:54.781097Z\",\"price_level\":\"1.5553\",\"new_quantity\":\"1233.43\"},{\"side\":\"bid\",\"event_time\":\"2026-08-26T12:13:54.781097Z\",\"price_level\":\"1.5551\",\"new_quantity\":\"20.25\"},{\"side\":\"bid\",\"event_time\":\"2026-08-26T12:13:54.781097Z\",\"price_level\":\"1.555\",\"new_quantity\":\"341.79\"},{\"side\":\"bid\",\"event_time\":\"2026-08-26T12:13:54.781097Z\",\"price_level\":\"1.5549\",\"new_quantity\":\"643.11\"},{\"side\":\"bid\",\"event_time\":\"2026-08-26T12:13:54.781097Z\",\"price_level\":\"1.5546\",\"new_quantity\":\"0\"},{\"side\":\"bid\",\"event_time\":\"2026-08-26T12:13:54.781097Z\",\"price_level\":\"1.5545\",\"new_quantity\":\"0\"},{\"side\":\"bid\",\"event_time\":\"2026-08-26T12:13:54.781097Z\",\"price_level\":\"1.5543\",\"new_quantity\":\"5677.03\"},{\"side\":\"bid\",\"event_time\":\"2026-08-26T12:13:54.781097Z\",\"price_level\":\"1.5533\",\"new_quantity\":\"0\"},{\"side\":\"bid\",\"event_time\":\"2026-08-26T12:13:54.781097Z\",\"price_level\":\"1.5518\",\"new_quantity\":\"0\"},{\"side\":\"bid\",\"event_time\":\"2026-08-26T12:13:54.781097Z\",\"price_level\":\"1.5502\",\"new_quantity\":\"20.25\"},{\"side\":\"bid\",\"event_time\":\"2026-08-26T12:13:54.781097Z\",\"price_level\":\"1.5499\",\"new_quantity\":\"5880.2\"},{\"side\":\"bid\",\"event_time\":\"2026-08-26T12:13:54.781097Z\",\"price_level\":\"1.5472\",\"new_quantity\":\"0\"},{\"side\":\"offer\",\"event_time\":\"2026-08-26T12:13:54.781097Z\",\"price_level\":\"1.5589\",\"new_quantity\":\"312.86\"},{\"side\":\"offer\",\"event_time\":\"2026-08-26T12:13:54.781097Z\",\"price_level\":\"1.559\",\"new_quantity\":\"191.32\"},{\"side\":\"offer\",\"event_time\":\"2026-08-26T12:13:54.781097Z\",\"price_level\":\"1.5591\",\"new_quantity\":\"0\"},{\"side\":\"offer\",\"event_time\":\"2026-08-26T12:13:54.781097Z\",\"price_level\":\"1.5592\",\"new_quantity\":\"129.28\"},{\"side\":\"offer\",\"event_time\":\"2026-08-26T12:13:54.781097Z\",\"price_level\":\"1.5605\",\"new_quantity\":\"413.22\"},{\"side\":\"offer\",\"event_time\":\"2026-08-26T12:13:54.781097Z\",\"price_level\":\"1.5606\",\"new_quantity\":\"541.28\"},{\"side\":\"offer\",\"event_time\":\"2026-08-26T12:13:54.781097Z\",\"price_level\":\"1.5607\",\"new_quantity\":\"20.25\"},{\"side\":\"offer\",\"event_time\":\"2026-08-26T12:13:54.781097Z\",\"price_level\":\"1.561\",\"new_quantity\":\"7641.9\"},{\"side\":\"offer\",\"event_time\":\"2026-08-26T12:13:54.781097Z\",\"price_level\":\"1.5613\",\"new_quantity\":\"92.81\"},{\"side\":\"offer\",\"event_time\":\"2026-08-26T12:13:54.781097Z\",\"price_level\":\"1.5614\",\"new_quantity\":\"0\"},{\"side\":\"offer\",\"event_time\":\"2026-08-26T12:13:54.781097Z\",\"price_level\":\"1.5654\",\"new_quantity\":\"20.25\"},{\"side\":\"offer\",\"event_time\":\"2026-08-26T12:13:54.781097Z\",\"price_level\":\"1.5671\",\"new_quantity\":\"2485.89\"},{\"side\":\"offer\",\"event_time\":\"2026-08-26T12:13:54.781097Z\",\"price_level\":\"1.5686\",\"new_quantity\":\"2411\"},{\"side\":\"offer\",\"event_time\":\"2026-08-26T12:13:54.781097Z\",\"price_level\":\"1.5687\",\"new_quantity\":\"0\"}]}]}"}
{"recv_ts_ns": 1787746435129117290, "payload": "{\"channel\":\"l2_data\",\"timestamp\":\"2026-08-26T12:13:55.003873432Z\",\"sequence_num\":73,\"events\":[{\"type\":\"update\",\"product_id\":\"ATOM-USD\",\"updates\":[{\"side\":\"bid\",\"event_time\":\"2026-08-26T12:13:54.889476Z\",\"price_level\":\"1.5574\",\"new_quantity\":\"33.84\"},{\"side\":\"bid\",\"event_time\":\"2026-08-26T12:13:54.889476Z\",\"price_level\":\"1.5568\",\"new_quantity\":\"92.81\"},{\"side\":\"bid\",\"event_time\":\"2026-08-26T12:13:54.889476Z\",\"price_level\":\"1.5565\",\"new_quantity\":\"0\"},{\"side\":\"bid\",\"event_time\":\"2026-08-26T12:13:54.889476Z\",\"price_level\":\"1.5562\",\"new_quantity\":\"92.81\"},{\"side\":\"bid\",\"event_time\":\"2026-08-26T12:13:54.889476Z\",\"price_level\":\"1.5558\",\"new_quantity\":\"1119.31\"},{\"side\":\"bid\",\"event_time\":\"2026-08-26T12:13:54.889476Z\",\"price_level\":\"1.5557\",\"new_quantity\":\"642.79\"},{\"side\":\"bid\",\"event_time\":\"2026-08-26T12:13:54.889476Z\",\"price_level\":\"1.5551\",\"new_quantity\":\"212.21\"},{\"side\":\"bid\",\"event_time\":\"2026-08-26T12:13:54.889476Z\",\"price_level\":\"1.555\",\"new_quantity\":\"705.48\"},{\"side\":\"bid\",\"event_time\":\"2026-08-26T12:13:54.889476Z\",\"price_level\":\"1.5548\",\"new_quantity\":\"643.15\"},{\"side\":\"bid\",\"event_time\":\"2026-08-26T12:13:54.889476Z\",\"price_level\":\"1.5535\",\"new_quantity\":\"902.15\"},{\"side\":\"bid\",\"event_time\":\"2026-08-26T12:13:54.889476Z\",\"price_level\":\"1.5534\",\"new_quantity\":\"0\"},{\"side\":\"bid\",\"event_time\":\"2026-08-26T12:13:54.889476Z\",\"price_level\":\"1.5531\",\"new_quantity\":\"0\"},{\"side\":\"bid\",\"event_time\":\"2026-08-26T12:13:54.889476Z\",\"price_level\":\"1.5528\",\"new_quantity\":\"2083.37\"},{\"side\":\"bid\",\"event_time\":\"2026-08-26T12:13:54.889476Z\",\"price_level\":\"1.5519\",\"new_quantity\":\"20.25\"},{\"side\":\"bid\",\"event_time\":\"2026-08-26T12:13:54.889476Z\",\"price_level\":\"1.5504\",\"new_quantity\":\"7743.94\"},{\"side\":\"bid\",\"event_time\":\"2026-08-26T12:13:54.889476Z\",\"price_level\":\"1.5503\",\"new_quantity\":\"5880.2\"},{\"side\":\"bid\",\"event_time\":\"2026-08-26T12:13:54.889476Z\",\"price_level\":\"1.5502\",\"new_quantity\":\"0\"},{\"side\":\"bid\",\"event_time\":\"2026-08-26T12:13:54.889476Z\",\"price_level\":\"1.5487\",\"new_quantity\":\"5900.45\"},{\"side\":\"bid\",\"event_time\":\"2026-08-26T12:13:54.889476Z\",\"price_level\":\"1.5486\",\"new_quantity\":\"0\"},{\"side\":\"bid\",\"event_time\":\"2026-08-26T12:13:54.889476Z\",\"price_level\":\"1.5471\",\"new_quantity\":\"0\"},{\"side\":\"bid\",\"event_time\":\"2026-08-26T12:13:54.889476Z\",\"price_level\":\"1.5456\",\"new_quantity\":\"0.72\"},{\"side\":\"bid\",\"event_time\":\"2026-08-26T12:13:54.889476Z\",\"price_level\":\"1.5455\",\"new_quantity\":\"0\"},{\"side\":\"offer\",\"event_time\":\"2026-08-26T12:13:54.889476Z\",\"price_level\":\"1.5588\",\"new_quantity\":\"186.78\"},{\"side\":\"offer\",\"event_time\":\"2026-08-26T12:13:54.889476Z\",\"price_level\":\"1.5589\",\"new_quantity\":\"405.67\"},{\"side\":\"offer\",\"event_time\":\"2026-08-26T12:13:54.889476Z\",\"price_level\":\"1.559\",\"new_quantity\":\"0\"},{\"side\":\"offer\",\"event_time\":\"2026-08-26T12:13:54.889476Z\",\"price_level\":\"1.5595\",\"new_quantity\":\"80.15\"},{\"side\":\"offer\",\"event_time\":\"2026-08-26T12:13:54.889476Z\",\"price_level\":\"1.5599\",\"new_quantity\":\"614.27\"},{\"side\":\"offer\",\"event_time\":\"2026-08-26T12:13:54.889476Z\",\"price_level\":\"1.5601\",\"new_quantity\":\"799.3\"},{\"side\":\"offer\",\"event_time\":\"2026-08-26T12:13:54.889476Z\",\"price_level\":\"1.5607\",\"new_quantity\":\"0\"},{\"side\":\"offer\",\"event_time\":\"2026-08-26T12:13:54.889476Z\",\"price_level\":\"1.5655\",\"new_quantity\":\"92.81\"},{\"side\":\"offer\",\"event_time\":\"2026-08-26T12:13:54.889476Z\",\"price_level\":\"1.5686\",\"new_quantity\":\"2411\"}]}]}"}
{"recv_ts_ns": 1787746435196603242, "payload": "{\"channel\":\"l2_data\",\"timestamp\":\"2026-08-26T12:13:55.076973842Z\",\"sequence_num\":74,\"events\":[{\"type\":\"update\",\"product_id\":\"ATOM-USD\",\"updates\":[{\"side\":\"bid\",\"event_time\":\"2026-08-26T12:13:54.922568Z\",\"price_level\":\"1.557\",\"new_quantity\":\"253.36\"},{\"side\":\"bid\",\"event_time\":\"2026-08-26T12:13:54.922568Z\",\"price_level\":\"1.5569\",\"new_quantity\":\"150.09\"},{\"side\":\"bid\",\"event_time\":\"2026-08-26T12:13:54.922568Z\",\"price_level\":\"1.5567\",\"new_quantity\":\"122.1\"},{\"side\":\"bid\",\"event_time\":\"2026-08-26T12:13:54.922568Z\",\"price_level\":\"1.5561\",\"new_quantity\":\"102.63\"},{\"side\":\"bid\",\"event_time\":\"2026-08-26T12:13:54.922568Z\",\"price_level\":\"1.556\",\"new_quantity\":\"253.47\"},{\"side\":\"bid\",\"event_time\":\"2026-08-26T12:13:54.922568Z\",\"price_level\":\"1.5545\",\"new_quantity\":\"347.45\"},{\"side\":\"offer\",\"event_time\":\"2026-08-26T12:13:54.922568Z\",\"price_level\":\"1.5587\",\"new_quantity\":\"0\"},{\"side\":\"offer\",\"event_time\":\"2026-08-26T12:13:54.922568Z\",\"price_level\":\"1.5599\",\"new_quantity\":\"515.98\"}]}]}"}
{"recv_ts_ns": 1787746435212290574, "payload": "{\"channel\":\"l2_data\",\"timestamp\":\"2026-08-26T12:13:55.091956714Z\",\"sequence_num\":75,\"events\":[{\"type\":\"update\",\"product_id\":\"ATOM-USD\",\"updates\":[{\"side\":\"bid\",\"event_time\":\"2026-08-26T12:13:55.012259Z\",\"price_level\":\"1.5575\",\"new_quantity\":\"0\"},{\"side\":\"bid\",\"event_time\":\"2026-08-26T12:13:55.012259Z\",\"price_level\":\"1.5574\",\"new_quantity\":\"0\"},{\"side\":\"bid\",\"event_time\":\"2026-08-26T12:13:55.012259Z\",\"price_level\":\"1.5571\",\"new_quantity\":\"151.26\"},{\"side\":\"bid\",\"event_time\":\"2026-08-26T12:13:55.012259Z\",\"price_level\":\"1.557\",\"new_quantity\":\"234.5\"},{\"side\":\"bid\",\"event_time\":\"2026-08-26T12:13:55.012259Z\",\"price_level\":\"1.5568\",\"new_quantity\":\"92.81\"},{\"side\":\"bid\",\"event_time\":\"2026-08-26T12:13:55.012259Z\",\"price_level\":\"1.5561\",\"new_quantity\":\"253.95\"},{\"side\":\"bid\",\"event_time\":\"2026-08-26T12:13:55.012259Z\",\"price_level\":\"1.5543\",\"new_quantity\":\"0\"},{\"side\":\"offer\",\"event_time\":\"2026-08-26T12:13:55.012259Z\",\"price_level\":\"1.5586\",\"new_quantity\":\"80.2\"},{\"side\":\"offer\",\"event_time\":\"2026-08-26T12:13:55.012259Z\",\"price_level\":\"1.5587\",\"new_quantity\":\"92.81\"},{\"side\":\"offer\",\"event_time\":\"2026-08-26T12:13:55.012259Z\",\"price_level\":\"1.5594\",\"new_quantity\":\"86.33\"},{\"side\":\"offer\",\"event_time\":\"2026-08-26T12:13:55.012259Z\",\"price_level\":\"1.56\",\"new_quantity\":\"274.76\"},{\"side\":\"offer\",\"event_time\":\"2026-08-26T12:13:55.012259Z\",\"price_level\":\"1.5604\",\"new_quantity\":\"0\"},{\"side\":\"offer\",\"event_time\":\"2026-08-26T12:13:55.012259Z\",\"price_level\":\"1.5608\",\"new_quantity\":\"530.05\"},{\"side\":\"offer\",\"event_time\":\"2026-08-26T12:13:55.012259Z\",\"price_level\":\"1.5609\",\"new_quantity\":\"3538.42\"},{\"side\":\"offer\",\"event_time\":\"2026-08-26T12:13:55.012259Z\",\"price_level\":\"1.561\",\"new_quantity\":\"1921.06\"}]}]}"}
{"recv_ts_ns": 1787746435282669109, "payload": "{\"channel\":\"l2_data\",\"timestamp\":\"2026-08-26T12:13:55.166564704Z\",\"sequence_num\":76,\"events\":[{\"type\":\"update\",\"product_id\":\"ATOM-USD\",\"updates\":[{\"side\":\"bid\",\"event_time\":\"2026-08-26T12:13:55.042177Z\",\"price_level\":\"1.5572\",\"new_quantity\":\"0\"},{\"side\":\"bid\",\"event_time\":\"2026-08-26T12:13:55.042177Z\",\"price_level\":\"1.557\",\"new_quantity\":\"92.81\"},{\"side\":\"bid\",\"event_time\":\"2026-08-26T12:13:55.042177Z\",\"price_level\":\"1.5556\",\"new_quantity\":\"570.41\"},{\"side\":\"bid\",\"event_time\":\"2026-08-26T12:13:55.042177Z\",\"price_level\":\"1.5544\",\"new_quantity\":\"6458.22\"},{\"side\":\"offer\",\"event_time\":\"2026-08-26T12:13:55.042177Z\",\"price_level\":\"1.5586\",\"new_quantity\":\"173.01\"},{\"side\":\"offer\",\"event_time\":\"2026-08-26T12:13:55.042177Z\",\"price_level\":\"1.5587\",\"new_quantity\":\"346.67\"},{\"side\":\"offer\",\"event_time\":\"2026-08-26T12:13:55.042177Z\",\"price_level\":\"1.5589\",\"new_quantity\":\"92.81\"},{\"side\":\"offer\",\"event_time\":\"2026-08-26T12:13:55.042177Z\",\"price_level\":\"1.5599\",\"new_quantity\":\"413.35\"}]}]}"}
{"recv_ts_ns": 1787746435359196799, "payload": "{\"channel\":\"l2_data\",\"timestamp\":\"2026-08-26T12:13:55.243185427Z\",\"sequence_num\":77,\"events\":[{\"type\":\"update\",\"product_id\":\"ATOM-USD\",\"updates\":[{\"side\":\"bid\",\"event_time\":\"2026-08-26T12:13:55.104238Z\",\"price_level\":\"1.5572\",\"new_quantity\":\"92.81\"},{\"side\":\"bid\",\"event_time\":\"2026-08-26T12:13:55.104238Z\",\"price_level\":\"1.5571\",\"new_quantity\":\"0\"},{\"side\":\"bid\",\"event_time\":\"2026-08-26T12:13:55.104238Z\",\"price_level\":\"1.5569\",\"new_quantity\":\"150.09\"},{\"side\":\"bid\",\"event_time\":\"2026-08-26T12:13:55.104238Z\",\"price_level\":\"1.5561\",\"new_quantity\":\"263.28\"},{\"side\":\"bid\",\"event_time\":\"2026-08-26T12:13:55.104238Z\",\"price_level\":\"1.556\",\"new_quantity\":\"92.81\"},{\"side\":\"bid\",\"event_time\":\"2026-08-26T12:13:55.104238Z\",\"price_level\":\"1.5545\",\"new_quantity\":\"0\"},{\"side\":\"bid\",\"event_time\":\"2026-08-26T12:13:55.104238Z\",\"price_level\":\"1.5544\",\"new_quantity\":\"781.55\"},{\"side\":\"bid\",\"event_time\":\"2026-08-26T12:13:55.104238Z\",\"price_level\":\"1.5536\",\"new_quantity\":\"5679.59\"},{\"side\":\"bid\",\"event_time\":\"2026-08-26T12:13:55.104238Z\",\"price_level\":\"1.5528\",\"new_quantity\":\"1787.83\"},{\"side\":\"bid\",\"event_time\":\"2026-08-26T12:13:55.104238Z\",\"price_level\":\"1.5513\",\"new_quantity\":\"0\"},{\"side\":\"bid\",\"event_time\":\"2026-08-26T12:13:55.104238Z\",\"price_level\":\"1.5508\",\"new_quantity\":\"746.26\"},{\"side\":\"bid\",\"event_time\":\"2026-08-26T12:13:55.104238Z\",\"price_level\":\"1.5495\",\"new_quantity\":\"0\"},{\"side\":\"bid\",\"event_time\":\"2026-08-26T12:13:55.104238Z\",\"price_level\":\"1.5488\",\"new_quantity\":\"274.02\"},{\"side\":\"bid\",\"event_time\":\"2026-08-26T12:13:55.104238Z\",\"price_level\":\"1.5305\",\"new_quantity\":\"0\"},{\"side\":\"bid\",\"event_time\":\"2026-08-26T12:13:55.104238Z\",\"price_level\":\"1.5237\",\"new_quantity\":\"0\"},{\"side\":\"bid\",\"event_time\":\"2026-08-26T12:13:55.104238Z\",\"price_level\":\"1.5169\",\"new_quantity\":\"0\"},{\"side\":\"offer\",\"event_time\":\"2026-08-26T12:13:55.104238Z\",\"price_level\":\"1.5588\",\"new_quantity\":\"0\"},{\"side\":\"offer\",\"event_time\":\"2026-08-26T12:13:55.104238Z\",\"price_level\":\"1.5594\",\"new_quantity\":\"102.63\"},{\"side\":\"offer\",\"event_time\":\"2026-08-26T12:13:55.104238Z\",\"price_level\":\"1.5595\",\"new_quantity\":\"173.41\"},{\"side\":\"offer\",\"event_time\":\"2026-08-26T12:13:55.104238Z\",\"price_level\":\"1.5607\",\"new_quantity\":\"3218.09\"},{\"side\":\"offer\",\"event_time\":\"2026-08-26T12:13:55.104238Z\",\"price_level\":\"1.5608\",\"new_quantity\":\"92.81\"},{\"side\":\"offer\",\"event_time\":\"2026-08-26T12:13:55.104238Z\",\"price_level\":\"1.5609\",\"new_quantity\":\"320.33\"}]}]}"}
{"recv_ts_ns": 1787746435359284334, "payload": "{\"channel\":\"l2_data\",\"timestamp\":\"2026-08-26T12:13:55.243536957Z\",\"sequence_num\":78,\"events\":[{\"type\":\"update\",\"product_id\":\"ATOM-USD\",\"updates\":[{\"side\":\"offer\",\"event_time\":\"2026-08-26T12:13:55.118852Z\",\"price_level\":\"1.5587\",\"new_quantity\":\"0\"},{\"side\":\"offer\",\"event_time\":\"2026-08-26T12:13:55.118852Z\",\"price_level\":\"1.565\",\"new_quantity\":\"279.58\"},{\"side\":\"offer\",\"event_time\":\"2026-08-26T12:13:55.118852Z\",\"price_level\":\"1.5662\",\"new_quantity\":\"0\"},{\"side\":\"offer\",\"event_time\":\"2026-08-26T12:13:55.118852Z\",\"price_level\":\"1.5682\",\"new_quantity\":\"0\"}]}]}"}
{"recv_ts_ns": 1787746435403664980, "payload": "{\"channel\":\"l2_data\",\"timestamp\":\"2026-08-26T12:13:55.286131769Z\",\"sequence_num\":79,\"events\":[{\"type\":\"update\",\"product_id\":\"ATOM-USD\",\"updates\":[{\"side\":\"bid\",\"event_time\":\"2026-08-26T12:13:55.256769Z\",\"price_level\":\"1.5572\",\"new_quantity\":\"160.53\"},{\"side\":\"offer\",\"event_time\":\"2026-08-26T12:13:55.256769Z\",\"price_level\":\"1.5585\",\"new_quantity\":\"0\"},{\"side\":\"offer\",\"event_time\":\"2026-08-26T12:13:55.256769Z\",\"price_level\":\"1.5632\",\"new_quantity\":\"284.53\"},{\"side\":\"offer\",\"event_time\":\"2026-08-26T12:13:55.256769Z\",\"price_level\":\"1.5642\",\"new_quantity\":\"92.81\"},{\"side\":\"offer\",\"event_time\":\"2026-08-26T12:13:55.256769Z\",\"price_level\":\"1.567\",\"new_quantity\":\"313.39\"}]}]}"}
{"recv_ts_ns": 1787746435497291762, "payload": "{\"channel\":\"l2_data\",\"timestamp\":\"2026-08-26T12:13:55.382590494Z\",\"sequence_num\":81,\"events\":[{\"type\":\"update\",\"product_id\":\"ATOM-USD\",\"updates\":[{\"side\":\"offer\",\"event_time\":\"2026-08-26T12:13:55.353593Z\",\"price_level\":\"1.5583\",\"new_quantity\":\"0\"},{\"side\":\"offer\",\"event_time\":\"2026-08-26T12:13:55.353593Z\",\"price_level\":\"1.5584\",\"new_quantity\":\"0\"}]}]}"}
{"recv_ts_ns": 1787746435548332314, "payload": "{\"channel\":\"l2_data\",\"timestamp\":\"2026-08-26T12:13:55.433060397Z\",\"sequence_num\":82,\"events\":[{\"type\":\"update\",\"product_id\":\"ATOM-USD\",\"updates\":[{\"side\":\"bid\",\"event_time\":\"2026-08-26T12:13:55.400729Z\",\"price_level\":\"1.5572\",\"new_quantity\":\"0\"},{\"side\":\"bid\",\"event_time\":\"2026-08-26T12:13:55.400729Z\",\"price_level\":\"1.557\",\"new_quantity\":\"0\"},{\"side\":\"bid\",\"event_time\":\"2026-08-26T12:13:55.400729Z\",\"price_level\":\"1.5567\",\"new_quantity\":\"0\"},{\"side\":\"bid\",\"event_time\":\"2026-08-26T12:13:55.400729Z\",\"price_level\":\"1.5566\",\"new_quantity\":\"253.41\"},{\"side\":\"bid\",\"event_time\":\"2026-08-26T12:13:55.400729Z\",\"price_level\":\"1.5564\",\"new_quantity\":\"199.14\"},{\"side\":\"bid\",\"event_time\":\"2026-08-26T12:13:55.400729Z\",\"price_level\":\"1.5561\",\"new_quantity\":\"102.63\"},{\"side\":\"bid\",\"event_time\":\"2026-08-26T12:13:55.400729Z\",\"price_level\":\"1.5559\",\"new_quantity\":\"0\"},{\"side\":\"bid\",\"event_time\":\"2026-08-26T12:13:55.400729Z\",\"price_level\":\"1.5558\",\"new_quantity\":\"476.56\"},{\"side\":\"bid\",\"event_time\":\"2026-08-26T12:13:55.400729Z\",\"price_level\":\"1.5555\",\"new_quantity\":\"1382.9\"},{\"side\":\"bid\",\"event_time\":\"2026-08-26T12:13:55.400729Z\",\"price_level\":\"1.5554\",\"new_quantity\":\"1258.18\"},{\"side\":\"bid\",\"event_time\":\"2026-08-26T12:13:55.400729Z\",\"price_level\":\"1.5552\",\"new_quantity\":\"782.26\"},{\"side\":\"bid\",\"event_time\":\"2026-08-26T12:13:55.400729Z\",\"price_level\":\"1.5549\",\"new_quantity\":\"1027.07\"},{\"side\":\"bid\",\"event_time\":\"2026-08-26T12:13:55.400729Z\",\"price_level\":\"1.5541\",\"new_quantity\":\"643.42\"},{\"side\":\"bid\",\"event_time\":\"2026-08-26T12:13:55.400729Z\",\"price_level\":\"1.5536\",\"new_quantity\":\"0\"},{\"side\":\"bid\",\"event_time\":\"2026-08-26T12:13:55.400729Z\",\"price_level\":\"1.5535\",\"new_quantity\":\"20.25\"},{\"side\":\"bid\",\"event_time\":\"2026-08-26T12:13:55.400729Z\",\"price_level\":\"1.5528\",\"new_quantity\":\"0.71\"},{\"side\":\"bid\",\"event_time\":\"2026-08-26T12:13:55.400729Z\",\"price_level\":\"1.5525\",\"new_quantity\":\"819.87\"},{\"side\":\"bid\",\"event_time\":\"2026-08-26T12:13:55.400729Z\",\"price_level\":\"1.5519\",\"new_quantity\":\"1510.94\"},{\"side\":\"bid\",\"event_time\":\"2026-08-26T12:13:55.400729Z\",\"price_level\":\"1.551\",\"new_quantity\":\"0\"},{\"side\":\"bid\",\"event_time\":\"2026-08-26T12:13:55.400729Z\",\"price_level\":\"1.5504\",\"new_quantity\":\"5880.91\"},{\"side\":\"bid\",\"event_time\":\"2026-08-26T12:13:55.400729Z\",\"price_level\":\"1.5487\",\"new_quantity\":\"7846.06\"},{\"side\":\"offer\",\"event_time\":\"2026-08-26T12:13:55.400729Z\",\"price_level\":\"1.5582\",\"new_quantity\":\"80.22\"},{\"side\":\"offer\",\"event_time\":\"2026-08-26T12:13:55.400729Z\",\"price_level\":\"1.5586\",\"new_quantity\":\"0\"},{\"side\":\"offer\",\"event_time\":\"2026-08-26T12:13:55.400729Z\",\"price_level\":\"1.5593\",\"new_quantity\":\"0\"},{\"side\":\"offer\",\"event_time\":\"2026-08-26T12:13:55.400729Z\",\"price_level\":\"1.5595\",\"new_quantity\":\"320.62\"},{\"side\":\"offer\",\"event_time\":\"2026-08-26T12:13:55.400729Z\",\"price_level\":\"1.5607\",\"new_quantity\":\"0\"},{\"side\":\"offer\",\"event_time\":\"2026-08-26T12:13:55.400729Z\",\"price_level\":\"1.5609\",\"new_quantity\":\"0\"},{\"side\":\"offer\",\"event_time\":\"2026-08-26T12:13:55.400729Z\",\"price_level\":\"1.5636\",\"new_quantity\":\"661.4\"},{\"side\":\"offer\",\"event_time\":\"2026-08-26T12:13:55.400729Z\",\"price_level\":\"1.5653\",\"new_quantity\":\"105.72\"},{\"side\":\"offer\",\"event_time\":\"2026-08-26T12:13:55.400729Z\",\"price_level\":\"1.5654\",\"new_quantity\":\"2415.92\"},{\"side\":\"offer\",\"event_time\":\"2026-08-26T12:13:55.400729Z\",\"price_level\":\"1.5718\",\"new_quantity\":\"0\"}]}]}"}
{"recv_ts_ns": 1787746435597451130, "payload": "{\"channel\":\"l2_data\",\"timestamp\":\"2026-08-26T12:13:55.482801308Z\",\"sequence_num\":83,\"events\":[{\"type\":\"update\",\"product_id\":\"ATOM-USD\",\"updates\":[{\"side\":\"bid\",\"event_time\":\"2026-08-26T12:13:55.456835Z\",\"price_level\":\"1.557\",\"new_quantity\":\"92.81\"},{\"side\":\"bid\",\"event_time\":\"2026-08-26T12:13:55.456835Z\",\"price_level\":\"1.5561\",\"new_quantity\":\"0\"},{\"side\":\"bid\",\"event_time\":\"2026-08-26T12:13:55.456835Z\",\"price_level\":\"1.5542\",\"new_quantity\":\"5905.97\"},{\"side\":\"bid\",\"event_time\":\"2026-08-26T12:13:55.456835Z\",\"price_level\":\"1.5532\",\"new_quantity\":\"206.87\"},{\"side\":\"bid\",\"event_time\":\"2026-08-26T12:13:55.456835Z\",\"price_level\":\"1.5494\",\"new_quantity\":\"1034.35\"},{\"side\":\"offer\",\"event_time\":\"2026-08-26T12:13:55.456835Z\",\"price_level\":\"1.5582\",\"new_quantity\":\"0\"},{\"side\":\"offer\",\"event_time\":\"2026-08-26T12:13:55.456835Z\",\"price_level\":\"1.5587\",\"new_quantity\":\"102.63\"},{\"side\":\"offer\",\"event_time\":\"2026-08-26T12:13:55.456835Z\",\"price_level\":\"1.5594\",\"new_quantity\":\"512.05\"},{\"side\":\"offer\",\"event_time\":\"2026-08-26T12:13:55.456835Z\",\"price_level\":\"1.5602\",\"new_quantity\":\"818.3\"},{\"side\":\"offer\",\"event_time\":\"2026-08-26T12:13:55.456835Z\",\"price_level\":\"1.5603\",\"new_quantity\":\"497.94\"},{\"side\":\"offer\",\"event_time\":\"2026-08-26T12:13:55.456835Z\",\"price_level\":\"1.5609\",\"new_quantity\":\"5720.84\"},{\"side\":\"offer\",\"event_time\":\"2026-08-26T12:13:55.456835Z\",\"price_level\":\"1.5615\",\"new_quantity\":\"92.81\"},{\"side\":\"offer\",\"event_time\":\"2026-08-26T12:13:55.456835Z\",\"price_level\":\"1.5632\",\"new_quantity\":\"0\"},{\"side\":\"offer\",\"event_time\":\"2026-08-26T12:13:55.456835Z\",\"price_level\":\"1.5635\",\"new_quantity\":\"277.13\"}]}]}"}
{"recv_ts_ns": 1787746435648218451, "payload": "{\"channel\":\"l2_data\",\"timestamp\":\"2026-08-26T12:13:55.532877847Z\",\"sequence_num\":84,\"events\":[{\"type\":\"update\",\"product_id\":\"ATOM-USD\",\"updates\":[{\"side\":\"bid\",\"event_time\":\"2026-08-26T12:13:55.495107Z\",\"price_level\":\"1.557\",\"new_quantity\":\"0\"},{\"side\":\"bid\",\"event_time\":\"2026-08-26T12:13:55.495107Z\",\"price_level\":\"1.5554\",\"new_quantity\":\"1360.81\"},{\"side\":\"bid\",\"event_time\":\"2026-08-26T12:13:55.495107Z\",\"price_level\":\"1.5524\",\"new_quantity\":\"0\"},{\"side\":\"offer\",\"event_time\":\"2026-08-26T12:13:55.495107Z\",\"price_level\":\"1.5582\",\"new_quantity\":\"80.22\"},{\"side\":\"offer\",\"event_time\":\"2026-08-26T12:13:55.495107Z\",\"price_level\":\"1.5584\",\"new_quantity\":\"398.77\"},{\"side\":\"offer\",\"event_time\":\"2026-08-26T12:13:55.495107Z\",\"price_level\":\"1.5587\",\"new_quantity\":\"195.44\"},{\"side\":\"offer\",\"event_time\":\"2026-08-26T12:13:55.495107Z\",\"price_level\":\"1.559\",\"new_quantity\":\"86.51\"},{\"side\":\"offer\",\"event_time\":\"2026-08-26T12:13:55.495107Z\",\"price_level\":\"1.5592\",\"new_quantity\":\"209.44\"}]}]}"}
{"recv_ts_ns": 1787746435697367965, "payload": "{\"channel\":\"l2_data\",\"timestamp\":\"2026-08-26T12:13:55.582466057Z\",\"sequence_num\":85,\"events\":[{\"type\":\"update\",\"product_id\":\"ATOM-USD\",\"updates\":[{\"side\":\"bid\",\"event_time\":\"2026-08-26T12:13:55.558128Z\",\"price_level\":\"1.5551\",\"new_quantity\":\"20.25\"},{\"side\":\"bid\",\"event_time\":\"2026-08-26T12:13:55.558128Z\",\"price_level\":\"1.555\",\"new_quantity\":\"383.94\"},{\"side\":\"bid\",\"event_time\":\"2026-08-26T12:13:55.558128Z\",\"price_level\":\"1.5542\",\"new_quantity\":\"228.57\"},{\"side\":\"bid\",\"event_time\":\"2026-08-26T12:13:55.558128Z\",\"price_level\":\"1.5533\",\"new_quantity\":\"5680.69\"},{\"side\":\"bid\",\"event_time\":\"2026-08-26T12:13:55.558128Z\",\"price_level\":\"1.5523\",\"new_quantity\":\"261.27\"},{\"side\":\"bid\",\"event_time\":\"2026-08-26T12:13:55.558128Z\",\"price_level\":\"1.552\",\"new_quantity\":\"0\"},{\"side\":\"bid\",\"event_time\":\"2026-08-26T12:13:55.558128Z\",\"price_level\":\"1.55\",\"new_quantity\":\"0\"},{\"side\":\"bid\",\"event_time\":\"2026-08-26T12:13:55.558128Z\",\"price_level\":\"1.5398\",\"new_quantity\":\"0\"},{\"side\":\"offer\",\"event_time\":\"2026-08-26T12:13:55.558128Z\",\"price_level\":\"1.5582\",\"new_quantity\":\"173.03\"},{\"side\":\"offer\",\"event_time\":\"2026-08-26T12:13:55.558128Z\",\"price_level\":\"1.5604\",\"new_quantity\":\"5720.84\"},{\"side\":\"offer\",\"event_time\":\"2026-08-26T12:13:55.558128Z\",\"price_level\":\"1.5609\",\"new_quantity\":\"0\"}]}]}"}
{"recv_ts_ns": 1787746435773667318, "payload": "{\"channel\":\"l2_data\",\"timestamp\":\"2026-08-26T12:13:55.6573557Z\",\"sequence_num\":86,\"events\":[{\"type\":\"update\",\"product_id\":\"ATOM-USD\",\"updates\":[{\"side\":\"bid\",\"event_time\":\"2026-08-26T12:13:55.589917Z\",\"price_level\":\"1.5561\",\"new_quantity\":\"46.93\"},{\"side\":\"offer\",\"event_time\":\"2026-08-26T12:13:55.589917Z\",\"price_level\":\"1.5593\",\"new_quantity\":\"46.93\"},{\"side\":\"offer\",\"event_time\":\"2026-08-26T12:13:55.589917Z\",\"price_level\":\"1.5601\",\"new_quantity\":\"752.37\"},{\"side\":\"offer\",\"event_time\":\"2026-08-26T12:13:55.589917Z\",\"price_level\":\"1.5604\",\"new_quantity\":\"6520.84\"}]}]}"}
{"recv_ts_ns": 1787746435797927119, "payload": "{\"channel\":\"l2_data\",\"timestamp\":\"2026-08-26T12:13:55.683406508Z\",\"sequence_num\":87,\"events\":[{\"type\":\"update\",\"product_id\":\"ATOM-USD\",\"updates\":[{\"side\":\"offer\",\"event_time\":\"2026-08-26T12:13:55.650349Z\",\"price_level\":\"1.5709\",\"new_quantity\":\"1273.15\"},{\"side\":\"offer\",\"event_time\":\"2026-08-26T12:13:55.650349Z\",\"price_level\":\"1.5729\",\"new_quantity\":\"93.83\"}]}]}"}
{"recv_ts_ns": 1787746435849047665, "payload": "{\"channel\":\"l2_data\",\"timestamp\":\"2026-08-26T12:13:55.733557896Z\",\"sequence_num\":88,\"events\":[{\"type\":\"update\",\"product_id\":\"ATOM-USD\",\"updates\":[{\"side\":\"bid\",\"event_time\":\"2026-08-26T12:13:55.692009Z\",\"price_level\":\"1.5498\",\"new_quantity\":\"20.25\"},{\"side\":\"bid\",\"event_time\":\"2026-08-26T12:13:55.692009Z\",\"price_level\":\"1.5466\",\"new_quantity\":\"20.25\"},{\"side\":\"bid\",\"event_time\":\"2026-08-26T12:13:55.692009Z\",\"price_level\":\"1.545\",\"new_quantity\":\"20.25\"},{\"side\":\"bid\",\"event_time\":\"2026-08-26T12:13:55.692009Z\",\"price_level\":\"1.5383\",\"new_quantity\":\"3250.34\"},{\"side\":\"bid\",\"event_time\":\"2026-08-26T12:13:55.692009Z\",\"price_level\":\"1.5249\",\"new_quantity\":\"178.03\"},{\"side\":\"offer\",\"event_time\":\"2026-08-26T12:13:55.692009Z\",\"price_level\":\"1.5581\",\"new_quantity\":\"173.03\"},{\"side\":\"offer\",\"event_time\":\"2026-08-26T12:13:55.692009Z\",\"price_level\":\"1.5582\",\"new_quantity\":\"0\"},{\"side\":\"offer\",\"event_time\":\"2026-08-26T12:13:55.692009Z\",\"price_level\":\"1.5583\",\"new_quantity\":\"238.07\"},{\"side\":\"offer\",\"event_time\":\"2026-08-26T12:13:55.692009Z\",\"price_level\":\"1.5585\",\"new_quantity\":\"20.25\"},{\"side\":\"offer\",\"event_time\":\"2026-08-26T12:13:55.692009Z\",\"price_level\":\"1.5593\",\"new_quantity\":\"238.35\"},{\"side\":\"offer\",\"event_time\":\"2026-08-26T12:13:55.692009Z\",\"price_level\":\"1.56\",\"new_quantity\":\"274.76\"},{\"side\":\"offer\",\"event_time\":\"2026-08-26T12:13:55.692009Z\",\"price_level\":\"1.5612\",\"new_quantity\":\"320.97\"},{\"side\":\"offer\",\"event_time\":\"2026-08-26T12:13:55.692009Z\",\"price_level\":\"1.5631\",\"new_quantity\":\"0\"},{\"side\":\"offer\",\"event_time\":\"2026-08-26T12:13:55.692009Z\",\"price_level\":\"1.5648\",\"new_quantity\":\"33.78\"},{\"side\":\"offer\",\"event_time\":\"2026-08-26T12:13:55.692009Z\",\"price_level\":\"1.568\",\"new_quantity\":\"30.25\"},{\"side\":\"offer\",\"event_time\":\"2026-08-26T12:13:55.692009Z\",\"price_level\":\"1.5686\",\"new_quantity\":\"2390.75\"},{\"side\":\"offer\",\"event_time\":\"2026-08-26T12:13:55.692009Z\",\"price_level\":\"1.6036\",\"new_quantity\":\"3117.98\"},{\"side\":\"offer\",\"event_time\":\"2026-08-26T12:13:55.692009Z\",\"price_level\":\"1.6077\",\"new_quantity\":\"0\"}]}]}"}
{"recv_ts_ns": 1787746435897797242, "payload": "{\"channel\":\"l2_data\",\"timestamp\":\"2026-08-26T12:13:55.782596042Z\",\"sequence_num\":89,\"events\":[{\"type\":\"update\",\"product_id\":\"ATOM-USD\",\"updates\":[{\"side\":\"bid\",\"event_time\":\"2026-08-26T12:13:55.753511Z\",\"price_level\":\"1.5543\",\"new_quantity\":\"321.68\"},{\"side\":\"offer\",\"event_time\":\"2026-08-26T12:13:55.753511Z\",\"price_level\":\"1.559\",\"new_quantity\":\"0\"},{\"side\":\"offer\",\"event_time\":\"2026-08-26T12:13:55.753511Z\",\"price_level\":\"1.5591\",\"new_quantity\":\"97.09\"}]}]}"}
{"recv_ts_ns": 1787746435948669037, "payload": "{\"channel\":\"l2_data\",\"timestamp\":\"2026-08-26T12:13:55.832561703Z\",\"sequence_num\":90,\"events\":[{\"type\":\"update\",\"product_id\":\"ATOM-USD\",\"updates\":[{\"side\":\"bid\",\"event_time\":\"2026-08-26T12:13:55.775071Z\",\"price_level\":\"1.549\",\"new_quantity\":\"1291.15\"},{\"side\":\"offer\",\"event_time\":\"2026-08-26T12:13:55.775071Z\",\"price_level\":\"1.5583\",\"new_quantity\":\"0\"},{\"side\":\"offer\",\"event_time\":\"2026-08-26T12:13:55.775071Z\",\"price_level\":\"1.5584\",\"new_quantity\":\"92.81\"},{\"side\":\"offer\",\"event_time\":\"2026-08-26T12:13:55.775071Z\",\"price_level\":\"1.5601\",\"new_quantity\":\"772.62\"},{\"side\":\"offer\",\"event_time\":\"2026-08-26T12:13:55.775071Z\",\"price_level\":\"1.5602\",\"new_quantity\":\"521.03\"},{\"side\":\"offer\",\"event_time\":\"2026-08-26T12:13:55.775071Z\",\"price_level\":\"1.5606\",\"new_quantity\":\"521.03\"},{\"side\":\"offer\",\"event_time\":\"2026-08-26T12:13:55.775071Z\",\"price_level\":\"1.5617\",\"new_quantity\":\"113.06\"},{\"side\":\"offer\",\"event_time\":\"2026-08-26T12:13:55.775071Z\",\"price_level\":\"1.5629\",\"new_quantity\":\"0\"},{\"side\":\"offer\",\"event_time\":\"2026-08-26T12:13:55.775071Z\",\"price_level\":\"1.568\",\"new_quantity\":\"30.25\"}]}]}"}
{"recv_ts_ns": 1787746436000535009, "payload": "{\"channel\":\"l2_data\",\"timestamp\":\"2026-08-26T12:13:55.882349689Z\",\"sequence_num\":91,\"events\":[{\"type\":\"update\",\"product_id\":\"ATOM-USD\",\"updates\":[{\"side\":\"bid\",\"event_time\":\"2026-08-26T12:13:55.861652Z\",\"price_level\":\"1.5564\",\"new_quantity\":\"93.52\"},{\"side\":\"offer\",\"event_time\":\"2026-08-26T12:13:55.861652Z\",\"price_level\":\"1.5592\",\"new_quantity\":\"172.97\"},{\"side\":\"offer\",\"event_time\":\"2026-08-26T12:13:55.861652Z\",\"price_level\":\"1.5633\",\"new_quantity\":\"20.25\"},{\"side\":\"offer\",\"event_time\":\"2026-08-26T12:13:55.861652Z\",\"price_level\":\"1.5648\",\"new_quantity\":\"13.53\"},{\"side\":\"offer\",\"event_time\":\"2026-08-26T12:13:55.861652Z\",\"price_level\":\"1.5649\",\"new_quantity\":\"20.25\"},{\"side\":\"offer\",\"event_time\":\"2026-08-26T12:13:55.861652Z\",\"price_level\":\"1.5654\",\"new_quantity\":\"2395.67\"},{\"side\":\"offer\",\"event_time\":\"2026-08-26T12:13:55.861652Z\",\"price_level\":\"1.568\",\"new_quantity\":\"10\"}]}]}"}
{"recv_ts_ns": 1787746436004094877, "payload": "{\"channel\":\"heartbeats\",\"timestamp\":\"2026-08-26T12:13:55.888149384Z\",\"sequence_num\":92,\"events\":[{\"current_time\":\"2026-08-26 12:13:55.88520967 +0000 UTC m=+24617.287195704\",\"heartbeat_counter\":24617}]}"}
{"recv_ts_ns": 1787746436049789118, "payload": "{\"channel\":\"l2_data\",\"timestamp\":\"2026-08-26T12:13:55.933601845Z\",\"sequence_num\":93,\"events\":[{\"type\":\"update\",\"product_id\":\"ATOM-USD\",\"updates\":[{\"side\":\"bid\",\"event_time\":\"2026-08-26T12:13:55.875721Z\",\"price_level\":\"1.5567\",\"new_quantity\":\"151.29\"},{\"side\":\"bid\",\"event_time\":\"2026-08-26T12:13:55.875721Z\",\"price_level\":\"1.5563\",\"new_quantity\":\"100.65\"},{\"side\":\"offer\",\"event_time\":\"2026-08-26T12:13:55.875721Z\",\"price_level\":\"1.5665\",\"new_quantity\":\"20.25\"},{\"side\":\"offer\",\"event_time\":\"2026-08-26T12:13:55.875721Z\",\"price_level\":\"1.568\",\"new_quantity\":\"30.25\"}]}]}"}
{"recv_ts_ns": 1787746436098688269, "payload": "{\"channel\":\"l2_data\",\"timestamp\":\"2026-08-26T12:13:55.982278215Z\",\"sequence_num\":94,\"events\":[{\"type\":\"update\",\"product_id\":\"ATOM-USD\",\"updates\":[{\"side\":\"bid\",\"event_time\":\"2026-08-26T12:13:55.93636Z\",\"price_level\":\"1.5563\",\"new_quantity\":\"120.9\"},{\"side\":\"bid\",\"event_time\":\"2026-08-26T12:13:55.93636Z\",\"price_level\":\"1.5556\",\"new_quantity\":\"92.81\"},{\"side\":\"bid\",\"event_time\":\"2026-08-26T12:13:55.93636Z\",\"price_level\":\"1.5555\",\"new_quantity\":\"582.9\"},{\"side\":\"bid\",\"event_time\":\"2026-08-26T12:13:55.93636Z\",\"price_level\":\"1.5499\",\"new_quantity\":\"5900.45\"},{\"side\":\"bid\",\"event_time\":\"2026-08-26T12:13:55.93636Z\",\"price_level\":\"1.5487\",\"new_quantity\":\"7825.81\"},{\"side\":\"bid\",\"event_time\":\"2026-08-26T12:13:55.93636Z\",\"price_level\":\"1.5467\",\"new_quantity\":\"20.25\"},{\"side\":\"bid\",\"event_time\":\"2026-08-26T12:13:55.93636Z\",\"price_level\":\"1.5466\",\"new_quantity\":\"0\"},{\"side\":\"bid\",\"event_time\":\"2026-08-26T12:13:55.93636Z\",\"price_level\":\"1.545\",\"new_quantity\":\"0\"}]}]}"}
{"recv_ts_ns": 1787746436197157789, "payload": "{\"channel\":\"l2_data\",\"timestamp\":\"2026-08-26T12:13:56.082347925Z\",\"sequence_num\":95,\"events\":[{\"type\":\"update\",\"product_id\":\"ATOM-USD\",\"updates\":[{\"side\":\"bid\",\"event_time\":\"2026-08-26T12:13:56.065491Z\",\"price_level\":\"1.5546\",\"new_quantity\":\"477.6\"},{\"side\":\"bid\",\"event_time\":\"2026-08-26T12:13:56.065491Z\",\"price_level\":\"1.5545\",\"new_quantity\":\"800\"},{\"side\":\"bid\",\"event_time\":\"2026-08-26T12:13:56.065491Z\",\"price_level\":\"1.5498\",\"new_quantity\":\"0\"},{\"side\":\"bid\",\"event_time\":\"2026-08-26T12:13:56.065491Z\",\"price_level\":\"1.5482\",\"new_quantity\":\"20.25\"}]}]}"}
{"recv_ts_ns": 1787746436252406654, "payload": "{\"channel\":\"l2_data\",\"timestamp\":\"2026-08-26T12:13:56.136895936Z\",\"sequence_num\":96,\"events\":[{\"type\":\"update\",\"product_id\":\"ATOM-USD\",\"updates\":[{\"side\":\"bid\",\"event_time\":\"2026-08-26T12:13:56.091134Z\",\"price_level\":\"1.5483\",\"new_quantity\":\"20.25\"},{\"side\":\"bid\",\"event_time\":\"2026-08-26T12:13:56.091134Z\",\"price_level\":\"1.5482\",\"new_quantity\":\"0\"},{\"side\":\"bid\",\"event_time\":\"2026-08-26T12:13:56.091134Z\",\"price_level\":\"1.5467\",\"new_quantity\":\"0\"},{\"side\":\"bid\",\"event_time\":\"2026-08-26T12:13:56.091134Z\",\"price_level\":\"1.5466\",\"new_quantity\":\"20.25\"}]}]}"}
{"recv_ts_ns": 1787746436397665535, "payload": "{\"channel\":\"l2_data\",\"timestamp\":\"2026-08-26T12:13:56.28237916Z\",\"sequence_num\":97,\"events\":[{\"type\":\"update\",\"product_id\":\"ATOM-USD\",\"updates\":[{\"side\":\"offer\",\"event_time\":\"2026-08-26T12:13:56.253821Z\",\"price_level\":\"1.5613\",\"new_quantity\":\"0\"}]}]}"}
{"recv_ts_ns": 1787746436446703525, "payload": "{\"channel\":\"l2_data\",\"timestamp\":\"2026-08-26T12:13:56.332445145Z\",\"sequence_num\":98,\"events\":[{\"type\":\"update\",\"product_id\":\"ATOM-USD\",\"updates\":[{\"side\":\"bid\",\"event_time\":\"2026-08-26T12:13:56.310663Z\",\"price_level\":\"1.5571\",\"new_quantity\":\"306.7\"},{\"side\":\"bid\",\"event_time\":\"2026-08-26T12:13:56.310663Z\",\"price_level\":\"1.557\",\"new_quantity\":\"92.81\"},{\"side\":\"bid\",\"event_time\":\"2026-08-26T12:13:56.310663Z\",\"price_level\":\"1.5567\",\"new_quantity\":\"0\"},{\"side\":\"bid\",\"event_time\":\"2026-08-26T12:13:56.310663Z\",\"price_level\":\"1.5566\",\"new_quantity\":\"92.81\"},{\"side\":\"bid\",\"event_time\":\"2026-08-26T12:13:56.310663Z\",\"price_level\":\"1.5565\",\"new_quantity\":\"20.25\"},{\"side\":\"bid\",\"event_time\":\"2026-08-26T12:13:56.310663Z\",\"price_level\":\"1.5563\",\"new_quantity\":\"100.65\"},{\"side\":\"bid\",\"event_time\":\"2026-08-26T12:13:56.310663Z\",\"price_level\":\"1.5557\",\"new_quantity\":\"794.14\"},{\"side\":\"bid\",\"event_time\":\"2026-08-26T12:13:56.310663Z\",\"price_level\":\"1.5556\",\"new_quantity\":\"253.51\"},{\"side\":\"bid\",\"event_time\":\"2026-08-26T12:13:56.310663Z\",\"price_level\":\"1.5555\",\"new_quantity\":\"422.19\"},{\"side\":\"bid\",\"event_time\":\"2026-08-26T12:13:56.310663Z\",\"price_level\":\"1.5501\",\"new_quantity\":\"20.25\"},{\"side\":\"bid\",\"event_time\":\"2026-08-26T12:13:56.310663Z\",\"price_level\":\"1.55\",\"new_quantity\":\"20.25\"},{\"side\":\"bid\",\"event_time\":\"2026-08-26T12:13:56.310663Z\",\"price_level\":\"1.5499\",\"new_quantity\":\"5880.2\"},{\"side\":\"bid\",\"event_time\":\"2026-08-26T12:13:56.310663Z\",\"price_level\":\"1.5466\",\"new_quantity\":\"0\"},{\"side\":\"offer\",\"event_time\":\"2026-08-26T12:13:56.310663Z\",\"price_level\":\"1.5581\",\"new_quantity\":\"0\"},{\"side\":\"offer\",\"event_time\":\"2026-08-26T12:13:56.310663Z\",\"price_level\":\"1.5583\",\"new_quantity\":\"173.02\"},{\"side\":\"offer\",\"event_time\":\"2026-08-26T12:13:56.310663Z\",\"price_level\":\"1.5584\",\"new_quantity\":\"0\"},{\"side\":\"offer\",\"event_time\":\"2026-08-26T12:13:56.310663Z\",\"price_level\":\"1.5602\",\"new_quantity\":\"735.15\"},{\"side\":\"offer\",\"event_time\":\"2026-08-26T12:13:56.310663Z\",\"price_level\":\"1.5604\",\"new_quantity\":\"800\"},{\"side\":\"offer\",\"event_time\":\"2026-08-26T12:13:56.310663Z\",\"price_level\":\"1.5607\",\"new_quantity\":\"5721.94\"},{\"side\":\"offer\",\"event_time\":\"2026-08-26T12:13:56.310663Z\",\"price_level\":\"1.5612\",\"new_quantity\":\"0.71\"}]}]}"}
{"recv_ts_ns": 1787746436497833990, "payload": "{\"channel\":\"l2_data\",\"timestamp\":\"2026-08-26T12:13:56.382728175Z\",\"sequence_num\":99,\"events\":[{\"type\":\"update\",\"product_id\":\"ATOM-USD\",\"updates\":[{\"side\":\"bid\",\"event_time\":\"2026-08-26T12:13:56.351114Z\",\"price_level\":\"1.5453\",\"new_quantity\":\"20.25\"}]}]}"}
{"recv_ts_ns": 1787746436547428905, "payload": "{\"channel\":\"l2_data\",\"timestamp\":\"2026-08-26T12:13:56.432397453Z\",\"sequence_num\":100,\"events\":[{\"type\":\"update\",\"product_id\":\"ATOM-USD\",\"updates\":[{\"side\":\"bid\",\"event_time\":\"2026-08-26T12:13:56.406749Z\",\"price_level\":\"1.5571\",\"new_quantity\":\"0\"},{\"side\":\"bid\",\"event_time\":\"2026-08-26T12:13:56.406749Z\",\"price_level\":\"1.5513\",\"new_quantity\":\"1737.99\"}]}]}"}
{"recv_ts_ns": 1787746436609606348, "payload": "{\"channel\":\"l2_data\",\"timestamp\":\"2026-08-26T12:13:56.494599526Z\",\"sequence_num\":101,\"events\":[{\"type\":\"update\",\"product_id\":\"ATOM-USD\",\"updates\":[{\"side\":\"bid\",\"event_time\":\"2026-08-26T12:13:56.452211Z\",\"price_level\":\"1.55\",\"new_quantity\":\"0\"},{\"side\":\"bid\",\"event_time\":\"2026-08-26T12:13:56.452211Z\",\"price_level\":\"1.5485\",\"new_quantity\":\"20.25\"},{\"side\":\"bid\",\"event_time\":\"2026-08-26T12:13:56.452211Z\",\"price_level\":\"1.5484\",\"new_quantity\":\"20.25\"},{\"side\":\"bid\",\"event_time\":\"2026-08-26T12:13:56.452211Z\",\"price_level\":\"1.5483\",\"new_quantity\":\"0\"},{\"side\":\"bid\",\"event_time\":\"2026-08-26T12:13:56.452211Z\",\"price_level\":\"1.5453\",\"new_quantity\":\"0\"},{\"side\":\"offer\",\"event_time\":\"2026-08-26T12:13:56.452211Z\",\"price_level\":\"1.5605\",\"new_quantity\":\"6135.89\"},{\"side\":\"offer\",\"event_time\":\"2026-08-26T12:13:56.452211Z\",\"price_level\":\"1.5607\",\"new_quantity\":\"0\"}]}]}"}
{"recv_ts_ns": 1787746436846457359, "payload": "{\"channel\":\"l2_data\",\"timestamp\":\"2026-08-26T12:13:56.732392688Z\",\"sequence_num\":102,\"events\":[{\"type\":\"update\",\"product_id\":\"ATOM-USD\",\"updates\":[{\"side\":\"offer\",\"event_time\":\"2026-08-26T12:13:56.699489Z\",\"price_level\":\"1.5612\",\"new_quantity\":\"320.97\"}]}]}"}
{"recv_ts_ns": 1787746436899229210, "payload": "{\"channel\":\"l2_data\",\"timestamp\":\"2026-08-26T12:13:56.782682957Z\",\"sequence_num\":103,\"events\":[{\"type\":\"update\",\"product_id\":\"ATOM-USD\",\"updates\":[{\"side\":\"offer\",\"event_time\":\"2026-08-26T12:13:56.716132Z\",\"price_level\":\"1.5591\",\"new_quantity\":\"228.37\"},{\"side\":\"offer\",\"event_time\":\"2026-08-26T12:13:56.716132Z\",\"price_level\":\"1.5592\",\"new_quantity\":\"219.9\"},{\"side\":\"offer\",\"event_time\":\"2026-08-26T12:13:56.716132Z\",\"price_level\":\"1.5593\",\"new_quantity\":\"191.42\"}]}]}"}
{"recv_ts_ns": 1787746437007628566, "payload": "{\"channel\":\"heartbeats\",\"timestamp\":\"2026-08-26T12:13:56.886093832Z\",\"sequence_num\":104,\"events\":[{\"current_time\":\"2026-08-26 12:13:56.885367592 +0000 UTC m=+24618.287353625\",\"heartbeat_counter\":24618}]}"}
{"recv_ts_ns": 1787746437197539042, "payload": "{\"channel\":\"l2_data\",\"timestamp\":\"2026-08-26T12:13:57.08239524Z\",\"sequence_num\":105,\"events\":[{\"type\":\"update\",\"product_id\":\"ATOM-USD\",\"updates\":[{\"side\":\"bid\",\"event_time\":\"2026-08-26T12:13:57.041174Z\",\"price_level\":\"1.5569\",\"new_quantity\":\"301.36\"},{\"side\":\"bid\",\"event_time\":\"2026-08-26T12:13:57.041174Z\",\"price_level\":\"1.5568\",\"new_quantity\":\"253.38\"},{\"side\":\"bid\",\"event_time\":\"2026-08-26T12:13:57.041174Z\",\"price_level\":\"1.5236\",\"new_quantity\":\"0\"},{\"side\":\"bid\",\"event_time\":\"2026-08-26T12:13:57.041174Z\",\"price_level\":\"1.515\",\"new_quantity\":\"2.5\"},{\"side\":\"bid\",\"event_time\":\"2026-08-26T12:13:57.041174Z\",\"price_level\":\"1.5065\",\"new_quantity\":\"0\"}]}]}"}
{"recv_ts_ns": 1787746438005364458, "payload": "{\"channel\":\"heartbeats\",\"timestamp\":\"2026-08-26T12:13:57.88916838Z\",\"sequence_num\":106,\"events\":[{\"current_time\":\"2026-08-26 12:13:57.885192807 +0000 UTC m=+24619.287178838\",\"heartbeat_counter\":24619}]}"}
{"recv_ts_ns": 1787746438698219958, "payload": "{\"channel\":\"l2_data\",\"timestamp\":\"2026-08-26T12:13:58.58250359Z\",\"sequence_num\":107,\"events\":[{\"type\":\"update\",\"product_id\":\"ATOM-USD\",\"updates\":[{\"side\":\"bid\",\"event_time\":\"2026-08-26T12:13:58.532371Z\",\"price_level\":\"1.5544\",\"new_quantity\":\"2315.02\"},{\"side\":\"bid\",\"event_time\":\"2026-08-26T12:13:58.532371Z\",\"price_level\":\"1.5543\",\"new_quantity\":\"2568.63\"}]}]}"}
{"recv_ts_ns": 1787746438860942751, "payload": "{\"channel\":\"l2_data\",\"timestamp\":\"2026-08-26T12:13:58.746900876Z\",\"sequence_num\":108,\"events\":[{\"type\":\"update\",\"product_id\":\"ATOM-USD\",\"updates\":[{\"side\":\"offer\",\"event_time\":\"2026-08-26T12:13:58.713775Z\",\"price_level\":\"1.5602\",\"new_quantity\":\"214.12\"}]}]}"}
{"recv_ts_ns": 1787746438898546682, "payload": "{\"channel\":\"l2_data\",\"timestamp\":\"2026-08-26T12:13:58.783162827Z\",\"sequence_num\":109,\"events\":[{\"type\":\"update\",\"product_id\":\"ATOM-USD\",\"updates\":[{\"side\":\"offer\",\"event_time\":\"2026-08-26T12:13:58.731687Z\",\"price_level\":\"1.5596\",\"new_quantity\":\"311.05\"},{\"side\":\"offer\",\"event_time\":\"2026-08-26T12:13:58.731687Z\",\"price_level\":\"1.5597\",\"new_quantity\":\"521.03\"},{\"side\":\"offer\",\"event_time\":\"2026-08-26T12:13:58.731687Z\",\"price_level\":\"1.5601\",\"new_quantity\":\"433.55\"}]}]}"}
{"recv_ts_ns": 1787746438947623934, "payload": "{\"channel\":\"l2_data\",\"timestamp\":\"2026-08-26T12:13:58.83277545Z\",\"sequence_num\":110,\"events\":[{\"type\":\"update\",\"product_id\":\"ATOM-USD\",\"updates\":[{\"side\":\"bid\",\"event_time\":\"2026-08-26T12:13:58.773055Z\",\"price_level\":\"1.5515\",\"new_quantity\":\"1868.77\"},{\"side\":\"bid\",\"event_time\":\"2026-08-26T12:13:58.773055Z\",\"price_level\":\"1.5513\",\"new_quantity\":\"0\"},{\"side\":\"offer\",\"event_time\":\"2026-08-26T12:13:58.773055Z\",\"price_level\":\"1.5636\",\"new_quantity\":\"93.52\"}]}]}"}
{"recv_ts_ns": 1787746439011796660, "payload": "{\"channel\":\"heartbeats\",\"timestamp\":\"2026-08-26T12:13:58.88556624Z\",\"sequence_num\":111,\"events\":[{\"current_time\":\"2026-08-26 12:13:58.885218841 +0000 UTC m=+24620.287204873\",\"heartbeat_counter\":24620}]}"}
{"recv_ts_ns": 1787746439098518734, "payload": "{\"channel\":\"l2_data\",\"timestamp\":\"2026-08-26T12:13:58.98231285Z\",\"sequence_num\":112,\"events\":[{\"type\":\"update\",\"product_id\":\"ATOM-USD\",\"updates\":[{\"side\":\"bid\",\"event_time\":\"2026-08-26T12:13:58.918496Z\",\"price_level\":\"1.5453\",\"new_quantity\":\"20.25\"}]}]}"}
{"recv_ts_ns": 1787746439348653036, "payload": "{\"channel\":\"l2_data\",\"timestamp\":\"2026-08-26T12:13:59.232215144Z\",\"sequence_num\":113,\"events\":[{\"type\":\"update\",\"product_id\":\"ATOM-USD\",\"updates\":[{\"side\":\"bid\",\"event_time\":\"2026-08-26T12:13:59.191088Z\",\"price_level\":\"1.5484\",\"new_quantity\":\"0\"},{\"side\":\"bid\",\"event_time\":\"2026-08-26T12:13:59.191088Z\",\"price_level\":\"1.5468\",\"new_quantity\":\"20.97\"},{\"side\":\"bid\",\"event_time\":\"2026-08-26T12:13:59.191088Z\",\"price_level\":\"1.5453\",\"new_quantity\":\"0\"}]}]}"}
{"recv_ts_ns": 1787746439447453847, "payload": "{\"channel\":\"l2_data\",\"timestamp\":\"2026-08-26T12:13:59.332104923Z\",\"sequence_num\":114,\"events\":[{\"type\":\"update\",\"product_id\":\"ATOM-USD\",\"updates\":[{\"side\":\"bid\",\"event_time\":\"2026-08-26T12:13:59.288941Z\",\"price_level\":\"1.5333\",\"new_quantity\":\"0\"},{\"side\":\"bid\",\"event_time\":\"2026-08-26T12:13:59.288941Z\",\"price_level\":\"1.5318\",\"new_quantity\":\"897.04\"}]}]}"}
{"recv_ts_ns": 1787746439905524809, "payload": "{\"channel\":\"l2_data\",\"timestamp\":\"2026-08-26T12:13:59.790986803Z\",\"sequence_num\":115,\"events\":[{\"type\":\"update\",\"product_id\":\"ATOM-USD\",\"updates\":[{\"side\":\"bid\",\"event_time\":\"2026-08-26T12:13:59.648473Z\",\"price_level\":\"1.5572\",\"new_quantity\":\"319.67\"},{\"side\":\"bid\",\"event_time\":\"2026-08-26T12:13:59.648473Z\",\"price_level\":\"1.5571\",\"new_quantity\":\"168.25\"},{\"side\":\"bid\",\"event_time\":\"2026-08-26T12:13:59.648473Z\",\"price_level\":\"1.557\",\"new_quantity\":\"177.46\"},{\"side\":\"bid\",\"event_time\":\"2026-08-26T12:13:59.648473Z\",\"price_level\":\"1.5563\",\"new_quantity\":\"147.58\"},{\"side\":\"bid\",\"event_time\":\"2026-08-26T12:13:59.648473Z\",\"price_level\":\"1.5561\",\"new_quantity\":\"0\"},{\"side\":\"bid\",\"event_time\":\"2026-08-26T12:13:59.648473Z\",\"price_level\":\"1.5554\",\"new_quantity\":\"1268\"},{\"side\":\"bid\",\"event_time\":\"2026-08-26T12:13:59.648473Z\",\"price_level\":\"1.5545\",\"new_quantity\":\"1266.59\"},{\"side\":\"bid\",\"event_time\":\"2026-08-26T12:13:59.648473Z\",\"price_level\":\"1.5469\",\"new_quantity\":\"20.25\"},{\"side\":\"offer\",\"event_time\":\"2026-08-26T12:13:59.648473Z\",\"price_level\":\"1.5592\",\"new_quantity\":\"172.97\"},{\"side\":\"offer\",\"event_time\":\"2026-08-26T12:13:59.648473Z\",\"price_level\":\"1.5593\",\"new_quantity\":\"238.35\"},{\"side\":\"offer\",\"event_time\":\"2026-08-26T12:13:59.648473Z\",\"price_level\":\"1.56\",\"new_quantity\":\"359.41\"},{\"side\":\"offer\",\"event_time\":\"2026-08-26T12:13:59.648473Z\",\"price_level\":\"1.5605\",\"new_quantity\":\"413.22\"},{\"side\":\"offer\",\"event_time\":\"2026-08-26T12:13:59.648473Z\",\"price_level\":\"1.5607\",\"new_quantity\":\"5575.75\"}]}]}"}
{"recv_ts_ns": 1787746439912254965, "payload": "{\"channel\":\"l2_data\",\"timestamp\":\"2026-08-26T12:13:59.795353519Z\",\"sequence_num\":116,\"events\":[{\"type\":\"update\",\"product_id\":\"ATOM-USD\",\"updates\":[{\"side\":\"bid\",\"event_time\":\"2026-08-26T12:13:59.747375Z\",\"price_level\":\"1.557\",\"new_quantity\":\"92.81\"}]}]}"}
{"recv_ts_ns": 1787746439979061194, "payload": "{\"channel\":\"l2_data\",\"timestamp\":\"2026-08-26T12:13:59.863881602Z\",\"sequence_num\":117,\"events\":[{\"type\":\"update\",\"product_id\":\"ATOM-USD\",\"updates\":[{\"side\":\"bid\",\"event_time\":\"2026-08-26T12:13:59.761611Z\",\"price_level\":\"1.5573\",\"new_quantity\":\"84.65\"},{\"side\":\"bid\",\"event_time\":\"2026-08-26T12:13:59.761611Z\",\"price_level\":\"1.5572\",\"new_quantity\":\"92.81\"},{\"side\":\"bid\",\"event_time\":\"2026-08-26T12:13:59.761611Z\",\"price_level\":\"1.557\",\"new_quantity\":\"278.27\"},{\"side\":\"bid\",\"event_time\":\"2026-08-26T12:13:59.761611Z\",\"price_level\":\"1.5569\",\"new_quantity\":\"310.66\"},{\"side\":\"bid\",\"event_time\":\"2026-08-26T12:13:59.761611Z\",\"price_level\":\"1.5568\",\"new_quantity\":\"92.81\"},{\"side\":\"bid\",\"event_time\":\"2026-08-26T12:13:59.761611Z\",\"price_level\":\"1.5559\",\"new_quantity\":\"151.33\"},{\"side\":\"bid\",\"event_time\":\"2026-08-26T12:13:59.761611Z\",\"price_level\":\"1.5558\",\"new_quantity\":\"637.24\"},{\"side\":\"bid\",\"event_time\":\"2026-08-26T12:13:59.761611Z\",\"price_level\":\"1.5557\",\"new_quantity\":\"642.79\"},{\"side\":\"bid\",\"event_time\":\"2026-08-26T12:13:59.761611Z\",\"price_level\":\"1.5556\",\"new_quantity\":\"92.81\"}]}]}"}
{"recv_ts_ns": 1787746440004941990, "payload": "{\"channel\":\"heartbeats\",\"timestamp\":\"2026-08-26T12:13:59.888338692Z\",\"sequence_num\":118,\"events\":[{\"current_time\":\"2026-08-26 12:13:59.885354056 +0000 UTC m=+24621.287340087\",\"heartbeat_counter\":24621}]}"}
{"recv_ts_ns": 1787746440022612939, "payload": "{\"channel\":\"l2_data\",\"timestamp\":\"2026-08-26T12:13:59.907397206Z\",\"sequence_num\":119,\"events\":[{\"type\":\"update\",\"product_id\":\"ATOM-USD\",\"updates\":[{\"side\":\"bid\",\"event_time\":\"2026-08-26T12:13:59.862099Z\",\"price_level\":\"1.5571\",\"new_quantity\":\"83.6\"}]}]}"}
{"recv_ts_ns": 1787746440058977953, "payload": "{\"channel\":\"l2_data\",\"timestamp\":\"2026-08-26T12:13:59.94286127Z\",\"sequence_num\":120,\"events\":[{\"type\":\"update\",\"product_id\":\"ATOM-USD\",\"updates\":[{\"side\":\"bid\",\"event_time\":\"2026-08-26T12:13:59.911877Z\",\"price_level\":\"1.5572\",\"new_quantity\":\"0\"}]}]}"}
{"recv_ts_ns": 1787746440597201298, "payload": "{\"channel\":\"l2_data\",\"timestamp\":\"2026-08-26T12:14:00.482776022Z\",\"sequence_num\":121,\"events\":[{\"type\":\"update\",\"product_id\":\"ATOM-USD\",\"updates\":[{\"side\":\"bid\",\"event_time\":\"2026-08-26T12:14:00.447678Z\",\"price_level\":\"1.5573\",\"new_quantity\":\"0\"},{\"side\":\"bid\",\"event_time\":\"2026-08-26T12:14:00.447678Z\",\"price_level\":\"1.5571\",\"new_quantity\":\"168.25\"},{\"side\":\"bid\",\"event_time\":\"2026-08-26T12:14:00.447678Z\",\"price_level\":\"1.557\",\"new_quantity\":\"185.46\"},{\"side\":\"bid\",\"event_time\":\"2026-08-26T12:14:00.447678Z\",\"price_level\":\"1.5563\",\"new_quantity\":\"100.65\"},{\"side\":\"bid\",\"event_time\":\"2026-08-26T12:14:00.447678Z\",\"price_level\":\"1.5554\",\"new_quantity\":\"1360.81\"},{\"side\":\"bid\",\"event_time\":\"2026-08-26T12:14:00.447678Z\",\"price_level\":\"1.5536\",\"new_quantity\":\"5876.31\"},{\"side\":\"bid\",\"event_time\":\"2026-08-26T12:14:00.447678Z\",\"price_level\":\"1.5535\",\"new_quantity\":\"20.25\"},{\"side\":\"bid\",\"event_time\":\"2026-08-26T12:14:00.447678Z\",\"price_level\":\"1.5533\",\"new_quantity\":\"0\"},{\"side\":\"bid\",\"event_time\":\"2026-08-26T12:14:00.447678Z\",\"price_level\":\"1.5468\",\"new_quantity\":\"0.72\"},{\"side\":\"bid\",\"event_time\":\"2026-08-26T12:14:00.447678Z\",\"price_level\":\"1.5452\",\"new_quantity\":\"20.25\"},{\"side\":\"offer\",\"event_time\":\"2026-08-26T12:14:00.447678Z\",\"price_level\":\"1.5612\",\"new_quantity\":\"0.71\"}]}]}"}
{"recv_ts_ns": 1787746440799385418, "payload": "{\"channel\":\"l2_data\",\"timestamp\":\"2026-08-26T12:14:00.684052324Z\",\"sequence_num\":122,\"events\":[{\"type\":\"update\",\"product_id\":\"ATOM-USD\",\"updates\":[{\"side\":\"bid\",\"event_time\":\"2026-08-26T12:14:00.654742Z\",\"price_level\":\"1.5536\",\"new_quantity\":\"0\"},{\"side\":\"bid\",\"event_time\":\"2026-08-26T12:14:00.654742Z\",\"price_level\":\"1.5533\",\"new_quantity\":\"5877.45\"},{\"side\":\"bid\",\"event_time\":\"2026-08-26T12:14:00.654742Z\",\"price_level\":\"1.5452\",\"new_quantity\":\"0\"},{\"side\":\"offer\",\"event_time\":\"2026-08-26T12:14:00.654742Z\",\"price_level\":\"1.5612\",\"new_quantity\":\"320.97\"}]}]}"}
{"recv_ts_ns": 1787746440847229685, "payload": "{\"channel\":\"l2_data\",\"timestamp\":\"2026-08-26T12:14:00.732863115Z\",\"sequence_num\":123,\"events\":[{\"type\":\"update\",\"product_id\":\"ATOM-USD\",\"updates\":[{\"side\":\"bid\",\"event_time\":\"2026-08-26T12:14:00.673296Z\",\"price_level\":\"1.5558\",\"new_quantity\":\"684.17\"},{\"side\":\"bid\",\"event_time\":\"2026-08-26T12:14:00.673296Z\",\"price_level\":\"1.5453\",\"new_quantity\":\"20.25\"}]}]}"}
{"recv_ts_ns": 1787746440946874317, "payload": "{\"channel\":\"l2_data\",\"timestamp\":\"2026-08-26T12:14:00.832353433Z\",\"sequence_num\":124,\"events\":[{\"type\":\"update\",\"product_id\":\"ATOM-USD\",\"updates\":[{\"side\":\"offer\",\"event_time\":\"2026-08-26T12:14:00.782326Z\",\"price_level\":\"1.5592\",\"new_quantity\":\"442.85\"},{\"side\":\"offer\",\"event_time\":\"2026-08-26T12:14:00.782326Z\",\"price_level\":\"1.5593\",\"new_quantity\":\"643.48\"},{\"side\":\"offer\",\"event_time\":\"2026-08-26T12:14:00.782326Z\",\"price_level\":\"1.5602\",\"new_quantity\":\"0\"},{\"side\":\"offer\",\"event_time\":\"2026-08-26T12:14:00.782326Z\",\"price_level\":\"1.5603\",\"new_quantity\":\"92.81\"}]}]}"}
{"recv_ts_ns": 1787746441002705324, "payload": "{\"channel\":\"heartbeats\",\"timestamp\":\"2026-08-26T12:14:00.887668958Z\",\"sequence_num\":125,\"events\":[{\"current_time\":\"2026-08-26 12:14:00.885240415 +0000 UTC m=+24622.287226446\",\"heartbeat_counter\":24622}]}"}
{"recv_ts_ns": 1787746441046075331, "payload": "{\"channel\":\"l2_data\",\"timestamp\":\"2026-08-26T12:14:00.931999053Z\",\"sequence_num\":126,\"events\":[{\"type\":\"update\",\"product_id\":\"ATOM-USD\",\"updates\":[{\"side\":\"bid\",\"event_time\":\"2026-08-26T12:14:00.908933Z\",\"price_level\":\"1.5542\",\"new_quantity\":\"0\"},{\"side\":\"bid\",\"event_time\":\"2026-08-26T12:14:00.908933Z\",\"price_level\":\"1.5535\",\"new_quantity\":\"5896.94\"},{\"side\":\"bid\",\"event_time\":\"2026-08-26T12:14:00.908933Z\",\"price_level\":\"1.5534\",\"new_quantity\":\"222.46\"},{\"side\":\"bid\",\"event_time\":\"2026-08-26T12:14:00.908933Z\",\"price_level\":\"1.5533\",\"new_quantity\":\"0\"}]}]}"}
{"recv_ts_ns": 1787746441259492435, "payload": "{\"channel\":\"l2_data\",\"timestamp\":\"2026-08-26T12:14:01.145387527Z\",\"sequence_num\":127,\"events\":[{\"type\":\"update\",\"product_id\":\"ATOM-USD\",\"updates\":[{\"side\":\"bid\",\"event_time\":\"2026-08-26T12:14:01.104945Z\",\"price_level\":\"1.5543\",\"new_quantity\":\"321.68\"}]}]}"}
{"recv_ts_ns": 1787746441305596564, "payload": "{\"channel\":\"l2_data\",\"timestamp\":\"2026-08-26T12:14:01.189908985Z\",\"sequence_num\":128,\"events\":[{\"type\":\"update\",\"product_id\":\"ATOM-USD\",\"updates\":[{\"side\":\"bid\",\"event_time\":\"2026-08-26T12:14:01.129102Z\",\"price_level\":\"1.5544\",\"new_quantity\":\"781.55\"}]}]}"}
{"recv_ts_ns": 1787746441447344904, "payload": "{\"channel\":\"l2_data\",\"timestamp\":\"2026-08-26T12:14:01.332304664Z\",\"sequence_num\":129,\"events\":[{\"type\":\"update\",\"product_id\":\"ATOM-USD\",\"updates\":[{\"side\":\"bid\",\"event_time\":\"2026-08-26T12:14:01.306758Z\",\"price_level\":\"1.5215\",\"new_quantity\":\"17.45\"}]}]}"}
{"recv_ts_ns": 1787746441499052402, "payload": "{\"channel\":\"l2_data\",\"timestamp\":\"2026-08-26T12:14:01.382348867Z\",\"sequence_num\":130,\"events\":[{\"type\":\"update\",\"product_id\":\"ATOM-USD\",\"updates\":[{\"side\":\"bid\",\"event_time\":\"2026-08-26T12:14:01.316734Z\",\"price_level\":\"1.5124\",\"new_quantity\":\"21.94\"},{\"side\":\"bid\",\"event_time\":\"2026-08-26T12:14:01.316734Z\",\"price_level\":\"1.5033\",\"new_quantity\":\"26.48\"}]}]}"}
{"recv_ts_ns": 1787746441597109584, "payload": "{\"channel\":\"l2_data\",\"timestamp\":\"2026-08-26T12:14:01.482618471Z\",\"sequence_num\":131,\"events\":[{\"type\":\"update\",\"product_id\":\"ATOM-USD\",\"updates\":[{\"side\":\"bid\",\"event_time\":\"2026-08-26T12:14:01.455187Z\",\"price_level\":\"1.5572\",\"new_quantity\":\"84.65\"},{\"side\":\"bid\",\"event_time\":\"2026-08-26T12:14:01.455187Z\",\"price_level\":\"1.5571\",\"new_quantity\":\"229.99\"},{\"side\":\"bid\",\"event_time\":\"2026-08-26T12:14:01.455187Z\",\"price_level\":\"1.557\",\"new_quantity\":\"245.21\"},{\"side\":\"bid\",\"event_time\":\"2026-08-26T12:14:01.455187Z\",\"price_level\":\"1.5569\",\"new_quantity\":\"150.09\"},{\"side\":\"bid\",\"event_time\":\"2026-08-26T12:14:01.455187Z\",\"price_level\":\"1.5559\",\"new_quantity\":\"160.67\"},{\"side\":\"bid\",\"event_time\":\"2026-08-26T12:14:01.455187Z\",\"price_level\":\"1.5558\",\"new_quantity\":\"523.49\"},{\"side\":\"bid\",\"event_time\":\"2026-08-26T12:14:01.455187Z\",\"price_level\":\"1.5551\",\"new_quantity\":\"0\"},{\"side\":\"bid\",\"event_time\":\"2026-08-26T12:14:01.455187Z\",\"price_level\":\"1.5502\",\"new_quantity\":\"20.25\"},{\"side\":\"bid\",\"event_time\":\"2026-08-26T12:14:01.455187Z\",\"price_level\":\"1.5453\",\"new_quantity\":\"0\"},{\"side\":\"offer\",\"event_time\":\"2026-08-26T12:14:01.455187Z\",\"price_level\":\"1.5583\",\"new_quantity\":\"92.81\"},{\"side\":\"offer\",\"event_time\":\"2026-08-26T12:14:01.455187Z\",\"price_level\":\"1.5585\",\"new_quantity\":\"80.2\"},{\"side\":\"offer\",\"event_time\":\"2026-08-26T12:14:01.455187Z\",\"price_level\":\"1.5588\",\"new_quantity\":\"20.25\"},{\"side\":\"offer\",\"event_time\":\"2026-08-26T12:14:01.455187Z\",\"price_level\":\"1.568\",\"new_quantity\":\"10\"},{\"side\":\"offer\",\"event_time\":\"2026-08-26T12:14:01.455187Z\",\"price_level\":\"1.5684\",\"new_quantity\":\"20.96\"}]}]}"}
{"recv_ts_ns": 1787746441696256964, "payload": "{\"channel\":\"l2_data\",\"timestamp\":\"2026-08-26T12:14:01.582013509Z\",\"sequence_num\":132,\"events\":[{\"type\":\"update\",\"product_id\":\"ATOM-USD\",\"updates\":[{\"side\":\"bid\",\"event_time\":\"2026-08-26T12:14:01.556838Z\",\"price_level\":\"1.5571\",\"new_quantity\":\"83.6\"},{\"side\":\"bid\",\"event_time\":\"2026-08-26T12:14:01.556838Z\",\"price_level\":\"1.557\",\"new_quantity\":\"160.56\"}]}]}"}
{"recv_ts_ns": 1787746441848034409, "payload": "{\"channel\":\"l2_data\",\"timestamp\":\"2026-08-26T12:14:01.732390658Z\",\"sequence_num\":133,\"events\":[{\"type\":\"update\",\"product_id\":\"ATOM-USD\",\"updates\":[{\"side\":\"bid\",\"event_time\":\"2026-08-26T12:14:01.681164Z\",\"price_level\":\"1.5563\",\"new_quantity\":\"147.58\"},{\"side\":\"bid\",\"event_time\":\"2026-08-26T12:14:01.681164Z\",\"price_level\":\"1.5558\",\"new_quantity\":\"476.56\"},{\"side\":\"offer\",\"event_time\":\"2026-08-26T12:14:01.681164Z\",\"price_level\":\"1.5584\",\"new_quantity\":\"80.21\"},{\"side\":\"offer\",\"event_time\":\"2026-08-26T12:14:01.681164Z\",\"price_level\":\"1.5585\",\"new_quantity\":\"0\"}]}]}"}
{"recv_ts_ns": 1787746441965773477, "payload": "{\"channel\":\"l2_data\",\"timestamp\":\"2026-08-26T12:14:01.851052976Z\",\"sequence_num\":134,\"events\":[{\"type\":\"update\",\"product_id\":\"ATOM-USD\",\"updates\":[{\"side\":\"bid\",\"event_time\":\"2026-08-26T12:14:01.79961Z\",\"price_level\":\"1.5567\",\"new_quantity\":\"20.25\"},{\"side\":\"bid\",\"event_time\":\"2026-08-26T12:14:01.79961Z\",\"price_level\":\"1.5503\",\"new_quantity\":\"5900.45\"},{\"side\":\"bid\",\"event_time\":\"2026-08-26T12:14:01.79961Z\",\"price_level\":\"1.5501\",\"new_quantity\":\"0\"},{\"side\":\"bid\",\"event_time\":\"2026-08-26T12:14:01.79961Z\",\"price_level\":\"1.5469\",\"new_quantity\":\"0\"}]}]}"}
{"recv_ts_ns": 1787746442008097994, "payload": "{\"channel\":\"heartbeats\",\"timestamp\":\"2026-08-26T12:14:01.888132785Z\",\"sequence_num\":135,\"events\":[{\"current_time\":\"2026-08-26 12:14:01.885198579 +0000 UTC m=+24623.287184612\",\"heartbeat_counter\":24623}]}"}
{"recv_ts_ns": 1787746442008195709, "payload": "{\"channel\":\"l2_data\",\"timestamp\":\"2026-08-26T12:14:01.892138466Z\",\"sequence_num\":136,\"events\":[{\"type\":\"update\",\"product_id\":\"ATOM-USD\",\"updates\":[{\"side\":\"bid\",\"event_time\":\"2026-08-26T12:14:01.843027Z\",\"price_level\":\"1.5571\",\"new_quantity\":\"234.86\"},{\"side\":\"bid\",\"event_time\":\"2026-08-26T12:14:01.843027Z\",\"price_level\":\"1.557\",\"new_quantity\":\"253.37\"},{\"side\":\"bid\",\"event_time\":\"2026-08-26T12:14:01.843027Z\",\"price_level\":\"1.5568\",\"new_quantity\":\"92.81\"},{\"side\":\"bid\",\"event_time\":\"2026-08-26T12:14:01.843027Z\",\"price_level\":\"1.5567\",\"new_quantity\":\"20.25\"},{\"side\":\"bid\",\"event_time\":\"2026-08-26T12:14:01.843027Z\",\"price_level\":\"1.5554\",\"new_quantity\":\"1268\"},{\"side\":\"bid\",\"event_time\":\"2026-08-26T12:14:01.843027Z\",\"price_level\":\"1.5536\",\"new_quantity\":\"20.25\"},{\"side\":\"bid\",\"event_time\":\"2026-08-26T12:14:01.843027Z\",\"price_level\":\"1.5535\",\"new_quantity\":\"5876.69\"},{\"side\":\"bid\",\"event_time\":\"2026-08-26T12:14:01.843027Z\",\"price_level\":\"1.5502\",\"new_quantity\":\"0\"},{\"side\":\"bid\",\"event_time\":\"2026-08-26T12:14:01.843027Z\",\"price_level\":\"1.5487\",\"new_quantity\":\"7846.06\"},{\"side\":\"bid\",\"event_time\":\"2026-08-26T12:14:01.843027Z\",\"price_level\":\"1.5485\",\"new_quantity\":\"0\"},{\"side\":\"bid\",\"event_time\":\"2026-08-26T12:14:01.843027Z\",\"price_level\":\"1.5456\",\"new_quantity\":\"0.72\"}]}]}"}
{"recv_ts_ns": 1787746442065086086, "payload": "{\"channel\":\"l2_data\",\"timestamp\":\"2026-08-26T12:14:01.951370943Z\",\"sequence_num\":137,\"events\":[{\"type\":\"update\",\"product_id\":\"ATOM-USD\",\"updates\":[{\"side\":\"bid\",\"event_time\":\"2026-08-26T12:14:01.897236Z\",\"price_level\":\"1.5561\",\"new_quantity\":\"151.32\"},{\"side\":\"bid\",\"event_time\":\"2026-08-26T12:14:01.897236Z\",\"price_level\":\"1.556\",\"new_quantity\":\"253.47\"},{\"side\":\"bid\",\"event_time\":\"2026-08-26T12:14:01.897236Z\",\"price_level\":\"1.5559\",\"new_quantity\":\"0\"},{\"side\":\"bid\",\"event_time\":\"2026-08-26T12:14:01.897236Z\",\"price_level\":\"1.5556\",\"new_quantity\":\"735.58\"},{\"side\":\"bid\",\"event_time\":\"2026-08-26T12:14:01.897236Z\",\"price_level\":\"1.5541\",\"new_quantity\":\"0\"}]}]}"}
{"recv_ts_ns": 1787746442155018887, "payload": "{\"channel\":\"l2_data\",\"timestamp\":\"2026-08-26T12:14:02.040659689Z\",\"sequence_num\":138,\"events\":[{\"type\":\"update\",\"product_id\":\"ATOM-USD\",\"updates\":[{\"side\":\"bid\",\"event_time\":\"2026-08-26T12:14:01.998249Z\",\"price_level\":\"1.5568\",\"new_quantity\":\"113.06\"},{\"side\":\"bid\",\"event_time\":\"2026-08-26T12:14:01.998249Z\",\"price_level\":\"1.5567\",\"new_quantity\":\"0\"},{\"side\":\"bid\",\"event_time\":\"2026-08-26T12:14:01.998249Z\",\"price_level\":\"1.5565\",\"new_quantity\":\"0\"},{\"side\":\"bid\",\"event_time\":\"2026-08-26T12:14:01.998249Z\",\"price_level\":\"1.552\",\"new_quantity\":\"20.25\"},{\"side\":\"bid\",\"event_time\":\"2026-08-26T12:14:01.998249Z\",\"price_level\":\"1.5456\",\"new_quantity\":\"0.72\"}]}]}"}
{"recv_ts_ns": 1787746442207947536, "payload": "{\"channel\":\"l2_data\",\"timestamp\":\"2026-08-26T12:14:02.093585833Z\",\"sequence_num\":139,\"events\":[{\"type\":\"update\",\"product_id\":\"ATOM-USD\",\"updates\":[{\"side\":\"bid\",\"event_time\":\"2026-08-26T12:14:02.05512Z\",\"price_level\":\"1.5568\",\"new_quantity\":\"92.81\"},{\"side\":\"bid\",\"event_time\":\"2026-08-26T12:14:02.05512Z\",\"price_level\":\"1.5567\",\"new_quantity\":\"20.25\"},{\"side\":\"bid\",\"event_time\":\"2026-08-26T12:14:02.05512Z\",\"price_level\":\"1.5551\",\"new_quantity\":\"20.25\"},{\"side\":\"bid\",\"event_time\":\"2026-08-26T12:14:02.05512Z\",\"price_level\":\"1.5519\",\"new_quantity\":\"1490.69\"}]}]}"}
{"recv_ts_ns": 1787746442296707450, "payload": "{\"channel\":\"l2_data\",\"timestamp\":\"2026-08-26T12:14:02.181683265Z\",\"sequence_num\":140,\"events\":[{\"type\":\"update\",\"product_id\":\"ATOM-USD\",\"updates\":[{\"side\":\"bid\",\"event_time\":\"2026-08-26T12:14:02.072738Z\",\"price_level\":\"1.5471\",\"new_quantity\":\"20.25\"},{\"side\":\"bid\",\"event_time\":\"2026-08-26T12:14:02.072738Z\",\"price_level\":\"1.5455\",\"new_quantity\":\"20.25\"}]}]}"}
{"recv_ts_ns": 1787746442698045495, "payload": "{\"channel\":\"l2_data\",\"timestamp\":\"2026-08-26T12:14:02.582333323Z\",\"sequence_num\":141,\"events\":[{\"type\":\"update\",\"product_id\":\"ATOM-USD\",\"updates\":[{\"side\":\"bid\",\"event_time\":\"2026-08-26T12:14:02.542909Z\",\"price_level\":\"1.5542\",\"new_quantity\":\"2176.36\"}]}]}"}
{"recv_ts_ns": 1787746443003254378, "payload": "{\"channel\":\"heartbeats\",\"timestamp\":\"2026-08-26T12:14:02.887541384Z\",\"sequence_num\":142,\"events\":[{\"current_time\":\"2026-08-26 12:14:02.885193316 +0000 UTC m=+24624.287179350\",\"heartbeat_counter\":24624}]}"}
{"recv_ts_ns": 1787746443147768466, "payload": "{\"channel\":\"l2_data\",\"timestamp\":\"2026-08-26T12:14:03.033190096Z\",\"sequence_num\":143,\"events\":[{\"type\":\"update\",\"product_id\":\"ATOM-USD\",\"updates\":[{\"side\":\"bid\",\"event_time\":\"2026-08-26T12:14:03.002989Z\",\"price_level\":\"1.5569\",\"new_quantity\":\"0\"},{\"side\":\"bid\",\"event_time\":\"2026-08-26T12:14:03.002989Z\",\"price_level\":\"1.5557\",\"new_quantity\":\"1081.93\"},{\"side\":\"offer\",\"event_time\":\"2026-08-26T12:14:03.002989Z\",\"price_level\":\"1.5592\",\"new_quantity\":\"172.97\"},{\"side\":\"offer\",\"event_time\":\"2026-08-26T12:14:03.002989Z\",\"price_level\":\"1.5593\",\"new_quantity\":\"238.35\"}]}]}"}
{"recv_ts_ns": 1787746443547672396, "payload": "{\"channel\":\"l2_data\",\"timestamp\":\"2026-08-26T12:14:03.432076089Z\",\"sequence_num\":144,\"events\":[{\"type\":\"update\",\"product_id\":\"ATOM-USD\",\"updates\":[{\"side\":\"bid\",\"event_time\":\"2026-08-26T12:14:03.399071Z\",\"price_level\":\"1.5573\",\"new_quantity\":\"92.81\"}]}]}"}
{"recv_ts_ns": 1787746443596873293, "payload": "{\"channel\":\"l2_data\",\"timestamp\":\"2026-08-26T12:14:03.482591714Z\",\"sequence_num\":145,\"events\":[{\"type\":\"update\",\"product_id\":\"ATOM-USD\",\"updates\":[{\"side\":\"bid\",\"event_time\":\"2026-08-26T12:14:03.421858Z\",\"price_level\":\"1.5573\",\"new_quantity\":\"0\"},{\"side\":\"bid\",\"event_time\":\"2026-08-26T12:14:03.421858Z\",\"price_level\":\"1.5572\",\"new_quantity\":\"84.65\"}]}]}"}
{"recv_ts_ns": 1787746443846730594, "payload": "{\"channel\":\"l2_data\",\"timestamp\":\"2026-08-26T12:14:03.732195278Z\",\"sequence_num\":146,\"events\":[{\"type\":\"update\",\"product_id\":\"ATOM-USD\",\"updates\":[{\"side\":\"bid\",\"event_time\":\"2026-08-26T12:14:03.695621Z\",\"price_level\":\"1.5573\",\"new_quantity\":\"92.81\"}]}]}"}
{"recv_ts_ns": 1787746443897314078, "payload": "{\"channel\":\"l2_data\",\"timestamp\":\"2026-08-26T12:14:03.782200764Z\",\"sequence_num\":147,\"events\":[{\"type\":\"update\",\"product_id\":\"ATOM-USD\",\"updates\":[{\"side\":\"bid\",\"event_time\":\"2026-08-26T12:14:03.752605Z\",\"price_level\":\"1.5573\",\"new_quantity\":\"0\"},{\"side\":\"bid\",\"event_time\":\"2026-08-26T12:14:03.752605Z\",\"price_level\":\"1.5572\",\"new_quantity\":\"84.65\"}]}]}"}
{"recv_ts_ns": 1787746443996965840, "payload": "{\"channel\":\"l2_data\",\"timestamp\":\"2026-08-26T12:14:03.882729002Z\",\"sequence_num\":148,\"events\":[{\"type\":\"update\",\"product_id\":\"ATOM-USD\",\"updates\":[{\"side\":\"bid\",\"event_time\":\"2026-08-26T12:14:03.83426Z\",\"price_level\":\"1.5561\",\"new_quantity\":\"160.65\"},{\"side\":\"bid\",\"event_time\":\"2026-08-26T12:14:03.83426Z\",\"price_level\":\"1.556\",\"new_quantity\":\"92.81\"}]}]}"}
{"recv_ts_ns": 1787746444000663420, "payload": "{\"channel\":\"heartbeats\",\"timestamp\":\"2026-08-26T12:14:03.886378678Z\",\"sequence_num\":149,\"events\":[{\"current_time\":\"2026-08-26 12:14:03.885279139 +0000 UTC m=+24625.287265171\",\"heartbeat_counter\":24625}]}"}
{"recv_ts_ns": 1787746444199671065, "payload": "{\"channel\":\"l2_data\",\"timestamp\":\"2026-08-26T12:14:04.082838116Z\",\"sequence_num\":150,\"events\":[{\"type\":\"update\",\"product_id\":\"ATOM-USD\",\"updates\":[{\"side\":\"bid\",\"event_time\":\"2026-08-26T12:14:04.053591Z\",\"price_level\":\"1.5215\",\"new_quantity\":\"0\"},{\"side\":\"bid\",\"event_time\":\"2026-08-26T12:14:04.053591Z\",\"price_level\":\"1.5124\",\"new_quantity\":\"0\"},{\"side\":\"bid\",\"event_time\":\"2026-08-26T12:14:04.053591Z\",\"price_level\":\"1.5033\",\"new_quantity\":\"0\"}]}]}"}
{"recv_ts_ns": 1787746444834724992, "payload": "{\"channel\":\"l2_data\",\"timestamp\":\"2026-08-26T12:14:04.719388666Z\",\"sequence_num\":151,\"events\":[{\"type\":\"update\",\"product_id\":\"ATOM-USD\",\"updates\":[{\"side\":\"bid\",\"event_time\":\"2026-08-26T12:14:04.664503Z\",\"price_level\":\"1.5571\",\"new_quantity\":\"244.15\"},{\"side\":\"bid\",\"event_time\":\"2026-08-26T12:14:04.664503Z\",\"price_level\":\"1.557\",\"new_quantity\":\"92.81\"}]}]}"}
{"recv_ts_ns": 1787746444854959512, "payload": "{\"channel\":\"l2_data\",\"timestamp\":\"2026-08-26T12:14:04.739727183Z\",\"sequence_num\":152,\"events\":[{\"type\":\"update\",\"product_id\":\"ATOM-USD\",\"updates\":[{\"side\":\"bid\",\"event_time\":\"2026-08-26T12:14:04.671857Z\",\"price_level\":\"1.5573\",\"new_quantity\":\"84.65\"},{\"side\":\"bid\",\"event_time\":\"2026-08-26T12:14:04.671857Z\",\"price_level\":\"1.5572\",\"new_quantity\":\"145.76\"},{\"side\":\"bid\",\"event_time\":\"2026-08-26T12:14:04.671857Z\",\"price_level\":\"1.5571\",\"new_quantity\":\"328.8\"},{\"side\":\"offer\",\"event_time\":\"2026-08-26T12:14:04.671857Z\",\"price_level\":\"1.5605\",\"new_quantity\":\"5989.69\"},{\"side\":\"offer\",\"event_time\":\"2026-08-26T12:14:04.671857Z\",\"price_level\":\"1.5607\",\"new_quantity\":\"0\"}]}]}"}
{"recv_ts_ns": 1787746444918877916, "payload": "{\"channel\":\"l2_data\",\"timestamp\":\"2026-08-26T12:14:04.8044254Z\",\"sequence_num\":153,\"events\":[{\"type\":\"update\",\"product_id\":\"ATOM-USD\",\"updates\":[{\"side\":\"bid\",\"event_time\":\"2026-08-26T12:14:04.774207Z\",\"price_level\":\"1.5571\",\"new_quantity\":\"244.15\"}]}]}"}
{"recv_ts_ns": 1787746444950033001, "payload": "{\"channel\":\"l2_data\",\"timestamp\":\"2026-08-26T12:14:04.833252518Z\",\"sequence_num\":154,\"events\":[{\"type\":\"update\",\"product_id\":\"ATOM-USD\",\"updates\":[{\"side\":\"offer\",\"event_time\":\"2026-08-26T12:14:04.781081Z\",\"price_level\":\"1.5605\",\"new_quantity\":\"413.22\"},{\"side\":\"offer\",\"event_time\":\"2026-08-26T12:14:04.781081Z\",\"price_level\":\"1.5607\",\"new_quantity\":\"5575.75\"}]}]}"}
{"recv_ts_ns": 1787746445006072359, "payload": "{\"channel\":\"heartbeats\",\"timestamp\":\"2026-08-26T12:14:04.888417268Z\",\"sequence_num\":155,\"events\":[{\"current_time\":\"2026-08-26 12:14:04.885181187 +0000 UTC m=+24626.287167218\",\"heartbeat_counter\":24626}]}"}
{"recv_ts_ns": 1787746445198548407, "payload": "{\"channel\":\"l2_data\",\"timestamp\":\"2026-08-26T12:14:05.082101874Z\",\"sequence_num\":156,\"events\":[{\"type\":\"update\",\"product_id\":\"ATOM-USD\",\"updates\":[{\"side\":\"bid\",\"event_time\":\"2026-08-26T12:14:05.06029Z\",\"price_level\":\"1.5287\",\"new_quantity\":\"16.97\"}]}]}"}
{"recv_ts_ns": 1787746445247750923, "payload": "{\"channel\":\"l2_data\",\"timestamp\":\"2026-08-26T12:14:05.132395221Z\",\"sequence_num\":157,\"events\":[{\"type\":\"update\",\"product_id\":\"ATOM-USD\",\"updates\":[{\"side\":\"bid\",\"event_time\":\"2026-08-26T12:14:05.075984Z\",\"price_level\":\"1.5214\",\"new_quantity\":\"21.31\"},{\"side\":\"bid\",\"event_time\":\"2026-08-26T12:14:05.075984Z\",\"price_level\":\"1.5141\",\"new_quantity\":\"25.7\"}]}]}"}
{"recv_ts_ns": 1787746445797409860, "payload": "{\"channel\":\"l2_data\",\"timestamp\":\"2026-08-26T12:14:05.682624773Z\",\"sequence_num\":158,\"events\":[{\"type\":\"update\",\"product_id\":\"ATOM-USD\",\"updates\":[{\"side\":\"bid\",\"event_time\":\"2026-08-26T12:14:05.659137Z\",\"price_level\":\"1.557\",\"new_quantity\":\"0\"},{\"side\":\"bid\",\"event_time\":\"2026-08-26T12:14:05.659137Z\",\"price_level\":\"1.5554\",\"new_quantity\":\"1360.81\"}]}]}"}
