{"recv_ts_ns":1787745356222520059,"payload":"{\"channel\":\"status\",\"type\":\"update\",\"data\":[{\"version\":\"2.0.10\",\"system\":\"online\",\"api_version\":\"v2\",\"connection_id\":17408390984690501469}]}"}
{"recv_ts_ns":1787745356526583840,"payload":"{\"method\":\"subscribe\",\"result\":{\"channel\":\"instrument\",\"snapshot\":true,\"warnings\":[\"tick_size is deprecated, use price_increment\"]},\"success\":true,\"time_in\":\"2026-08-26T11:55:56.381008Z\",\"time_out\":\"2026-08-26T11:55:56.381042Z\"}"}
{"recv_ts_ns":1787745356526640542,"payload":"{\"method\":\"subscribe\",\"result\":{\"channel\":\"book\",\"depth\":25,\"snapshot\":true,\"symbol\":\"BTC/USD\"},\"success\":true,\"time_in\":\"2026-08-26T11:55:56.381072Z\",\"time_out\":\"2026-08-26T11:55:56.381094Z\"}"}
{"recv_ts_ns":1787745356526680637,"payload":"{\"method\":\"subscribe\",\"result\":{\"channel\":\"trade\",\"snapshot\":false,\"symbol\":\"BTC/USD\"},\"success\":true,\"time_in\":\"2026-08-26T11:55:56.381114Z\",\"time_out\":\"2026-08-26T11:55:56.381124Z\"}"}
{"recv_ts_ns":1787745357149287135,"payload":"{\"channel\":\"instrument\",\"type\":\"snapshot\",\"data\":{\"assets\":[],\"pairs\":[{\"symbol\":\"BTC/USD\",\"base\":\"BTC\",\"quote\":\"USD\",\"status\":\"online\",\"qty_precision\":8,\"qty_increment\":1e-08,\"price_precision\":1,\"cost_precision\":5,\"marginable\":true,\"has_index\":true,\"ws_display_price_precision\":1,\"cost_min\":0.5,\"margin_initial\":0.1,\"position_limit_long\":350,\"position_limit_short\":250,\"tick_size\":0.1,\"price_increment\":0.1,\"qty_min\":5e-05}]}}"}
{"recv_ts_ns":1787745357169778300,"payload":"{\"channel\":\"book\",\"type\":\"snapshot\",\"data\":[{\"symbol\":\"BTC/USD\",\"bids\":[{\"price\":78500.6,\"qty\":0.03755097},{\"price\":78500.5,\"qty\":0.00031250},{\"price\":78500.0,\"qty\":0.00006370},{\"price\":78498.1,\"qty\":0.00030000},{\"price\":78496.8,\"qty\":0.63696846},{\"price\":78496.6,\"qty\":0.00005100},{\"price\":78495.4,\"qty\":0.01273960},{\"price\":78494.3,\"qty\":0.04603199},{\"price\":78494.2,\"qty\":0.63698895},{\"price\":78492.7,\"qty\":0.00005100},{\"price\":78492.6,\"qty\":0.05060000},{\"price\":78490.6,\"qty\":0.01518308},{\"price\":78490.2,\"qty\":0.95541150},{\"price\":78490.0,\"qty\":0.85606579},{\"price\":78489.9,\"qty\":0.63702417},{\"price\":78488.8,\"qty\":0.00005100},{\"price\":78486.5,\"qty\":0.04795432},{\"price\":78486.4,\"qty\":0.11000000},{\"price\":78484.8,\"qty\":0.00005100},{\"price\":78484.7,\"qty\":0.05060000},{\"price\":78482.7,\"qty\":0.00005000},{\"price\":78480.6,\"qty\":0.00010100},{\"price\":78480.1,\"qty\":3.03208694},{\"price\":78480.0,\"qty\":0.57349550},{\"price\":78479.9,\"qty\":1.92115694}],\"asks\":[{\"price\":78500.7,\"qty\":0.05733533},{\"price\":78503.1,\"qty\":1.13192174},{\"price\":78503.3,\"qty\":0.01538470},{\"price\":78504.3,\"qty\":3.03206150},{\"price\":78504.4,\"qty\":0.63695851},{\"price\":78505.4,\"qty\":0.01655857},{\"price\":78505.5,\"qty\":0.95541150},{\"price\":78506.9,\"qty\":1.49295294},{\"price\":78508.3,\"qty\":0.00005100},{\"price\":78508.4,\"qty\":0.46086803},{\"price\":78508.8,\"qty\":0.22392245},{\"price\":78510.8,\"qty\":1.27399169},{\"price\":78510.9,\"qty\":0.27750776},{\"price\":78511.2,\"qty\":0.02567256},{\"price\":78511.8,\"qty\":0.12224800},{\"price\":78512.2,\"qty\":0.00005100},{\"price\":78512.3,\"qty\":0.05060000},{\"price\":78512.7,\"qty\":0.02292622},{\"price\":78513.0,\"qty\":0.00254734},{\"price\":78513.6,\"qty\":0.63683307},{\"price\":78514.2,\"qty\":0.11000000},{\"price\":78515.7,\"qty\":0.14841444},{\"price\":78515.8,\"qty\":0.11364277},{\"price\":78516.0,\"qty\":0.01273625},{\"price\":78516.2,\"qty\":0.00005100}],\"checksum\":1184156425,\"timestamp\":\"2026-08-26T11:55:56.663054Z\"}]}"}
{"recv_ts_ns":1787745357169843067,"payload":"{\"channel\":\"heartbeat\"}"}
{"recv_ts_ns":1787745357169878764,"payload":"{\"channel\":\"book\",\"type\":\"update\",\"data\":[{\"symbol\":\"BTC/USD\",\"bids\":[{\"price\":78480.1,\"qty\":0.00000000},{\"price\":78476.5,\"qty\":0.00005000},{\"price\":78484.8,\"qty\":3.03210574}],\"asks\":[],\"checksum\":1184156425,\"timestamp\":\"2026-08-26T11:55:56.865741Z\"}]}"}
{"recv_ts_ns":1787745357169892353,"payload":"{\"channel\":\"book\",\"type\":\"update\",\"data\":[{\"symbol\":\"BTC/USD\",\"bids\":[{\"price\":78486.5,\"qty\":0.00000000},{\"price\":78475.0,\"qty\":1.27429881}],\"asks\":[],\"checksum\":1184156425,\"timestamp\":\"2026-08-26T11:55:56.867236Z\"}]}"}
{"recv_ts_ns":1787745357169903508,"payload":"{\"channel\":\"book\",\"type\":\"update\",\"data\":[{\"symbol\":\"BTC/USD\",\"bids\":[{\"price\":78484.9,\"qty\":0.53588010}],\"asks\":[],\"checksum\":1184156425,\"timestamp\":\"2026-08-26T11:55:56.868865Z\"}]}"}
{"recv_ts_ns":1787745357169918107,"payload":"{\"channel\":\"book\",\"type\":\"update\",\"data\":[{\"symbol\":\"BTC/USD\",\"bids\":[{\"price\":78484.8,\"qty\":0.00005100},{\"price\":78480.1,\"qty\":3.03208167}],\"asks\":[],\"checksum\":1184156425,\"timestamp\":\"2026-08-26T11:55:56.895375Z\"}]}"}
{"recv_ts_ns":1787745357169928631,"payload":"{\"channel\":\"book\",\"type\":\"update\",\"data\":[{\"symbol\":\"BTC/USD\",\"bids\":[{\"price\":78484.9,\"qty\":0.00000000},{\"price\":78476.5,\"qty\":0.00005000}],\"asks\":[],\"checksum\":1184156425,\"timestamp\":\"2026-08-26T11:55:56.896933Z\"}]}"}
{"recv_ts_ns":1787745357169940072,"payload":"{\"channel\":\"book\",\"type\":\"update\",\"data\":[{\"symbol\":\"BTC/USD\",\"bids\":[{\"price\":78486.5,\"qty\":0.04795432}],\"asks\":[],\"checksum\":1184156425,\"timestamp\":\"2026-08-26T11:55:56.898428Z\"}]}"}
{"recv_ts_ns":1787745357169951147,"payload":"{\"channel\":\"book\",\"type\":\"update\",\"data\":[{\"symbol\":\"BTC/USD\",\"bids\":[],\"asks\":[{\"price\":78503.1,\"qty\":1.15329850}],\"checksum\":400418376,\"timestamp\":\"2026-08-26T11:55:56.960852Z\"}]}"}
{"recv_ts_ns":1787745357169962101,"payload":"{\"channel\":\"book\",\"type\":\"update\",\"data\":[{\"symbol\":\"BTC/USD\",\"bids\":[{\"price\":78480.1,\"qty\":0.00000000},{\"price\":78476.5,\"qty\":0.00005000},{\"price\":78484.8,\"qty\":3.03210646}],\"asks\":[],\"checksum\":400418376,\"timestamp\":\"2026-08-26T11:55:56.983262Z\"}]}"}
{"recv_ts_ns":1787745357169974583,"payload":"{\"channel\":\"book\",\"type\":\"update\",\"data\":[{\"symbol\":\"BTC/USD\",\"bids\":[{\"price\":78486.5,\"qty\":0.00000000},{\"price\":78475.0,\"qty\":1.27429881}],\"asks\":[],\"checksum\":400418376,\"timestamp\":\"2026-08-26T11:55:56.984554Z\"}]}"}
{"recv_ts_ns":1787745357169993188,"payload":"{\"channel\":\"book\",\"type\":\"update\",\"data\":[{\"symbol\":\"BTC/USD\",\"bids\":[{\"price\":78484.9,\"qty\":0.53588010}],\"asks\":[],\"checksum\":400418376,\"timestamp\":\"2026-08-26T11:55:56.985908Z\"}]}"}
{"recv_ts_ns":1787745357170004438,"payload":"{\"channel\":\"book\",\"type\":\"update\",\"data\":[{\"symbol\":\"BTC/USD\",\"bids\":[],\"asks\":[{\"price\":78515.7,\"qty\":0.00000000},{\"price\":78516.3,\"qty\":0.01292474}],\"checksum\":400418376,\"timestamp\":\"2026-08-26T11:55:56.988514Z\"}]}"}
{"recv_ts_ns":1787745357170014978,"payload":"{\"channel\":\"book\",\"type\":\"update\",\"data\":[{\"symbol\":\"BTC/USD\",\"bids\":[],\"asks\":[{\"price\":78515.7,\"qty\":0.06821332}],\"checksum\":400418376,\"timestamp\":\"2026-08-26T11:55:56.990215Z\"}]}"}
{"recv_ts_ns":1787745357170025613,"payload":"{\"channel\":\"book\",\"type\":\"update\",\"data\":[{\"symbol\":\"BTC/USD\",\"bids\":[{\"price\":78500.5,\"qty\":0.00010000}],\"asks\":[],\"checksum\":2753459978,\"timestamp\":\"2026-08-26T11:55:56.996786Z\"}]}"}
{"recv_ts_ns":1787745357184451420,"payload":"{\"channel\":\"book\",\"type\":\"update\",\"data\":[{\"symbol\":\"BTC/USD\",\"bids\":[{\"price\":78500.5,\"qty\":0.00000000},{\"price\":78475.0,\"qty\":1.27429881}],\"asks\":[],\"checksum\":484426174,\"timestamp\":\"2026-08-26T11:55:57.034582Z\"}]}"}
{"recv_ts_ns":1787745357285163535,"payload":"{\"channel\":\"book\",\"type\":\"update\",\"data\":[{\"symbol\":\"BTC/USD\",\"bids\":[{\"price\":78484.8,\"qty\":0.00005100},{\"price\":78480.1,\"qty\":3.03208560}],\"asks\":[],\"checksum\":484426174,\"timestamp\":\"2026-08-26T11:55:57.137805Z\"}]}"}
{"recv_ts_ns":1787745357285205315,"payload":"{\"channel\":\"book\",\"type\":\"update\",\"data\":[{\"symbol\":\"BTC/USD\",\"bids\":[{\"price\":78484.9,\"qty\":0.00000000},{\"price\":78475.0,\"qty\":1.27429881}],\"asks\":[],\"checksum\":484426174,\"timestamp\":\"2026-08-26T11:55:57.139414Z\"}]}"}
{"recv_ts_ns":1787745357308219119,"payload":"{\"channel\":\"book\",\"type\":\"update\",\"data\":[{\"symbol\":\"BTC/USD\",\"bids\":[],\"asks\":[{\"price\":78511.8,\"qty\":0.00000000},{\"price\":78516.3,\"qty\":0.01292474}],\"checksum\":484426174,\"timestamp\":\"2026-08-26T11:55:57.162396Z\"}]}"}
{"recv_ts_ns":1787745357309968323,"payload":"{\"channel\":\"book\",\"type\":\"update\",\"data\":[{\"symbol\":\"BTC/USD\",\"bids\":[{\"price\":78480.0,\"qty\":0.61302750}],\"asks\":[],\"checksum\":484426174,\"timestamp\":\"2026-08-26T11:55:57.164478Z\"}]}"}
{"recv_ts_ns":1787745357407283835,"payload":"{\"channel\":\"book\",\"type\":\"update\",\"data\":[{\"symbol\":\"BTC/USD\",\"bids\":[],\"asks\":[{\"price\":78508.1,\"qty\":0.12228700}],\"checksum\":2889230717,\"timestamp\":\"2026-08-26T11:55:57.262114Z\"}]}"}
{"recv_ts_ns":1787745357423874887,"payload":"{\"channel\":\"book\",\"type\":\"update\",\"data\":[{\"symbol\":\"BTC/USD\",\"bids\":[{\"price\":78480.1,\"qty\":0.00000000},{\"price\":78474.9,\"qty\":0.67473263},{\"price\":78485.0,\"qty\":3.03205901}],\"asks\":[],\"checksum\":2889230717,\"timestamp\":\"2026-08-26T11:55:57.278205Z\"}]}"}
{"recv_ts_ns":1787745357426056658,"payload":"{\"channel\":\"book\",\"type\":\"update\",\"data\":[{\"symbol\":\"BTC/USD\",\"bids\":[{\"price\":78485.1,\"qty\":0.51263350}],\"asks\":[],\"checksum\":2889230717,\"timestamp\":\"2026-08-26T11:55:57.279614Z\"}]}"}
{"recv_ts_ns":1787745357453490453,"payload":"{\"channel\":\"book\",\"type\":\"update\",\"data\":[{\"symbol\":\"BTC/USD\",\"bids\":[{\"price\":78485.0,\"qty\":0.00000000},{\"price\":78475.0,\"qty\":1.27429881},{\"price\":78480.1,\"qty\":3.03209738}],\"asks\":[],\"checksum\":2889230717,\"timestamp\":\"2026-08-26T11:55:57.308049Z\"}]}"}
{"recv_ts_ns":1787745357456354560,"payload":"{\"channel\":\"book\",\"type\":\"update\",\"data\":[{\"symbol\":\"BTC/USD\",\"bids\":[{\"price\":78485.1,\"qty\":0.00000000},{\"price\":78475.0,\"qty\":1.27429881}],\"asks\":[],\"checksum\":2889230717,\"timestamp\":\"2026-08-26T11:55:57.309358Z\"}]}"}
{"recv_ts_ns":1787745357456742298,"payload":"{\"channel\":\"book\",\"type\":\"update\",\"data\":[{\"symbol\":\"BTC/USD\",\"bids\":[{\"price\":78486.5,\"qty\":0.04795432}],\"asks\":[],\"checksum\":2889230717,\"timestamp\":\"2026-08-26T11:55:57.311028Z\"}]}"}
{"recv_ts_ns":1787745357657344759,"payload":"{\"channel\":\"book\",\"type\":\"update\",\"data\":[{\"symbol\":\"BTC/USD\",\"bids\":[],\"asks\":[{\"price\":78508.1,\"qty\":0.00000000},{\"price\":78516.3,\"qty\":0.01292474}],\"checksum\":484426174,\"timestamp\":\"2026-08-26T11:55:57.511423Z\"}]}"}
{"recv_ts_ns":1787745357662538098,"payload":"{\"channel\":\"book\",\"type\":\"update\",\"data\":[{\"symbol\":\"BTC/USD\",\"bids\":[{\"price\":78480.1,\"qty\":0.00000000},{\"price\":78475.0,\"qty\":1.27429881},{\"price\":78484.8,\"qty\":3.03210224}],\"asks\":[],\"checksum\":484426174,\"timestamp\":\"2026-08-26T11:55:57.515872Z\"}]}"}
{"recv_ts_ns":1787745357667053059,"payload":"{\"channel\":\"book\",\"type\":\"update\",\"data\":[{\"symbol\":\"BTC/USD\",\"bids\":[{\"price\":78486.5,\"qty\":0.00000000},{\"price\":78474.9,\"qty\":0.67473263}],\"asks\":[],\"checksum\":484426174,\"timestamp\":\"2026-08-26T11:55:57.518734Z\"}]}"}
{"recv_ts_ns":1787745357667181242,"payload":"{\"channel\":\"book\",\"type\":\"update\",\"data\":[{\"symbol\":\"BTC/USD\",\"bids\":[{\"price\":78484.9,\"qty\":0.53588010}],\"asks\":[],\"checksum\":484426174,\"timestamp\":\"2026-08-26T11:55:57.520070Z\"}]}"}
{"recv_ts_ns":1787745357714133968,"payload":"{\"channel\":\"book\",\"type\":\"update\",\"data\":[{\"symbol\":\"BTC/USD\",\"bids\":[{\"price\":78484.8,\"qty\":0.00005100},{\"price\":78480.1,\"qty\":3.03208741}],\"asks\":[],\"checksum\":484426174,\"timestamp\":\"2026-08-26T11:55:57.568542Z\"}]}"}
{"recv_ts_ns":1787745357716281203,"payload":"{\"channel\":\"book\",\"type\":\"update\",\"data\":[{\"symbol\":\"BTC/USD\",\"bids\":[{\"price\":78484.9,\"qty\":0.00000000},{\"price\":78475.0,\"qty\":1.27429881}],\"asks\":[],\"checksum\":484426174,\"timestamp\":\"2026-08-26T11:55:57.570693Z\"}]}"}
{"recv_ts_ns":1787745357717518592,"payload":"{\"channel\":\"book\",\"type\":\"update\",\"data\":[{\"symbol\":\"BTC/USD\",\"bids\":[{\"price\":78486.5,\"qty\":0.04795432}],\"asks\":[],\"checksum\":484426174,\"timestamp\":\"2026-08-26T11:55:57.572274Z\"}]}"}
{"recv_ts_ns":1787745357833413596,"payload":"{\"channel\":\"book\",\"type\":\"update\",\"data\":[{\"symbol\":\"BTC/USD\",\"bids\":[],\"asks\":[{\"price\":78510.6,\"qty\":0.12230400}],\"checksum\":484426174,\"timestamp\":\"2026-08-26T11:55:57.688175Z\"}]}"}
{"recv_ts_ns":1787745357925566614,"payload":"{\"channel\":\"heartbeat\"}"}
{"recv_ts_ns":1787745358054214331,"payload":"{\"channel\":\"book\",\"type\":\"update\",\"data\":[{\"symbol\":\"BTC/USD\",\"bids\":[{\"price\":78496.6,\"qty\":0.00000000},{\"price\":78474.9,\"qty\":0.67473263}],\"asks\":[],\"checksum\":3554656479,\"timestamp\":\"2026-08-26T11:55:57.906121Z\"}]}"}
{"recv_ts_ns":1787745358064301909,"payload":"{\"channel\":\"book\",\"type\":\"update\",\"data\":[{\"symbol\":\"BTC/USD\",\"bids\":[],\"asks\":[{\"price\":78504.3,\"qty\":0.00000000},{\"price\":78516.3,\"qty\":0.01292474},{\"price\":78500.7,\"qty\":3.08953432}],\"checksum\":668671173,\"timestamp\":\"2026-08-26T11:55:57.917836Z\"}]}"}
{"recv_ts_ns":1787745358065384617,"payload":"{\"channel\":\"book\",\"type\":\"update\",\"data\":[{\"symbol\":\"BTC/USD\",\"bids\":[{\"price\":78500.6,\"qty\":0.11555097}],\"asks\":[],\"checksum\":1146039822,\"timestamp\":\"2026-08-26T11:55:57.919644Z\"}]}"}
{"recv_ts_ns":1787745358067694408,"payload":"{\"channel\":\"book\",\"type\":\"update\",\"data\":[{\"symbol\":\"BTC/USD\",\"bids\":[],\"asks\":[{\"price\":78500.7,\"qty\":3.09393432}],\"checksum\":3366096585,\"timestamp\":\"2026-08-26T11:55:57.921476Z\"}]}"}
{"recv_ts_ns":1787745358086208864,"payload":"{\"channel\":\"book\",\"type\":\"update\",\"data\":[{\"symbol\":\"BTC/USD\",\"bids\":[{\"price\":78496.6,\"qty\":0.00005100}],\"asks\":[],\"checksum\":1174863701,\"timestamp\":\"2026-08-26T11:55:57.940869Z\"}]}"}
{"recv_ts_ns":1787745358092546726,"payload":"{\"channel\":\"book\",\"type\":\"update\",\"data\":[{\"symbol\":\"BTC/USD\",\"bids\":[],\"asks\":[{\"price\":78500.7,\"qty\":0.06173533},{\"price\":78503.0,\"qty\":3.03215863}],\"checksum\":2904999148,\"timestamp\":\"2026-08-26T11:55:57.947042Z\"}]}"}
{"recv_ts_ns":1787745358093653735,"payload":"{\"channel\":\"book\",\"type\":\"update\",\"data\":[{\"symbol\":\"BTC/USD\",\"bids\":[],\"asks\":[{\"price\":78500.7,\"qty\":0.05733533}],\"checksum\":1888871690,\"timestamp\":\"2026-08-26T11:55:57.948867Z\"}]}"}
{"recv_ts_ns":1787745358093799442,"payload":"{\"channel\":\"book\",\"type\":\"update\",\"data\":[{\"symbol\":\"BTC/USD\",\"bids\":[{\"price\":78500.6,\"qty\":0.17925097}],\"asks\":[],\"checksum\":4050083151,\"timestamp\":\"2026-08-26T11:55:57.948977Z\"}]}"}
{"recv_ts_ns":1787745358096940851,"payload":"{\"channel\":\"book\",\"type\":\"update\",\"data\":[{\"symbol\":\"BTC/USD\",\"bids\":[{\"price\":78500.6,\"qty\":0.11555097}],\"asks\":[],\"checksum\":1888871690,\"timestamp\":\"2026-08-26T11:55:57.950753Z\"}]}"}
{"recv_ts_ns":1787745358190807928,"payload":"{\"channel\":\"book\",\"type\":\"update\",\"data\":[{\"symbol\":\"BTC/USD\",\"bids\":[{\"price\":78500.6,\"qty\":0.11565097}],\"asks\":[],\"checksum\":1897700444,\"timestamp\":\"2026-08-26T11:55:58.045082Z\"}]}"}
{"recv_ts_ns":1787745358192336573,"payload":"{\"channel\":\"book\",\"type\":\"update\",\"data\":[{\"symbol\":\"BTC/USD\",\"bids\":[{\"price\":78500.6,\"qty\":0.03765097}],\"asks\":[],\"checksum\":1014960342,\"timestamp\":\"2026-08-26T11:55:58.046677Z\"}]}"}
{"recv_ts_ns":1787745358218440591,"payload":"{\"channel\":\"book\",\"type\":\"update\",\"data\":[{\"symbol\":\"BTC/USD\",\"bids\":[],\"asks\":[{\"price\":78503.0,\"qty\":0.00000000},{\"price\":78516.3,\"qty\":0.01292474},{\"price\":78508.7,\"qty\":3.03217161}],\"checksum\":1425112955,\"timestamp\":\"2026-08-26T11:55:58.072431Z\"}]}"}
{"recv_ts_ns":1787745358242280042,"payload":"{\"channel\":\"trade\",\"type\":\"update\",\"data\":[{\"symbol\":\"BTC/USD\",\"side\":\"sell\",\"price\":78500.6,\"qty\":0.00035522,\"ord_type\":\"market\",\"trade_id\":105995616,\"timestamp\":\"2026-08-26T11:55:58.096474Z\"}]}"}
{"recv_ts_ns":1787745358242843836,"payload":"{\"channel\":\"book\",\"type\":\"update\",\"data\":[{\"symbol\":\"BTC/USD\",\"bids\":[{\"price\":78500.6,\"qty\":0.03729575}],\"asks\":[],\"checksum\":1029096968,\"timestamp\":\"2026-08-26T11:55:58.096474Z\"}]}"}
{"recv_ts_ns":1787745358269244163,"payload":"{\"channel\":\"book\",\"type\":\"update\",\"data\":[{\"symbol\":\"BTC/USD\",\"bids\":[],\"asks\":[{\"price\":78500.7,\"qty\":0.05912283}],\"checksum\":1536029077,\"timestamp\":\"2026-08-26T11:55:58.124577Z\"}]}"}
{"recv_ts_ns":1787745358344328494,"payload":"{\"channel\":\"book\",\"type\":\"update\",\"data\":[{\"symbol\":\"BTC/USD\",\"bids\":[],\"asks\":[{\"price\":78508.7,\"qty\":0.00000000},{\"price\":78516.3,\"qty\":0.01292474},{\"price\":78503.0,\"qty\":3.03214438}],\"checksum\":2156856478,\"timestamp\":\"2026-08-26T11:55:58.198015Z\"}]}"}
{"recv_ts_ns":1787745358345264486,"payload":"{\"channel\":\"book\",\"type\":\"update\",\"data\":[{\"symbol\":\"BTC/USD\",\"bids\":[],\"asks\":[{\"price\":78510.6,\"qty\":0.00000000},{\"price\":78516.3,\"qty\":0.01292474}],\"checksum\":2156856478,\"timestamp\":\"2026-08-26T11:55:58.200206Z\"}]}"}
{"recv_ts_ns":1787745358411632006,"payload":"{\"channel\":\"book\",\"type\":\"update\",\"data\":[{\"symbol\":\"BTC/USD\",\"bids\":[],\"asks\":[{\"price\":78516.0,\"qty\":0.33991048}],\"checksum\":2156856478,\"timestamp\":\"2026-08-26T11:55:58.264126Z\"}]}"}
{"recv_ts_ns":1787745358446986977,"payload":"{\"channel\":\"book\",\"type\":\"update\",\"data\":[{\"symbol\":\"BTC/USD\",\"bids\":[],\"asks\":[{\"price\":78509.5,\"qty\":0.12232900}],\"checksum\":2156856478,\"timestamp\":\"2026-08-26T11:55:58.300226Z\"}]}"}
{"recv_ts_ns":1787745358706333919,"payload":"{\"channel\":\"book\",\"type\":\"update\",\"data\":[{\"symbol\":\"BTC/USD\",\"bids\":[],\"asks\":[{\"price\":78509.5,\"qty\":0.23825066}],\"checksum\":2156856478,\"timestamp\":\"2026-08-26T11:55:58.558080Z\"}]}"}
{"recv_ts_ns":1787745358846528427,"payload":"{\"channel\":\"book\",\"type\":\"update\",\"data\":[{\"symbol\":\"BTC/USD\",\"bids\":[],\"asks\":[{\"price\":78509.5,\"qty\":0.11592166}],\"checksum\":2156856478,\"timestamp\":\"2026-08-26T11:55:58.701074Z\"}]}"}
{"recv_ts_ns":1787745358926288319,"payload":"{\"channel\":\"heartbeat\"}"}
{"recv_ts_ns":1787745358946333570,"payload":"{\"channel\":\"book\",\"type\":\"update\",\"data\":[{\"symbol\":\"BTC/USD\",\"bids\":[],\"asks\":[{\"price\":78506.7,\"qty\":0.12235000}],\"checksum\":3959824723,\"timestamp\":\"2026-08-26T11:55:58.801394Z\"}]}"}
{"recv_ts_ns":1787745359012407689,"payload":"{\"channel\":\"book\",\"type\":\"update\",\"data\":[{\"symbol\":\"BTC/USD\",\"bids\":[{\"price\":78480.1,\"qty\":0.00000000},{\"price\":78474.9,\"qty\":0.67473263},{\"price\":78484.8,\"qty\":3.03211651}],\"asks\":[],\"checksum\":3959824723,\"timestamp\":\"2026-08-26T11:55:58.867098Z\"}]}"}
{"recv_ts_ns":1787745359014611219,"payload":"{\"channel\":\"book\",\"type\":\"update\",\"data\":[{\"symbol\":\"BTC/USD\",\"bids\":[{\"price\":78486.5,\"qty\":0.00000000},{\"price\":78474.6,\"qty\":0.13109402}],\"asks\":[],\"checksum\":3959824723,\"timestamp\":\"2026-08-26T11:55:58.868269Z\"}]}"}
{"recv_ts_ns":1787745359016283335,"payload":"{\"channel\":\"book\",\"type\":\"update\",\"data\":[{\"symbol\":\"BTC/USD\",\"bids\":[{\"price\":78484.9,\"qty\":0.51792999}],\"asks\":[],\"checksum\":3959824723,\"timestamp\":\"2026-08-26T11:55:58.871044Z\"}]}"}
{"recv_ts_ns":1787745359020295444,"payload":"{\"channel\":\"book\",\"type\":\"update\",\"data\":[{\"symbol\":\"BTC/USD\",\"bids\":[],\"asks\":[{\"price\":78503.0,\"qty\":0.00000000},{\"price\":78516.2,\"qty\":0.00005100},{\"price\":78504.3,\"qty\":3.03206551}],\"checksum\":1123265069,\"timestamp\":\"2026-08-26T11:55:58.872140Z\"}]}"}
{"recv_ts_ns":1787745359020367693,"payload":"{\"channel\":\"book\",\"type\":\"update\",\"data\":[{\"symbol\":\"BTC/USD\",\"bids\":[{\"price\":78484.8,\"qty\":0.00005100},{\"price\":78480.1,\"qty\":3.03209133}],\"asks\":[],\"checksum\":1123265069,\"timestamp\":\"2026-08-26T11:55:58.874204Z\"}]}"}
{"recv_ts_ns":1787745359020409299,"payload":"{\"channel\":\"book\",\"type\":\"update\",\"data\":[{\"symbol\":\"BTC/USD\",\"bids\":[{\"price\":78484.9,\"qty\":0.00000000},{\"price\":78474.9,\"qty\":0.67473263}],\"asks\":[],\"checksum\":1123265069,\"timestamp\":\"2026-08-26T11:55:58.875369Z\"}]}"}
{"recv_ts_ns":1787745359021068848,"payload":"{\"channel\":\"book\",\"type\":\"update\",\"data\":[{\"symbol\":\"BTC/USD\",\"bids\":[{\"price\":78486.5,\"qty\":0.04795432}],\"asks\":[],\"checksum\":1123265069,\"timestamp\":\"2026-08-26T11:55:58.876764Z\"}]}"}
{"recv_ts_ns":1787745359116336667,"payload":"{\"channel\":\"book\",\"type\":\"update\",\"data\":[{\"symbol\":\"BTC/USD\",\"bids\":[{\"price\":78480.1,\"qty\":0.00000000},{\"price\":78474.9,\"qty\":0.67473263},{\"price\":78484.8,\"qty\":3.03209936}],\"asks\":[],\"checksum\":1123265069,\"timestamp\":\"2026-08-26T11:55:58.971177Z\"}]}"}
{"recv_ts_ns":1787745359118280557,"payload":"{\"channel\":\"book\",\"type\":\"update\",\"data\":[{\"symbol\":\"BTC/USD\",\"bids\":[{\"price\":78486.5,\"qty\":0.00000000},{\"price\":78474.6,\"qty\":0.13109402}],\"asks\":[],\"checksum\":1123265069,\"timestamp\":\"2026-08-26T11:55:58.972525Z\"}]}"}
{"recv_ts_ns":1787745359118768391,"payload":"{\"channel\":\"book\",\"type\":\"update\",\"data\":[{\"symbol\":\"BTC/USD\",\"bids\":[{\"price\":78484.9,\"qty\":0.51792999}],\"asks\":[],\"checksum\":1123265069,\"timestamp\":\"2026-08-26T11:55:58.974223Z\"}]}"}
{"recv_ts_ns":1787745359140510134,"payload":"{\"channel\":\"book\",\"type\":\"update\",\"data\":[{\"symbol\":\"BTC/USD\",\"bids\":[{\"price\":78484.8,\"qty\":0.00005100},{\"price\":78480.1,\"qty\":3.03209050}],\"asks\":[],\"checksum\":1123265069,\"timestamp\":\"2026-08-26T11:55:58.994056Z\"}]}"}
{"recv_ts_ns":1787745359141473384,"payload":"{\"channel\":\"book\",\"type\":\"update\",\"data\":[{\"symbol\":\"BTC/USD\",\"bids\":[{\"price\":78484.9,\"qty\":0.00000000},{\"price\":78474.9,\"qty\":0.67473263}],\"asks\":[],\"checksum\":1123265069,\"timestamp\":\"2026-08-26T11:55:58.995405Z\"}]}"}
{"recv_ts_ns":1787745359141587420,"payload":"{\"channel\":\"book\",\"type\":\"update\",\"data\":[{\"symbol\":\"BTC/USD\",\"bids\":[{\"price\":78486.5,\"qty\":0.04795432}],\"asks\":[],\"checksum\":1123265069,\"timestamp\":\"2026-08-26T11:55:58.996730Z\"}]}"}
{"recv_ts_ns":1787745359168949261,"payload":"{\"channel\":\"book\",\"type\":\"update\",\"data\":[{\"symbol\":\"BTC/USD\",\"bids\":[{\"price\":78480.1,\"qty\":0.00000000},{\"price\":78474.9,\"qty\":0.67473263},{\"price\":78484.8,\"qty\":3.03210228}],\"asks\":[],\"checksum\":1123265069,\"timestamp\":\"2026-08-26T11:55:59.023829Z\"}]}"}
{"recv_ts_ns":1787745359172428086,"payload":"{\"channel\":\"book\",\"type\":\"update\",\"data\":[{\"symbol\":\"BTC/USD\",\"bids\":[{\"price\":78486.5,\"qty\":0.00000000},{\"price\":78474.6,\"qty\":0.13109402}],\"asks\":[],\"checksum\":1123265069,\"timestamp\":\"2026-08-26T11:55:59.025199Z\"}]}"}
{"recv_ts_ns":1787745359172472307,"payload":"{\"channel\":\"book\",\"type\":\"update\",\"data\":[{\"symbol\":\"BTC/USD\",\"bids\":[{\"price\":78484.9,\"qty\":0.51792999}],\"asks\":[],\"checksum\":1123265069,\"timestamp\":\"2026-08-26T11:55:59.026436Z\"}]}"}
{"recv_ts_ns":1787745359199148349,"payload":"{\"channel\":\"book\",\"type\":\"update\",\"data\":[{\"symbol\":\"BTC/USD\",\"bids\":[{\"price\":78484.8,\"qty\":0.00005100},{\"price\":78480.1,\"qty\":3.03209291}],\"asks\":[],\"checksum\":1123265069,\"timestamp\":\"2026-08-26T11:55:59.053980Z\"}]}"}
{"recv_ts_ns":1787745359201198760,"payload":"{\"channel\":\"book\",\"type\":\"update\",\"data\":[{\"symbol\":\"BTC/USD\",\"bids\":[{\"price\":78484.9,\"qty\":0.00000000},{\"price\":78474.9,\"qty\":0.67473263}],\"asks\":[],\"checksum\":1123265069,\"timestamp\":\"2026-08-26T11:55:59.055284Z\"}]}"}
{"recv_ts_ns":1787745359201233610,"payload":"{\"channel\":\"book\",\"type\":\"update\",\"data\":[{\"symbol\":\"BTC/USD\",\"bids\":[{\"price\":78486.5,\"qty\":0.04795432}],\"asks\":[],\"checksum\":1123265069,\"timestamp\":\"2026-08-26T11:55:59.056917Z\"}]}"}
{"recv_ts_ns":1787745359283278816,"payload":"{\"channel\":\"book\",\"type\":\"update\",\"data\":[{\"symbol\":\"BTC/USD\",\"bids\":[{\"price\":78496.8,\"qty\":0.00000000},{\"price\":78474.9,\"qty\":0.67473263}],\"asks\":[],\"checksum\":3137184178,\"timestamp\":\"2026-08-26T11:55:59.134287Z\"}]}"}
{"recv_ts_ns":1787745359283334966,"payload":"{\"channel\":\"book\",\"type\":\"update\",\"data\":[{\"symbol\":\"BTC/USD\",\"bids\":[{\"price\":78497.6,\"qty\":0.63696196}],\"asks\":[],\"checksum\":1885731628,\"timestamp\":\"2026-08-26T11:55:59.135709Z\"}]}"}
{"recv_ts_ns":1787745359350048303,"payload":"{\"channel\":\"book\",\"type\":\"update\",\"data\":[{\"symbol\":\"BTC/USD\",\"bids\":[],\"asks\":[{\"price\":78506.7,\"qty\":0.00000000},{\"price\":78516.2,\"qty\":0.00005100}],\"checksum\":485285601,\"timestamp\":\"2026-08-26T11:55:59.204078Z\"}]}"}
{"recv_ts_ns":1787745359451441788,"payload":"{\"channel\":\"book\",\"type\":\"update\",\"data\":[{\"symbol\":\"BTC/USD\",\"bids\":[],\"asks\":[{\"price\":78506.4,\"qty\":0.12237000}],\"checksum\":3454333210,\"timestamp\":\"2026-08-26T11:55:59.304232Z\"}]}"}
{"recv_ts_ns":1787745359515622389,"payload":"{\"channel\":\"book\",\"type\":\"update\",\"data\":[{\"symbol\":\"BTC/USD\",\"bids\":[{\"price\":78494.3,\"qty\":0.00000000},{\"price\":78474.9,\"qty\":0.67473263},{\"price\":78495.5,\"qty\":0.04603180}],\"asks\":[],\"checksum\":784032506,\"timestamp\":\"2026-08-26T11:55:59.368791Z\"}]}"}
{"recv_ts_ns":1787745359851168613,"payload":"{\"channel\":\"book\",\"type\":\"update\",\"data\":[{\"symbol\":\"BTC/USD\",\"bids\":[],\"asks\":[{\"price\":78506.4,\"qty\":0.00000000},{\"price\":78516.2,\"qty\":0.00005100}],\"checksum\":4289940737,\"timestamp\":\"2026-08-26T11:55:59.706089Z\"}]}"}
{"recv_ts_ns":1787745359928930925,"payload":"{\"channel\":\"heartbeat\"}"}
{"recv_ts_ns":1787745359953139501,"payload":"{\"channel\":\"book\",\"type\":\"update\",\"data\":[{\"symbol\":\"BTC/USD\",\"bids\":[],\"asks\":[{\"price\":78506.2,\"qty\":0.12239100}],\"checksum\":2060059635,\"timestamp\":\"2026-08-26T11:55:59.806964Z\"}]}"}
{"recv_ts_ns":1787745360251510523,"payload":"{\"channel\":\"book\",\"type\":\"update\",\"data\":[{\"symbol\":\"BTC/USD\",\"bids\":[],\"asks\":[{\"price\":78500.7,\"qty\":0.06352283}],\"checksum\":4267309263,\"timestamp\":\"2026-08-26T11:56:00.102613Z\"}]}"}
{"recv_ts_ns":1787745360357744098,"payload":"{\"channel\":\"book\",\"type\":\"update\",\"data\":[{\"symbol\":\"BTC/USD\",\"bids\":[],\"asks\":[{\"price\":78506.2,\"qty\":0.00000000},{\"price\":78516.2,\"qty\":0.00005100}],\"checksum\":2065741373,\"timestamp\":\"2026-08-26T11:56:00.206456Z\"}]}"}
{"recv_ts_ns":1787745360452947690,"payload":"{\"channel\":\"book\",\"type\":\"update\",\"data\":[{\"symbol\":\"BTC/USD\",\"bids\":[],\"asks\":[{\"price\":78505.6,\"qty\":0.12241100}],\"checksum\":42433843,\"timestamp\":\"2026-08-26T11:56:00.306531Z\"}]}"}
{"recv_ts_ns":1787745360509301308,"payload":"{\"channel\":\"book\",\"type\":\"update\",\"data\":[{\"symbol\":\"BTC/USD\",\"bids\":[],\"asks\":[{\"price\":78503.1,\"qty\":0.38264178}],\"checksum\":3011021402,\"timestamp\":\"2026-08-26T11:56:00.362767Z\"}]}"}
{"recv_ts_ns":1787745360509384183,"payload":"{\"channel\":\"book\",\"type\":\"update\",\"data\":[{\"symbol\":\"BTC/USD\",\"bids\":[],\"asks\":[{\"price\":78506.9,\"qty\":0.63688715}],\"checksum\":3280367747,\"timestamp\":\"2026-08-26T11:56:00.363089Z\"}]}"}
{"recv_ts_ns":1787745360509411053,"payload":"{\"channel\":\"book\",\"type\":\"update\",\"data\":[{\"symbol\":\"BTC/USD\",\"bids\":[],\"asks\":[{\"price\":78500.7,\"qty\":0.01749084}],\"checksum\":33103907,\"timestamp\":\"2026-08-26T11:56:00.363101Z\"}]}"}
{"recv_ts_ns":1787745360511210008,"payload":"{\"channel\":\"book\",\"type\":\"update\",\"data\":[{\"symbol\":\"BTC/USD\",\"bids\":[],\"asks\":[{\"price\":78503.1,\"qty\":0.03261993}],\"checksum\":304644299,\"timestamp\":\"2026-08-26T11:56:00.363430Z\"}]}"}
{"recv_ts_ns":1787745360511249203,"payload":"{\"channel\":\"book\",\"type\":\"update\",\"data\":[{\"symbol\":\"BTC/USD\",\"bids\":[],\"asks\":[{\"price\":78505.5,\"qty\":0.00000000},{\"price\":78516.2,\"qty\":0.00005100}],\"checksum\":387874956,\"timestamp\":\"2026-08-26T11:56:00.363751Z\"}]}"}
{"recv_ts_ns":1787745360511288805,"payload":"{\"channel\":\"book\",\"type\":\"update\",\"data\":[{\"symbol\":\"BTC/USD\",\"bids\":[],\"asks\":[{\"price\":78508.4,\"qty\":0.00000000},{\"price\":78516.3,\"qty\":0.01292474}],\"checksum\":2047392954,\"timestamp\":\"2026-08-26T11:56:00.364192Z\"}]}"}
{"recv_ts_ns":1787745360517849796,"payload":"{\"channel\":\"book\",\"type\":\"update\",\"data\":[{\"symbol\":\"BTC/USD\",\"bids\":[],\"asks\":[{\"price\":78505.6,\"qty\":0.00000000},{\"price\":78517.1,\"qty\":0.02547587}],\"checksum\":4112131031,\"timestamp\":\"2026-08-26T11:56:00.364626Z\"}]}"}
{"recv_ts_ns":1787745360517891218,"payload":"{\"channel\":\"book\",\"type\":\"update\",\"data\":[{\"symbol\":\"BTC/USD\",\"bids\":[],\"asks\":[{\"price\":78515.7,\"qty\":0.00000000},{\"price\":78517.8,\"qty\":0.06368970}],\"checksum\":4112131031,\"timestamp\":\"2026-08-26T11:56:00.365102Z\"}]}"}
{"recv_ts_ns":1787745360517919701,"payload":"{\"channel\":\"book\",\"type\":\"update\",\"data\":[{\"symbol\":\"BTC/USD\",\"bids\":[],\"asks\":[{\"price\":78510.9,\"qty\":0.09922757}],\"checksum\":4112131031,\"timestamp\":\"2026-08-26T11:56:00.365703Z\"}]}"}
{"recv_ts_ns":1787745360517942979,"payload":"{\"channel\":\"book\",\"type\":\"update\",\"data\":[{\"symbol\":\"BTC/USD\",\"bids\":[],\"asks\":[{\"price\":78510.9,\"qty\":0.00000000},{\"price\":78518.7,\"qty\":0.04603180}],\"checksum\":4112131031,\"timestamp\":\"2026-08-26T11:56:00.365830Z\"}]}"}
{"recv_ts_ns":1787745360518295786,"payload":"{\"channel\":\"book\",\"type\":\"update\",\"data\":[{\"symbol\":\"BTC/USD\",\"bids\":[{\"price\":78500.6,\"qty\":0.10099575}],\"asks\":[],\"checksum\":219710025,\"timestamp\":\"2026-08-26T11:56:00.366327Z\"}]}"}
{"recv_ts_ns":1787745360518347178,"payload":"{\"channel\":\"book\",\"type\":\"update\",\"data\":[{\"symbol\":\"BTC/USD\",\"bids\":[],\"asks\":[{\"price\":78504.4,\"qty\":0.00005100}],\"checksum\":2721564683,\"timestamp\":\"2026-08-26T11:56:00.366606Z\"}]}"}
{"recv_ts_ns":1787745360522647198,"payload":"{\"channel\":\"book\",\"type\":\"update\",\"data\":[{\"symbol\":\"BTC/USD\",\"bids\":[],\"asks\":[{\"price\":78500.7,\"qty\":0.01309084}],\"checksum\":3280113085,\"timestamp\":\"2026-08-26T11:56:00.368527Z\"}]}"}
{"recv_ts_ns":1787745360522699613,"payload":"{\"channel\":\"book\",\"type\":\"update\",\"data\":[{\"symbol\":\"BTC/USD\",\"bids\":[],\"asks\":[{\"price\":78506.9,\"qty\":0.00000000},{\"price\":78518.8,\"qty\":0.02057681}],\"checksum\":3977361535,\"timestamp\":\"2026-08-26T11:56:00.368561Z\"}]}"}
{"recv_ts_ns":1787745360522722785,"payload":"{\"channel\":\"book\",\"type\":\"update\",\"data\":[{\"symbol\":\"BTC/USD\",\"bids\":[],\"asks\":[{\"price\":78505.4,\"qty\":0.00000000},{\"price\":78519.5,\"qty\":0.08956016}],\"checksum\":1839171837,\"timestamp\":\"2026-08-26T11:56:00.369483Z\"}]}"}
{"recv_ts_ns":1787745360530240656,"payload":"{\"channel\":\"book\",\"type\":\"update\",\"data\":[{\"symbol\":\"BTC/USD\",\"bids\":[{\"price\":78495.6,\"qty\":0.01518308}],\"asks\":[],\"checksum\":325971846,\"timestamp\":\"2026-08-26T11:56:00.378778Z\"}]}"}
{"recv_ts_ns":1787745360535837966,"payload":"{\"channel\":\"book\",\"type\":\"update\",\"data\":[{\"symbol\":\"BTC/USD\",\"bids\":[{\"price\":78490.6,\"qty\":0.00000000},{\"price\":78476.5,\"qty\":0.00005000}],\"asks\":[],\"checksum\":325971846,\"timestamp\":\"2026-08-26T11:56:00.380220Z\"}]}"}
{"recv_ts_ns":1787745360535884663,"payload":"{\"channel\":\"book\",\"type\":\"update\",\"data\":[{\"symbol\":\"BTC/USD\",\"bids\":[{\"price\":78490.2,\"qty\":0.00000000},{\"price\":78474.9,\"qty\":0.67473263}],\"asks\":[],\"checksum\":325971846,\"timestamp\":\"2026-08-26T11:56:00.381828Z\"}]}"}
{"recv_ts_ns":1787745360535926000,"payload":"{\"channel\":\"book\",\"type\":\"update\",\"data\":[{\"symbol\":\"BTC/USD\",\"bids\":[{\"price\":78494.2,\"qty\":0.00000000},{\"price\":78474.6,\"qty\":0.13109402}],\"asks\":[],\"checksum\":1888978881,\"timestamp\":\"2026-08-26T11:56:00.381972Z\"}]}"}
{"recv_ts_ns":1787745360547373916,"payload":"{\"channel\":\"book\",\"type\":\"update\",\"data\":[{\"symbol\":\"BTC/USD\",\"bids\":[],\"asks\":[{\"price\":78509.5,\"qty\":0.00000000},{\"price\":78519.6,\"qty\":0.08956015}],\"checksum\":2382724631,\"timestamp\":\"2026-08-26T11:56:00.390776Z\"}]}"}
{"recv_ts_ns":1787745360547467774,"payload":"{\"channel\":\"book\",\"type\":\"update\",\"data\":[{\"symbol\":\"BTC/USD\",\"bids\":[{\"price\":78497.6,\"qty\":0.00000000},{\"price\":78474.0,\"qty\":1.27431505}],\"asks\":[],\"checksum\":98797957,\"timestamp\":\"2026-08-26T11:56:00.391220Z\"}]}"}
{"recv_ts_ns":1787745360547537189,"payload":"{\"channel\":\"book\",\"type\":\"update\",\"data\":[{\"symbol\":\"BTC/USD\",\"bids\":[],\"asks\":[{\"price\":78510.6,\"qty\":0.01655857}],\"checksum\":1439331100,\"timestamp\":\"2026-08-26T11:56:00.391606Z\"}]}"}
{"recv_ts_ns":1787745360549362562,"payload":"{\"channel\":\"book\",\"type\":\"update\",\"data\":[{\"symbol\":\"BTC/USD\",\"bids\":[{\"price\":78489.9,\"qty\":0.00000000},{\"price\":78473.9,\"qty\":0.40000000}],\"asks\":[],\"checksum\":1439331100,\"timestamp\":\"2026-08-26T11:56:00.394469Z\"}]}"}
{"recv_ts_ns":1787745360549462402,"payload":"{\"channel\":\"book\",\"type\":\"update\",\"data\":[{\"symbol\":\"BTC/USD\",\"bids\":[{\"price\":78479.9,\"qty\":0.00984023}],\"asks\":[],\"checksum\":1439331100,\"timestamp\":\"2026-08-26T11:56:00.395487Z\"}]}"}
{"recv_ts_ns":1787745360553013250,"payload":"{\"channel\":\"book\",\"type\":\"update\",\"data\":[{\"symbol\":\"BTC/USD\",\"bids\":[],\"asks\":[{\"price\":78517.9,\"qty\":0.02636066}],\"checksum\":1439331100,\"timestamp\":\"2026-08-26T11:56:00.396599Z\"}]}"}
{"recv_ts_ns":1787745360553120275,"payload":"{\"channel\":\"book\",\"type\":\"update\",\"data\":[{\"symbol\":\"BTC/USD\",\"bids\":[],\"asks\":[{\"price\":78503.3,\"qty\":0.00000000},{\"price\":78519.5,\"qty\":0.08956016}],\"checksum\":230119741,\"timestamp\":\"2026-08-26T11:56:00.397282Z\"}]}"}
{"recv_ts_ns":1787745360555644876,"payload":"{\"channel\":\"book\",\"type\":\"update\",\"data\":[{\"symbol\":\"BTC/USD\",\"bids\":[],\"asks\":[{\"price\":78513.6,\"qty\":0.00000000},{\"price\":78519.6,\"qty\":0.08956015}],\"checksum\":230119741,\"timestamp\":\"2026-08-26T11:56:00.400326Z\"}]}"}
{"recv_ts_ns":1787745360555761760,"payload":"{\"channel\":\"book\",\"type\":\"update\",\"data\":[{\"symbol\":\"BTC/USD\",\"bids\":[{\"price\":78500.6,\"qty\":0.15159575}],\"asks\":[],\"checksum\":1977240572,\"timestamp\":\"2026-08-26T11:56:00.400358Z\"}]}"}
{"recv_ts_ns":1787745360555810399,"payload":"{\"channel\":\"book\",\"type\":\"update\",\"data\":[{\"symbol\":\"BTC/USD\",\"bids\":[],\"asks\":[{\"price\":78511.2,\"qty\":0.00000000},{\"price\":78520.0,\"qty\":0.02449286}],\"checksum\":145988166,\"timestamp\":\"2026-08-26T11:56:00.400783Z\"}]}"}
{"recv_ts_ns":1787745360560571168,"payload":"{\"channel\":\"book\",\"type\":\"update\",\"data\":[{\"symbol\":\"BTC/USD\",\"bids\":[],\"asks\":[{\"price\":78512.3,\"qty\":0.00000000},{\"price\":78520.1,\"qty\":0.00005100}],\"checksum\":3585787958,\"timestamp\":\"2026-08-26T11:56:00.401356Z\"}]}"}
{"recv_ts_ns":1787745360563554012,"payload":"{\"channel\":\"book\",\"type\":\"update\",\"data\":[{\"symbol\":\"BTC/USD\",\"bids\":[{\"price\":78495.4,\"qty\":0.96817016}],\"asks\":[],\"checksum\":3026980215,\"timestamp\":\"2026-08-26T11:56:00.408992Z\"}]}"}
{"recv_ts_ns":1787745360568816270,"payload":"{\"channel\":\"book\",\"type\":\"update\",\"data\":[{\"symbol\":\"BTC/USD\",\"bids\":[{\"price\":78496.6,\"qty\":0.00132494}],\"asks\":[],\"checksum\":283063980,\"timestamp\":\"2026-08-26T11:56:00.410126Z\"}]}"}
{"recv_ts_ns":1787745360570507819,"payload":"{\"channel\":\"book\",\"type\":\"update\",\"data\":[{\"symbol\":\"BTC/USD\",\"bids\":[{\"price\":78490.0,\"qty\":0.00000000},{\"price\":78471.9,\"qty\":6.37170716}],\"asks\":[],\"checksum\":3276507910,\"timestamp\":\"2026-08-26T11:56:00.415795Z\"}]}"}
{"recv_ts_ns":1787745360576350658,"payload":"{\"channel\":\"book\",\"type\":\"update\",\"data\":[{\"symbol\":\"BTC/USD\",\"bids\":[{\"price\":78500.6,\"qty\":0.10099575}],\"asks\":[],\"checksum\":2844846158,\"timestamp\":\"2026-08-26T11:56:00.420445Z\"}]}"}
{"recv_ts_ns":1787745360576482447,"payload":"{\"channel\":\"book\",\"type\":\"update\",\"data\":[{\"symbol\":\"BTC/USD\",\"bids\":[{\"price\":78495.5,\"qty\":0.00000000},{\"price\":78470.2,\"qty\":1.27404207},{\"price\":78495.7,\"qty\":0.04603180}],\"asks\":[],\"checksum\":1334271136,\"timestamp\":\"2026-08-26T11:56:00.421255Z\"}]}"}
{"recv_ts_ns":1787745360576540461,"payload":"{\"channel\":\"book\",\"type\":\"update\",\"data\":[{\"symbol\":\"BTC/USD\",\"bids\":[{\"price\":78480.2,\"qty\":0.91981734}],\"asks\":[],\"checksum\":1334271136,\"timestamp\":\"2026-08-26T11:56:00.422253Z\"}]}"}
{"recv_ts_ns":1787745360576598016,"payload":"{\"channel\":\"book\",\"type\":\"update\",\"data\":[{\"symbol\":\"BTC/USD\",\"bids\":[],\"asks\":[{\"price\":78513.9,\"qty\":0.63683061}],\"checksum\":1334271136,\"timestamp\":\"2026-08-26T11:56:00.422421Z\"}]}"}
{"recv_ts_ns":1787745360581316650,"payload":"{\"channel\":\"book\",\"type\":\"update\",\"data\":[{\"symbol\":\"BTC/USD\",\"bids\":[],\"asks\":[{\"price\":78517.3,\"qty\":0.63680249}],\"checksum\":1334271136,\"timestamp\":\"2026-08-26T11:56:00.422785Z\"}]}"}
{"recv_ts_ns":1787745360581429087,"payload":"{\"channel\":\"book\",\"type\":\"update\",\"data\":[{\"symbol\":\"BTC/USD\",\"bids\":[{\"price\":78500.3,\"qty\":0.63693950}],\"asks\":[],\"checksum\":1002445576,\"timestamp\":\"2026-08-26T11:56:00.423232Z\"}]}"}
{"recv_ts_ns":1787745360581485817,"payload":"{\"channel\":\"book\",\"type\":\"update\",\"data\":[{\"symbol\":\"BTC/USD\",\"bids\":[{\"price\":78474.0,\"qty\":0.00000000},{\"price\":78473.9,\"qty\":0.40000000},{\"price\":78475.0,\"qty\":1.27429881}],\"asks\":[],\"checksum\":1002445576,\"timestamp\":\"2026-08-26T11:56:00.423275Z\"}]}"}
{"recv_ts_ns":1787745360581550040,"payload":"{\"channel\":\"book\",\"type\":\"update\",\"data\":[{\"symbol\":\"BTC/USD\",\"bids\":[{\"price\":78495.7,\"qty\":0.68300917}],\"asks\":[],\"checksum\":1032279281,\"timestamp\":\"2026-08-26T11:56:00.423520Z\"}]}"}
{"recv_ts_ns":1787745360581610604,"payload":"{\"channel\":\"book\",\"type\":\"update\",\"data\":[{\"symbol\":\"BTC/USD\",\"bids\":[{\"price\":78484.9,\"qty\":1.91119373}],\"asks\":[],\"checksum\":1032279281,\"timestamp\":\"2026-08-26T11:56:00.424113Z\"}]}"}
{"recv_ts_ns":1787745360581716165,"payload":"{\"channel\":\"book\",\"type\":\"update\",\"data\":[{\"symbol\":\"BTC/USD\",\"bids\":[],\"asks\":[{\"price\":78517.3,\"qty\":0.00000000},{\"price\":78520.0,\"qty\":0.02449286}],\"checksum\":1032279281,\"timestamp\":\"2026-08-26T11:56:00.424279Z\"}]}"}
{"recv_ts_ns":1787745360583638705,"payload":"{\"channel\":\"book\",\"type\":\"update\",\"data\":[{\"symbol\":\"BTC/USD\",\"bids\":[],\"asks\":[{\"price\":78513.9,\"qty\":0.00000000},{\"price\":78520.1,\"qty\":0.00005100}],\"checksum\":1032279281,\"timestamp\":\"2026-08-26T11:56:00.425338Z\"}]}"}
{"recv_ts_ns":1787745360583828387,"payload":"{\"channel\":\"book\",\"type\":\"update\",\"data\":[{\"symbol\":\"BTC/USD\",\"bids\":[{\"price\":78496.6,\"qty\":0.00005100}],\"asks\":[],\"checksum\":2545526845,\"timestamp\":\"2026-08-26T11:56:00.427290Z\"}]}"}
{"recv_ts_ns":1787745360583921923,"payload":"{\"channel\":\"book\",\"type\":\"update\",\"data\":[{\"symbol\":\"BTC/USD\",\"bids\":[{\"price\":78484.9,\"qty\":0.00000000},{\"price\":78474.6,\"qty\":0.13109402}],\"asks\":[],\"checksum\":2545526845,\"timestamp\":\"2026-08-26T11:56:00.427723Z\"}]}"}
{"recv_ts_ns":1787745360584023279,"payload":"{\"channel\":\"book\",\"type\":\"update\",\"data\":[{\"symbol\":\"BTC/USD\",\"bids\":[{\"price\":78480.1,\"qty\":0.00000000},{\"price\":78473.9,\"qty\":0.40000000},{\"price\":78486.6,\"qty\":3.03192991}],\"asks\":[],\"checksum\":2545526845,\"timestamp\":\"2026-08-26T11:56:00.428392Z\"}]}"}
{"recv_ts_ns":1787745360584909723,"payload":"{\"channel\":\"book\",\"type\":\"update\",\"data\":[{\"symbol\":\"BTC/USD\",\"bids\":[{\"price\":78480.2,\"qty\":0.00000000},{\"price\":78473.9,\"qty\":0.40000000}],\"asks\":[],\"checksum\":2545526845,\"timestamp\":\"2026-08-26T11:56:00.431029Z\"}]}"}
{"recv_ts_ns":1787745360588079187,"payload":"{\"channel\":\"book\",\"type\":\"update\",\"data\":[{\"symbol\":\"BTC/USD\",\"bids\":[{\"price\":78490.3,\"qty\":0.72338211}],\"asks\":[],\"checksum\":2545526845,\"timestamp\":\"2026-08-26T11:56:00.433451Z\"}]}"}
{"recv_ts_ns":1787745360593465994,"payload":"{\"channel\":\"book\",\"type\":\"update\",\"data\":[{\"symbol\":\"BTC/USD\",\"bids\":[],\"asks\":[{\"price\":78504.3,\"qty\":0.00000000},{\"price\":78520.2,\"qty\":0.05060000},{\"price\":78508.3,\"qty\":3.03198091}],\"checksum\":1216784293,\"timestamp\":\"2026-08-26T11:56:00.438224Z\"}]}"}
{"recv_ts_ns":1787745360593625860,"payload":"{\"channel\":\"book\",\"type\":\"update\",\"data\":[{\"symbol\":\"BTC/USD\",\"bids\":[],\"asks\":[{\"price\":78514.1,\"qty\":0.03283500}],\"checksum\":1216784293,\"timestamp\":\"2026-08-26T11:56:00.438884Z\"}]}"}
{"recv_ts_ns":1787745360599557055,"payload":"{\"channel\":\"book\",\"type\":\"update\",\"data\":[{\"symbol\":\"BTC/USD\",\"bids\":[{\"price\":78490.3,\"qty\":0.00000000},{\"price\":78473.9,\"qty\":0.40000000}],\"asks\":[],\"checksum\":1216784293,\"timestamp\":\"2026-08-26T11:56:00.439149Z\"}]}"}
{"recv_ts_ns":1787745360599680073,"payload":"{\"channel\":\"book\",\"type\":\"update\",\"data\":[{\"symbol\":\"BTC/USD\",\"bids\":[{\"price\":78480.0,\"qty\":0.03953200}],\"asks\":[],\"checksum\":1216784293,\"timestamp\":\"2026-08-26T11:56:00.440730Z\"}]}"}
{"recv_ts_ns":1787745360599725875,"payload":"{\"channel\":\"book\",\"type\":\"update\",\"data\":[{\"symbol\":\"BTC/USD\",\"bids\":[],\"asks\":[{\"price\":78510.8,\"qty\":0.00000000},{\"price\":78520.2,\"qty\":0.05060000},{\"price\":78513.5,\"qty\":1.27393169}],\"checksum\":1409742742,\"timestamp\":\"2026-08-26T11:56:00.441221Z\"}]}"}
{"recv_ts_ns":1787745360601618665,"payload":"{\"channel\":\"book\",\"type\":\"update\",\"data\":[{\"symbol\":\"BTC/USD\",\"bids\":[],\"asks\":[{\"price\":78514.1,\"qty\":0.00000000},{\"price\":78520.2,\"qty\":0.05060000}],\"checksum\":1409742742,\"timestamp\":\"2026-08-26T11:56:00.444817Z\"}]}"}
{"recv_ts_ns":1787745360607112974,"payload":"{\"channel\":\"book\",\"type\":\"update\",\"data\":[{\"symbol\":\"BTC/USD\",\"bids\":[],\"asks\":[{\"price\":78519.9,\"qty\":0.26887464}],\"checksum\":1409742742,\"timestamp\":\"2026-08-26T11:56:00.449880Z\"}]}"}
{"recv_ts_ns":1787745360614134050,"payload":"{\"channel\":\"book\",\"type\":\"update\",\"data\":[{\"symbol\":\"BTC/USD\",\"bids\":[{\"price\":78495.4,\"qty\":0.01273960}],\"asks\":[],\"checksum\":3762246201,\"timestamp\":\"2026-08-26T11:56:00.450890Z\"}]}"}
{"recv_ts_ns":1787745360614168507,"payload":"{\"channel\":\"book\",\"type\":\"update\",\"data\":[{\"symbol\":\"BTC/USD\",\"bids\":[],\"asks\":[{\"price\":78517.9,\"qty\":0.00000000},{\"price\":78520.2,\"qty\":0.05060000}],\"checksum\":3762246201,\"timestamp\":\"2026-08-26T11:56:00.450912Z\"}]}"}
{"recv_ts_ns":1787745360614188012,"payload":"{\"channel\":\"book\",\"type\":\"update\",\"data\":[{\"symbol\":\"BTC/USD\",\"bids\":[{\"price\":78490.1,\"qty\":0.25555086}],\"asks\":[],\"checksum\":3762246201,\"timestamp\":\"2026-08-26T11:56:00.452651Z\"}]}"}
{"recv_ts_ns":1787745360614205828,"payload":"{\"channel\":\"book\",\"type\":\"update\",\"data\":[{\"symbol\":\"BTC/USD\",\"bids\":[],\"asks\":[{\"price\":78500.7,\"qty\":0.01749084}],\"checksum\":1048917991,\"timestamp\":\"2026-08-26T11:56:00.452778Z\"}]}"}
{"recv_ts_ns":1787745360618294803,"payload":"{\"channel\":\"book\",\"type\":\"update\",\"data\":[{\"symbol\":\"BTC/USD\",\"bids\":[{\"price\":78500.6,\"qty\":0.03729575}],\"asks\":[],\"checksum\":3442422171,\"timestamp\":\"2026-08-26T11:56:00.458118Z\"}]}"}
{"recv_ts_ns":1787745360619898861,"payload":"{\"channel\":\"book\",\"type\":\"update\",\"data\":[{\"symbol\":\"BTC/USD\",\"bids\":[{\"price\":78490.1,\"qty\":0.00000000},{\"price\":78473.9,\"qty\":0.40000000}],\"asks\":[],\"checksum\":3442422171,\"timestamp\":\"2026-08-26T11:56:00.462028Z\"}]}"}
{"recv_ts_ns":1787745360626849632,"payload":"{\"channel\":\"book\",\"type\":\"update\",\"data\":[{\"symbol\":\"BTC/USD\",\"bids\":[{\"price\":78492.7,\"qty\":0.01515510}],\"asks\":[],\"checksum\":1266096436,\"timestamp\":\"2026-08-26T11:56:00.471044Z\"}]}"}
{"recv_ts_ns":1787745360629572991,"payload":"{\"channel\":\"book\",\"type\":\"update\",\"data\":[{\"symbol\":\"BTC/USD\",\"bids\":[{\"price\":78474.7,\"qty\":1.27392488}],\"asks\":[],\"checksum\":1266096436,\"timestamp\":\"2026-08-26T11:56:00.473874Z\"}]}"}
{"recv_ts_ns":1787745360634020754,"payload":"{\"channel\":\"book\",\"type\":\"update\",\"data\":[{\"symbol\":\"BTC/USD\",\"bids\":[],\"asks\":[{\"price\":78519.7,\"qty\":0.12241900}],\"checksum\":1266096436,\"timestamp\":\"2026-08-26T11:56:00.477075Z\"}]}"}
{"recv_ts_ns":1787745360637473624,"payload":"{\"channel\":\"book\",\"type\":\"update\",\"data\":[{\"symbol\":\"BTC/USD\",\"bids\":[{\"price\":78495.0,\"qty\":0.95543056}],\"asks\":[],\"checksum\":2031229557,\"timestamp\":\"2026-08-26T11:56:00.479953Z\"}]}"}
{"recv_ts_ns":1787745360649606329,"payload":"{\"channel\":\"book\",\"type\":\"update\",\"data\":[{\"symbol\":\"BTC/USD\",\"bids\":[{\"price\":78475.0,\"qty\":0.00000000},{\"price\":78474.6,\"qty\":0.13109402},{\"price\":78480.0,\"qty\":1.31374962}],\"asks\":[],\"checksum\":2031229557,\"timestamp\":\"2026-08-26T11:56:00.492088Z\"}]}"}
{"recv_ts_ns":1787745360649730834,"payload":"{\"channel\":\"book\",\"type\":\"update\",\"data\":[{\"symbol\":\"BTC/USD\",\"bids\":[{\"price\":78486.7,\"qty\":0.95298540}],\"asks\":[],\"checksum\":2031229557,\"timestamp\":\"2026-08-26T11:56:00.493633Z\"}]}"}
{"recv_ts_ns":1787745360651700163,"payload":"{\"channel\":\"book\",\"type\":\"update\",\"data\":[{\"symbol\":\"BTC/USD\",\"bids\":[],\"asks\":[{\"price\":78517.8,\"qty\":0.00000000},{\"price\":78520.2,\"qty\":0.05060000}],\"checksum\":2031229557,\"timestamp\":\"2026-08-26T11:56:00.494985Z\"}]}"}
{"recv_ts_ns":1787745360651816968,"payload":"{\"channel\":\"book\",\"type\":\"update\",\"data\":[{\"symbol\":\"BTC/USD\",\"bids\":[],\"asks\":[{\"price\":78517.1,\"qty\":0.00000000},{\"price\":78520.4,\"qty\":0.80604145}],\"checksum\":2031229557,\"timestamp\":\"2026-08-26T11:56:00.495346Z\"}]}"}
{"recv_ts_ns":1787745360654332230,"payload":"{\"channel\":\"book\",\"type\":\"update\",\"data\":[{\"symbol\":\"BTC/USD\",\"bids\":[{\"price\":78486.5,\"qty\":0.00000000},{\"price\":78474.6,\"qty\":0.13109402}],\"asks\":[],\"checksum\":2031229557,\"timestamp\":\"2026-08-26T11:56:00.497419Z\"}]}"}
{"recv_ts_ns":1787745360654382520,"payload":"{\"channel\":\"book\",\"type\":\"update\",\"data\":[{\"symbol\":\"BTC/USD\",\"bids\":[],\"asks\":[{\"price\":78515.9,\"qty\":0.15356161}],\"checksum\":2031229557,\"timestamp\":\"2026-08-26T11:56:00.497543Z\"}]}"}
{"recv_ts_ns":1787745360654423997,"payload":"{\"channel\":\"book\",\"type\":\"update\",\"data\":[{\"symbol\":\"BTC/USD\",\"bids\":[],\"asks\":[{\"price\":78510.6,\"qty\":0.00000000},{\"price\":78520.4,\"qty\":0.80604145}],\"checksum\":3063119707,\"timestamp\":\"2026-08-26T11:56:00.497615Z\"}]}"}
{"recv_ts_ns":1787745360662653892,"payload":"{\"channel\":\"book\",\"type\":\"update\",\"data\":[{\"symbol\":\"BTC/USD\",\"bids\":[{\"price\":78500.6,\"qty\":0.10298941}],\"asks\":[],\"checksum\":25294983,\"timestamp\":\"2026-08-26T11:56:00.503420Z\"}]}"}
{"recv_ts_ns":1787745360662706494,"payload":"{\"channel\":\"book\",\"type\":\"update\",\"data\":[{\"symbol\":\"BTC/USD\",\"bids\":[],\"asks\":[{\"price\":78500.7,\"qty\":0.00666521}],\"checksum\":4269408814,\"timestamp\":\"2026-08-26T11:56:00.503932Z\"}]}"}
{"recv_ts_ns":1787745360689982661,"payload":"{\"channel\":\"book\",\"type\":\"update\",\"data\":[{\"symbol\":\"BTC/USD\",\"bids\":[],\"asks\":[{\"price\":78510.3,\"qty\":0.95543056}],\"checksum\":4291610614,\"timestamp\":\"2026-08-26T11:56:00.525619Z\"}]}"}
{"recv_ts_ns":1787745360693455179,"payload":"{\"channel\":\"book\",\"type\":\"update\",\"data\":[{\"symbol\":\"BTC/USD\",\"bids\":[],\"asks\":[{\"price\":78508.3,\"qty\":0.00005100},{\"price\":78511.0,\"qty\":3.03193780}],\"checksum\":1593312893,\"timestamp\":\"2026-08-26T11:56:00.528784Z\"}]}"}
{"recv_ts_ns":1787745360693590024,"payload":"{\"channel\":\"book\",\"type\":\"update\",\"data\":[{\"symbol\":\"BTC/USD\",\"bids\":[{\"price\":78480.1,\"qty\":0.01473761}],\"asks\":[],\"checksum\":1593312893,\"timestamp\":\"2026-08-26T11:56:00.529343Z\"}]}"}
{"recv_ts_ns":1787745360693652172,"payload":"{\"channel\":\"book\",\"type\":\"update\",\"data\":[{\"symbol\":\"BTC/USD\",\"bids\":[],\"asks\":[{\"price\":78511.0,\"qty\":0.00000000},{\"price\":78520.2,\"qty\":0.05060000}],\"checksum\":692078424,\"timestamp\":\"2026-08-26T11:56:00.531898Z\"}]}"}
{"recv_ts_ns":1787745360693805421,"payload":"{\"channel\":\"book\",\"type\":\"update\",\"data\":[{\"symbol\":\"BTC/USD\",\"bids\":[{\"price\":78480.0,\"qty\":0.03953200},{\"price\":78475.0,\"qty\":1.27429881}],\"asks\":[],\"checksum\":692078424,\"timestamp\":\"2026-08-26T11:56:00.532062Z\"}]}"}
{"recv_ts_ns":1787745360695272793,"payload":"{\"channel\":\"book\",\"type\":\"update\",\"data\":[{\"symbol\":\"BTC/USD\",\"bids\":[],\"asks\":[{\"price\":78507.6,\"qty\":0.01655857}],\"checksum\":2799525512,\"timestamp\":\"2026-08-26T11:56:00.534513Z\"}]}"}
{"recv_ts_ns":1787745360695355980,"payload":"{\"channel\":\"book\",\"type\":\"update\",\"data\":[{\"symbol\":\"BTC/USD\",\"bids\":[],\"asks\":[{\"price\":78500.7,\"qty\":0.00226521}],\"checksum\":2260186569,\"timestamp\":\"2026-08-26T11:56:00.535280Z\"}]}"}
{"recv_ts_ns":1787745360702494988,"payload":"{\"channel\":\"book\",\"type\":\"update\",\"data\":[{\"symbol\":\"BTC/USD\",\"bids\":[],\"asks\":[{\"price\":78513.4,\"qty\":0.41310361}],\"checksum\":2260186569,\"timestamp\":\"2026-08-26T11:56:00.541454Z\"}]}"}
{"recv_ts_ns":1787745360705336255,"payload":"{\"channel\":\"book\",\"type\":\"update\",\"data\":[{\"symbol\":\"BTC/USD\",\"bids\":[],\"asks\":[{\"price\":78515.9,\"qty\":0.00000000},{\"price\":78520.1,\"qty\":0.00005100}],\"checksum\":2260186569,\"timestamp\":\"2026-08-26T11:56:00.543015Z\"}]}"}
{"recv_ts_ns":1787745360705432451,"payload":"{\"channel\":\"book\",\"type\":\"update\",\"data\":[{\"symbol\":\"BTC/USD\",\"bids\":[],\"asks\":[{\"price\":78513.4,\"qty\":0.00000000},{\"price\":78520.2,\"qty\":0.05060000}],\"checksum\":2260186569,\"timestamp\":\"2026-08-26T11:56:00.543035Z\"}]}"}
{"recv_ts_ns":1787745360707200844,"payload":"{\"channel\":\"book\",\"type\":\"update\",\"data\":[{\"symbol\":\"BTC/USD\",\"bids\":[],\"asks\":[{\"price\":78512.2,\"qty\":0.63689497}],\"checksum\":58565476,\"timestamp\":\"2026-08-26T11:56:00.544810Z\"}]}"}
{"recv_ts_ns":1787745360707290453,"payload":"{\"channel\":\"book\",\"type\":\"update\",\"data\":[{\"symbol\":\"BTC/USD\",\"bids\":[],\"asks\":[{\"price\":78514.5,\"qty\":0.63682508}],\"checksum\":58565476,\"timestamp\":\"2026-08-26T11:56:00.545181Z\"}]}"}
{"recv_ts_ns":1787745360707348183,"payload":"{\"channel\":\"book\",\"type\":\"update\",\"data\":[{\"symbol\":\"BTC/USD\",\"bids\":[{\"price\":78495.7,\"qty\":0.63697737},{\"price\":78496.7,\"qty\":0.04603180}],\"asks\":[],\"checksum\":3307907229,\"timestamp\":\"2026-08-26T11:56:00.545348Z\"}]}"}
{"recv_ts_ns":1787745360707414090,"payload":"{\"channel\":\"book\",\"type\":\"update\",\"data\":[{\"symbol\":\"BTC/USD\",\"bids\":[{\"price\":78498.7,\"qty\":0.63695276}],\"asks\":[],\"checksum\":1293862242,\"timestamp\":\"2026-08-26T11:56:00.545371Z\"}]}"}
{"recv_ts_ns":1787745360710005178,"payload":"{\"channel\":\"book\",\"type\":\"update\",\"data\":[{\"symbol\":\"BTC/USD\",\"bids\":[],\"asks\":[{\"price\":78513.4,\"qty\":0.41310361}],\"checksum\":1293862242,\"timestamp\":\"2026-08-26T11:56:00.546952Z\"}]}"}
{"recv_ts_ns":1787745360710072791,"payload":"{\"channel\":\"book\",\"type\":\"update\",\"data\":[{\"symbol\":\"BTC/USD\",\"bids\":[],\"asks\":[{\"price\":78508.7,\"qty\":0.35203687}],\"checksum\":1217446301,\"timestamp\":\"2026-08-26T11:56:00.547233Z\"}]}"}
{"recv_ts_ns":1787745360712060757,"payload":"{\"channel\":\"book\",\"type\":\"update\",\"data\":[{\"symbol\":\"BTC/USD\",\"bids\":[],\"asks\":[{\"price\":78513.4,\"qty\":0.00000000},{\"price\":78520.0,\"qty\":0.02449286}],\"checksum\":1217446301,\"timestamp\":\"2026-08-26T11:56:00.549057Z\"}]}"}
{"recv_ts_ns":1787745360718344725,"payload":"{\"channel\":\"book\",\"type\":\"update\",\"data\":[{\"symbol\":\"BTC/USD\",\"bids\":[],\"asks\":[{\"price\":78512.1,\"qty\":0.80091290}],\"checksum\":2400237849,\"timestamp\":\"2026-08-26T11:56:00.553863Z\"}]}"}
{"recv_ts_ns":1787745360724865657,"payload":"{\"channel\":\"book\",\"type\":\"update\",\"data\":[{\"symbol\":\"BTC/USD\",\"bids\":[],\"asks\":[{\"price\":78515.7,\"qty\":0.15299940}],\"checksum\":2400237849,\"timestamp\":\"2026-08-26T11:56:00.559897Z\"}]}"}
{"recv_ts_ns":1787745360726055770,"payload":"{\"channel\":\"book\",\"type\":\"update\",\"data\":[{\"symbol\":\"BTC/USD\",\"bids\":[],\"asks\":[{\"price\":78513.5,\"qty\":0.00000000},{\"price\":78519.9,\"qty\":0.26887464},{\"price\":78515.9,\"qty\":1.27392302}],\"checksum\":2400237849,\"timestamp\":\"2026-08-26T11:56:00.561861Z\"}]}"}
{"recv_ts_ns":1787745360731120575,"payload":"{\"channel\":\"book\",\"type\":\"update\",\"data\":[{\"symbol\":\"BTC/USD\",\"bids\":[],\"asks\":[{\"price\":78512.1,\"qty\":0.00000000},{\"price\":78519.9,\"qty\":0.26887464}],\"checksum\":1217446301,\"timestamp\":\"2026-08-26T11:56:00.565396Z\"}]}"}
{"recv_ts_ns":1787745360731173102,"payload":"{\"channel\":\"book\",\"type\":\"update\",\"data\":[{\"symbol\":\"BTC/USD\",\"bids\":[],\"asks\":[{\"price\":78512.1,\"qty\":0.42064429}],\"checksum\":1894032300,\"timestamp\":\"2026-08-26T11:56:00.565511Z\"}]}"}
{"recv_ts_ns":1787745360751896544,"payload":"{\"channel\":\"book\",\"type\":\"update\",\"data\":[{\"symbol\":\"BTC/USD\",\"bids\":[],\"asks\":[{\"price\":78505.7,\"qty\":0.01521967}],\"checksum\":3802457024,\"timestamp\":\"2026-08-26T11:56:00.588633Z\"}]}"}
{"recv_ts_ns":1787745360752025207,"payload":"{\"channel\":\"book\",\"type\":\"update\",\"data\":[{\"symbol\":\"BTC/USD\",\"bids\":[],\"asks\":[{\"price\":78513.6,\"qty\":0.02523935}],\"checksum\":3802457024,\"timestamp\":\"2026-08-26T11:56:00.588660Z\"}]}"}
{"recv_ts_ns":1787745360756727556,"payload":"{\"channel\":\"book\",\"type\":\"update\",\"data\":[{\"symbol\":\"BTC/USD\",\"bids\":[],\"asks\":[{\"price\":78515.7,\"qty\":0.51370475}],\"checksum\":3802457024,\"timestamp\":\"2026-08-26T11:56:00.595008Z\"}]}"}
{"recv_ts_ns":1787745360756825958,"payload":"{\"channel\":\"book\",\"type\":\"update\",\"data\":[{\"symbol\":\"BTC/USD\",\"bids\":[{\"price\":78500.6,\"qty\":0.10053448}],\"asks\":[],\"checksum\":3448307747,\"timestamp\":\"2026-08-26T11:56:00.596037Z\"}]}"}
{"recv_ts_ns":1787745360756876075,"payload":"{\"channel\":\"book\",\"type\":\"update\",\"data\":[{\"symbol\":\"BTC/USD\",\"bids\":[],\"asks\":[{\"price\":78515.9,\"qty\":0.00000000},{\"price\":78519.6,\"qty\":0.08956015}],\"checksum\":3448307747,\"timestamp\":\"2026-08-26T11:56:00.596333Z\"}]}"}
{"recv_ts_ns":1787745360763582441,"payload":"{\"channel\":\"book\",\"type\":\"update\",\"data\":[{\"symbol\":\"BTC/USD\",\"bids\":[{\"price\":78486.6,\"qty\":0.00000000},{\"price\":78474.9,\"qty\":0.67473263}],\"asks\":[],\"checksum\":3448307747,\"timestamp\":\"2026-08-26T11:56:00.598522Z\"}]}"}
{"recv_ts_ns":1787745360763650815,"payload":"{\"channel\":\"book\",\"type\":\"update\",\"data\":[{\"symbol\":\"BTC/USD\",\"bids\":[],\"asks\":[{\"price\":78515.7,\"qty\":0.15299940}],\"checksum\":3448307747,\"timestamp\":\"2026-08-26T11:56:00.598805Z\"}]}"}
{"recv_ts_ns":1787745360763713901,"payload":"{\"channel\":\"book\",\"type\":\"update\",\"data\":[{\"symbol\":\"BTC/USD\",\"bids\":[{\"price\":78486.7,\"qty\":1.00093972}],\"asks\":[],\"checksum\":3448307747,\"timestamp\":\"2026-08-26T11:56:00.600964Z\"}]}"}
{"recv_ts_ns":1787745360763778866,"payload":"{\"channel\":\"book\",\"type\":\"update\",\"data\":[{\"symbol\":\"BTC/USD\",\"bids\":[{\"price\":78486.7,\"qty\":0.04795432}],\"asks\":[],\"checksum\":3448307747,\"timestamp\":\"2026-08-26T11:56:00.601029Z\"}]}"}
{"recv_ts_ns":1787745360763829150,"payload":"{\"channel\":\"book\",\"type\":\"update\",\"data\":[{\"symbol\":\"BTC/USD\",\"bids\":[],\"asks\":[{\"price\":78515.6,\"qty\":0.26868048}],\"checksum\":3448307747,\"timestamp\":\"2026-08-26T11:56:00.601676Z\"}]}"}
{"recv_ts_ns":1787745360763882683,"payload":"{\"channel\":\"book\",\"type\":\"update\",\"data\":[{\"symbol\":\"BTC/USD\",\"bids\":[],\"asks\":[{\"price\":78515.5,\"qty\":0.23320052}],\"checksum\":3448307747,\"timestamp\":\"2026-08-26T11:56:00.604474Z\"}]}"}
{"recv_ts_ns":1787745360768774870,"payload":"{\"channel\":\"book\",\"type\":\"update\",\"data\":[{\"symbol\":\"BTC/USD\",\"bids\":[],\"asks\":[{\"price\":78515.7,\"qty\":0.00000000},{\"price\":78519.5,\"qty\":0.08956016}],\"checksum\":3448307747,\"timestamp\":\"2026-08-26T11:56:00.604809Z\"}]}"}
{"recv_ts_ns":1787745360768899244,"payload":"{\"channel\":\"book\",\"type\":\"update\",\"data\":[{\"symbol\":\"BTC/USD\",\"bids\":[],\"asks\":[{\"price\":78519.5,\"qty\":0.34150945}],\"checksum\":3448307747,\"timestamp\":\"2026-08-26T11:56:00.607461Z\"}]}"}
{"recv_ts_ns":1787745360822547305,"payload":"{\"channel\":\"book\",\"type\":\"update\",\"data\":[{\"symbol\":\"BTC/USD\",\"bids\":[],\"asks\":[{\"price\":78519.5,\"qty\":0.08956016}],\"checksum\":3448307747,\"timestamp\":\"2026-08-26T11:56:00.674506Z\"}]}"}
{"recv_ts_ns":1787745360822762213,"payload":"{\"channel\":\"book\",\"type\":\"update\",\"data\":[{\"symbol\":\"BTC/USD\",\"bids\":[],\"asks\":[{\"price\":78519.5,\"qty\":0.17129884}],\"checksum\":3448307747,\"timestamp\":\"2026-08-26T11:56:00.674780Z\"}]}"}
{"recv_ts_ns":1787745360822805312,"payload":"{\"channel\":\"book\",\"type\":\"update\",\"data\":[{\"symbol\":\"BTC/USD\",\"bids\":[],\"asks\":[{\"price\":78518.7,\"qty\":0.00000000},{\"price\":78519.6,\"qty\":0.08956015},{\"price\":78514.4,\"qty\":0.04603180}],\"checksum\":3448307747,\"timestamp\":\"2026-08-26T11:56:00.675069Z\"}]}"}
{"recv_ts_ns":1787745360838489957,"payload":"{\"channel\":\"book\",\"type\":\"update\",\"data\":[{\"symbol\":\"BTC/USD\",\"bids\":[{\"price\":78475.1,\"qty\":1.27429718}],\"asks\":[],\"checksum\":3448307747,\"timestamp\":\"2026-08-26T11:56:00.691255Z\"}]}"}
{"recv_ts_ns":1787745360864887653,"payload":"{\"channel\":\"book\",\"type\":\"update\",\"data\":[{\"symbol\":\"BTC/USD\",\"bids\":[],\"asks\":[{\"price\":78507.6,\"qty\":0.00000000},{\"price\":78519.6,\"qty\":0.08956015}],\"checksum\":388666668,\"timestamp\":\"2026-08-26T11:56:00.717958Z\"}]}"}
{"recv_ts_ns":1787745360864927045,"payload":"{\"channel\":\"book\",\"type\":\"update\",\"data\":[{\"symbol\":\"BTC/USD\",\"bids\":[],\"asks\":[{\"price\":78505.6,\"qty\":0.01655857}],\"checksum\":3608606951,\"timestamp\":\"2026-08-26T11:56:00.718097Z\"}]}"}
{"recv_ts_ns":1787745360870562448,"payload":"{\"channel\":\"book\",\"type\":\"update\",\"data\":[{\"symbol\":\"BTC/USD\",\"bids\":[{\"price\":78484.8,\"qty\":3.03206103}],\"asks\":[],\"checksum\":3608606951,\"timestamp\":\"2026-08-26T11:56:00.724304Z\"}]}"}
{"recv_ts_ns":1787745360870612191,"payload":"{\"channel\":\"book\",\"type\":\"update\",\"data\":[{\"symbol\":\"BTC/USD\",\"bids\":[],\"asks\":[{\"price\":78511.3,\"qty\":0.12173800}],\"checksum\":3459614548,\"timestamp\":\"2026-08-26T11:56:00.724943Z\"}]}"}
{"recv_ts_ns":1787745360873480986,"payload":"{\"channel\":\"book\",\"type\":\"update\",\"data\":[{\"symbol\":\"BTC/USD\",\"bids\":[],\"asks\":[{\"price\":78512.2,\"qty\":0.00005100}],\"checksum\":3459614548,\"timestamp\":\"2026-08-26T11:56:00.726621Z\"}]}"}
{"recv_ts_ns":1787745360873506784,"payload":"{\"channel\":\"book\",\"type\":\"update\",\"data\":[{\"symbol\":\"BTC/USD\",\"bids\":[{\"price\":78486.7,\"qty\":0.61381456}],\"asks\":[],\"checksum\":3459614548,\"timestamp\":\"2026-08-26T11:56:00.727060Z\"}]}"}
{"recv_ts_ns":1787745360875450283,"payload":"{\"channel\":\"book\",\"type\":\"update\",\"data\":[{\"symbol\":\"BTC/USD\",\"bids\":[],\"asks\":[{\"price\":78511.2,\"qty\":0.63685210}],\"checksum\":2935444425,\"timestamp\":\"2026-08-26T11:56:00.729032Z\"}]}"}
{"recv_ts_ns":1787745360875486215,"payload":"{\"channel\":\"book\",\"type\":\"update\",\"data\":[{\"symbol\":\"BTC/USD\",\"bids\":[],\"asks\":[{\"price\":78512.1,\"qty\":0.00000000},{\"price\":78518.6,\"qty\":0.63679188}],\"checksum\":2935444425,\"timestamp\":\"2026-08-26T11:56:00.729315Z\"}]}"}
{"recv_ts_ns":1787745360878260817,"payload":"{\"channel\":\"book\",\"type\":\"update\",\"data\":[{\"symbol\":\"BTC/USD\",\"bids\":[{\"price\":78490.1,\"qty\":1.91106797}],\"asks\":[],\"checksum\":2935444425,\"timestamp\":\"2026-08-26T11:56:00.731559Z\"}]}"}
{"recv_ts_ns":1787745360880402228,"payload":"{\"channel\":\"book\",\"type\":\"update\",\"data\":[{\"symbol\":\"BTC/USD\",\"bids\":[],\"asks\":[{\"price\":78511.1,\"qty\":0.47825995}],\"checksum\":3310905737,\"timestamp\":\"2026-08-26T11:56:00.733284Z\"}]}"}
{"recv_ts_ns":1787745360886784089,"payload":"{\"channel\":\"book\",\"type\":\"update\",\"data\":[{\"symbol\":\"BTC/USD\",\"bids\":[{\"price\":78495.0,\"qty\":0.00000000},{\"price\":78475.1,\"qty\":1.27429718}],\"asks\":[],\"checksum\":3310905737,\"timestamp\":\"2026-08-26T11:56:00.739456Z\"}]}"}
{"recv_ts_ns":1787745360886828632,"payload":"{\"channel\":\"book\",\"type\":\"update\",\"data\":[{\"symbol\":\"BTC/USD\",\"bids\":[{\"price\":78493.0,\"qty\":0.85606579}],\"asks\":[],\"checksum\":3310905737,\"timestamp\":\"2026-08-26T11:56:00.739623Z\"}]}"}
{"recv_ts_ns":1787745360886860783,"payload":"{\"channel\":\"book\",\"type\":\"update\",\"data\":[{\"symbol\":\"BTC/USD\",\"bids\":[],\"asks\":[{\"price\":78510.3,\"qty\":0.00000000},{\"price\":78518.6,\"qty\":0.63679188}],\"checksum\":519436523,\"timestamp\":\"2026-08-26T11:56:00.739698Z\"}]}"}
{"recv_ts_ns":1787745360890482363,"payload":"{\"channel\":\"book\",\"type\":\"update\",\"data\":[{\"symbol\":\"BTC/USD\",\"bids\":[],\"asks\":[{\"price\":78508.7,\"qty\":0.00000000},{\"price\":78518.8,\"qty\":0.02057681}],\"checksum\":3775183629,\"timestamp\":\"2026-08-26T11:56:00.742129Z\"}]}"}
{"recv_ts_ns":1787745360894787337,"payload":"{\"channel\":\"book\",\"type\":\"update\",\"data\":[{\"symbol\":\"BTC/USD\",\"bids\":[],\"asks\":[{\"price\":78508.7,\"qty\":0.06684085}],\"checksum\":113047026,\"timestamp\":\"2026-08-26T11:56:00.744650Z\"}]}"}
{"recv_ts_ns":1787745360918038842,"payload":"{\"channel\":\"book\",\"type\":\"update\",\"data\":[{\"symbol\":\"BTC/USD\",\"bids\":[],\"asks\":[{\"price\":78509.3,\"qty\":0.95543056}],\"checksum\":948979393,\"timestamp\":\"2026-08-26T11:56:00.771245Z\"}]}"}
{"recv_ts_ns":1787745360918118399,"payload":"{\"channel\":\"book\",\"type\":\"update\",\"data\":[{\"symbol\":\"BTC/USD\",\"bids\":[{\"price\":78494.0,\"qty\":0.95543056}],\"asks\":[],\"checksum\":948979393,\"timestamp\":\"2026-08-26T11:56:00.771536Z\"}]}"}
{"recv_ts_ns":1787745360918160117,"payload":"{\"channel\":\"book\",\"type\":\"update\",\"data\":[{\"symbol\":\"BTC/USD\",\"bids\":[],\"asks\":[{\"price\":78515.4,\"qty\":1.27395476}],\"checksum\":948979393,\"timestamp\":\"2026-08-26T11:56:00.772675Z\"}]}"}
{"recv_ts_ns":1787745360925570265,"payload":"{\"channel\":\"heartbeat\"}"}
{"recv_ts_ns":1787745360932071904,"payload":"{\"channel\":\"book\",\"type\":\"update\",\"data\":[{\"symbol\":\"BTC/USD\",\"bids\":[],\"asks\":[{\"price\":78515.5,\"qty\":0.00000000},{\"price\":78516.3,\"qty\":0.01292474}],\"checksum\":948979393,\"timestamp\":\"2026-08-26T11:56:00.774307Z\"}]}"}
{"recv_ts_ns":1787745360932159886,"payload":"{\"channel\":\"book\",\"type\":\"update\",\"data\":[{\"symbol\":\"BTC/USD\",\"bids\":[],\"asks\":[{\"price\":78508.7,\"qty\":0.34349140}],\"checksum\":2444102076,\"timestamp\":\"2026-08-26T11:56:00.776570Z\"}]}"}
{"recv_ts_ns":1787745361020547298,"payload":"{\"channel\":\"book\",\"type\":\"update\",\"data\":[{\"symbol\":\"BTC/USD\",\"bids\":[],\"asks\":[{\"price\":78515.6,\"qty\":0.00000000},{\"price\":78518.6,\"qty\":0.63679188}],\"checksum\":2444102076,\"timestamp\":\"2026-08-26T11:56:00.873269Z\"}]}"}
{"recv_ts_ns":1787745361020724707,"payload":"{\"channel\":\"book\",\"type\":\"update\",\"data\":[{\"symbol\":\"BTC/USD\",\"bids\":[],\"asks\":[{\"price\":78514.4,\"qty\":0.00000000},{\"price\":78518.8,\"qty\":0.02057681},{\"price\":78512.2,\"qty\":0.04608280}],\"checksum\":2444102076,\"timestamp\":\"2026-08-26T11:56:00.874356Z\"}]}"}
{"recv_ts_ns":1787745361081408281,"payload":"{\"channel\":\"book\",\"type\":\"update\",\"data\":[{\"symbol\":\"BTC/USD\",\"bids\":[],\"asks\":[{\"price\":78515.3,\"qty\":0.70961678}],\"checksum\":2444102076,\"timestamp\":\"2026-08-26T11:56:00.935349Z\"}]}"}
{"recv_ts_ns":1787745361134930895,"payload":"{\"channel\":\"book\",\"type\":\"update\",\"data\":[{\"symbol\":\"BTC/USD\",\"bids\":[],\"asks\":[{\"price\":78509.3,\"qty\":0.00000000},{\"price\":78518.8,\"qty\":0.02057681}],\"checksum\":2944580239,\"timestamp\":\"2026-08-26T11:56:00.988831Z\"}]}"}
{"recv_ts_ns":1787745361134991055,"payload":"{\"channel\":\"book\",\"type\":\"update\",\"data\":[{\"symbol\":\"BTC/USD\",\"bids\":[{\"price\":78494.0,\"qty\":0.00000000},{\"price\":78476.5,\"qty\":0.00005000}],\"asks\":[],\"checksum\":2944580239,\"timestamp\":\"2026-08-26T11:56:00.988960Z\"}]}"}
{"recv_ts_ns":1787745361135016430,"payload":"{\"channel\":\"book\",\"type\":\"update\",\"data\":[{\"symbol\":\"BTC/USD\",\"bids\":[],\"asks\":[{\"price\":78508.7,\"qty\":0.06684085}],\"checksum\":113047026,\"timestamp\":\"2026-08-26T11:56:00.990150Z\"}]}"}
{"recv_ts_ns":1787745361153561806,"payload":"{\"channel\":\"book\",\"type\":\"update\",\"data\":[{\"symbol\":\"BTC/USD\",\"bids\":[],\"asks\":[{\"price\":78515.2,\"qty\":0.08956015}],\"checksum\":113047026,\"timestamp\":\"2026-08-26T11:56:01.007045Z\"}]}"}
{"recv_ts_ns":1787745361159550779,"payload":"{\"channel\":\"book\",\"type\":\"update\",\"data\":[{\"symbol\":\"BTC/USD\",\"bids\":[],\"asks\":[{\"price\":78508.4,\"qty\":0.95543056}],\"checksum\":645138892,\"timestamp\":\"2026-08-26T11:56:01.014269Z\"}]}"}
{"recv_ts_ns":1787745361159622966,"payload":"{\"channel\":\"book\",\"type\":\"update\",\"data\":[{\"symbol\":\"BTC/USD\",\"bids\":[{\"price\":78493.1,\"qty\":0.95543056}],\"asks\":[],\"checksum\":645138892,\"timestamp\":\"2026-08-26T11:56:01.014473Z\"}]}"}
{"recv_ts_ns":1787745361162852218,"payload":"{\"channel\":\"book\",\"type\":\"update\",\"data\":[{\"symbol\":\"BTC/USD\",\"bids\":[],\"asks\":[{\"price\":78508.7,\"qty\":0.00000000},{\"price\":78518.6,\"qty\":0.63679188}],\"checksum\":1859233489,\"timestamp\":\"2026-08-26T11:56:01.015499Z\"}]}"}
{"recv_ts_ns":1787745361162976432,"payload":"{\"channel\":\"book\",\"type\":\"update\",\"data\":[{\"symbol\":\"BTC/USD\",\"bids\":[],\"asks\":[{\"price\":78508.3,\"qty\":0.35208787}],\"checksum\":1745946317,\"timestamp\":\"2026-08-26T11:56:01.016709Z\"}]}"}
{"recv_ts_ns":1787745361234293068,"payload":"{\"channel\":\"book\",\"type\":\"update\",\"data\":[{\"symbol\":\"BTC/USD\",\"bids\":[],\"asks\":[{\"price\":78512.2,\"qty\":0.00005100},{\"price\":78512.1,\"qty\":0.04603180}],\"checksum\":1745946317,\"timestamp\":\"2026-08-26T11:56:01.089130Z\"}]}"}
{"recv_ts_ns":1787745361265654211,"payload":"{\"channel\":\"book\",\"type\":\"update\",\"data\":[{\"symbol\":\"BTC/USD\",\"bids\":[],\"asks\":[{\"price\":78515.2,\"qty\":0.35824063}],\"checksum\":1745946317,\"timestamp\":\"2026-08-26T11:56:01.119789Z\"}]}"}
{"recv_ts_ns":1787745361361873594,"payload":"{\"channel\":\"book\",\"type\":\"update\",\"data\":[{\"symbol\":\"BTC/USD\",\"bids\":[],\"asks\":[{\"price\":78511.3,\"qty\":0.00000000},{\"price\":78518.6,\"qty\":0.63679188}],\"checksum\":1745946317,\"timestamp\":\"2026-08-26T11:56:01.215118Z\"}]}"}
{"recv_ts_ns":1787745361392055117,"payload":"{\"channel\":\"book\",\"type\":\"update\",\"data\":[{\"symbol\":\"BTC/USD\",\"bids\":[],\"asks\":[{\"price\":78511.2,\"qty\":0.00000000},{\"price\":78518.8,\"qty\":0.02057681}],\"checksum\":3163632130,\"timestamp\":\"2026-08-26T11:56:01.246199Z\"}]}"}
{"recv_ts_ns":1787745361393326796,"payload":"{\"channel\":\"book\",\"type\":\"update\",\"data\":[{\"symbol\":\"BTC/USD\",\"bids\":[],\"asks\":[{\"price\":78514.5,\"qty\":0.00000000},{\"price\":78519.4,\"qty\":0.13310362}],\"checksum\":3163632130,\"timestamp\":\"2026-08-26T11:56:01.246227Z\"}]}"}
{"recv_ts_ns":1787745361393799649,"payload":"{\"channel\":\"book\",\"type\":\"update\",\"data\":[{\"symbol\":\"BTC/USD\",\"bids\":[],\"asks\":[{\"price\":78510.5,\"qty\":0.63685750}],\"checksum\":1007492213,\"timestamp\":\"2026-08-26T11:56:01.247916Z\"}]}"}
{"recv_ts_ns":1787745361393884559,"payload":"{\"channel\":\"book\",\"type\":\"update\",\"data\":[{\"symbol\":\"BTC/USD\",\"bids\":[],\"asks\":[{\"price\":78511.1,\"qty\":0.00000000},{\"price\":78519.4,\"qty\":0.13310362}],\"checksum\":3132561316,\"timestamp\":\"2026-08-26T11:56:01.247957Z\"}]}"}
{"recv_ts_ns":1787745361394208540,"payload":"{\"channel\":\"book\",\"type\":\"update\",\"data\":[{\"symbol\":\"BTC/USD\",\"bids\":[],\"asks\":[{\"price\":78513.1,\"qty\":0.63683660}],\"checksum\":3132561316,\"timestamp\":\"2026-08-26T11:56:01.248269Z\"}]}"}
{"recv_ts_ns":1787745361394278633,"payload":"{\"channel\":\"book\",\"type\":\"update\",\"data\":[{\"symbol\":\"BTC/USD\",\"bids\":[],\"asks\":[{\"price\":78508.3,\"qty\":0.49718262}],\"checksum\":1717350917,\"timestamp\":\"2026-08-26T11:56:01.249372Z\"}]}"}
{"recv_ts_ns":1787745361461690639,"payload":"{\"channel\":\"book\",\"type\":\"update\",\"data\":[{\"symbol\":\"BTC/USD\",\"bids\":[],\"asks\":[{\"price\":78514.5,\"qty\":0.12158300}],\"checksum\":1717350917,\"timestamp\":\"2026-08-26T11:56:01.315976Z\"}]}"}
{"recv_ts_ns":1787745361568914713,"payload":"{\"channel\":\"book\",\"type\":\"update\",\"data\":[{\"symbol\":\"BTC/USD\",\"bids\":[{\"price\":78493.1,\"qty\":0.00000000},{\"price\":78476.5,\"qty\":0.00005000}],\"asks\":[],\"checksum\":1717350917,\"timestamp\":\"2026-08-26T11:56:01.422587Z\"}]}"}
{"recv_ts_ns":1787745361569058709,"payload":"{\"channel\":\"book\",\"type\":\"update\",\"data\":[{\"symbol\":\"BTC/USD\",\"bids\":[],\"asks\":[{\"price\":78508.4,\"qty\":0.00000000},{\"price\":78518.8,\"qty\":0.02057681}],\"checksum\":3019554345,\"timestamp\":\"2026-08-26T11:56:01.422708Z\"}]}"}
{"recv_ts_ns":1787745361574116844,"payload":"{\"channel\":\"book\",\"type\":\"update\",\"data\":[{\"symbol\":\"BTC/USD\",\"bids\":[],\"asks\":[{\"price\":78508.3,\"qty\":0.35208787}],\"checksum\":3665570919,\"timestamp\":\"2026-08-26T11:56:01.424013Z\"}]}"}
{"recv_ts_ns":1787745361574211806,"payload":"{\"channel\":\"book\",\"type\":\"update\",\"data\":[{\"symbol\":\"BTC/USD\",\"bids\":[],\"asks\":[{\"price\":78508.3,\"qty\":0.00005100}],\"checksum\":1270451382,\"timestamp\":\"2026-08-26T11:56:01.424159Z\"}]}"}
{"recv_ts_ns":1787745361574253743,"payload":"{\"channel\":\"book\",\"type\":\"update\",\"data\":[{\"symbol\":\"BTC/USD\",\"bids\":[],\"asks\":[{\"price\":78508.7,\"qty\":0.25694282}],\"checksum\":189115430,\"timestamp\":\"2026-08-26T11:56:01.425322Z\"}]}"}
{"recv_ts_ns":1787745361599082165,"payload":"{\"channel\":\"book\",\"type\":\"update\",\"data\":[{\"symbol\":\"BTC/USD\",\"bids\":[],\"asks\":[{\"price\":78513.0,\"qty\":0.26930454}],\"checksum\":189115430,\"timestamp\":\"2026-08-26T11:56:01.451215Z\"}]}"}
{"recv_ts_ns":1787745361616619355,"payload":"{\"channel\":\"book\",\"type\":\"update\",\"data\":[{\"symbol\":\"BTC/USD\",\"bids\":[],\"asks\":[{\"price\":78509.8,\"qty\":0.95543056}],\"checksum\":4130556176,\"timestamp\":\"2026-08-26T11:56:01.470861Z\"}]}"}
{"recv_ts_ns":1787745361616836117,"payload":"{\"channel\":\"book\",\"type\":\"update\",\"data\":[{\"symbol\":\"BTC/USD\",\"bids\":[{\"price\":78494.5,\"qty\":0.95543056}],\"asks\":[],\"checksum\":4130556176,\"timestamp\":\"2026-08-26T11:56:01.470974Z\"}]}"}
{"recv_ts_ns":1787745361649799229,"payload":"{\"channel\":\"book\",\"type\":\"update\",\"data\":[{\"symbol\":\"BTC/USD\",\"bids\":[{\"price\":78480.6,\"qty\":0.00000000},{\"price\":78476.5,\"qty\":0.00005000},{\"price\":78481.4,\"qty\":0.00010100}],\"asks\":[],\"checksum\":4130556176,\"timestamp\":\"2026-08-26T11:56:01.502650Z\"}]}"}
{"recv_ts_ns":1787745361860958413,"payload":"{\"channel\":\"book\",\"type\":\"update\",\"data\":[{\"symbol\":\"BTC/USD\",\"bids\":[],\"asks\":[{\"price\":78514.5,\"qty\":0.00000000},{\"price\":78518.6,\"qty\":0.63679188}],\"checksum\":4130556176,\"timestamp\":\"2026-08-26T11:56:01.715613Z\"}]}"}
{"recv_ts_ns":1787745361897894848,"payload":"{\"channel\":\"book\",\"type\":\"update\",\"data\":[{\"symbol\":\"BTC/USD\",\"bids\":[],\"asks\":[{\"price\":78510.5,\"qty\":0.00000000},{\"price\":78518.8,\"qty\":0.02057681}],\"checksum\":1019957451,\"timestamp\":\"2026-08-26T11:56:01.752130Z\"}]}"}
{"recv_ts_ns":1787745361903508587,"payload":"{\"channel\":\"book\",\"type\":\"update\",\"data\":[{\"symbol\":\"BTC/USD\",\"bids\":[],\"asks\":[{\"price\":78511.3,\"qty\":0.63685126}],\"checksum\":1454621825,\"timestamp\":\"2026-08-26T11:56:01.753770Z\"}]}"}
{"recv_ts_ns":1787745361903748001,"payload":"{\"channel\":\"book\",\"type\":\"update\",\"data\":[{\"symbol\":\"BTC/USD\",\"bids\":[],\"asks\":[{\"price\":78513.0,\"qty\":0.00254734}],\"checksum\":1454621825,\"timestamp\":\"2026-08-26T11:56:01.755030Z\"}]}"}
{"recv_ts_ns":1787745361903841566,"payload":"{\"channel\":\"book\",\"type\":\"update\",\"data\":[{\"symbol\":\"BTC/USD\",\"bids\":[],\"asks\":[{\"price\":78511.2,\"qty\":0.44192435}],\"checksum\":2070795859,\"timestamp\":\"2026-08-26T11:56:01.756571Z\"}]}"}
{"recv_ts_ns":1787745361905153231,"payload":"{\"channel\":\"book\",\"type\":\"update\",\"data\":[{\"symbol\":\"BTC/USD\",\"bids\":[],\"asks\":[{\"price\":78509.8,\"qty\":0.00000000},{\"price\":78518.6,\"qty\":0.63679188}],\"checksum\":4022706656,\"timestamp\":\"2026-08-26T11:56:01.759424Z\"}]}"}
{"recv_ts_ns":1787745361905370266,"payload":"{\"channel\":\"book\",\"type\":\"update\",\"data\":[{\"symbol\":\"BTC/USD\",\"bids\":[{\"price\":78494.5,\"qty\":0.00000000},{\"price\":78476.5,\"qty\":0.00005000}],\"asks\":[],\"checksum\":4022706656,\"timestamp\":\"2026-08-26T11:56:01.759435Z\"}]}"}
{"recv_ts_ns":1787745361905485373,"payload":"{\"channel\":\"book\",\"type\":\"update\",\"data\":[{\"symbol\":\"BTC/USD\",\"bids\":[],\"asks\":[{\"price\":78508.7,\"qty\":0.00000000},{\"price\":78518.8,\"qty\":0.02057681}],\"checksum\":1598695493,\"timestamp\":\"2026-08-26T11:56:01.760696Z\"}]}"}
{"recv_ts_ns":1787745361906760628,"payload":"{\"channel\":\"book\",\"type\":\"update\",\"data\":[{\"symbol\":\"BTC/USD\",\"bids\":[],\"asks\":[{\"price\":78508.7,\"qty\":0.06684085}],\"checksum\":2188329576,\"timestamp\":\"2026-08-26T11:56:01.762008Z\"}]}"}
{"recv_ts_ns":1787745361917519157,"payload":"{\"channel\":\"book\",\"type\":\"update\",\"data\":[{\"symbol\":\"BTC/USD\",\"bids\":[],\"asks\":[{\"price\":78508.8,\"qty\":1.17935301}],\"checksum\":1928477904,\"timestamp\":\"2026-08-26T11:56:01.771000Z\"}]}"}
{"recv_ts_ns":1787745361917683232,"payload":"{\"channel\":\"book\",\"type\":\"update\",\"data\":[{\"symbol\":\"BTC/USD\",\"bids\":[{\"price\":78493.5,\"qty\":0.95543056}],\"asks\":[],\"checksum\":1928477904,\"timestamp\":\"2026-08-26T11:56:01.771015Z\"}]}"}
{"recv_ts_ns":1787745361926606476,"payload":"{\"channel\":\"heartbeat\"}"}
{"recv_ts_ns":1787745361961004536,"payload":"{\"channel\":\"book\",\"type\":\"update\",\"data\":[{\"symbol\":\"BTC/USD\",\"bids\":[],\"asks\":[{\"price\":78512.9,\"qty\":0.12154400}],\"checksum\":1928477904,\"timestamp\":\"2026-08-26T11:56:01.815680Z\"}]}"}
{"recv_ts_ns":1787745362366592931,"payload":"{\"channel\":\"book\",\"type\":\"update\",\"data\":[{\"symbol\":\"BTC/USD\",\"bids\":[],\"asks\":[{\"price\":78512.9,\"qty\":0.00000000},{\"price\":78518.6,\"qty\":0.63679188}],\"checksum\":1928477904,\"timestamp\":\"2026-08-26T11:56:02.221383Z\"}]}"}
{"recv_ts_ns":1787745362468051490,"payload":"{\"channel\":\"book\",\"type\":\"update\",\"data\":[{\"symbol\":\"BTC/USD\",\"bids\":[],\"asks\":[{\"price\":78512.6,\"qty\":0.12160300}],\"checksum\":1928477904,\"timestamp\":\"2026-08-26T11:56:02.321314Z\"}]}"}
{"recv_ts_ns":1787745362468230807,"payload":"{\"channel\":\"book\",\"type\":\"update\",\"data\":[{\"symbol\":\"BTC/USD\",\"bids\":[],\"asks\":[{\"price\":78508.7,\"qty\":0.34349140}],\"checksum\":1559170846,\"timestamp\":\"2026-08-26T11:56:02.322834Z\"}]}"}
{"recv_ts_ns":1787745362500784432,"payload":"{\"channel\":\"book\",\"type\":\"update\",\"data\":[{\"symbol\":\"BTC/USD\",\"bids\":[{\"price\":78500.6,\"qty\":0.12348931}],\"asks\":[],\"checksum\":990157009,\"timestamp\":\"2026-08-26T11:56:02.350765Z\"}]}"}
{"recv_ts_ns":1787745362500955617,"payload":"{\"channel\":\"book\",\"type\":\"update\",\"data\":[{\"symbol\":\"BTC/USD\",\"bids\":[{\"price\":78500.6,\"qty\":0.18718931}],\"asks\":[],\"checksum\":3173665444,\"timestamp\":\"2026-08-26T11:56:02.353201Z\"}]}"}
{"recv_ts_ns":1787745362501157117,"payload":"{\"channel\":\"book\",\"type\":\"update\",\"data\":[{\"symbol\":\"BTC/USD\",\"bids\":[{\"price\":78500.6,\"qty\":0.78885755}],\"asks\":[],\"checksum\":651423831,\"timestamp\":\"2026-08-26T11:56:02.354868Z\"}]}"}
{"recv_ts_ns":1787745362566476290,"payload":"{\"channel\":\"book\",\"type\":\"update\",\"data\":[{\"symbol\":\"BTC/USD\",\"bids\":[],\"asks\":[{\"price\":78509.6,\"qty\":0.85606579}],\"checksum\":539164964,\"timestamp\":\"2026-08-26T11:56:02.421279Z\"}]}"}
{"recv_ts_ns":1787745362568937635,"payload":"{\"channel\":\"book\",\"type\":\"update\",\"data\":[{\"symbol\":\"BTC/USD\",\"bids\":[],\"asks\":[{\"price\":78508.7,\"qty\":0.90714921}],\"checksum\":1683226802,\"timestamp\":\"2026-08-26T11:56:02.423019Z\"}]}"}
{"recv_ts_ns":1787745362569100721,"payload":"{\"channel\":\"book\",\"type\":\"update\",\"data\":[{\"symbol\":\"BTC/USD\",\"bids\":[],\"asks\":[{\"price\":78508.7,\"qty\":0.84030836}],\"checksum\":1498353787,\"timestamp\":\"2026-08-26T11:56:02.423037Z\"}]}"}
{"recv_ts_ns":1787745362569164839,"payload":"{\"channel\":\"book\",\"type\":\"update\",\"data\":[{\"symbol\":\"BTC/USD\",\"bids\":[],\"asks\":[{\"price\":78508.7,\"qty\":0.56365781}],\"checksum\":3474033129,\"timestamp\":\"2026-08-26T11:56:02.423181Z\"}]}"}
{"recv_ts_ns":1787745362772540931,"payload":"{\"channel\":\"book\",\"type\":\"update\",\"data\":[{\"symbol\":\"BTC/USD\",\"bids\":[],\"asks\":[{\"price\":78515.2,\"qty\":0.08956015}],\"checksum\":3474033129,\"timestamp\":\"2026-08-26T11:56:02.626832Z\"}]}"}
{"recv_ts_ns":1787745362871764489,"payload":"{\"channel\":\"book\",\"type\":\"update\",\"data\":[{\"symbol\":\"BTC/USD\",\"bids\":[],\"asks\":[{\"price\":78512.6,\"qty\":0.00000000},{\"price\":78516.3,\"qty\":0.01292474}],\"checksum\":3474033129,\"timestamp\":\"2026-08-26T11:56:02.726244Z\"}]}"}
{"recv_ts_ns":1787745362927134130,"payload":"{\"channel\":\"heartbeat\"}"}
{"recv_ts_ns":1787745362954174936,"payload":"{\"channel\":\"book\",\"type\":\"update\",\"data\":[{\"symbol\":\"BTC/USD\",\"bids\":[],\"asks\":[{\"price\":78512.1,\"qty\":0.00000000},{\"price\":78518.6,\"qty\":0.63679188},{\"price\":78500.7,\"qty\":0.04829701}],\"checksum\":898336917,\"timestamp\":\"2026-08-26T11:56:02.808323Z\"}]}"}
{"recv_ts_ns":1787745362972353861,"payload":"{\"channel\":\"book\",\"type\":\"update\",\"data\":[{\"symbol\":\"BTC/USD\",\"bids\":[],\"asks\":[{\"price\":78512.4,\"qty\":0.12165800}],\"checksum\":898336917,\"timestamp\":\"2026-08-26T11:56:02.826269Z\"}]}"}
{"recv_ts_ns":1787745362985645303,"payload":"{\"channel\":\"book\",\"type\":\"update\",\"data\":[{\"symbol\":\"BTC/USD\",\"bids\":[{\"price\":78484.9,\"qty\":0.00900000}],\"asks\":[],\"checksum\":898336917,\"timestamp\":\"2026-08-26T11:56:02.837537Z\"}]}"}
{"recv_ts_ns":1787745363378390598,"payload":"{\"channel\":\"book\",\"type\":\"update\",\"data\":[{\"symbol\":\"BTC/USD\",\"bids\":[],\"asks\":[{\"price\":78512.4,\"qty\":0.00000000},{\"price\":78518.6,\"qty\":0.63679188}],\"checksum\":898336917,\"timestamp\":\"2026-08-26T11:56:03.230991Z\"}]}"}
{"recv_ts_ns":1787745363476382494,"payload":"{\"channel\":\"book\",\"type\":\"update\",\"data\":[{\"symbol\":\"BTC/USD\",\"bids\":[],\"asks\":[{\"price\":78512.1,\"qty\":0.12170900}],\"checksum\":898336917,\"timestamp\":\"2026-08-26T11:56:03.330939Z\"}]}"}
{"recv_ts_ns":1787745363770244241,"payload":"{\"channel\":\"book\",\"type\":\"update\",\"data\":[{\"symbol\":\"BTC/USD\",\"bids\":[{\"price\":78490.2,\"qty\":0.33481637}],\"asks\":[],\"checksum\":898336917,\"timestamp\":\"2026-08-26T11:56:03.624399Z\"}]}"}
{"recv_ts_ns":1787745363837992934,"payload":"{\"channel\":\"book\",\"type\":\"update\",\"data\":[{\"symbol\":\"BTC/USD\",\"bids\":[{\"price\":78484.0,\"qty\":0.12613757}],\"asks\":[],\"checksum\":898336917,\"timestamp\":\"2026-08-26T11:56:03.690648Z\"}]}"}
{"recv_ts_ns":1787745363867074795,"payload":"{\"channel\":\"book\",\"type\":\"update\",\"data\":[{\"symbol\":\"BTC/USD\",\"bids\":[],\"asks\":[{\"price\":78513.1,\"qty\":0.00000000},{\"price\":78518.6,\"qty\":0.63679188}],\"checksum\":898336917,\"timestamp\":\"2026-08-26T11:56:03.722212Z\"}]}"}
{"recv_ts_ns":1787745363869528925,"payload":"{\"channel\":\"book\",\"type\":\"update\",\"data\":[{\"symbol\":\"BTC/USD\",\"bids\":[{\"price\":78493.5,\"qty\":0.00000000},{\"price\":78480.1,\"qty\":0.01473761}],\"asks\":[],\"checksum\":898336917,\"timestamp\":\"2026-08-26T11:56:03.722337Z\"}]}"}
{"recv_ts_ns":1787745363869605123,"payload":"{\"channel\":\"book\",\"type\":\"update\",\"data\":[{\"symbol\":\"BTC/USD\",\"bids\":[],\"asks\":[{\"price\":78508.8,\"qty\":0.22392245}],\"checksum\":624556914,\"timestamp\":\"2026-08-26T11:56:03.722423Z\"}]}"}
{"recv_ts_ns":1787745363871076277,"payload":"{\"channel\":\"book\",\"type\":\"update\",\"data\":[{\"symbol\":\"BTC/USD\",\"bids\":[],\"asks\":[{\"price\":78511.3,\"qty\":0.00000000},{\"price\":78518.8,\"qty\":0.02057681}],\"checksum\":624556914,\"timestamp\":\"2026-08-26T11:56:03.723194Z\"}]}"}
{"recv_ts_ns":1787745363871233290,"payload":"{\"channel\":\"book\",\"type\":\"update\",\"data\":[{\"symbol\":\"BTC/USD\",\"bids\":[],\"asks\":[{\"price\":78509.6,\"qty\":0.00000000},{\"price\":78519.4,\"qty\":0.05290250}],\"checksum\":408511266,\"timestamp\":\"2026-08-26T11:56:03.723234Z\"}]}"}
{"recv_ts_ns":1787745363871332762,"payload":"{\"channel\":\"book\",\"type\":\"update\",\"data\":[{\"symbol\":\"BTC/USD\",\"bids\":[],\"asks\":[{\"price\":78511.2,\"qty\":0.00000000},{\"price\":78520.0,\"qty\":0.02449286}],\"checksum\":3860149886,\"timestamp\":\"2026-08-26T11:56:03.723657Z\"}]}"}
{"recv_ts_ns":1787745363871416629,"payload":"{\"channel\":\"book\",\"type\":\"update\",\"data\":[{\"symbol\":\"BTC/USD\",\"bids\":[],\"asks\":[{\"price\":78505.6,\"qty\":0.00000000},{\"price\":78520.1,\"qty\":0.00005100}],\"checksum\":1243335787,\"timestamp\":\"2026-08-26T11:56:03.723946Z\"}]}"}
{"recv_ts_ns":1787745363872045254,"payload":"{\"channel\":\"book\",\"type\":\"update\",\"data\":[{\"symbol\":\"BTC/USD\",\"bids\":[],\"asks\":[{\"price\":78508.7,\"qty\":0.00000000},{\"price\":78520.2,\"qty\":0.05060000}],\"checksum\":4083813826,\"timestamp\":\"2026-08-26T11:56:03.724553Z\"}]}"}
{"recv_ts_ns":1787745363872150710,"payload":"{\"channel\":\"book\",\"type\":\"update\",\"data\":[{\"symbol\":\"BTC/USD\",\"bids\":[],\"asks\":[{\"price\":78512.1,\"qty\":0.75855413}],\"checksum\":2584321314,\"timestamp\":\"2026-08-26T11:56:03.724844Z\"}]}"}
{"recv_ts_ns":1787745363872226415,"payload":"{\"channel\":\"book\",\"type\":\"update\",\"data\":[{\"symbol\":\"BTC/USD\",\"bids\":[],\"asks\":[{\"price\":78515.2,\"qty\":0.00000000},{\"price\":78521.8,\"qty\":0.02547406}],\"checksum\":2584321314,\"timestamp\":\"2026-08-26T11:56:03.725169Z\"}]}"}
{"recv_ts_ns":1787745363872298425,"payload":"{\"channel\":\"book\",\"type\":\"update\",\"data\":[{\"symbol\":\"BTC/USD\",\"bids\":[],\"asks\":[{\"price\":78514.5,\"qty\":0.63682542}],\"checksum\":2584321314,\"timestamp\":\"2026-08-26T11:56:03.725277Z\"}]}"}
{"recv_ts_ns":1787745363872381166,"payload":"{\"channel\":\"book\",\"type\":\"update\",\"data\":[{\"symbol\":\"BTC/USD\",\"bids\":[],\"asks\":[{\"price\":78515.9,\"qty\":0.15284794}],\"checksum\":2584321314,\"timestamp\":\"2026-08-26T11:56:03.725481Z\"}]}"}
{"recv_ts_ns":1787745363872471229,"payload":"{\"channel\":\"book\",\"type\":\"update\",\"data\":[{\"symbol\":\"BTC/USD\",\"bids\":[],\"asks\":[{\"price\":78511.5,\"qty\":0.01565551}],\"checksum\":1625263514,\"timestamp\":\"2026-08-26T11:56:03.725883Z\"}]}"}
{"recv_ts_ns":1787745363874771491,"payload":"{\"channel\":\"book\",\"type\":\"update\",\"data\":[{\"symbol\":\"BTC/USD\",\"bids\":[],\"asks\":[{\"price\":78508.7,\"qty\":0.06684085}],\"checksum\":2830499984,\"timestamp\":\"2026-08-26T11:56:03.725988Z\"}]}"}
{"recv_ts_ns":1787745363874874530,"payload":"{\"channel\":\"book\",\"type\":\"update\",\"data\":[{\"symbol\":\"BTC/USD\",\"bids\":[],\"asks\":[{\"price\":78512.1,\"qty\":0.12170900}],\"checksum\":3678456327,\"timestamp\":\"2026-08-26T11:56:03.726071Z\"}]}"}
{"recv_ts_ns":1787745363874940721,"payload":"{\"channel\":\"book\",\"type\":\"update\",\"data\":[{\"symbol\":\"BTC/USD\",\"bids\":[],\"asks\":[{\"price\":78514.5,\"qty\":0.00000000},{\"price\":78520.0,\"qty\":0.02449286}],\"checksum\":3678456327,\"timestamp\":\"2026-08-26T11:56:03.726208Z\"}]}"}
{"recv_ts_ns":1787745363875030157,"payload":"{\"channel\":\"book\",\"type\":\"update\",\"data\":[{\"symbol\":\"BTC/USD\",\"bids\":[{\"price\":78500.6,\"qty\":0.83945755}],\"asks\":[],\"checksum\":115053993,\"timestamp\":\"2026-08-26T11:56:03.726318Z\"}]}"}
{"recv_ts_ns":1787745363875112890,"payload":"{\"channel\":\"book\",\"type\":\"update\",\"data\":[{\"symbol\":\"BTC/USD\",\"bids\":[],\"asks\":[{\"price\":78512.1,\"qty\":0.00000000},{\"price\":78520.1,\"qty\":0.00005100}],\"checksum\":2420023968,\"timestamp\":\"2026-08-26T11:56:03.726914Z\"}]}"}
{"recv_ts_ns":1787745363875198494,"payload":"{\"channel\":\"book\",\"type\":\"update\",\"data\":[{\"symbol\":\"BTC/USD\",\"bids\":[],\"asks\":[{\"price\":78512.0,\"qty\":0.27441643}],\"checksum\":1456637646,\"timestamp\":\"2026-08-26T11:56:03.727570Z\"}]}"}
{"recv_ts_ns":1787745363875288698,"payload":"{\"channel\":\"book\",\"type\":\"update\",\"data\":[{\"symbol\":\"BTC/USD\",\"bids\":[],\"asks\":[{\"price\":78512.6,\"qty\":0.95543056}],\"checksum\":1456637646,\"timestamp\":\"2026-08-26T11:56:03.727692Z\"}]}"}
{"recv_ts_ns":1787745363875369586,"payload":"{\"channel\":\"book\",\"type\":\"update\",\"data\":[{\"symbol\":\"BTC/USD\",\"bids\":[{\"price\":78497.4,\"qty\":0.95543056}],\"asks\":[],\"checksum\":3354393950,\"timestamp\":\"2026-08-26T11:56:03.727762Z\"}]}"}
{"recv_ts_ns":1787745363878221180,"payload":"{\"channel\":\"book\",\"type\":\"update\",\"data\":[{\"symbol\":\"BTC/USD\",\"bids\":[],\"asks\":[{\"price\":78500.7,\"qty\":0.00226521}],\"checksum\":2699995055,\"timestamp\":\"2026-08-26T11:56:03.728131Z\"}]}"}
{"recv_ts_ns":1787745363878330606,"payload":"{\"channel\":\"book\",\"type\":\"update\",\"data\":[{\"symbol\":\"BTC/USD\",\"bids\":[],\"asks\":[{\"price\":78513.6,\"qty\":0.00000000},{\"price\":78520.0,\"qty\":0.02449286}],\"checksum\":2699995055,\"timestamp\":\"2026-08-26T11:56:03.728710Z\"}]}"}
{"recv_ts_ns":1787745363878435893,"payload":"{\"channel\":\"book\",\"type\":\"update\",\"data\":[{\"symbol\":\"BTC/USD\",\"bids\":[],\"asks\":[{\"price\":78505.7,\"qty\":0.00000000},{\"price\":78520.1,\"qty\":0.00005100}],\"checksum\":1610461630,\"timestamp\":\"2026-08-26T11:56:03.728721Z\"}]}"}
{"recv_ts_ns":1787745363878532300,"payload":"{\"channel\":\"book\",\"type\":\"update\",\"data\":[{\"symbol\":\"BTC/USD\",\"bids\":[],\"asks\":[{\"price\":78514.2,\"qty\":0.00000000},{\"price\":78520.2,\"qty\":0.05060000}],\"checksum\":1610461630,\"timestamp\":\"2026-08-26T11:56:03.729119Z\"}]}"}
{"recv_ts_ns":1787745363878619029,"payload":"{\"channel\":\"book\",\"type\":\"update\",\"data\":[{\"symbol\":\"BTC/USD\",\"bids\":[{\"price\":78500.6,\"qty\":0.91745755}],\"asks\":[],\"checksum\":217045922,\"timestamp\":\"2026-08-26T11:56:03.729210Z\"}]}"}
{"recv_ts_ns":1787745363878774742,"payload":"{\"channel\":\"book\",\"type\":\"update\",\"data\":[{\"symbol\":\"BTC/USD\",\"bids\":[],\"asks\":[{\"price\":78512.0,\"qty\":0.00000000},{\"price\":78521.8,\"qty\":0.02547406}],\"checksum\":2132811102,\"timestamp\":\"2026-08-26T11:56:03.729249Z\"}]}"}
{"recv_ts_ns":1787745363878846584,"payload":"{\"channel\":\"book\",\"type\":\"update\",\"data\":[{\"symbol\":\"BTC/USD\",\"bids\":[],\"asks\":[{\"price\":78508.7,\"qty\":0.00000000},{\"price\":78522.3,\"qty\":0.01292474}],\"checksum\":3968657636,\"timestamp\":\"2026-08-26T11:56:03.730659Z\"}]}"}
{"recv_ts_ns":1787745363878918418,"payload":"{\"channel\":\"book\",\"type\":\"update\",\"data\":[{\"symbol\":\"BTC/USD\",\"bids\":[{\"price\":78483.4,\"qty\":0.13109402}],\"asks\":[],\"checksum\":3968657636,\"timestamp\":\"2026-08-26T11:56:03.730749Z\"}]}"}
{"recv_ts_ns":1787745363880342339,"payload":"{\"channel\":\"book\",\"type\":\"update\",\"data\":[{\"symbol\":\"BTC/USD\",\"bids\":[],\"asks\":[{\"price\":78512.6,\"qty\":0.00000000},{\"price\":78522.6,\"qty\":0.06368515}],\"checksum\":3336614876,\"timestamp\":\"2026-08-26T11:56:03.731532Z\"}]}"}
{"recv_ts_ns":1787745363880452304,"payload":"{\"channel\":\"book\",\"type\":\"update\",\"data\":[{\"symbol\":\"BTC/USD\",\"bids\":[{\"price\":78497.4,\"qty\":0.00000000},{\"price\":78481.4,\"qty\":0.00010100}],\"asks\":[],\"checksum\":2196570767,\"timestamp\":\"2026-08-26T11:56:03.731638Z\"}]}"}
{"recv_ts_ns":1787745363880547812,"payload":"{\"channel\":\"book\",\"type\":\"update\",\"data\":[{\"symbol\":\"BTC/USD\",\"bids\":[],\"asks\":[{\"price\":78503.1,\"qty\":0.02137676}],\"checksum\":3260514760,\"timestamp\":\"2026-08-26T11:56:03.731645Z\"}]}"}
{"recv_ts_ns":1787745363880687564,"payload":"{\"channel\":\"book\",\"type\":\"update\",\"data\":[{\"symbol\":\"BTC/USD\",\"bids\":[],\"asks\":[{\"price\":78512.5,\"qty\":0.33316883}],\"checksum\":1856390326,\"timestamp\":\"2026-08-26T11:56:03.732144Z\"}]}"}
{"recv_ts_ns":1787745363880793810,"payload":"{\"channel\":\"book\",\"type\":\"update\",\"data\":[{\"symbol\":\"BTC/USD\",\"bids\":[],\"asks\":[{\"price\":78503.1,\"qty\":0.00000000},{\"price\":78522.6,\"qty\":0.06368515}],\"checksum\":1431238741,\"timestamp\":\"2026-08-26T11:56:03.732968Z\"}]}"}
{"recv_ts_ns":1787745363880876835,"payload":"{\"channel\":\"book\",\"type\":\"update\",\"data\":[{\"symbol\":\"BTC/USD\",\"bids\":[],\"asks\":[{\"price\":78508.2,\"qty\":0.04603180}],\"checksum\":2647257036,\"timestamp\":\"2026-08-26T11:56:03.732977Z\"}]}"}
{"recv_ts_ns":1787745363880966332,"payload":"{\"channel\":\"book\",\"type\":\"update\",\"data\":[{\"symbol\":\"BTC/USD\",\"bids\":[{\"price\":78496.7,\"qty\":0.00000000},{\"price\":78480.1,\"qty\":0.01473761},{\"price\":78497.5,\"qty\":0.04603180}],\"asks\":[],\"checksum\":1628173595,\"timestamp\":\"2026-08-26T11:56:03.733089Z\"}]}"}
{"recv_ts_ns":1787745363881064535,"payload":"{\"channel\":\"book\",\"type\":\"update\",\"data\":[{\"symbol\":\"BTC/USD\",\"bids\":[{\"price\":78493.1,\"qty\":0.27065496}],\"asks\":[],\"checksum\":1628173595,\"timestamp\":\"2026-08-26T11:56:03.733340Z\"}]}"}
{"recv_ts_ns":1787745363889150893,"payload":"{\"channel\":\"book\",\"type\":\"update\",\"data\":[{\"symbol\":\"BTC/USD\",\"bids\":[{\"price\":78493.0,\"qty\":0.00000000},{\"price\":78481.4,\"qty\":0.00010100}],\"asks\":[],\"checksum\":1628173595,\"timestamp\":\"2026-08-26T11:56:03.733498Z\"}]}"}
{"recv_ts_ns":1787745363889284036,"payload":"{\"channel\":\"book\",\"type\":\"update\",\"data\":[{\"symbol\":\"BTC/USD\",\"bids\":[],\"asks\":[{\"price\":78514.5,\"qty\":0.95543056}],\"checksum\":1628173595,\"timestamp\":\"2026-08-26T11:56:03.733524Z\"}]}"}
{"recv_ts_ns":1787745363889362655,"payload":"{\"channel\":\"book\",\"type\":\"update\",\"data\":[{\"symbol\":\"BTC/USD\",\"bids\":[],\"asks\":[{\"price\":78518.6,\"qty\":0.00000000},{\"price\":78522.3,\"qty\":0.01292474}],\"checksum\":1628173595,\"timestamp\":\"2026-08-26T11:56:03.733587Z\"}]}"}
{"recv_ts_ns":1787745363889464524,"payload":"{\"channel\":\"book\",\"type\":\"update\",\"data\":[{\"symbol\":\"BTC/USD\",\"bids\":[],\"asks\":[{\"price\":78515.7,\"qty\":0.85606579}],\"checksum\":1628173595,\"timestamp\":\"2026-08-26T11:56:03.733730Z\"}]}"}
{"recv_ts_ns":1787745363889560907,"payload":"{\"channel\":\"book\",\"type\":\"update\",\"data\":[{\"symbol\":\"BTC/USD\",\"bids\":[{\"price\":78492.7,\"qty\":0.00005100}],\"asks\":[],\"checksum\":1628173595,\"timestamp\":\"2026-08-26T11:56:03.733772Z\"}]}"}
{"recv_ts_ns":1787745363889690909,"payload":"{\"channel\":\"book\",\"type\":\"update\",\"data\":[{\"symbol\":\"BTC/USD\",\"bids\":[],\"asks\":[{\"price\":78512.5,\"qty\":0.00000000},{\"price\":78522.3,\"qty\":0.01292474}],\"checksum\":2016010151,\"timestamp\":\"2026-08-26T11:56:03.734498Z\"}]}"}
{"recv_ts_ns":1787745363889788887,"payload":"{\"channel\":\"book\",\"type\":\"update\",\"data\":[{\"symbol\":\"BTC/USD\",\"bids\":[{\"price\":78500.6,\"qty\":0.83945755}],\"asks\":[],\"checksum\":3654349653,\"timestamp\":\"2026-08-26T11:56:03.734611Z\"}]}"}
{"recv_ts_ns":1787745363889884273,"payload":"{\"channel\":\"book\",\"type\":\"update\",\"data\":[{\"symbol\":\"BTC/USD\",\"bids\":[],\"asks\":[{\"price\":78508.2,\"qty\":0.00000000},{\"price\":78522.6,\"qty\":0.06368515}],\"checksum\":2729797361,\"timestamp\":\"2026-08-26T11:56:03.734648Z\"}]}"}
{"recv_ts_ns":1787745363889975221,"payload":"{\"channel\":\"book\",\"type\":\"update\",\"data\":[{\"symbol\":\"BTC/USD\",\"bids\":[],\"asks\":[{\"price\":78522.6,\"qty\":0.29633662}],\"checksum\":2729797361,\"timestamp\":\"2026-08-26T11:56:03.735229Z\"}]}"}
{"recv_ts_ns":1787745363890079718,"payload":"{\"channel\":\"book\",\"type\":\"update\",\"data\":[{\"symbol\":\"BTC/USD\",\"bids\":[{\"price\":78481.7,\"qty\":6.37090838}],\"asks\":[],\"checksum\":2729797361,\"timestamp\":\"2026-08-26T11:56:03.736677Z\"}]}"}
{"recv_ts_ns":1787745363890157954,"payload":"{\"channel\":\"book\",\"type\":\"update\",\"data\":[{\"symbol\":\"BTC/USD\",\"bids\":[],\"asks\":[{\"price\":78515.4,\"qty\":0.00000000},{\"price\":78522.7,\"qty\":0.63675875},{\"price\":78518.5,\"qty\":1.27381691}],\"checksum\":2729797361,\"timestamp\":\"2026-08-26T11:56:03.736998Z\"}]}"}
{"recv_ts_ns":1787745363890272228,"payload":"{\"channel\":\"book\",\"type\":\"update\",\"data\":[{\"symbol\":\"BTC/USD\",\"bids\":[{\"price\":78493.1,\"qty\":0.00000000},{\"price\":78481.4,\"qty\":0.00010100}],\"asks\":[],\"checksum\":2729797361,\"timestamp\":\"2026-08-26T11:56:03.737233Z\"}]}"}
{"recv_ts_ns":1787745363890364997,"payload":"{\"channel\":\"book\",\"type\":\"update\",\"data\":[{\"symbol\":\"BTC/USD\",\"bids\":[],\"asks\":[{\"price\":78514.4,\"qty\":0.28519602}],\"checksum\":4261506330,\"timestamp\":\"2026-08-26T11:56:03.737798Z\"}]}"}
{"recv_ts_ns":1787745363890507161,"payload":"{\"channel\":\"book\",\"type\":\"update\",\"data\":[{\"symbol\":\"BTC/USD\",\"bids\":[{\"price\":78493.1,\"qty\":0.01511932}],\"asks\":[],\"checksum\":4261506330,\"timestamp\":\"2026-08-26T11:56:03.738029Z\"}]}"}
{"recv_ts_ns":1787745363890606883,"payload":"{\"channel\":\"book\",\"type\":\"update\",\"data\":[{\"symbol\":\"BTC/USD\",\"bids\":[{\"price\":78484.8,\"qty\":0.00005100},{\"price\":78493.6,\"qty\":3.03168214}],\"asks\":[],\"checksum\":4261506330,\"timestamp\":\"2026-08-26T11:56:03.738313Z\"}]}"}
{"recv_ts_ns":1787745363890745464,"payload":"{\"channel\":\"book\",\"type\":\"update\",\"data\":[{\"symbol\":\"BTC/USD\",\"bids\":[{\"price\":78490.2,\"qty\":0.52766340}],\"asks\":[],\"checksum\":4261506330,\"timestamp\":\"2026-08-26T11:56:03.738988Z\"}]}"}
{"recv_ts_ns":1787745363890862810,"payload":"{\"channel\":\"book\",\"type\":\"update\",\"data\":[{\"symbol\":\"BTC/USD\",\"bids\":[{\"price\":78486.7,\"qty\":0.04795432}],\"asks\":[],\"checksum\":4261506330,\"timestamp\":\"2026-08-26T11:56:03.743824Z\"}]}"}
{"recv_ts_ns":1787745363890938277,"payload":"{\"channel\":\"book\",\"type\":\"update\",\"data\":[{\"symbol\":\"BTC/USD\",\"bids\":[{\"price\":78493.7,\"qty\":0.64683148}],\"asks\":[],\"checksum\":4261506330,\"timestamp\":\"2026-08-26T11:56:03.743975Z\"}]}"}
{"recv_ts_ns":1787745363893838889,"payload":"{\"channel\":\"book\",\"type\":\"update\",\"data\":[{\"symbol\":\"BTC/USD\",\"bids\":[{\"price\":78493.1,\"qty\":0.00000000},{\"price\":78482.7,\"qty\":0.00005000}],\"asks\":[],\"checksum\":4261506330,\"timestamp\":\"2026-08-26T11:56:03.744364Z\"}]}"}
{"recv_ts_ns":1787745363895805959,"payload":"{\"channel\":\"book\",\"type\":\"update\",\"data\":[{\"symbol\":\"BTC/USD\",\"bids\":[],\"asks\":[{\"price\":78511.5,\"qty\":0.00000000},{\"price\":78522.6,\"qty\":0.29633662}],\"checksum\":1863257985,\"timestamp\":\"2026-08-26T11:56:03.747794Z\"}]}"}
{"recv_ts_ns":1787745363895915653,"payload":"{\"channel\":\"book\",\"type\":\"update\",\"data\":[{\"symbol\":\"BTC/USD\",\"bids\":[],\"asks\":[{\"price\":78509.0,\"qty\":0.01565551}],\"checksum\":50763074,\"timestamp\":\"2026-08-26T11:56:03.748164Z\"}]}"}
{"recv_ts_ns":1787745363895992808,"payload":"{\"channel\":\"book\",\"type\":\"update\",\"data\":[{\"symbol\":\"BTC/USD\",\"bids\":[{\"price\":78499.2,\"qty\":0.95543056}],\"asks\":[],\"checksum\":370601972,\"timestamp\":\"2026-08-26T11:56:03.748978Z\"}]}"}
{"recv_ts_ns":1787745363927019108,"payload":"{\"channel\":\"heartbeat\"}"}
{"recv_ts_ns":1787745363971055054,"payload":"{\"channel\":\"book\",\"type\":\"update\",\"data\":[{\"symbol\":\"BTC/USD\",\"bids\":[],\"asks\":[{\"price\":78516.0,\"qty\":0.97672355}],\"checksum\":370601972,\"timestamp\":\"2026-08-26T11:56:03.825094Z\"}]}"}
{"recv_ts_ns":1787745363979833548,"payload":"{\"channel\":\"book\",\"type\":\"update\",\"data\":[{\"symbol\":\"BTC/USD\",\"bids\":[],\"asks\":[{\"price\":78518.8,\"qty\":0.00000000},{\"price\":78522.6,\"qty\":0.29633662}],\"checksum\":370601972,\"timestamp\":\"2026-08-26T11:56:03.831252Z\"}]}"}
{"recv_ts_ns":1787745363981992082,"payload":"{\"channel\":\"book\",\"type\":\"update\",\"data\":[{\"symbol\":\"BTC/USD\",\"bids\":[{\"price\":78499.2,\"qty\":0.00000000},{\"price\":78482.7,\"qty\":0.00005000}],\"asks\":[],\"checksum\":50763074,\"timestamp\":\"2026-08-26T11:56:03.833337Z\"}]}"}
{"recv_ts_ns":1787745363982110600,"payload":"{\"channel\":\"book\",\"type\":\"update\",\"data\":[{\"symbol\":\"BTC/USD\",\"bids\":[],\"asks\":[{\"price\":78514.5,\"qty\":0.00000000},{\"price\":78522.7,\"qty\":0.63675875}],\"checksum\":3067443840,\"timestamp\":\"2026-08-26T11:56:03.835204Z\"}]}"}
{"recv_ts_ns":1787745363988347921,"payload":"{\"channel\":\"book\",\"type\":\"update\",\"data\":[{\"symbol\":\"BTC/USD\",\"bids\":[{\"price\":78500.6,\"qty\":0.94945755}],\"asks\":[],\"checksum\":3911528938,\"timestamp\":\"2026-08-26T11:56:03.835466Z\"}]}"}
{"recv_ts_ns":1787745363988473300,"payload":"{\"channel\":\"book\",\"type\":\"update\",\"data\":[{\"symbol\":\"BTC/USD\",\"bids\":[{\"price\":78500.4,\"qty\":0.95543056}],\"asks\":[],\"checksum\":1125863216,\"timestamp\":\"2026-08-26T11:56:03.835998Z\"}]}"}
{"recv_ts_ns":1787745363988558123,"payload":"{\"channel\":\"book\",\"type\":\"update\",\"data\":[{\"symbol\":\"BTC/USD\",\"bids\":[],\"asks\":[{\"price\":78515.9,\"qty\":0.00000000},{\"price\":78524.9,\"qty\":0.11000000},{\"price\":78518.4,\"qty\":0.15284794}],\"checksum\":1125863216,\"timestamp\":\"2026-08-26T11:56:03.838636Z\"}]}"}
{"recv_ts_ns":1787745363988688324,"payload":"{\"channel\":\"book\",\"type\":\"update\",\"data\":[{\"symbol\":\"BTC/USD\",\"bids\":[],\"asks\":[{\"price\":78514.4,\"qty\":0.00000000},{\"price\":78524.9,\"qty\":0.11000000}],\"checksum\":1565281951,\"timestamp\":\"2026-08-26T11:56:03.838969Z\"}]}"}
{"recv_ts_ns":1787745363991290323,"payload":"{\"channel\":\"book\",\"type\":\"update\",\"data\":[{\"symbol\":\"BTC/USD\",\"bids\":[{\"price\":78500.4,\"qty\":0.00000000},{\"price\":78482.7,\"qty\":0.00005000}],\"asks\":[],\"checksum\":3218536056,\"timestamp\":\"2026-08-26T11:56:03.842535Z\"}]}"}
{"recv_ts_ns":1787745363991431482,"payload":"{\"channel\":\"book\",\"type\":\"update\",\"data\":[{\"symbol\":\"BTC/USD\",\"bids\":[],\"asks\":[{\"price\":78514.6,\"qty\":0.95543056}],\"checksum\":834350465,\"timestamp\":\"2026-08-26T11:56:03.842853Z\"}]}"}
{"recv_ts_ns":1787745363991485382,"payload":"{\"channel\":\"book\",\"type\":\"update\",\"data\":[{\"symbol\":\"BTC/USD\",\"bids\":[],\"asks\":[{\"price\":78516.0,\"qty\":0.33991048}],\"checksum\":834350465,\"timestamp\":\"2026-08-26T11:56:03.842907Z\"}]}"}
{"recv_ts_ns":1787745363992861048,"payload":"{\"channel\":\"book\",\"type\":\"update\",\"data\":[{\"symbol\":\"BTC/USD\",\"bids\":[],\"asks\":[{\"price\":78514.5,\"qty\":0.28519602}],\"checksum\":2338101437,\"timestamp\":\"2026-08-26T11:56:03.844858Z\"}]}"}
{"recv_ts_ns":1787745364014222275,"payload":"{\"channel\":\"book\",\"type\":\"update\",\"data\":[{\"symbol\":\"BTC/USD\",\"bids\":[],\"asks\":[{\"price\":78518.4,\"qty\":0.00000000},{\"price\":78522.7,\"qty\":0.63675875},{\"price\":78517.3,\"qty\":0.15284794}],\"checksum\":2338101437,\"timestamp\":\"2026-08-26T11:56:03.865909Z\"}]}"}
{"recv_ts_ns":1787745364017652713,"payload":"{\"channel\":\"book\",\"type\":\"update\",\"data\":[{\"symbol\":\"BTC/USD\",\"bids\":[{\"price\":78499.3,\"qty\":0.95543056}],\"asks\":[],\"checksum\":1637874363,\"timestamp\":\"2026-08-26T11:56:03.871328Z\"}]}"}
{"recv_ts_ns":1787745364033162569,"payload":"{\"channel\":\"book\",\"type\":\"update\",\"data\":[{\"symbol\":\"BTC/USD\",\"bids\":[],\"asks\":[{\"price\":78517.3,\"qty\":0.00000000},{\"price\":78522.7,\"qty\":0.63675875},{\"price\":78518.4,\"qty\":0.15284794}],\"checksum\":1637874363,\"timestamp\":\"2026-08-26T11:56:03.888249Z\"}]}"}
{"recv_ts_ns":1787745364039623623,"payload":"{\"channel\":\"book\",\"type\":\"update\",\"data\":[{\"symbol\":\"BTC/USD\",\"bids\":[],\"asks\":[{\"price\":78518.5,\"qty\":0.00000000},{\"price\":78522.7,\"qty\":0.63675875},{\"price\":78522.5,\"qty\":1.27382376}],\"checksum\":1637874363,\"timestamp\":\"2026-08-26T11:56:03.893426Z\"}]}"}
{"recv_ts_ns":1787745364039740642,"payload":"{\"channel\":\"book\",\"type\":\"update\",\"data\":[{\"symbol\":\"BTC/USD\",\"bids\":[{\"price\":78497.5,\"qty\":0.00000000},{\"price\":78482.7,\"qty\":0.00005000},{\"price\":78500.6,\"qty\":0.99548935}],\"asks\":[],\"checksum\":395923196,\"timestamp\":\"2026-08-26T11:56:03.894684Z\"}]}"}
{"recv_ts_ns":1787745364039785494,"payload":"{\"channel\":\"book\",\"type\":\"update\",\"data\":[{\"symbol\":\"BTC/USD\",\"bids\":[],\"asks\":[{\"price\":78515.3,\"qty\":0.00000000},{\"price\":78522.7,\"qty\":0.63675875}],\"checksum\":395923196,\"timestamp\":\"2026-08-26T11:56:03.894747Z\"}]}"}
{"recv_ts_ns":1787745364039829141,"payload":"{\"channel\":\"book\",\"type\":\"update\",\"data\":[{\"symbol\":\"BTC/USD\",\"bids\":[],\"asks\":[{\"price\":78512.1,\"qty\":0.04603180}],\"checksum\":2868838996,\"timestamp\":\"2026-08-26T11:56:03.894873Z\"}]}"}
{"recv_ts_ns":1787745364039865123,"payload":"{\"channel\":\"book\",\"type\":\"update\",\"data\":[{\"symbol\":\"BTC/USD\",\"bids\":[],\"asks\":[{\"price\":78515.3,\"qty\":0.44041965}],\"checksum\":2868838996,\"timestamp\":\"2026-08-26T11:56:03.894977Z\"}]}"}
{"recv_ts_ns":1787745364043834962,"payload":"{\"channel\":\"book\",\"type\":\"update\",\"data\":[{\"symbol\":\"BTC/USD\",\"bids\":[],\"asks\":[{\"price\":78511.4,\"qty\":0.01493805}],\"checksum\":2401775680,\"timestamp\":\"2026-08-26T11:56:03.898040Z\"}]}"}
{"recv_ts_ns":1787745364043901322,"payload":"{\"channel\":\"book\",\"type\":\"update\",\"data\":[{\"symbol\":\"BTC/USD\",\"bids\":[],\"asks\":[{\"price\":78507.5,\"qty\":0.01127330}],\"checksum\":4226881386,\"timestamp\":\"2026-08-26T11:56:03.898059Z\"}]}"}
{"recv_ts_ns":1787745364043956621,"payload":"{\"channel\":\"book\",\"type\":\"update\",\"data\":[{\"symbol\":\"BTC/USD\",\"bids\":[],\"asks\":[{\"price\":78519.3,\"qty\":0.02638373}],\"checksum\":4226881386,\"timestamp\":\"2026-08-26T11:56:03.899408Z\"}]}"}
{"recv_ts_ns":1787745364047090670,"payload":"{\"channel\":\"book\",\"type\":\"update\",\"data\":[{\"symbol\":\"BTC/USD\",\"bids\":[],\"asks\":[{\"price\":78519.4,\"qty\":0.42637541}],\"checksum\":4226881386,\"timestamp\":\"2026-08-26T11:56:03.901400Z\"}]}"}
{"recv_ts_ns":1787745364055097803,"payload":"{\"channel\":\"book\",\"type\":\"update\",\"data\":[{\"symbol\":\"BTC/USD\",\"bids\":[],\"asks\":[{\"price\":78518.4,\"qty\":0.00000000},{\"price\":78522.3,\"qty\":0.01292474}],\"checksum\":4226881386,\"timestamp\":\"2026-08-26T11:56:03.908808Z\"}]}"}
{"recv_ts_ns":1787745364082549599,"payload":"{\"channel\":\"book\",\"type\":\"update\",\"data\":[{\"symbol\":\"BTC/USD\",\"bids\":[{\"price\":78486.4,\"qty\":0.00000000},{\"price\":78482.5,\"qty\":0.40000000}],\"asks\":[],\"checksum\":4226881386,\"timestamp\":\"2026-08-26T11:56:03.935928Z\"}]}"}
{"recv_ts_ns":1787745364114935962,"payload":"{\"channel\":\"book\",\"type\":\"update\",\"data\":[{\"symbol\":\"BTC/USD\",\"bids\":[{\"price\":78500.6,\"qty\":0.39382111}],\"asks\":[],\"checksum\":2413154826,\"timestamp\":\"2026-08-26T11:56:03.967346Z\"}]}"}
{"recv_ts_ns":1787745364114986671,"payload":"{\"channel\":\"book\",\"type\":\"update\",\"data\":[{\"symbol\":\"BTC/USD\",\"bids\":[{\"price\":78500.6,\"qty\":0.47182111}],\"asks\":[],\"checksum\":839617447,\"timestamp\":\"2026-08-26T11:56:03.969779Z\"}]}"}
{"recv_ts_ns":1787745364140318842,"payload":"{\"channel\":\"book\",\"type\":\"update\",\"data\":[{\"symbol\":\"BTC/USD\",\"bids\":[],\"asks\":[{\"price\":78518.3,\"qty\":1.27380635}],\"checksum\":839617447,\"timestamp\":\"2026-08-26T11:56:03.993156Z\"}]}"}
{"recv_ts_ns":1787745364140364053,"payload":"{\"channel\":\"book\",\"type\":\"update\",\"data\":[{\"symbol\":\"BTC/USD\",\"bids\":[],\"asks\":[{\"price\":78519.4,\"qty\":0.05290250}],\"checksum\":839617447,\"timestamp\":\"2026-08-26T11:56:03.994643Z\"}]}"}
{"recv_ts_ns":1787745364140389059,"payload":"{\"channel\":\"book\",\"type\":\"update\",\"data\":[{\"symbol\":\"BTC/USD\",\"bids\":[],\"asks\":[{\"price\":78515.3,\"qty\":0.71871895}],\"checksum\":839617447,\"timestamp\":\"2026-08-26T11:56:03.994729Z\"}]}"}
{"recv_ts_ns":1787745364140409439,"payload":"{\"channel\":\"book\",\"type\":\"update\",\"data\":[{\"symbol\":\"BTC/USD\",\"bids\":[],\"asks\":[{\"price\":78519.4,\"qty\":0.00000000},{\"price\":78522.3,\"qty\":0.01292474}],\"checksum\":839617447,\"timestamp\":\"2026-08-26T11:56:03.994770Z\"}]}"}
{"recv_ts_ns":1787745364140437305,"payload":"{\"channel\":\"book\",\"type\":\"update\",\"data\":[{\"symbol\":\"BTC/USD\",\"bids\":[],\"asks\":[{\"price\":78519.2,\"qty\":0.03416402}],\"checksum\":839617447,\"timestamp\":\"2026-08-26T11:56:03.995936Z\"}]}"}
{"recv_ts_ns":1787745364164510670,"payload":"{\"channel\":\"book\",\"type\":\"update\",\"data\":[{\"symbol\":\"BTC/USD\",\"bids\":[],\"asks\":[{\"price\":78518.3,\"qty\":0.00000000},{\"price\":78522.3,\"qty\":0.01292474}],\"checksum\":839617447,\"timestamp\":\"2026-08-26T11:56:04.017543Z\"}]}"}
{"recv_ts_ns":1787745364164618488,"payload":"{\"channel\":\"book\",\"type\":\"update\",\"data\":[{\"symbol\":\"BTC/USD\",\"bids\":[],\"asks\":[{\"price\":78515.3,\"qty\":0.44041965}],\"checksum\":839617447,\"timestamp\":\"2026-08-26T11:56:04.019007Z\"}]}"}
{"recv_ts_ns":1787745364164919049,"payload":"{\"channel\":\"book\",\"type\":\"update\",\"data\":[{\"symbol\":\"BTC/USD\",\"bids\":[],\"asks\":[{\"price\":78519.2,\"qty\":0.41002747}],\"checksum\":839617447,\"timestamp\":\"2026-08-26T11:56:04.019407Z\"}]}"}
{"recv_ts_ns":1787745364212774085,"payload":"{\"channel\":\"book\",\"type\":\"update\",\"data\":[{\"symbol\":\"BTC/USD\",\"bids\":[],\"asks\":[{\"price\":78505.8,\"qty\":0.02123955}],\"checksum\":1871866284,\"timestamp\":\"2026-08-26T11:56:04.066873Z\"}]}"}
{"recv_ts_ns":1787745364215962514,"payload":"{\"channel\":\"book\",\"type\":\"update\",\"data\":[{\"symbol\":\"BTC/USD\",\"bids\":[],\"asks\":[{\"price\":78512.1,\"qty\":0.00000000},{\"price\":78522.3,\"qty\":0.01292474},{\"price\":78511.3,\"qty\":0.04603180}],\"checksum\":1637367327,\"timestamp\":\"2026-08-26T11:56:04.068542Z\"}]}"}
{"recv_ts_ns":1787745364236964247,"payload":"{\"channel\":\"book\",\"type\":\"update\",\"data\":[{\"symbol\":\"BTC/USD\",\"bids\":[{\"price\":78499.3,\"qty\":0.00000000},{\"price\":78481.8,\"qty\":2.07169251}],\"asks\":[],\"checksum\":3831844403,\"timestamp\":\"2026-08-26T11:56:04.090804Z\"}]}"}
{"recv_ts_ns":1787745364237041996,"payload":"{\"channel\":\"book\",\"type\":\"update\",\"data\":[{\"symbol\":\"BTC/USD\",\"bids\":[],\"asks\":[{\"price\":78514.6,\"qty\":0.00000000},{\"price\":78522.3,\"qty\":0.01292474}],\"checksum\":3831844403,\"timestamp\":\"2026-08-26T11:56:04.090828Z\"}]}"}
{"recv_ts_ns":1787745364240680431,"payload":"{\"channel\":\"book\",\"type\":\"update\",\"data\":[{\"symbol\":\"BTC/USD\",\"bids\":[],\"asks\":[{\"price\":78514.5,\"qty\":0.00000000},{\"price\":78522.5,\"qty\":1.27380653}],\"checksum\":3831844403,\"timestamp\":\"2026-08-26T11:56:04.092606Z\"}]}"}
{"recv_ts_ns":1787745364266173832,"payload":"{\"channel\":\"book\",\"type\":\"update\",\"data\":[{\"symbol\":\"BTC/USD\",\"bids\":[{\"price\":78498.3,\"qty\":0.95543056}],\"asks\":[],\"checksum\":1807382230,\"timestamp\":\"2026-08-26T11:56:04.119768Z\"}]}"}
{"recv_ts_ns":1787745364266313932,"payload":"{\"channel\":\"book\",\"type\":\"update\",\"data\":[{\"symbol\":\"BTC/USD\",\"bids\":[],\"asks\":[{\"price\":78513.6,\"qty\":0.95543056}],\"checksum\":1807382230,\"timestamp\":\"2026-08-26T11:56:04.119785Z\"}]}"}
{"recv_ts_ns":1787745364266646684,"payload":"{\"channel\":\"book\",\"type\":\"update\",\"data\":[{\"symbol\":\"BTC/USD\",\"bids\":[],\"asks\":[{\"price\":78513.5,\"qty\":0.28519602}],\"checksum\":1807382230,\"timestamp\":\"2026-08-26T11:56:04.121602Z\"}]}"}
{"recv_ts_ns":1787745364310496214,"payload":"{\"channel\":\"book\",\"type\":\"update\",\"data\":[{\"symbol\":\"BTC/USD\",\"bids\":[],\"asks\":[{\"price\":78513.5,\"qty\":0.00000000},{\"price\":78522.3,\"qty\":0.01292474}],\"checksum\":1807382230,\"timestamp\":\"2026-08-26T11:56:04.162673Z\"}]}"}
{"recv_ts_ns":1787745364381431026,"payload":"{\"channel\":\"book\",\"type\":\"update\",\"data\":[{\"symbol\":\"BTC/USD\",\"bids\":[],\"asks\":[{\"price\":78511.3,\"qty\":0.00000000},{\"price\":78522.5,\"qty\":1.27380653},{\"price\":78507.4,\"qty\":0.04603180}],\"checksum\":4007655903,\"timestamp\":\"2026-08-26T11:56:04.236287Z\"}]}"}
{"recv_ts_ns":1787745364472290915,"payload":"{\"channel\":\"book\",\"type\":\"update\",\"data\":[{\"symbol\":\"BTC/USD\",\"bids\":[],\"asks\":[{\"price\":78515.3,\"qty\":0.00000000},{\"price\":78522.5,\"qty\":1.27380653}],\"checksum\":4007655903,\"timestamp\":\"2026-08-26T11:56:04.323367Z\"}]}"}
{"recv_ts_ns":1787745364474172993,"payload":"{\"channel\":\"book\",\"type\":\"update\",\"data\":[{\"symbol\":\"BTC/USD\",\"bids\":[],\"asks\":[{\"price\":78515.7,\"qty\":0.00000000},{\"price\":78522.6,\"qty\":0.23265147}],\"checksum\":4007655903,\"timestamp\":\"2026-08-26T11:56:04.323749Z\"}]}"}
{"recv_ts_ns":1787745364474359239,"payload":"{\"channel\":\"book\",\"type\":\"update\",\"data\":[{\"symbol\":\"BTC/USD\",\"bids\":[],\"asks\":[{\"price\":78513.6,\"qty\":0.00000000},{\"price\":78522.7,\"qty\":0.63675875}],\"checksum\":4007655903,\"timestamp\":\"2026-08-26T11:56:04.323830Z\"}]}"}
{"recv_ts_ns":1787745364474460373,"payload":"{\"channel\":\"book\",\"type\":\"update\",\"data\":[{\"symbol\":\"BTC/USD\",\"bids\":[],\"asks\":[{\"price\":78519.2,\"qty\":0.03416402}],\"checksum\":4007655903,\"timestamp\":\"2026-08-26T11:56:04.324264Z\"}]}"}
{"recv_ts_ns":1787745364474542828,"payload":"{\"channel\":\"book\",\"type\":\"update\",\"data\":[{\"symbol\":\"BTC/USD\",\"bids\":[],\"asks\":[{\"price\":78522.6,\"qty\":0.00000000},{\"price\":78522.8,\"qty\":0.12066700}],\"checksum\":4007655903,\"timestamp\":\"2026-08-26T11:56:04.324273Z\"}]}"}
{"recv_ts_ns":1787745364474640347,"payload":"{\"channel\":\"book\",\"type\":\"update\",\"data\":[{\"symbol\":\"BTC/USD\",\"bids\":[],\"asks\":[{\"price\":78506.8,\"qty\":0.01565551}],\"checksum\":2751561425,\"timestamp\":\"2026-08-26T11:56:04.324855Z\"}]}"}
{"recv_ts_ns":1787745364480167358,"payload":"{\"channel\":\"book\",\"type\":\"update\",\"data\":[{\"symbol\":\"BTC/USD\",\"bids\":[],\"asks\":[{\"price\":78519.2,\"qty\":0.00000000},{\"price\":78522.8,\"qty\":0.12066700}],\"checksum\":2751561425,\"timestamp\":\"2026-08-26T11:56:04.325287Z\"}]}"}
{"recv_ts_ns":1787745364480315595,"payload":"{\"channel\":\"book\",\"type\":\"update\",\"data\":[{\"symbol\":\"BTC/USD\",\"bids\":[],\"asks\":[{\"price\":78509.0,\"qty\":0.00000000},{\"price\":78524.4,\"qty\":0.02547363}],\"checksum\":2119064311,\"timestamp\":\"2026-08-26T11:56:04.325550Z\"}]}"}
{"recv_ts_ns":1787745364480416202,"payload":"{\"channel\":\"book\",\"type\":\"update\",\"data\":[{\"symbol\":\"BTC/USD\",\"bids\":[],\"asks\":[{\"price\":78519.1,\"qty\":0.15284794}],\"checksum\":2119064311,\"timestamp\":\"2026-08-26T11:56:04.325686Z\"}]}"}
{"recv_ts_ns":1787745364480496233,"payload":"{\"channel\":\"book\",\"type\":\"update\",\"data\":[{\"symbol\":\"BTC/USD\",\"bids\":[{\"price\":78500.4,\"qty\":0.53859879}],\"asks\":[],\"checksum\":2595160986,\"timestamp\":\"2026-08-26T11:56:04.325931Z\"}]}"}
{"recv_ts_ns":1787745364480586728,"payload":"{\"channel\":\"book\",\"type\":\"update\",\"data\":[{\"symbol\":\"BTC/USD\",\"bids\":[],\"asks\":[{\"price\":78522.8,\"qty\":0.00000000},{\"price\":78524.4,\"qty\":0.02547363}],\"checksum\":2595160986,\"timestamp\":\"2026-08-26T11:56:04.326778Z\"}]}"}
{"recv_ts_ns":1787745364480797263,"payload":"{\"channel\":\"book\",\"type\":\"update\",\"data\":[{\"symbol\":\"BTC/USD\",\"bids\":[],\"asks\":[{\"price\":78515.8,\"qty\":0.00000000},{\"price\":78524.9,\"qty\":0.11000000}],\"checksum\":2595160986,\"timestamp\":\"2026-08-26T11:56:04.327979Z\"}]}"}
{"recv_ts_ns":1787745364480879176,"payload":"{\"channel\":\"book\",\"type\":\"update\",\"data\":[{\"symbol\":\"BTC/USD\",\"bids\":[],\"asks\":[{\"price\":78507.4,\"qty\":0.00000000},{\"price\":78525.2,\"qty\":0.06368410}],\"checksum\":811175858,\"timestamp\":\"2026-08-26T11:56:04.329987Z\"}]}"}
{"recv_ts_ns":1787745364480971106,"payload":"{\"channel\":\"book\",\"type\":\"update\",\"data\":[{\"symbol\":\"BTC/USD\",\"bids\":[{\"price\":78498.3,\"qty\":0.00000000},{\"price\":78482.5,\"qty\":0.40000000}],\"asks\":[],\"checksum\":3419687305,\"timestamp\":\"2026-08-26T11:56:04.330006Z\"}]}"}
{"recv_ts_ns":1787745364481498350,"payload":"{\"channel\":\"book\",\"type\":\"update\",\"data\":[{\"symbol\":\"BTC/USD\",\"bids\":[],\"asks\":[{\"price\":78506.8,\"qty\":0.00000000},{\"price\":78525.5,\"qty\":0.01292474}],\"checksum\":1555187664,\"timestamp\":\"2026-08-26T11:56:04.332775Z\"}]}"}
{"recv_ts_ns":1787745364481631428,"payload":"{\"channel\":\"book\",\"type\":\"update\",\"data\":[{\"symbol\":\"BTC/USD\",\"bids\":[],\"asks\":[{\"price\":78519.3,\"qty\":0.66317054}],\"checksum\":1555187664,\"timestamp\":\"2026-08-26T11:56:04.333345Z\"}]}"}
{"recv_ts_ns":1787745364481756435,"payload":"{\"channel\":\"book\",\"type\":\"update\",\"data\":[{\"symbol\":\"BTC/USD\",\"bids\":[],\"asks\":[{\"price\":78507.5,\"qty\":0.00000000},{\"price\":78525.7,\"qty\":0.01591793}],\"checksum\":3323609837,\"timestamp\":\"2026-08-26T11:56:04.333792Z\"}]}"}
{"recv_ts_ns":1787745364485548285,"payload":"{\"channel\":\"book\",\"type\":\"update\",\"data\":[{\"symbol\":\"BTC/USD\",\"bids\":[{\"price\":78500.6,\"qty\":1.32788690}],\"asks\":[],\"checksum\":911844813,\"timestamp\":\"2026-08-26T11:56:04.335065Z\"}]}"}
{"recv_ts_ns":1787745364488310770,"payload":"{\"channel\":\"book\",\"type\":\"update\",\"data\":[{\"symbol\":\"BTC/USD\",\"bids\":[],\"asks\":[{\"price\":78522.7,\"qty\":0.00000000},{\"price\":78526.5,\"qty\":0.63672840}],\"checksum\":911844813,\"timestamp\":\"2026-08-26T11:56:04.339433Z\"}]}"}
{"recv_ts_ns":1787745364493109198,"payload":"{\"channel\":\"book\",\"type\":\"update\",\"data\":[{\"symbol\":\"BTC/USD\",\"bids\":[],\"asks\":[{\"price\":78511.4,\"qty\":0.00000000},{\"price\":78527.0,\"qty\":0.02057681}],\"checksum\":2186428825,\"timestamp\":\"2026-08-26T11:56:04.344661Z\"}]}"}
{"recv_ts_ns":1787745364496227846,"payload":"{\"channel\":\"book\",\"type\":\"update\",\"data\":[{\"symbol\":\"BTC/USD\",\"bids\":[],\"asks\":[{\"price\":78519.3,\"qty\":0.63678681}],\"checksum\":2186428825,\"timestamp\":\"2026-08-26T11:56:04.347182Z\"}]}"}
{"recv_ts_ns":1787745364501369313,"payload":"{\"channel\":\"book\",\"type\":\"update\",\"data\":[{\"symbol\":\"BTC/USD\",\"bids\":[{\"price\":78490.3,\"qty\":1.27405041}],\"asks\":[],\"checksum\":2186428825,\"timestamp\":\"2026-08-26T11:56:04.347643Z\"}]}"}
{"recv_ts_ns":1787745364501449525,"payload":"{\"channel\":\"book\",\"type\":\"update\",\"data\":[{\"symbol\":\"BTC/USD\",\"bids\":[{\"price\":78500.6,\"qty\":2.28331746}],\"asks\":[],\"checksum\":684815553,\"timestamp\":\"2026-08-26T11:56:04.347842Z\"}]}"}
{"recv_ts_ns":1787745364501507562,"payload":"{\"channel\":\"book\",\"type\":\"update\",\"data\":[{\"symbol\":\"BTC/USD\",\"bids\":[],\"asks\":[{\"price\":78520.2,\"qty\":0.00000000},{\"price\":78527.1,\"qty\":0.17912031}],\"checksum\":684815553,\"timestamp\":\"2026-08-26T11:56:04.349406Z\"}]}"}
{"recv_ts_ns":1787745364502495898,"payload":"{\"channel\":\"book\",\"type\":\"update\",\"data\":[{\"symbol\":\"BTC/USD\",\"bids\":[{\"price\":78490.3,\"qty\":0.00000000},{\"price\":78482.5,\"qty\":0.40000000},{\"price\":78482.6,\"qty\":1.27417541}],\"asks\":[],\"checksum\":684815553,\"timestamp\":\"2026-08-26T11:56:04.351731Z\"}]}"}
{"recv_ts_ns":1787745364502565063,"payload":"{\"channel\":\"book\",\"type\":\"update\",\"data\":[{\"symbol\":\"BTC/USD\",\"bids\":[{\"price\":78482.6,\"qty\":2.54795889}],\"asks\":[],\"checksum\":684815553,\"timestamp\":\"2026-08-26T11:56:04.351834Z\"}]}"}
{"recv_ts_ns":1787745364502601530,"payload":"{\"channel\":\"book\",\"type\":\"update\",\"data\":[{\"symbol\":\"BTC/USD\",\"bids\":[],\"asks\":[{\"price\":78516.3,\"qty\":0.00000000},{\"price\":78527.3,\"qty\":0.08956016}],\"checksum\":684815553,\"timestamp\":\"2026-08-26T11:56:04.352028Z\"}]}"}
{"recv_ts_ns":1787745364505779103,"payload":"{\"channel\":\"book\",\"type\":\"update\",\"data\":[{\"symbol\":\"BTC/USD\",\"bids\":[],\"asks\":[{\"price\":78524.9,\"qty\":0.00000000},{\"price\":78528.2,\"qty\":0.05060000}],\"checksum\":684815553,\"timestamp\":\"2026-08-26T11:56:04.354080Z\"}]}"}
{"recv_ts_ns":1787745364505889774,"payload":"{\"channel\":\"book\",\"type\":\"update\",\"data\":[{\"symbol\":\"BTC/USD\",\"bids\":[],\"asks\":[{\"price\":78519.3,\"qty\":0.00000000},{\"price\":78528.5,\"qty\":0.00021200}],\"checksum\":684815553,\"timestamp\":\"2026-08-26T11:56:04.354155Z\"}]}"}
{"recv_ts_ns":1787745364505942744,"payload":"{\"channel\":\"book\",\"type\":\"update\",\"data\":[{\"symbol\":\"BTC/USD\",\"bids\":[],\"asks\":[{\"price\":78527.0,\"qty\":0.00000000},{\"price\":78528.9,\"qty\":0.26868048}],\"checksum\":684815553,\"timestamp\":\"2026-08-26T11:56:04.354248Z\"}]}"}
{"recv_ts_ns":1787745364505982536,"payload":"{\"channel\":\"book\",\"type\":\"update\",\"data\":[{\"symbol\":\"BTC/USD\",\"bids\":[],\"asks\":[{\"price\":78526.5,\"qty\":0.00000000},{\"price\":78529.4,\"qty\":0.85776251}],\"checksum\":684815553,\"timestamp\":\"2026-08-26T11:56:04.354811Z\"}]}"}
{"recv_ts_ns":1787745364511305924,"payload":"{\"channel\":\"book\",\"type\":\"update\",\"data\":[{\"symbol\":\"BTC/USD\",\"bids\":[],\"asks\":[{\"price\":78511.8,\"qty\":0.01565551}],\"checksum\":1084438845,\"timestamp\":\"2026-08-26T11:56:04.358768Z\"}]}"}
{"recv_ts_ns":1787745364515396683,"payload":"{\"channel\":\"book\",\"type\":\"update\",\"data\":[{\"symbol\":\"BTC/USD\",\"bids\":[{\"price\":78482.6,\"qty\":1.27417541},{\"price\":78483.5,\"qty\":1.27373954}],\"asks\":[],\"checksum\":1084438845,\"timestamp\":\"2026-08-26T11:56:04.360194Z\"}]}"}
{"recv_ts_ns":1787745364515502897,"payload":"{\"channel\":\"book\",\"type\":\"update\",\"data\":[{\"symbol\":\"BTC/USD\",\"bids\":[],\"asks\":[{\"price\":78522.5,\"qty\":0.00000000},{\"price\":78529.4,\"qty\":0.85776251},{\"price\":78527.0,\"qty\":1.27373954}],\"checksum\":1084438845,\"timestamp\":\"2026-08-26T11:56:04.361383Z\"}]}"}
{"recv_ts_ns":1787745364517336340,"payload":"{\"channel\":\"book\",\"type\":\"update\",\"data\":[{\"symbol\":\"BTC/USD\",\"bids\":[],\"asks\":[{\"price\":78505.8,\"qty\":0.00000000},{\"price\":78529.4,\"qty\":0.85776251}],\"checksum\":3968205386,\"timestamp\":\"2026-08-26T11:56:04.362772Z\"}]}"}
{"recv_ts_ns":1787745364517432606,"payload":"{\"channel\":\"book\",\"type\":\"update\",\"data\":[{\"symbol\":\"BTC/USD\",\"bids\":[],\"asks\":[{\"price\":78527.0,\"qty\":1.27371055}],\"checksum\":3968205386,\"timestamp\":\"2026-08-26T11:56:04.365830Z\"}]}"}
{"recv_ts_ns":1787745364517473284,"payload":"{\"channel\":\"book\",\"type\":\"update\",\"data\":[{\"symbol\":\"BTC/USD\",\"bids\":[],\"asks\":[{\"price\":78519.1,\"qty\":0.00000000},{\"price\":78531.4,\"qty\":0.00664366},{\"price\":78522.3,\"qty\":0.16577268}],\"checksum\":3968205386,\"timestamp\":\"2026-08-26T11:56:04.366002Z\"}]}"}
{"recv_ts_ns":1787745364517545160,"payload":"{\"channel\":\"book\",\"type\":\"update\",\"data\":[{\"symbol\":\"BTC/USD\",\"bids\":[{\"price\":78500.6,\"qty\":2.41441148}],\"asks\":[],\"checksum\":3828539945,\"timestamp\":\"2026-08-26T11:56:04.366281Z\"}]}"}
{"recv_ts_ns":1787745364517589075,"payload":"{\"channel\":\"book\",\"type\":\"update\",\"data\":[{\"symbol\":\"BTC/USD\",\"bids\":[],\"asks\":[{\"price\":78527.1,\"qty\":0.08956015}],\"checksum\":3828539945,\"timestamp\":\"2026-08-26T11:56:04.366694Z\"}]}"}
{"recv_ts_ns":1787745364526530483,"payload":"{\"channel\":\"book\",\"type\":\"update\",\"data\":[{\"symbol\":\"BTC/USD\",\"bids\":[],\"asks\":[{\"price\":78520.0,\"qty\":0.02194573}],\"checksum\":3828539945,\"timestamp\":\"2026-08-26T11:56:04.373606Z\"}]}"}
{"recv_ts_ns":1787745364526649770,"payload":"{\"channel\":\"book\",\"type\":\"update\",\"data\":[{\"symbol\":\"BTC/USD\",\"bids\":[],\"asks\":[{\"price\":78527.0,\"qty\":1.27367941}],\"checksum\":3828539945,\"timestamp\":\"2026-08-26T11:56:04.375118Z\"}]}"}
{"recv_ts_ns":1787745364527884314,"payload":"{\"channel\":\"book\",\"type\":\"update\",\"data\":[{\"symbol\":\"BTC/USD\",\"bids\":[{\"price\":78490.3,\"qty\":1.27405041}],\"asks\":[],\"checksum\":3828539945,\"timestamp\":\"2026-08-26T11:56:04.376919Z\"}]}"}
{"recv_ts_ns":1787745364531399056,"payload":"{\"channel\":\"book\",\"type\":\"update\",\"data\":[{\"symbol\":\"BTC/USD\",\"bids\":[{\"price\":78493.6,\"qty\":0.00000000},{\"price\":78482.7,\"qty\":0.00005000},{\"price\":78500.6,\"qty\":5.44585048}],\"asks\":[],\"checksum\":1008237711,\"timestamp\":\"2026-08-26T11:56:04.379519Z\"}]}"}
{"recv_ts_ns":1787745364532852039,"payload":"{\"channel\":\"book\",\"type\":\"update\",\"data\":[{\"symbol\":\"BTC/USD\",\"bids\":[],\"asks\":[{\"price\":78527.1,\"qty\":0.00000000},{\"price\":78532.3,\"qty\":0.90252926}],\"checksum\":1008237711,\"timestamp\":\"2026-08-26T11:56:04.382069Z\"}]}"}
{"recv_ts_ns":1787745364532923381,"payload":"{\"channel\":\"book\",\"type\":\"update\",\"data\":[{\"symbol\":\"BTC/USD\",\"bids\":[],\"asks\":[{\"price\":78527.0,\"qty\":1.44924904}],\"checksum\":1008237711,\"timestamp\":\"2026-08-26T11:56:04.382122Z\"}]}"}
{"recv_ts_ns":1787745364532987079,"payload":"{\"channel\":\"book\",\"type\":\"update\",\"data\":[{\"symbol\":\"BTC/USD\",\"bids\":[],\"asks\":[{\"price\":78532.3,\"qty\":0.00000000},{\"price\":78534.4,\"qty\":3.03201003}],\"checksum\":1008237711,\"timestamp\":\"2026-08-26T11:56:04.382275Z\"}]}"}
{"recv_ts_ns":1787745364533058940,"payload":"{\"channel\":\"book\",\"type\":\"update\",\"data\":[{\"symbol\":\"BTC/USD\",\"bids\":[],\"asks\":[{\"price\":78528.9,\"qty\":0.00000000},{\"price\":78535.1,\"qty\":0.00005000},{\"price\":78534.3,\"qty\":0.26868048}],\"checksum\":1008237711,\"timestamp\":\"2026-08-26T11:56:04.382310Z\"}]}"}
{"recv_ts_ns":1787745364537747966,"payload":"{\"channel\":\"book\",\"type\":\"update\",\"data\":[{\"symbol\":\"BTC/USD\",\"bids\":[],\"asks\":[{\"price\":78527.3,\"qty\":0.00000000},{\"price\":78535.1,\"qty\":0.00005000}],\"checksum\":1008237711,\"timestamp\":\"2026-08-26T11:56:04.382702Z\"}]}"}
{"recv_ts_ns":1787745364537816421,"payload":"{\"channel\":\"book\",\"type\":\"update\",\"data\":[{\"symbol\":\"BTC/USD\",\"bids\":[],\"asks\":[{\"price\":78512.7,\"qty\":0.00000000},{\"price\":78536.4,\"qty\":0.00050000}],\"checksum\":2500984169,\"timestamp\":\"2026-08-26T11:56:04.383610Z\"}]}"}
{"recv_ts_ns":1787745364537845239,"payload":"{\"channel\":\"book\",\"type\":\"update\",\"data\":[{\"symbol\":\"BTC/USD\",\"bids\":[],\"asks\":[{\"price\":78532.8,\"qty\":0.00254670}],\"checksum\":2500984169,\"timestamp\":\"2026-08-26T11:56:04.383769Z\"}]}"}
{"recv_ts_ns":1787745364537875853,"payload":"{\"channel\":\"book\",\"type\":\"update\",\"data\":[{\"symbol\":\"BTC/USD\",\"bids\":[],\"asks\":[{\"price\":78526.9,\"qty\":0.52903852}],\"checksum\":2500984169,\"timestamp\":\"2026-08-26T11:56:04.384758Z\"}]}"}
{"recv_ts_ns":1787745364542555071,"payload":"{\"channel\":\"book\",\"type\":\"update\",\"data\":[{\"symbol\":\"BTC/USD\",\"bids\":[],\"asks\":[{\"price\":78529.4,\"qty\":0.00000000},{\"price\":78535.1,\"qty\":0.00005000}],\"checksum\":2500984169,\"timestamp\":\"2026-08-26T11:56:04.386264Z\"}]}"}
{"recv_ts_ns":1787745364542587091,"payload":"{\"channel\":\"book\",\"type\":\"update\",\"data\":[{\"symbol\":\"BTC/USD\",\"bids\":[],\"asks\":[{\"price\":78525.2,\"qty\":0.00000000},{\"price\":78536.4,\"qty\":0.00050000},{\"price\":78527.6,\"qty\":0.02547272}],\"checksum\":2500984169,\"timestamp\":\"2026-08-26T11:56:04.387225Z\"}]}"}
{"recv_ts_ns":1787745364542601594,"payload":"{\"channel\":\"book\",\"type\":\"update\",\"data\":[{\"symbol\":\"BTC/USD\",\"bids\":[{\"price\":78500.6,\"qty\":2.41441148},{\"price\":78498.8,\"qty\":3.03152674}],\"asks\":[],\"checksum\":152715795,\"timestamp\":\"2026-08-26T11:56:04.387354Z\"}]}"}
{"recv_ts_ns":1787745364542619770,"payload":"{\"channel\":\"book\",\"type\":\"update\",\"data\":[{\"symbol\":\"BTC/USD\",\"bids\":[{\"price\":78498.8,\"qty\":0.00000000},{\"price\":78482.7,\"qty\":0.00005000},{\"price\":78500.6,\"qty\":5.44582185}],\"asks\":[],\"checksum\":3555350786,\"timestamp\":\"2026-08-26T11:56:04.387570Z\"}]}"}
{"recv_ts_ns":1787745364544568384,"payload":"{\"channel\":\"book\",\"type\":\"update\",\"data\":[{\"symbol\":\"BTC/USD\",\"bids\":[],\"asks\":[{\"price\":78534.1,\"qty\":0.13366854}],\"checksum\":3555350786,\"timestamp\":\"2026-08-26T11:56:04.388185Z\"}]}"}
{"recv_ts_ns":1787745364544582292,"payload":"{\"channel\":\"book\",\"type\":\"update\",\"data\":[{\"symbol\":\"BTC/USD\",\"bids\":[],\"asks\":[{\"price\":78534.3,\"qty\":1.18900375}],\"checksum\":3555350786,\"timestamp\":\"2026-08-26T11:56:04.388569Z\"}]}"}
{"recv_ts_ns":1787745364544592922,"payload":"{\"channel\":\"book\",\"type\":\"update\",\"data\":[{\"symbol\":\"BTC/USD\",\"bids\":[],\"asks\":[{\"price\":78534.3,\"qty\":1.27856390}],\"checksum\":3555350786,\"timestamp\":\"2026-08-26T11:56:04.388807Z\"}]}"}
{"recv_ts_ns":1787745364544600861,"payload":"{\"channel\":\"book\",\"type\":\"update\",\"data\":[{\"symbol\":\"BTC/USD\",\"bids\":[],\"asks\":[{\"price\":78525.7,\"qty\":0.00320915}],\"checksum\":3555350786,\"timestamp\":\"2026-08-26T11:56:04.389183Z\"}]}"}
{"recv_ts_ns":1787745364544612899,"payload":"{\"channel\":\"book\",\"type\":\"update\",\"data\":[{\"symbol\":\"BTC/USD\",\"bids\":[{\"price\":78487.4,\"qty\":0.01274089}],\"asks\":[],\"checksum\":3555350786,\"timestamp\":\"2026-08-26T11:56:04.391072Z\"}]}"}
{"recv_ts_ns":1787745364544628085,"payload":"{\"channel\":\"book\",\"type\":\"update\",\"data\":[{\"symbol\":\"BTC/USD\",\"bids\":[],\"asks\":[{\"price\":78525.1,\"qty\":0.21768267}],\"checksum\":3555350786,\"timestamp\":\"2026-08-26T11:56:04.391971Z\"}]}"}
{"recv_ts_ns":1787745364548088928,"payload":"{\"channel\":\"book\",\"type\":\"update\",\"data\":[{\"symbol\":\"BTC/USD\",\"bids\":[],\"asks\":[{\"price\":78534.3,\"qty\":1.36812406}],\"checksum\":3555350786,\"timestamp\":\"2026-08-26T11:56:04.392402Z\"}]}"}
{"recv_ts_ns":1787745364548124265,"payload":"{\"channel\":\"book\",\"type\":\"update\",\"data\":[{\"symbol\":\"BTC/USD\",\"bids\":[],\"asks\":[{\"price\":78522.3,\"qty\":0.01292474},{\"price\":78525.5,\"qty\":0.16577268}],\"checksum\":3555350786,\"timestamp\":\"2026-08-26T11:56:04.392651Z\"}]}"}
{"recv_ts_ns":1787745364548144149,"payload":"{\"channel\":\"book\",\"type\":\"update\",\"data\":[{\"symbol\":\"BTC/USD\",\"bids\":[],\"asks\":[{\"price\":78534.3,\"qty\":1.45768422}],\"checksum\":3555350786,\"timestamp\":\"2026-08-26T11:56:04.393308Z\"}]}"}
{"recv_ts_ns":1787745364554100121,"payload":"{\"channel\":\"book\",\"type\":\"update\",\"data\":[{\"symbol\":\"BTC/USD\",\"bids\":[{\"price\":78493.7,\"qty\":0.66195080}],\"asks\":[],\"checksum\":3555350786,\"timestamp\":\"2026-08-26T11:56:04.397794Z\"}]}"}
{"recv_ts_ns":1787745364554153347,"payload":"{\"channel\":\"book\",\"type\":\"update\",\"data\":[{\"symbol\":\"BTC/USD\",\"bids\":[],\"asks\":[{\"price\":78527.0,\"qty\":1.27367941}],\"checksum\":3555350786,\"timestamp\":\"2026-08-26T11:56:04.398406Z\"}]}"}
{"recv_ts_ns":1787745364554190133,"payload":"{\"channel\":\"book\",\"type\":\"update\",\"data\":[{\"symbol\":\"BTC/USD\",\"bids\":[],\"asks\":[{\"price\":78519.9,\"qty\":0.04603180}],\"checksum\":1955758649,\"timestamp\":\"2026-08-26T11:56:04.398635Z\"}]}"}
{"recv_ts_ns":1787745364554236056,"payload":"{\"channel\":\"book\",\"type\":\"update\",\"data\":[{\"symbol\":\"BTC/USD\",\"bids\":[],\"asks\":[{\"price\":78513.0,\"qty\":0.00000000},{\"price\":78534.3,\"qty\":1.45768422}],\"checksum\":1514111430,\"timestamp\":\"2026-08-26T11:56:04.398777Z\"}]}"}
{"recv_ts_ns":1787745364554283582,"payload":"{\"channel\":\"book\",\"type\":\"update\",\"data\":[{\"symbol\":\"BTC/USD\",\"bids\":[],\"asks\":[{\"price\":78526.9,\"qty\":0.00000000},{\"price\":78534.4,\"qty\":3.03201003}],\"checksum\":1514111430,\"timestamp\":\"2026-08-26T11:56:04.398979Z\"}]}"}
{"recv_ts_ns":1787745364554331244,"payload":"{\"channel\":\"book\",\"type\":\"update\",\"data\":[{\"symbol\":\"BTC/USD\",\"bids\":[],\"asks\":[{\"price\":78527.6,\"qty\":0.00000000},{\"price\":78535.1,\"qty\":0.00005000}],\"checksum\":1514111430,\"timestamp\":\"2026-08-26T11:56:04.399360Z\"}]}"}
{"recv_ts_ns":1787745364554381052,"payload":"{\"channel\":\"book\",\"type\":\"update\",\"data\":[{\"symbol\":\"BTC/USD\",\"bids\":[],\"asks\":[{\"price\":78516.0,\"qty\":0.01273625}],\"checksum\":1670330254,\"timestamp\":\"2026-08-26T11:56:04.399375Z\"}]}"}
{"recv_ts_ns":1787745364555369252,"payload":"{\"channel\":\"book\",\"type\":\"update\",\"data\":[{\"symbol\":\"BTC/USD\",\"bids\":[],\"asks\":[{\"price\":78508.8,\"qty\":0.00000000},{\"price\":78536.4,\"qty\":0.00050000}],\"checksum\":2200186922,\"timestamp\":\"2026-08-26T11:56:04.400234Z\"}]}"}
{"recv_ts_ns":1787745364555442859,"payload":"{\"channel\":\"book\",\"type\":\"update\",\"data\":[{\"symbol\":\"BTC/USD\",\"bids\":[],\"asks\":[{\"price\":78526.9,\"qty\":0.39536069}],\"checksum\":2200186922,\"timestamp\":\"2026-08-26T11:56:04.400627Z\"}]}"}
{"recv_ts_ns":1787745364555479247,"payload":"{\"channel\":\"book\",\"type\":\"update\",\"data\":[{\"symbol\":\"BTC/USD\",\"bids\":[{\"price\":78490.2,\"qty\":0.19284703}],\"asks\":[],\"checksum\":2200186922,\"timestamp\":\"2026-08-26T11:56:04.401544Z\"}]}"}
{"recv_ts_ns":1787745364555522302,"payload":"{\"channel\":\"book\",\"type\":\"update\",\"data\":[{\"symbol\":\"BTC/USD\",\"bids\":[],\"asks\":[{\"price\":78524.3,\"qty\":0.01621342}],\"checksum\":2200186922,\"timestamp\":\"2026-08-26T11:56:04.403698Z\"}]}"}
{"recv_ts_ns":1787745364559950272,"payload":"{\"channel\":\"book\",\"type\":\"update\",\"data\":[{\"symbol\":\"BTC/USD\",\"bids\":[],\"asks\":[{\"price\":78516.0,\"qty\":0.00000000},{\"price\":78535.1,\"qty\":0.00005000},{\"price\":78528.9,\"qty\":0.01273416}],\"checksum\":327787413,\"timestamp\":\"2026-08-26T11:56:04.404890Z\"}]}"}
{"recv_ts_ns":1787745364560043066,"payload":"{\"channel\":\"book\",\"type\":\"update\",\"data\":[{\"symbol\":\"BTC/USD\",\"bids\":[],\"asks\":[{\"price\":78525.1,\"qty\":0.00000000},{\"price\":78535.1,\"qty\":0.00005000}],\"checksum\":327787413,\"timestamp\":\"2026-08-26T11:56:04.405308Z\"}]}"}
{"recv_ts_ns":1787745364560110150,"payload":"{\"channel\":\"book\",\"type\":\"update\",\"data\":[{\"symbol\":\"BTC/USD\",\"bids\":[{\"price\":78500.6,\"qty\":5.44586625}],\"asks\":[],\"checksum\":848557367,\"timestamp\":\"2026-08-26T11:56:04.406347Z\"}]}"}
{"recv_ts_ns":1787745364564876129,"payload":"{\"channel\":\"book\",\"type\":\"update\",\"data\":[{\"symbol\":\"BTC/USD\",\"bids\":[{\"price\":78500.2,\"qty\":0.04195800}],\"asks\":[],\"checksum\":2012167883,\"timestamp\":\"2026-08-26T11:56:04.415101Z\"}]}"}
{"recv_ts_ns":1787745364568249149,"payload":"{\"channel\":\"book\",\"type\":\"update\",\"data\":[{\"symbol\":\"BTC/USD\",\"bids\":[{\"price\":78500.6,\"qty\":2.41441148},{\"price\":78498.8,\"qty\":3.03148761}],\"asks\":[],\"checksum\":3286858584,\"timestamp\":\"2026-08-26T11:56:04.417592Z\"}]}"}
{"recv_ts_ns":1787745364571295438,"payload":"{\"channel\":\"book\",\"type\":\"update\",\"data\":[{\"symbol\":\"BTC/USD\",\"bids\":[],\"asks\":[{\"price\":78524.4,\"qty\":0.00000000},{\"price\":78537.0,\"qty\":0.05060000}],\"checksum\":3286858584,\"timestamp\":\"2026-08-26T11:56:04.418124Z\"}]}"}
{"recv_ts_ns":1787745364571426250,"payload":"{\"channel\":\"book\",\"type\":\"update\",\"data\":[{\"symbol\":\"BTC/USD\",\"bids\":[{\"price\":78493.7,\"qty\":0.01511932}],\"asks\":[],\"checksum\":3286858584,\"timestamp\":\"2026-08-26T11:56:04.418381Z\"}]}"}
{"recv_ts_ns":1787745364571489599,"payload":"{\"channel\":\"book\",\"type\":\"update\",\"data\":[{\"symbol\":\"BTC/USD\",\"bids\":[],\"asks\":[{\"price\":78522.2,\"qty\":0.04948314}],\"checksum\":342752843,\"timestamp\":\"2026-08-26T11:56:04.418716Z\"}]}"}
{"recv_ts_ns":1787745364571548531,"payload":"{\"channel\":\"book\",\"type\":\"update\",\"data\":[{\"symbol\":\"BTC/USD\",\"bids\":[{\"price\":78490.4,\"qty\":0.90327407}],\"asks\":[],\"checksum\":342752843,\"timestamp\":\"2026-08-26T11:56:04.418862Z\"}]}"}
{"recv_ts_ns":1787745364571690393,"payload":"{\"channel\":\"book\",\"type\":\"update\",\"data\":[{\"symbol\":\"BTC/USD\",\"bids\":[],\"asks\":[{\"price\":78522.2,\"qty\":0.00000000},{\"price\":78537.0,\"qty\":0.05060000}],\"checksum\":3286858584,\"timestamp\":\"2026-08-26T11:56:04.419088Z\"}]}"}
{"recv_ts_ns":1787745364571796182,"payload":"{\"channel\":\"book\",\"type\":\"update\",\"data\":[{\"symbol\":\"BTC/USD\",\"bids\":[],\"asks\":[{\"price\":78534.2,\"qty\":0.08020112}],\"checksum\":3286858584,\"timestamp\":\"2026-08-26T11:56:04.419569Z\"}]}"}
{"recv_ts_ns":1787745364572955998,"payload":"{\"channel\":\"book\",\"type\":\"update\",\"data\":[{\"symbol\":\"BTC/USD\",\"bids\":[],\"asks\":[{\"price\":78534.1,\"qty\":0.00000000},{\"price\":78537.0,\"qty\":0.05060000}],\"checksum\":3286858584,\"timestamp\":\"2026-08-26T11:56:04.421275Z\"}]}"}
{"recv_ts_ns":1787745364576128982,"payload":"{\"channel\":\"book\",\"type\":\"update\",\"data\":[{\"symbol\":\"BTC/USD\",\"bids\":[],\"asks\":[{\"price\":78524.3,\"qty\":0.05143654}],\"checksum\":3286858584,\"timestamp\":\"2026-08-26T11:56:04.422394Z\"}]}"}
{"recv_ts_ns":1787745364580373063,"payload":"{\"channel\":\"book\",\"type\":\"update\",\"data\":[{\"symbol\":\"BTC/USD\",\"bids\":[],\"asks\":[{\"price\":78526.8,\"qty\":0.63672568}],\"checksum\":3286858584,\"timestamp\":\"2026-08-26T11:56:04.423783Z\"}]}"}
{"recv_ts_ns":1787745364580515552,"payload":"{\"channel\":\"book\",\"type\":\"update\",\"data\":[{\"symbol\":\"BTC/USD\",\"bids\":[],\"asks\":[{\"price\":78526.8,\"qty\":0.00000000},{\"price\":78537.0,\"qty\":0.05060000}],\"checksum\":3286858584,\"timestamp\":\"2026-08-26T11:56:04.425221Z\"}]}"}
{"recv_ts_ns":1787745364580994217,"payload":"{\"channel\":\"book\",\"type\":\"update\",\"data\":[{\"symbol\":\"BTC/USD\",\"bids\":[],\"asks\":[{\"price\":78532.5,\"qty\":0.02292044}],\"checksum\":3286858584,\"timestamp\":\"2026-08-26T11:56:04.426823Z\"}]}"}
{"recv_ts_ns":1787745364584468804,"payload":"{\"channel\":\"book\",\"type\":\"update\",\"data\":[{\"symbol\":\"BTC/USD\",\"bids\":[{\"price\":78490.2,\"qty\":0.00000000},{\"price\":78484.0,\"qty\":0.12613757}],\"asks\":[],\"checksum\":3286858584,\"timestamp\":\"2026-08-26T11:56:04.427992Z\"}]}"}
{"recv_ts_ns":1787745364584599731,"payload":"{\"channel\":\"book\",\"type\":\"update\",\"data\":[{\"symbol\":\"BTC/USD\",\"bids\":[],\"asks\":[{\"price\":78525.5,\"qty\":0.01292474},{\"price\":78526.8,\"qty\":0.15284794}],\"checksum\":3286858584,\"timestamp\":\"2026-08-26T11:56:04.428076Z\"}]}"}
{"recv_ts_ns":1787745364584755831,"payload":"{\"channel\":\"book\",\"type\":\"update\",\"data\":[{\"symbol\":\"BTC/USD\",\"bids\":[],\"asks\":[{\"price\":78529.3,\"qty\":0.11364277}],\"checksum\":3286858584,\"timestamp\":\"2026-08-26T11:56:04.431502Z\"}]}"}
{"recv_ts_ns":1787745364586373575,"payload":"{\"channel\":\"book\",\"type\":\"update\",\"data\":[{\"symbol\":\"BTC/USD\",\"bids\":[],\"asks\":[{\"price\":78524.3,\"qty\":0.09119522}],\"checksum\":3286858584,\"timestamp\":\"2026-08-26T11:56:04.436131Z\"}]}"}
{"recv_ts_ns":1787745364591103875,"payload":"{\"channel\":\"book\",\"type\":\"update\",\"data\":[{\"symbol\":\"BTC/USD\",\"bids\":[],\"asks\":[{\"price\":78524.3,\"qty\":0.05597210}],\"checksum\":3286858584,\"timestamp\":\"2026-08-26T11:56:04.437700Z\"}]}"}
{"recv_ts_ns":1787745364591234320,"payload":"{\"channel\":\"book\",\"type\":\"update\",\"data\":[{\"symbol\":\"BTC/USD\",\"bids\":[],\"asks\":[{\"price\":78524.3,\"qty\":0.03975868}],\"checksum\":3286858584,\"timestamp\":\"2026-08-26T11:56:04.437775Z\"}]}"}
{"recv_ts_ns":1787745364592805933,"payload":"{\"channel\":\"book\",\"type\":\"update\",\"data\":[{\"symbol\":\"BTC/USD\",\"bids\":[],\"asks\":[{\"price\":78534.2,\"qty\":0.15014869}],\"checksum\":3286858584,\"timestamp\":\"2026-08-26T11:56:04.440615Z\"}]}"}
{"recv_ts_ns":1787745364595005793,"payload":"{\"channel\":\"book\",\"type\":\"update\",\"data\":[{\"symbol\":\"BTC/USD\",\"bids\":[],\"asks\":[{\"price\":78521.1,\"qty\":0.95543056}],\"checksum\":5245724,\"timestamp\":\"2026-08-26T11:56:04.441585Z\"}]}"}
{"recv_ts_ns":1787745364595086537,"payload":"{\"channel\":\"book\",\"type\":\"update\",\"data\":[{\"symbol\":\"BTC/USD\",\"bids\":[],\"asks\":[{\"price\":78523.2,\"qty\":0.85606579}],\"checksum\":5245724,\"timestamp\":\"2026-08-26T11:56:04.441626Z\"}]}"}
{"recv_ts_ns":1787745364597868162,"payload":"{\"channel\":\"book\",\"type\":\"update\",\"data\":[{\"symbol\":\"BTC/USD\",\"bids\":[],\"asks\":[{\"price\":78524.3,\"qty\":0.00000000},{\"price\":78534.2,\"qty\":0.15014869}],\"checksum\":5245724,\"timestamp\":\"2026-08-26T11:56:04.445359Z\"}]}"}
{"recv_ts_ns":1787745364598769085,"payload":"{\"channel\":\"book\",\"type\":\"update\",\"data\":[{\"symbol\":\"BTC/USD\",\"bids\":[],\"asks\":[{\"price\":78523.1,\"qty\":0.26035160}],\"checksum\":5245724,\"timestamp\":\"2026-08-26T11:56:04.447051Z\"}]}"}
{"recv_ts_ns":1787745364607750233,"payload":"{\"channel\":\"book\",\"type\":\"update\",\"data\":[{\"symbol\":\"BTC/USD\",\"bids\":[],\"asks\":[{\"price\":78526.8,\"qty\":0.00000000},{\"price\":78534.2,\"qty\":0.15014869},{\"price\":78525.7,\"qty\":0.15605709}],\"checksum\":5245724,\"timestamp\":\"2026-08-26T11:56:04.456498Z\"}]}"}
{"recv_ts_ns":1787745364614024475,"payload":"{\"channel\":\"book\",\"type\":\"update\",\"data\":[{\"symbol\":\"BTC/USD\",\"bids\":[{\"price\":78492.2,\"qty\":0.40000000}],\"asks\":[],\"checksum\":5245724,\"timestamp\":\"2026-08-26T11:56:04.468057Z\"}]}"}
{"recv_ts_ns":1787745364618081276,"payload":"{\"channel\":\"book\",\"type\":\"update\",\"data\":[{\"symbol\":\"BTC/USD\",\"bids\":[],\"asks\":[{\"price\":78511.8,\"qty\":0.00000000},{\"price\":78534.3,\"qty\":1.45768422}],\"checksum\":1377444540,\"timestamp\":\"2026-08-26T11:56:04.470645Z\"}]}"}
{"recv_ts_ns":1787745364618160362,"payload":"{\"channel\":\"book\",\"type\":\"update\",\"data\":[{\"symbol\":\"BTC/USD\",\"bids\":[{\"price\":78493.7,\"qty\":0.13258635}],\"asks\":[],\"checksum\":1377444540,\"timestamp\":\"2026-08-26T11:56:04.470794Z\"}]}"}
{"recv_ts_ns":1787745364618213923,"payload":"{\"channel\":\"book\",\"type\":\"update\",\"data\":[{\"symbol\":\"BTC/USD\",\"bids\":[],\"asks\":[{\"price\":78508.8,\"qty\":0.01565551}],\"checksum\":877088428,\"timestamp\":\"2026-08-26T11:56:04.470858Z\"}]}"}
{"recv_ts_ns":1787745364636013616,"payload":"{\"channel\":\"book\",\"type\":\"update\",\"data\":[{\"symbol\":\"BTC/USD\",\"bids\":[],\"asks\":[{\"price\":78525.7,\"qty\":0.00320915},{\"price\":78526.8,\"qty\":0.15284794}],\"checksum\":877088428,\"timestamp\":\"2026-08-26T11:56:04.487537Z\"}]}"}
{"recv_ts_ns":1787745364636134093,"payload":"{\"channel\":\"book\",\"type\":\"update\",\"data\":[{\"symbol\":\"BTC/USD\",\"bids\":[],\"asks\":[{\"price\":78521.0,\"qty\":0.28905406}],\"checksum\":3524148294,\"timestamp\":\"2026-08-26T11:56:04.489570Z\"}]}"}
{"recv_ts_ns":1787745364636191376,"payload":"{\"channel\":\"book\",\"type\":\"update\",\"data\":[{\"symbol\":\"BTC/USD\",\"bids\":[],\"asks\":[{\"price\":78516.7,\"qty\":0.01130046}],\"checksum\":3815491531,\"timestamp\":\"2026-08-26T11:56:04.491122Z\"}]}"}
{"recv_ts_ns":1787745364638116975,"payload":"{\"channel\":\"book\",\"type\":\"update\",\"data\":[{\"symbol\":\"BTC/USD\",\"bids\":[],\"asks\":[{\"price\":78520.6,\"qty\":0.01488201}],\"checksum\":3815491531,\"timestamp\":\"2026-08-26T11:56:04.491256Z\"}]}"}
{"recv_ts_ns":1787745364646214579,"payload":"{\"channel\":\"book\",\"type\":\"update\",\"data\":[{\"symbol\":\"BTC/USD\",\"bids\":[],\"asks\":[{\"price\":78521.1,\"qty\":0.00000000},{\"price\":78531.4,\"qty\":0.00664366}],\"checksum\":3815491531,\"timestamp\":\"2026-08-26T11:56:04.498193Z\"}]}"}
{"recv_ts_ns":1787745364646364296,"payload":"{\"channel\":\"book\",\"type\":\"update\",\"data\":[{\"symbol\":\"BTC/USD\",\"bids\":[],\"asks\":[{\"price\":78521.0,\"qty\":0.00000000},{\"price\":78532.5,\"qty\":0.02292044}],\"checksum\":3815491531,\"timestamp\":\"2026-08-26T11:56:04.499672Z\"}]}"}
{"recv_ts_ns":1787745364647309384,"payload":"{\"channel\":\"book\",\"type\":\"update\",\"data\":[{\"symbol\":\"BTC/USD\",\"bids\":[],\"asks\":[{\"price\":78519.8,\"qty\":0.02860683}],\"checksum\":697770220,\"timestamp\":\"2026-08-26T11:56:04.500066Z\"}]}"}
{"recv_ts_ns":1787745364658745067,"payload":"{\"channel\":\"book\",\"type\":\"update\",\"data\":[{\"symbol\":\"BTC/USD\",\"bids\":[],\"asks\":[{\"price\":78526.8,\"qty\":0.00000000},{\"price\":78532.5,\"qty\":0.02292044},{\"price\":78525.7,\"qty\":0.15605709}],\"checksum\":697770220,\"timestamp\":\"2026-08-26T11:56:04.512936Z\"}]}"}
{"recv_ts_ns":1787745364667855350,"payload":"{\"channel\":\"book\",\"type\":\"update\",\"data\":[{\"symbol\":\"BTC/USD\",\"bids\":[],\"asks\":[{\"price\":78519.8,\"qty\":0.98403739}],\"checksum\":363045548,\"timestamp\":\"2026-08-26T11:56:04.519914Z\"}]}"}
{"recv_ts_ns":1787745364671262717,"payload":"{\"channel\":\"book\",\"type\":\"update\",\"data\":[{\"symbol\":\"BTC/USD\",\"bids\":[],\"asks\":[{\"price\":78519.8,\"qty\":0.95543056}],\"checksum\":930729256,\"timestamp\":\"2026-08-26T11:56:04.521259Z\"}]}"}
{"recv_ts_ns":1787745364671359068,"payload":"{\"channel\":\"book\",\"type\":\"update\",\"data\":[{\"symbol\":\"BTC/USD\",\"bids\":[],\"asks\":[{\"price\":78519.7,\"qty\":0.31380285}],\"checksum\":18886970,\"timestamp\":\"2026-08-26T11:56:04.521480Z\"}]}"}
{"recv_ts_ns":1787745364701497956,"payload":"{\"channel\":\"book\",\"type\":\"update\",\"data\":[{\"symbol\":\"BTC/USD\",\"bids\":[],\"asks\":[{\"price\":78525.7,\"qty\":0.00320915},{\"price\":78525.5,\"qty\":0.16577268}],\"checksum\":18886970,\"timestamp\":\"2026-08-26T11:56:04.556271Z\"}]}"}
{"recv_ts_ns":1787745364703433385,"payload":"{\"channel\":\"book\",\"type\":\"update\",\"data\":[{\"symbol\":\"BTC/USD\",\"bids\":[],\"asks\":[{\"price\":78519.9,\"qty\":0.00000000},{\"price\":78532.5,\"qty\":0.02292044},{\"price\":78519.6,\"qty\":0.04603180}],\"checksum\":4101730073,\"timestamp\":\"2026-08-26T11:56:04.557720Z\"}]}"}
{"recv_ts_ns":1787745364726233724,"payload":"{\"channel\":\"book\",\"type\":\"update\",\"data\":[{\"symbol\":\"BTC/USD\",\"bids\":[],\"asks\":[{\"price\":78523.2,\"qty\":0.00000000},{\"price\":78532.5,\"qty\":0.02292044}],\"checksum\":4101730073,\"timestamp\":\"2026-08-26T11:56:04.580422Z\"}]}"}
{"recv_ts_ns":1787745364726339242,"payload":"{\"channel\":\"book\",\"type\":\"update\",\"data\":[{\"symbol\":\"BTC/USD\",\"bids\":[],\"asks\":[{\"price\":78525.5,\"qty\":0.01292474},{\"price\":78523.1,\"qty\":0.41319954}],\"checksum\":4101730073,\"timestamp\":\"2026-08-26T11:56:04.580570Z\"}]}"}
{"recv_ts_ns":1787745364726384300,"payload":"{\"channel\":\"book\",\"type\":\"update\",\"data\":[{\"symbol\":\"BTC/USD\",\"bids\":[],\"asks\":[{\"price\":78519.8,\"qty\":0.00000000},{\"price\":78532.8,\"qty\":0.00254670}],\"checksum\":196987072,\"timestamp\":\"2026-08-26T11:56:04.580715Z\"}]}"}
{"recv_ts_ns":1787745364728011767,"payload":"{\"channel\":\"book\",\"type\":\"update\",\"data\":[{\"symbol\":\"BTC/USD\",\"bids\":[],\"asks\":[{\"price\":78523.1,\"qty\":0.15284794}],\"checksum\":196987072,\"timestamp\":\"2026-08-26T11:56:04.582022Z\"}]}"}
{"recv_ts_ns":1787745364728094232,"payload":"{\"channel\":\"book\",\"type\":\"update\",\"data\":[{\"symbol\":\"BTC/USD\",\"bids\":[],\"asks\":[{\"price\":78523.1,\"qty\":0.20328902}],\"checksum\":196987072,\"timestamp\":\"2026-08-26T11:56:04.582166Z\"}]}"}
{"recv_ts_ns":1787745364728150956,"payload":"{\"channel\":\"book\",\"type\":\"update\",\"data\":[{\"symbol\":\"BTC/USD\",\"bids\":[],\"asks\":[{\"price\":78519.7,\"qty\":0.00000000},{\"price\":78534.2,\"qty\":0.15014869}],\"checksum\":806316383,\"timestamp\":\"2026-08-26T11:56:04.582309Z\"}]}"}
{"recv_ts_ns":1787745364728194066,"payload":"{\"channel\":\"book\",\"type\":\"update\",\"data\":[{\"symbol\":\"BTC/USD\",\"bids\":[],\"asks\":[{\"price\":78519.5,\"qty\":0.02860683}],\"checksum\":4093721810,\"timestamp\":\"2026-08-26T11:56:04.582318Z\"}]}"}
{"recv_ts_ns":1787745364728252322,"payload":"{\"channel\":\"book\",\"type\":\"update\",\"data\":[{\"symbol\":\"BTC/USD\",\"bids\":[],\"asks\":[{\"price\":78523.1,\"qty\":0.15284794}],\"checksum\":4093721810,\"timestamp\":\"2026-08-26T11:56:04.582394Z\"}]}"}
{"recv_ts_ns":1787745364729454739,"payload":"{\"channel\":\"book\",\"type\":\"update\",\"data\":[{\"symbol\":\"BTC/USD\",\"bids\":[],\"asks\":[{\"price\":78523.0,\"qty\":0.05044108}],\"checksum\":4093721810,\"timestamp\":\"2026-08-26T11:56:04.582657Z\"}]}"}
{"recv_ts_ns":1787745364758987349,"payload":"{\"channel\":\"book\",\"type\":\"update\",\"data\":[{\"symbol\":\"BTC/USD\",\"bids\":[],\"asks\":[{\"price\":78523.1,\"qty\":0.00000000},{\"price\":78532.8,\"qty\":0.00254670},{\"price\":78522.9,\"qty\":0.15284794}],\"checksum\":4093721810,\"timestamp\":\"2026-08-26T11:56:04.612792Z\"}]}"}
{"recv_ts_ns":1787745364759815987,"payload":"{\"channel\":\"book\",\"type\":\"update\",\"data\":[{\"symbol\":\"BTC/USD\",\"bids\":[],\"asks\":[{\"price\":78523.0,\"qty\":0.00000000},{\"price\":78532.8,\"qty\":0.00254670}],\"checksum\":4093721810,\"timestamp\":\"2026-08-26T11:56:04.614231Z\"}]}"}
{"recv_ts_ns":1787745364759908051,"payload":"{\"channel\":\"book\",\"type\":\"update\",\"data\":[{\"symbol\":\"BTC/USD\",\"bids\":[],\"asks\":[{\"price\":78522.8,\"qty\":0.05044108}],\"checksum\":4093721810,\"timestamp\":\"2026-08-26T11:56:04.614556Z\"}]}"}
{"recv_ts_ns":1787745364765275622,"payload":"{\"channel\":\"book\",\"type\":\"update\",\"data\":[{\"symbol\":\"BTC/USD\",\"bids\":[],\"asks\":[{\"price\":78518.2,\"qty\":0.95543056}],\"checksum\":3876261725,\"timestamp\":\"2026-08-26T11:56:04.619956Z\"}]}"}
{"recv_ts_ns":1787745364768092046,"payload":"{\"channel\":\"book\",\"type\":\"update\",\"data\":[{\"symbol\":\"BTC/USD\",\"bids\":[],\"asks\":[{\"price\":78518.1,\"qty\":0.28519602}],\"checksum\":1278415649,\"timestamp\":\"2026-08-26T11:56:04.621586Z\"}]}"}
{"recv_ts_ns":1787745364794635770,"payload":"{\"channel\":\"book\",\"type\":\"update\",\"data\":[{\"symbol\":\"BTC/USD\",\"bids\":[],\"asks\":[{\"price\":78518.2,\"qty\":0.00000000},{\"price\":78531.4,\"qty\":0.00664366}],\"checksum\":1235699445,\"timestamp\":\"2026-08-26T11:56:04.647785Z\"}]}"}
{"recv_ts_ns":1787745364798641007,"payload":"{\"channel\":\"book\",\"type\":\"update\",\"data\":[{\"symbol\":\"BTC/USD\",\"bids\":[],\"asks\":[{\"price\":78518.1,\"qty\":0.00000000},{\"price\":78532.5,\"qty\":0.02292044}],\"checksum\":4093721810,\"timestamp\":\"2026-08-26T11:56:04.650782Z\"}]}"}
{"recv_ts_ns":1787745364798792867,"payload":"{\"channel\":\"book\",\"type\":\"update\",\"data\":[{\"symbol\":\"BTC/USD\",\"bids\":[],\"asks\":[{\"price\":78522.9,\"qty\":0.00000000},{\"price\":78532.8,\"qty\":0.00254670},{\"price\":78522.8,\"qty\":0.20328902}],\"checksum\":4093721810,\"timestamp\":\"2026-08-26T11:56:04.651254Z\"}]}"}
{"recv_ts_ns":1787745364798866107,"payload":"{\"channel\":\"book\",\"type\":\"update\",\"data\":[{\"symbol\":\"BTC/USD\",\"bids\":[],\"asks\":[{\"price\":78516.5,\"qty\":0.95543056}],\"checksum\":643850720,\"timestamp\":\"2026-08-26T11:56:04.651661Z\"}]}"}
{"recv_ts_ns":1787745364799055258,"payload":"{\"channel\":\"book\",\"type\":\"update\",\"data\":[{\"symbol\":\"BTC/USD\",\"bids\":[],\"asks\":[{\"price\":78522.7,\"qty\":0.05044108}],\"checksum\":643850720,\"timestamp\":\"2026-08-26T11:56:04.652896Z\"}]}"}
{"recv_ts_ns":1787745364799132628,"payload":"{\"channel\":\"book\",\"type\":\"update\",\"data\":[{\"symbol\":\"BTC/USD\",\"bids\":[],\"asks\":[{\"price\":78522.8,\"qty\":0.15284794}],\"checksum\":643850720,\"timestamp\":\"2026-08-26T11:56:04.652939Z\"}]}"}
{"recv_ts_ns":1787745364821468697,"payload":"{\"channel\":\"book\",\"type\":\"update\",\"data\":[{\"symbol\":\"BTC/USD\",\"bids\":[{\"price\":78498.8,\"qty\":0.00000000},{\"price\":78484.0,\"qty\":0.12613757},{\"price\":78495.8,\"qty\":3.03153516}],\"asks\":[],\"checksum\":4226248177,\"timestamp\":\"2026-08-26T11:56:04.674750Z\"}]}"}
{"recv_ts_ns":1787745364821619485,"payload":"{\"channel\":\"book\",\"type\":\"update\",\"data\":[{\"symbol\":\"BTC/USD\",\"bids\":[],\"asks\":[{\"price\":78522.8,\"qty\":0.00000000},{\"price\":78532.5,\"qty\":0.02292044},{\"price\":78522.7,\"qty\":0.20328902}],\"checksum\":4226248177,\"timestamp\":\"2026-08-26T11:56:04.676023Z\"}]}"}
{"recv_ts_ns":1787745364822862441,"payload":"{\"channel\":\"book\",\"type\":\"update\",\"data\":[{\"symbol\":\"BTC/USD\",\"bids\":[],\"asks\":[{\"price\":78522.6,\"qty\":0.05044108}],\"checksum\":4226248177,\"timestamp\":\"2026-08-26T11:56:04.677241Z\"}]}"}
{"recv_ts_ns":1787745364822953596,"payload":"{\"channel\":\"book\",\"type\":\"update\",\"data\":[{\"symbol\":\"BTC/USD\",\"bids\":[],\"asks\":[{\"price\":78522.7,\"qty\":0.15284794}],\"checksum\":4226248177,\"timestamp\":\"2026-08-26T11:56:04.677338Z\"}]}"}
{"recv_ts_ns":1787745364824516261,"payload":"{\"channel\":\"book\",\"type\":\"update\",\"data\":[{\"symbol\":\"BTC/USD\",\"bids\":[],\"asks\":[{\"price\":78522.9,\"qty\":0.63675693}],\"checksum\":4226248177,\"timestamp\":\"2026-08-26T11:56:04.678665Z\"}]}"}
{"recv_ts_ns":1787745364824577428,"payload":"{\"channel\":\"book\",\"type\":\"update\",\"data\":[{\"symbol\":\"BTC/USD\",\"bids\":[],\"asks\":[{\"price\":78525.6,\"qty\":0.63673526}],\"checksum\":4226248177,\"timestamp\":\"2026-08-26T11:56:04.679002Z\"}]}"}
{"recv_ts_ns":1787745364826568042,"payload":"{\"channel\":\"book\",\"type\":\"update\",\"data\":[{\"symbol\":\"BTC/USD\",\"bids\":[],\"asks\":[{\"price\":78522.6,\"qty\":0.23406423}],\"checksum\":4226248177,\"timestamp\":\"2026-08-26T11:56:04.680393Z\"}]}"}
{"recv_ts_ns":1787745364826621667,"payload":"{\"channel\":\"book\",\"type\":\"update\",\"data\":[{\"symbol\":\"BTC/USD\",\"bids\":[],\"asks\":[{\"price\":78522.6,\"qty\":0.18362315}],\"checksum\":4226248177,\"timestamp\":\"2026-08-26T11:56:04.680443Z\"}]}"}
{"recv_ts_ns":1787745364826655492,"payload":"{\"channel\":\"book\",\"type\":\"update\",\"data\":[{\"symbol\":\"BTC/USD\",\"bids\":[],\"asks\":[{\"price\":78522.6,\"qty\":0.00000000},{\"price\":78529.3,\"qty\":0.11364277}],\"checksum\":4226248177,\"timestamp\":\"2026-08-26T11:56:04.680681Z\"}]}"}
{"recv_ts_ns":1787745364826744893,"payload":"{\"channel\":\"book\",\"type\":\"update\",\"data\":[{\"symbol\":\"BTC/USD\",\"bids\":[],\"asks\":[{\"price\":78522.6,\"qty\":0.40065384}],\"checksum\":4226248177,\"timestamp\":\"2026-08-26T11:56:04.680866Z\"}]}"}
{"recv_ts_ns":1787745364828699169,"payload":"{\"channel\":\"book\",\"type\":\"update\",\"data\":[{\"symbol\":\"BTC/USD\",\"bids\":[],\"asks\":[{\"price\":78506.4,\"qty\":0.01565551}],\"checksum\":823006890,\"timestamp\":\"2026-08-26T11:56:04.681920Z\"}]}"}
{"recv_ts_ns":1787745364828737065,"payload":"{\"channel\":\"book\",\"type\":\"update\",\"data\":[{\"symbol\":\"BTC/USD\",\"bids\":[],\"asks\":[{\"price\":78508.8,\"qty\":0.00000000},{\"price\":78528.9,\"qty\":0.01273416}],\"checksum\":2840052545,\"timestamp\":\"2026-08-26T11:56:04.681954Z\"}]}"}
{"recv_ts_ns":1787745364856854217,"payload":"{\"channel\":\"book\",\"type\":\"update\",\"data\":[{\"symbol\":\"BTC/USD\",\"bids\":[{\"price\":78486.7,\"qty\":0.00000000},{\"price\":78483.5,\"qty\":1.27373954}],\"asks\":[],\"checksum\":2840052545,\"timestamp\":\"2026-08-26T11:56:04.710721Z\"}]}"}
{"recv_ts_ns":1787745364856982878,"payload":"{\"channel\":\"book\",\"type\":\"update\",\"data\":[{\"symbol\":\"BTC/USD\",\"bids\":[],\"asks\":[{\"price\":78520.2,\"qty\":0.10290342}],\"checksum\":2840052545,\"timestamp\":\"2026-08-26T11:56:04.710774Z\"}]}"}
{"recv_ts_ns":1787745364857024182,"payload":"{\"channel\":\"book\",\"type\":\"update\",\"data\":[{\"symbol\":\"BTC/USD\",\"bids\":[],\"asks\":[{\"price\":78522.7,\"qty\":0.00000000},{\"price\":78528.9,\"qty\":0.01273416},{\"price\":78522.6,\"qty\":0.55350178}],\"checksum\":2840052545,\"timestamp\":\"2026-08-26T11:56:04.710812Z\"}]}"}
{"recv_ts_ns":1787745364858210931,"payload":"{\"channel\":\"book\",\"type\":\"update\",\"data\":[{\"symbol\":\"BTC/USD\",\"bids\":[],\"asks\":[{\"price\":78519.5,\"qty\":0.12643863}],\"checksum\":32071698,\"timestamp\":\"2026-08-26T11:56:04.712218Z\"}]}"}
{"recv_ts_ns":1787745364858281809,"payload":"{\"channel\":\"book\",\"type\":\"update\",\"data\":[{\"symbol\":\"BTC/USD\",\"bids\":[],\"asks\":[{\"price\":78519.5,\"qty\":0.09783180}],\"checksum\":2468944830,\"timestamp\":\"2026-08-26T11:56:04.712243Z\"}]}"}
{"recv_ts_ns":1787745364858331603,"payload":"{\"channel\":\"book\",\"type\":\"update\",\"data\":[{\"symbol\":\"BTC/USD\",\"bids\":[],\"asks\":[{\"price\":78519.5,\"qty\":0.12489115}],\"checksum\":894280833,\"timestamp\":\"2026-08-26T11:56:04.712574Z\"}]}"}
{"recv_ts_ns":1787745364858393577,"payload":"{\"channel\":\"book\",\"type\":\"update\",\"data\":[{\"symbol\":\"BTC/USD\",\"bids\":[],\"asks\":[{\"price\":78519.5,\"qty\":0.09783180}],\"checksum\":2468944830,\"timestamp\":\"2026-08-26T11:56:04.712818Z\"}]}"}
{"recv_ts_ns":1787745364863368084,"payload":"{\"channel\":\"book\",\"type\":\"update\",\"data\":[{\"symbol\":\"BTC/USD\",\"bids\":[],\"asks\":[{\"price\":78519.6,\"qty\":0.00000000},{\"price\":78529.3,\"qty\":0.11364277},{\"price\":78519.4,\"qty\":0.04603180}],\"checksum\":1687227453,\"timestamp\":\"2026-08-26T11:56:04.718262Z\"}]}"}
{"recv_ts_ns":1787745364877773749,"payload":"{\"channel\":\"book\",\"type\":\"update\",\"data\":[{\"symbol\":\"BTC/USD\",\"bids\":[],\"asks\":[{\"price\":78517.3,\"qty\":0.85606579}],\"checksum\":4114714271,\"timestamp\":\"2026-08-26T11:56:04.731057Z\"}]}"}
{"recv_ts_ns":1787745364881060287,"payload":"{\"channel\":\"book\",\"type\":\"update\",\"data\":[{\"symbol\":\"BTC/USD\",\"bids\":[],\"asks\":[{\"price\":78522.6,\"qty\":0.40065384},{\"price\":78522.3,\"qty\":0.16577268}],\"checksum\":4114714271,\"timestamp\":\"2026-08-26T11:56:04.734493Z\"}]}"}
{"recv_ts_ns":1787745364904374839,"payload":"{\"channel\":\"book\",\"type\":\"update\",\"data\":[{\"symbol\":\"BTC/USD\",\"bids\":[],\"asks\":[{\"price\":78516.5,\"qty\":0.00000000},{\"price\":78528.9,\"qty\":0.01273416}],\"checksum\":1209110392,\"timestamp\":\"2026-08-26T11:56:04.759273Z\"}]}"}
{"recv_ts_ns":1787745364906336122,"payload":"{\"channel\":\"book\",\"type\":\"update\",\"data\":[{\"symbol\":\"BTC/USD\",\"bids\":[],\"asks\":[{\"price\":78517.2,\"qty\":0.25553564}],\"checksum\":3992397450,\"timestamp\":\"2026-08-26T11:56:04.760751Z\"}]}"}
{"recv_ts_ns":1787745364920560318,"payload":"{\"channel\":\"book\",\"type\":\"update\",\"data\":[{\"symbol\":\"BTC/USD\",\"bids\":[],\"asks\":[{\"price\":78515.9,\"qty\":0.95543056}],\"checksum\":2292022901,\"timestamp\":\"2026-08-26T11:56:04.771154Z\"}]}"}
{"recv_ts_ns":1787745364921002699,"payload":"{\"channel\":\"book\",\"type\":\"update\",\"data\":[{\"symbol\":\"BTC/USD\",\"bids\":[],\"asks\":[{\"price\":78522.3,\"qty\":0.01292474},{\"price\":78519.7,\"qty\":0.15284794}],\"checksum\":2292022901,\"timestamp\":\"2026-08-26T11:56:04.773099Z\"}]}"}
{"recv_ts_ns":1787745364927737378,"payload":"{\"channel\":\"heartbeat\"}"}
{"recv_ts_ns":1787745364959415788,"payload":"{\"channel\":\"book\",\"type\":\"update\",\"data\":[{\"symbol\":\"BTC/USD\",\"bids\":[],\"asks\":[{\"price\":78522.9,\"qty\":0.00000000},{\"price\":78528.2,\"qty\":0.05060000}],\"checksum\":2292022901,\"timestamp\":\"2026-08-26T11:56:04.812961Z\"}]}"}
{"recv_ts_ns":1787745364959505926,"payload":"{\"channel\":\"book\",\"type\":\"update\",\"data\":[{\"symbol\":\"BTC/USD\",\"bids\":[],\"asks\":[{\"price\":78522.6,\"qty\":0.00000000},{\"price\":78528.5,\"qty\":0.00021200}],\"checksum\":2292022901,\"timestamp\":\"2026-08-26T11:56:04.814361Z\"}]}"}
{"recv_ts_ns":1787745364959549278,"payload":"{\"channel\":\"book\",\"type\":\"update\",\"data\":[{\"symbol\":\"BTC/USD\",\"bids\":[],\"asks\":[{\"price\":78522.6,\"qty\":0.19488144}],\"checksum\":2292022901,\"timestamp\":\"2026-08-26T11:56:04.814503Z\"}]}"}
{"recv_ts_ns":1787745364959735396,"payload":"{\"channel\":\"book\",\"type\":\"update\",\"data\":[{\"symbol\":\"BTC/USD\",\"bids\":[],\"asks\":[{\"price\":78522.1,\"qty\":0.63676350}],\"checksum\":2292022901,\"timestamp\":\"2026-08-26T11:56:04.814912Z\"}]}"}
{"recv_ts_ns":1787745364964981070,"payload":"{\"channel\":\"book\",\"type\":\"update\",\"data\":[{\"symbol\":\"BTC/USD\",\"bids\":[],\"asks\":[{\"price\":78519.5,\"qty\":0.26877442}],\"checksum\":2292022901,\"timestamp\":\"2026-08-26T11:56:04.816402Z\"}]}"}
{"recv_ts_ns":1787745365020286803,"payload":"{\"channel\":\"book\",\"type\":\"update\",\"data\":[{\"symbol\":\"BTC/USD\",\"bids\":[{\"price\":78490.3,\"qty\":0.00000000},{\"price\":78482.7,\"qty\":0.00005000},{\"price\":78483.6,\"qty\":1.27415917}],\"asks\":[],\"checksum\":2292022901,\"timestamp\":\"2026-08-26T11:56:04.871279Z\"}]}"}
{"recv_ts_ns":1787745365020452509,"payload":"{\"channel\":\"book\",\"type\":\"update\",\"data\":[{\"symbol\":\"BTC/USD\",\"bids\":[{\"price\":78490.4,\"qty\":0.00000000},{\"price\":78482.7,\"qty\":0.00005000}],\"asks\":[],\"checksum\":2292022901,\"timestamp\":\"2026-08-26T11:56:04.872538Z\"}]}"}
{"recv_ts_ns":1787745365020547733,"payload":"{\"channel\":\"book\",\"type\":\"update\",\"data\":[{\"symbol\":\"BTC/USD\",\"bids\":[{\"price\":78490.4,\"qty\":0.57046901}],\"asks\":[],\"checksum\":2292022901,\"timestamp\":\"2026-08-26T11:56:04.872758Z\"}]}"}
{"recv_ts_ns":1787745365041899545,"payload":"{\"channel\":\"book\",\"type\":\"update\",\"data\":[{\"symbol\":\"BTC/USD\",\"bids\":[],\"asks\":[{\"price\":78519.4,\"qty\":0.00000000},{\"price\":78528.2,\"qty\":0.05060000},{\"price\":78516.7,\"qty\":0.05733226}],\"checksum\":3483807998,\"timestamp\":\"2026-08-26T11:56:04.895851Z\"}]}"}
{"recv_ts_ns":1787745365110729134,"payload":"{\"channel\":\"book\",\"type\":\"update\",\"data\":[{\"symbol\":\"BTC/USD\",\"bids\":[],\"asks\":[{\"price\":78515.9,\"qty\":0.00000000},{\"price\":78528.5,\"qty\":0.00021200}],\"checksum\":3483019507,\"timestamp\":\"2026-08-26T11:56:04.965739Z\"}]}"}
{"recv_ts_ns":1787745365112053179,"payload":"{\"channel\":\"book\",\"type\":\"update\",\"data\":[{\"symbol\":\"BTC/USD\",\"bids\":[],\"asks\":[{\"price\":78519.7,\"qty\":0.00000000},{\"price\":78528.9,\"qty\":0.01273416},{\"price\":78522.0,\"qty\":0.15284794}],\"checksum\":3483019507,\"timestamp\":\"2026-08-26T11:56:04.966876Z\"}]}"}
{"recv_ts_ns":1787745365117885888,"payload":"{\"channel\":\"book\",\"type\":\"update\",\"data\":[{\"symbol\":\"BTC/USD\",\"bids\":[],\"asks\":[{\"price\":78516.0,\"qty\":0.95543056}],\"checksum\":2433175986,\"timestamp\":\"2026-08-26T11:56:04.969944Z\"}]}"}
{"recv_ts_ns":1787745365131349851,"payload":"{\"channel\":\"book\",\"type\":\"update\",\"data\":[{\"symbol\":\"BTC/USD\",\"bids\":[{\"price\":78483.7,\"qty\":0.38033651}],\"asks\":[],\"checksum\":2433175986,\"timestamp\":\"2026-08-26T11:56:04.986186Z\"}]}"}
{"recv_ts_ns":1787745365132947472,"payload":"{\"channel\":\"book\",\"type\":\"update\",\"data\":[{\"symbol\":\"BTC/USD\",\"bids\":[],\"asks\":[{\"price\":78522.0,\"qty\":0.00000000},{\"price\":78528.5,\"qty\":0.02567940},{\"price\":78519.7,\"qty\":0.15284794}],\"checksum\":2433175986,\"timestamp\":\"2026-08-26T11:56:04.987289Z\"}]}"}
{"recv_ts_ns":1787745365206971676,"payload":"{\"channel\":\"book\",\"type\":\"update\",\"data\":[{\"symbol\":\"BTC/USD\",\"bids\":[],\"asks\":[{\"price\":78517.3,\"qty\":0.00000000},{\"price\":78528.5,\"qty\":0.02567940}],\"checksum\":4176192722,\"timestamp\":\"2026-08-26T11:56:05.057839Z\"}]}"}
{"recv_ts_ns":1787745365207163746,"payload":"{\"channel\":\"book\",\"type\":\"update\",\"data\":[{\"symbol\":\"BTC/USD\",\"bids\":[],\"asks\":[{\"price\":78516.0,\"qty\":0.00000000},{\"price\":78528.9,\"qty\":0.01273416}],\"checksum\":2193910074,\"timestamp\":\"2026-08-26T11:56:05.058017Z\"}]}"}
{"recv_ts_ns":1787745365207285394,"payload":"{\"channel\":\"book\",\"type\":\"update\",\"data\":[{\"symbol\":\"BTC/USD\",\"bids\":[],\"asks\":[{\"price\":78519.5,\"qty\":0.09783180}],\"checksum\":1703657390,\"timestamp\":\"2026-08-26T11:56:05.058789Z\"}]}"}
{"recv_ts_ns":1787745365207366095,"payload":"{\"channel\":\"book\",\"type\":\"update\",\"data\":[{\"symbol\":\"BTC/USD\",\"bids\":[],\"asks\":[{\"price\":78522.6,\"qty\":0.00000000},{\"price\":78529.3,\"qty\":0.11364277}],\"checksum\":1703657390,\"timestamp\":\"2026-08-26T11:56:05.058817Z\"}]}"}
{"recv_ts_ns":1787745365207438710,"payload":"{\"channel\":\"book\",\"type\":\"update\",\"data\":[{\"symbol\":\"BTC/USD\",\"bids\":[],\"asks\":[{\"price\":78519.5,\"qty\":0.00000000},{\"price\":78530.5,\"qty\":0.36004071}],\"checksum\":2830761670,\"timestamp\":\"2026-08-26T11:56:05.058834Z\"}]}"}
{"recv_ts_ns":1787745365207521073,"payload":"{\"channel\":\"book\",\"type\":\"update\",\"data\":[{\"symbol\":\"BTC/USD\",\"bids\":[],\"asks\":[{\"price\":78517.2,\"qty\":0.00000000},{\"price\":78530.6,\"qty\":0.63669479}],\"checksum\":2331747377,\"timestamp\":\"2026-08-26T11:56:05.059023Z\"}]}"}
{"recv_ts_ns":1787745365207639008,"payload":"{\"channel\":\"book\",\"type\":\"update\",\"data\":[{\"symbol\":\"BTC/USD\",\"bids\":[],\"asks\":[{\"price\":78519.7,\"qty\":0.00000000},{\"price\":78532.0,\"qty\":0.33467767},{\"price\":78520.6,\"qty\":0.16772995}],\"checksum\":3860593214,\"timestamp\":\"2026-08-26T11:56:05.059317Z\"}]}"}
{"recv_ts_ns":1787745365210111759,"payload":"{\"channel\":\"book\",\"type\":\"update\",\"data\":[{\"symbol\":\"BTC/USD\",\"bids\":[],\"asks\":[{\"price\":78516.7,\"qty\":0.01130046},{\"price\":78528.1,\"qty\":0.04603180}],\"checksum\":3574528725,\"timestamp\":\"2026-08-26T11:56:05.060004Z\"}]}"}
{"recv_ts_ns":1787745365212859016,"payload":"{\"channel\":\"book\",\"type\":\"update\",\"data\":[{\"symbol\":\"BTC/USD\",\"bids\":[],\"asks\":[{\"price\":78525.5,\"qty\":0.20394815}],\"checksum\":3574528725,\"timestamp\":\"2026-08-26T11:56:05.062153Z\"}]}"}
{"recv_ts_ns":1787745365223998489,"payload":"{\"channel\":\"book\",\"type\":\"update\",\"data\":[{\"symbol\":\"BTC/USD\",\"bids\":[],\"asks\":[{\"price\":78522.1,\"qty\":0.00000000},{\"price\":78532.0,\"qty\":0.33467767}],\"checksum\":3574528725,\"timestamp\":\"2026-08-26T11:56:05.069191Z\"}]}"}
{"recv_ts_ns":1787745365224182584,"payload":"{\"channel\":\"book\",\"type\":\"update\",\"data\":[{\"symbol\":\"BTC/USD\",\"bids\":[],\"asks\":[{\"price\":78525.5,\"qty\":0.01292474}],\"checksum\":3574528725,\"timestamp\":\"2026-08-26T11:56:05.069649Z\"}]}"}
{"recv_ts_ns":1787745365228730857,"payload":"{\"channel\":\"book\",\"type\":\"update\",\"data\":[{\"symbol\":\"BTC/USD\",\"bids\":[],\"asks\":[{\"price\":78526.9,\"qty\":0.00000000},{\"price\":78532.5,\"qty\":0.02292044}],\"checksum\":3574528725,\"timestamp\":\"2026-08-26T11:56:05.074293Z\"}]}"}
{"recv_ts_ns":1787745365230782582,"payload":"{\"channel\":\"book\",\"type\":\"update\",\"data\":[{\"symbol\":\"BTC/USD\",\"bids\":[{\"price\":78500.4,\"qty\":1.08221041}],\"asks\":[],\"checksum\":2514297810,\"timestamp\":\"2026-08-26T11:56:05.075830Z\"}]}"}
{"recv_ts_ns":1787745365237631888,"payload":"{\"channel\":\"book\",\"type\":\"update\",\"data\":[{\"symbol\":\"BTC/USD\",\"bids\":[],\"asks\":[{\"price\":78528.1,\"qty\":0.00000000},{\"price\":78532.8,\"qty\":0.00254670}],\"checksum\":2514297810,\"timestamp\":\"2026-08-26T11:56:05.081686Z\"}]}"}
{"recv_ts_ns":1787745365242347640,"payload":"{\"channel\":\"book\",\"type\":\"update\",\"data\":[{\"symbol\":\"BTC/USD\",\"bids\":[],\"asks\":[{\"price\":78525.6,\"qty\":0.00000000},{\"price\":78534.3,\"qty\":1.45768422}],\"checksum\":2514297810,\"timestamp\":\"2026-08-26T11:56:05.082335Z\"}]}"}
{"recv_ts_ns":1787745365247528728,"payload":"{\"channel\":\"book\",\"type\":\"update\",\"data\":[{\"symbol\":\"BTC/USD\",\"bids\":[],\"asks\":[{\"price\":78527.5,\"qty\":0.63672004}],\"checksum\":2514297810,\"timestamp\":\"2026-08-26T11:56:05.086851Z\"}]}"}
{"recv_ts_ns":1787745365247879242,"payload":"{\"channel\":\"book\",\"type\":\"update\",\"data\":[{\"symbol\":\"BTC/USD\",\"bids\":[],\"asks\":[{\"price\":78520.6,\"qty\":0.01488201},{\"price\":78526.9,\"qty\":0.15284794}],\"checksum\":2514297810,\"timestamp\":\"2026-08-26T11:56:05.088810Z\"}]}"}
{"recv_ts_ns":1787745365247913813,"payload":"{\"channel\":\"book\",\"type\":\"update\",\"data\":[{\"symbol\":\"BTC/USD\",\"bids\":[{\"price\":78495.8,\"qty\":0.00000000},{\"price\":78483.5,\"qty\":1.27373954},{\"price\":78500.6,\"qty\":5.44581028}],\"asks\":[],\"checksum\":3134831705,\"timestamp\":\"2026-08-26T11:56:05.089321Z\"}]}"}
{"recv_ts_ns":1787745365257916528,"payload":"{\"channel\":\"book\",\"type\":\"update\",\"data\":[{\"symbol\":\"BTC/USD\",\"bids\":[{\"price\":78500.4,\"qty\":0.53859879}],\"asks\":[],\"checksum\":1925110775,\"timestamp\":\"2026-08-26T11:56:05.092307Z\"}]}"}
{"recv_ts_ns":1787745365257963262,"payload":"{\"channel\":\"book\",\"type\":\"update\",\"data\":[{\"symbol\":\"BTC/USD\",\"bids\":[],\"asks\":[{\"price\":78526.9,\"qty\":0.60727465}],\"checksum\":1925110775,\"timestamp\":\"2026-08-26T11:56:05.096466Z\"}]}"}
{"recv_ts_ns":1787745365257985358,"payload":"{\"channel\":\"book\",\"type\":\"update\",\"data\":[{\"symbol\":\"BTC/USD\",\"bids\":[{\"price\":78483.6,\"qty\":0.00000000},{\"price\":78482.7,\"qty\":0.00005000},{\"price\":78492.3,\"qty\":1.27401795}],\"asks\":[],\"checksum\":1925110775,\"timestamp\":\"2026-08-26T11:56:05.097075Z\"}]}"}
{"recv_ts_ns":1787745365259854361,"payload":"{\"channel\":\"book\",\"type\":\"update\",\"data\":[{\"symbol\":\"BTC/USD\",\"bids\":[{\"price\":78483.7,\"qty\":0.00000000},{\"price\":78482.7,\"qty\":0.00005000}],\"asks\":[],\"checksum\":1,\"timestamp\":\"2026-08-26T11:56:05.100341Z\"}]}"}
{"recv_ts_ns":1787745365259898986,"payload":"{\"channel\":\"book\",\"type\":\"update\",\"data\":[{\"symbol\":\"BTC/USD\",\"bids\":[{\"price\":78493.7,\"qty\":0.11746703}],\"asks\":[],\"checksum\":1925110775,\"timestamp\":\"2026-08-26T11:56:05.100504Z\"}]}"}
{"recv_ts_ns":1787745365259921857,"payload":"{\"channel\":\"book\",\"type\":\"update\",\"data\":[{\"symbol\":\"BTC/USD\",\"bids\":[],\"asks\":[{\"price\":78527.5,\"qty\":0.00000000},{\"price\":78532.8,\"qty\":0.00254670}],\"checksum\":1925110775,\"timestamp\":\"2026-08-26T11:56:05.100680Z\"}]}"}
{"recv_ts_ns":1787745365259948527,"payload":"{\"channel\":\"book\",\"type\":\"update\",\"data\":[{\"symbol\":\"BTC/USD\",\"bids\":[{\"price\":78493.7,\"qty\":0.00000000},{\"price\":78482.5,\"qty\":0.01163107}],\"asks\":[],\"checksum\":1925110775,\"timestamp\":\"2026-08-26T11:56:05.101307Z\"}]}"}
{"recv_ts_ns":1787745365259975408,"payload":"{\"channel\":\"book\",\"type\":\"update\",\"data\":[{\"symbol\":\"BTC/USD\",\"bids\":[],\"asks\":[{\"price\":78526.9,\"qty\":1.23802180}],\"checksum\":1925110775,\"timestamp\":\"2026-08-26T11:56:05.101454Z\"}]}"}
{"recv_ts_ns":1787745365266553534,"payload":"{\"channel\":\"book\",\"type\":\"update\",\"data\":[{\"symbol\":\"BTC/USD\",\"bids\":[],\"asks\":[{\"price\":78526.9,\"qty\":0.78359509}],\"checksum\":1925110775,\"timestamp\":\"2026-08-26T11:56:05.103739Z\"}]}"}
{"recv_ts_ns":1787745365266633394,"payload":"{\"channel\":\"book\",\"type\":\"update\",\"data\":[{\"symbol\":\"BTC/USD\",\"bids\":[],\"asks\":[{\"price\":78526.9,\"qty\":1.22428131}],\"checksum\":1925110775,\"timestamp\":\"2026-08-26T11:56:05.103925Z\"}]}"}
{"recv_ts_ns":1787745365266685461,"payload":"{\"channel\":\"book\",\"type\":\"update\",\"data\":[{\"symbol\":\"BTC/USD\",\"bids\":[],\"asks\":[{\"price\":78526.9,\"qty\":0.59353416}],\"checksum\":1925110775,\"timestamp\":\"2026-08-26T11:56:05.103939Z\"}]}"}
{"recv_ts_ns":1787745365266728022,"payload":"{\"channel\":\"book\",\"type\":\"update\",\"data\":[{\"symbol\":\"BTC/USD\",\"bids\":[{\"price\":78483.5,\"qty\":0.00000000},{\"price\":78481.8,\"qty\":0.79750411},{\"price\":78490.2,\"qty\":1.27366714}],\"asks\":[],\"checksum\":1925110775,\"timestamp\":\"2026-08-26T11:56:05.104068Z\"}]}"}
{"recv_ts_ns":1787745365266784216,"payload":"{\"channel\":\"book\",\"type\":\"update\",\"data\":[{\"symbol\":\"BTC/USD\",\"bids\":[],\"asks\":[{\"price\":78527.0,\"qty\":0.00000000},{\"price\":78534.3,\"qty\":1.45768422},{\"price\":78530.4,\"qty\":1.27366714}],\"checksum\":1925110775,\"timestamp\":\"2026-08-26T11:56:05.104093Z\"}]}"}
{"recv_ts_ns":1787745365266835666,"payload":"{\"channel\":\"book\",\"type\":\"update\",\"data\":[{\"symbol\":\"BTC/USD\",\"bids\":[],\"asks\":[{\"price\":78516.7,\"qty\":0.00000000},{\"price\":78534.3,\"qty\":1.45768422}],\"checksum\":3714382407,\"timestamp\":\"2026-08-26T11:56:05.105584Z\"}]}"}
{"recv_ts_ns":1787745365266870100,"payload":"{\"channel\":\"book\",\"type\":\"update\",\"data\":[{\"symbol\":\"BTC/USD\",\"bids\":[],\"asks\":[{\"price\":78528.5,\"qty\":0.00021200}],\"checksum\":3714382407,\"timestamp\":\"2026-08-26T11:56:05.105679Z\"}]}"}
{"recv_ts_ns":1787745365272912132,"payload":"{\"channel\":\"book\",\"type\":\"update\",\"data\":[{\"symbol\":\"BTC/USD\",\"bids\":[{\"price\":78485.0,\"qty\":0.01780582}],\"asks\":[],\"checksum\":3714382407,\"timestamp\":\"2026-08-26T11:56:05.108691Z\"}]}"}
{"recv_ts_ns":1787745365272982216,"payload":"{\"channel\":\"book\",\"type\":\"update\",\"data\":[{\"symbol\":\"BTC/USD\",\"bids\":[],\"asks\":[{\"price\":78522.3,\"qty\":0.00000000},{\"price\":78534.4,\"qty\":3.03201003}],\"checksum\":3714382407,\"timestamp\":\"2026-08-26T11:56:05.111536Z\"}]}"}
{"recv_ts_ns":1787745365275890250,"payload":"{\"channel\":\"book\",\"type\":\"update\",\"data\":[{\"symbol\":\"BTC/USD\",\"bids\":[{\"price\":78495.4,\"qty\":0.00000000},{\"price\":78482.5,\"qty\":0.01163107},{\"price\":78500.6,\"qty\":5.45854903}],\"asks\":[],\"checksum\":833527504,\"timestamp\":\"2026-08-26T11:56:05.112174Z\"}]}"}
{"recv_ts_ns":1787745365276030070,"payload":"{\"channel\":\"book\",\"type\":\"update\",\"data\":[{\"symbol\":\"BTC/USD\",\"bids\":[],\"asks\":[{\"price\":78520.6,\"qty\":0.00000000},{\"price\":78535.1,\"qty\":0.00005000}],\"checksum\":2977671535,\"timestamp\":\"2026-08-26T11:56:05.113153Z\"}]}"}
{"recv_ts_ns":1787745365276383340,"payload":"{\"channel\":\"book\",\"type\":\"update\",\"data\":[{\"symbol\":\"BTC/USD\",\"bids\":[],\"asks\":[{\"price\":78526.9,\"qty\":0.44068622},{\"price\":78529.3,\"qty\":0.26649071}],\"checksum\":2977671535,\"timestamp\":\"2026-08-26T11:56:05.114960Z\"}]}"}
{"recv_ts_ns":1787745365279284629,"payload":"{\"channel\":\"book\",\"type\":\"update\",\"data\":[{\"symbol\":\"BTC/USD\",\"bids\":[],\"asks\":[{\"price\":78506.4,\"qty\":0.00000000},{\"price\":78535.2,\"qty\":0.63665790}],\"checksum\":433110878,\"timestamp\":\"2026-08-26T11:56:05.115847Z\"}]}"}
{"recv_ts_ns":1787745365282282899,"payload":"{\"channel\":\"book\",\"type\":\"update\",\"data\":[{\"symbol\":\"BTC/USD\",\"bids\":[{\"price\":78493.7,\"qty\":0.49786278}],\"asks\":[],\"checksum\":433110878,\"timestamp\":\"2026-08-26T11:56:05.117240Z\"}]}"}
{"recv_ts_ns":1787745365282402122,"payload":"{\"channel\":\"book\",\"type\":\"update\",\"data\":[{\"symbol\":\"BTC/USD\",\"bids\":[],\"asks\":[{\"price\":78511.5,\"qty\":0.01565551}],\"checksum\":4004833155,\"timestamp\":\"2026-08-26T11:56:05.118590Z\"}]}"}
{"recv_ts_ns":1787745365285002582,"payload":"{\"channel\":\"book\",\"type\":\"update\",\"data\":[{\"symbol\":\"BTC/USD\",\"bids\":[{\"price\":78490.4,\"qty\":0.87772532}],\"asks\":[],\"checksum\":4004833155,\"timestamp\":\"2026-08-26T11:56:05.119632Z\"}]}"}
{"recv_ts_ns":1787745365290063006,"payload":"{\"channel\":\"book\",\"type\":\"update\",\"data\":[{\"symbol\":\"BTC/USD\",\"bids\":[],\"asks\":[{\"price\":78526.9,\"qty\":0.00000000},{\"price\":78535.2,\"qty\":0.63665790}],\"checksum\":4004833155,\"timestamp\":\"2026-08-26T11:56:05.125339Z\"}]}"}
{"recv_ts_ns":1787745365290194894,"payload":"{\"channel\":\"book\",\"type\":\"update\",\"data\":[{\"symbol\":\"BTC/USD\",\"bids\":[],\"asks\":[{\"price\":78529.2,\"qty\":0.45973712}],\"checksum\":4004833155,\"timestamp\":\"2026-08-26T11:56:05.126565Z\"}]}"}
{"recv_ts_ns":1787745365290247304,"payload":"{\"channel\":\"book\",\"type\":\"update\",\"data\":[{\"symbol\":\"BTC/USD\",\"bids\":[{\"price\":78489.0,\"qty\":0.00254813}],\"asks\":[],\"checksum\":4004833155,\"timestamp\":\"2026-08-26T11:56:05.126874Z\"}]}"}
{"recv_ts_ns":1787745365298894686,"payload":"{\"channel\":\"book\",\"type\":\"update\",\"data\":[{\"symbol\":\"BTC/USD\",\"bids\":[],\"asks\":[{\"price\":78511.5,\"qty\":0.00000000},{\"price\":78535.2,\"qty\":0.63665790}],\"checksum\":433110878,\"timestamp\":\"2026-08-26T11:56:05.146045Z\"}]}"}
{"recv_ts_ns":1787745365298987712,"payload":"{\"channel\":\"book\",\"type\":\"update\",\"data\":[{\"symbol\":\"BTC/USD\",\"bids\":[],\"asks\":[{\"price\":78506.7,\"qty\":0.01565551}],\"checksum\":1770660841,\"timestamp\":\"2026-08-26T11:56:05.146055Z\"}]}"}
{"recv_ts_ns":1787745365318201090,"payload":"{\"channel\":\"book\",\"type\":\"update\",\"data\":[{\"symbol\":\"BTC/USD\",\"bids\":[],\"asks\":[{\"price\":78521.8,\"qty\":0.95543056}],\"checksum\":796840577,\"timestamp\":\"2026-08-26T11:56:05.170951Z\"}]}"}
{"recv_ts_ns":1787745365319253747,"payload":"{\"channel\":\"book\",\"type\":\"update\",\"data\":[{\"symbol\":\"BTC/USD\",\"bids\":[],\"asks\":[{\"price\":78529.3,\"qty\":0.11364277},{\"price\":78529.2,\"qty\":0.61258506}],\"checksum\":796840577,\"timestamp\":\"2026-08-26T11:56:05.173266Z\"}]}"}
{"recv_ts_ns":1787745365323891718,"payload":"{\"channel\":\"book\",\"type\":\"update\",\"data\":[{\"symbol\":\"BTC/USD\",\"bids\":[],\"asks\":[{\"price\":78528.5,\"qty\":0.00000000},{\"price\":78535.1,\"qty\":0.00005000}],\"checksum\":796840577,\"timestamp\":\"2026-08-26T11:56:05.175035Z\"}]}"}
{"recv_ts_ns":1787745365324907572,"payload":"{\"channel\":\"book\",\"type\":\"update\",\"data\":[{\"symbol\":\"BTC/USD\",\"bids\":[],\"asks\":[{\"price\":78521.8,\"qty\":0.00000000},{\"price\":78535.2,\"qty\":0.63665790}],\"checksum\":1770660841,\"timestamp\":\"2026-08-26T11:56:05.176777Z\"}]}"}
{"recv_ts_ns":1787745365364460083,"payload":"{\"channel\":\"book\",\"type\":\"update\",\"data\":[{\"symbol\":\"BTC/USD\",\"bids\":[],\"asks\":[{\"price\":78521.0,\"qty\":0.95543056}],\"checksum\":2824276246,\"timestamp\":\"2026-08-26T11:56:05.219841Z\"}]}"}
{"recv_ts_ns":1787745365369105750,"payload":"{\"channel\":\"book\",\"type\":\"update\",\"data\":[{\"symbol\":\"BTC/USD\",\"bids\":[{\"price\":78494.6,\"qty\":0.05301108}],\"asks\":[],\"checksum\":2824276246,\"timestamp\":\"2026-08-26T11:56:05.221084Z\"}]}"}
{"recv_ts_ns":1787745365369145333,"payload":"{\"channel\":\"book\",\"type\":\"update\",\"data\":[{\"symbol\":\"BTC/USD\",\"bids\":[],\"asks\":[{\"price\":78528.8,\"qty\":0.04603180}],\"checksum\":2824276246,\"timestamp\":\"2026-08-26T11:56:05.221553Z\"}]}"}
{"recv_ts_ns":1787745365369172566,"payload":"{\"channel\":\"book\",\"type\":\"update\",\"data\":[{\"symbol\":\"BTC/USD\",\"bids\":[],\"asks\":[{\"price\":78529.2,\"qty\":0.45973712},{\"price\":78528.9,\"qty\":0.16558210}],\"checksum\":2824276246,\"timestamp\":\"2026-08-26T11:56:05.222808Z\"}]}"}
{"recv_ts_ns":1787745365432625714,"payload":"{\"channel\":\"book\",\"type\":\"update\",\"data\":[{\"symbol\":\"BTC/USD\",\"bids\":[],\"asks\":[{\"price\":78521.0,\"qty\":0.00000000},{\"price\":78535.1,\"qty\":0.00005000}],\"checksum\":1770660841,\"timestamp\":\"2026-08-26T11:56:05.287894Z\"}]}"}
{"recv_ts_ns":1787745365448270788,"payload":"{\"channel\":\"book\",\"type\":\"update\",\"data\":[{\"symbol\":\"BTC/USD\",\"bids\":[{\"price\":78492.3,\"qty\":0.00000000},{\"price\":78484.7,\"qty\":0.05060000}],\"asks\":[],\"checksum\":1770660841,\"timestamp\":\"2026-08-26T11:56:05.303361Z\"}]}"}
{"recv_ts_ns":1787745365450165408,"payload":"{\"channel\":\"book\",\"type\":\"update\",\"data\":[{\"symbol\":\"BTC/USD\",\"bids\":[{\"price\":78493.7,\"qty\":0.00000000},{\"price\":78482.7,\"qty\":0.00005000}],\"asks\":[],\"checksum\":1770660841,\"timestamp\":\"2026-08-26T11:56:05.304882Z\"}]}"}
{"recv_ts_ns":1787745365450224473,"payload":"{\"channel\":\"book\",\"type\":\"update\",\"data\":[{\"symbol\":\"BTC/USD\",\"bids\":[{\"price\":78493.7,\"qty\":0.13451932}],\"asks\":[],\"checksum\":1770660841,\"timestamp\":\"2026-08-26T11:56:05.305347Z\"}]}"}
{"recv_ts_ns":1787745365450831124,"payload":"{\"channel\":\"book\",\"type\":\"update\",\"data\":[{\"symbol\":\"BTC/USD\",\"bids\":[{\"price\":78490.2,\"qty\":0.00000000},{\"price\":78482.7,\"qty\":0.00005000}],\"asks\":[],\"checksum\":1770660841,\"timestamp\":\"2026-08-26T11:56:05.305757Z\"}]}"}
{"recv_ts_ns":1787745365450883476,"payload":"{\"channel\":\"book\",\"type\":\"update\",\"data\":[{\"symbol\":\"BTC/USD\",\"bids\":[],\"asks\":[{\"price\":78530.4,\"qty\":0.00000000},{\"price\":78535.2,\"qty\":0.63665790}],\"checksum\":1770660841,\"timestamp\":\"2026-08-26T11:56:05.305954Z\"}]}"}
{"recv_ts_ns":1787745365452974106,"payload":"{\"channel\":\"book\",\"type\":\"update\",\"data\":[{\"symbol\":\"BTC/USD\",\"bids\":[{\"price\":78490.4,\"qty\":0.57046901}],\"asks\":[],\"checksum\":1770660841,\"timestamp\":\"2026-08-26T11:56:05.307597Z\"}]}"}
{"recv_ts_ns":1787745365453040863,"payload":"{\"channel\":\"book\",\"type\":\"update\",\"data\":[{\"symbol\":\"BTC/USD\",\"bids\":[],\"asks\":[{\"price\":78529.2,\"qty\":0.00000000},{\"price\":78536.0,\"qty\":0.01270878}],\"checksum\":1770660841,\"timestamp\":\"2026-08-26T11:56:05.307801Z\"}]}"}
{"recv_ts_ns":1787745365453791678,"payload":"{\"channel\":\"book\",\"type\":\"update\",\"data\":[{\"symbol\":\"BTC/USD\",\"bids\":[],\"asks\":[{\"price\":78528.7,\"qty\":0.09708912}],\"checksum\":1770660841,\"timestamp\":\"2026-08-26T11:56:05.308109Z\"}]}"}
{"recv_ts_ns":1787745365461572518,"payload":"{\"channel\":\"book\",\"type\":\"update\",\"data\":[{\"symbol\":\"BTC/USD\",\"bids\":[],\"asks\":[{\"price\":78534.4,\"qty\":0.00000000},{\"price\":78536.0,\"qty\":0.01270878}],\"checksum\":1770660841,\"timestamp\":\"2026-08-26T11:56:05.316912Z\"}]}"}
{"recv_ts_ns":1787745365461684724,"payload":"{\"channel\":\"book\",\"type\":\"update\",\"data\":[{\"symbol\":\"BTC/USD\",\"bids\":[{\"price\":78500.6,\"qty\":2.42715023}],\"asks\":[],\"checksum\":3026720463,\"timestamp\":\"2026-08-26T11:56:05.317225Z\"}]}"}
{"recv_ts_ns":1787745365463020553,"payload":"{\"channel\":\"book\",\"type\":\"update\",\"data\":[{\"symbol\":\"BTC/USD\",\"bids\":[],\"asks\":[{\"price\":78534.3,\"qty\":0.53736095}],\"checksum\":3026720463,\"timestamp\":\"2026-08-26T11:56:05.318193Z\"}]}"}
{"recv_ts_ns":1787745365463099487,"payload":"{\"channel\":\"book\",\"type\":\"update\",\"data\":[{\"symbol\":\"BTC/USD\",\"bids\":[],\"asks\":[{\"price\":78534.3,\"qty\":0.77152830}],\"checksum\":3026720463,\"timestamp\":\"2026-08-26T11:56:05.318529Z\"}]}"}
{"recv_ts_ns":1787745365466257807,"payload":"{\"channel\":\"book\",\"type\":\"update\",\"data\":[{\"symbol\":\"BTC/USD\",\"bids\":[],\"asks\":[{\"price\":78521.7,\"qty\":0.95543056}],\"checksum\":3520610180,\"timestamp\":\"2026-08-26T11:56:05.319882Z\"}]}"}
{"recv_ts_ns":1787745365466343029,"payload":"{\"channel\":\"book\",\"type\":\"update\",\"data\":[{\"symbol\":\"BTC/USD\",\"bids\":[],\"asks\":[{\"price\":78528.9,\"qty\":0.01273416},{\"price\":78528.8,\"qty\":0.19887974}],\"checksum\":3520610180,\"timestamp\":\"2026-08-26T11:56:05.321216Z\"}]}"}
{"recv_ts_ns":1787745365466943296,"payload":"{\"channel\":\"book\",\"type\":\"update\",\"data\":[{\"symbol\":\"BTC/USD\",\"bids\":[],\"asks\":[{\"price\":78521.6,\"qty\":0.28519602}],\"checksum\":1255268445,\"timestamp\":\"2026-08-26T11:56:05.321874Z\"}]}"}
{"recv_ts_ns":1787745365492860996,"payload":"{\"channel\":\"book\",\"type\":\"update\",\"data\":[{\"symbol\":\"BTC/USD\",\"bids\":[],\"asks\":[{\"price\":78528.8,\"qty\":0.04603180},{\"price\":78528.7,\"qty\":0.24993706}],\"checksum\":1255268445,\"timestamp\":\"2026-08-26T11:56:05.348217Z\"}]}"}
{"recv_ts_ns":1787745365496075767,"payload":"{\"channel\":\"book\",\"type\":\"update\",\"data\":[{\"symbol\":\"BTC/USD\",\"bids\":[],\"asks\":[{\"price\":78528.6,\"qty\":0.09708912}],\"checksum\":1255268445,\"timestamp\":\"2026-08-26T11:56:05.350558Z\"}]}"}
{"recv_ts_ns":1787745365496202595,"payload":"{\"channel\":\"book\",\"type\":\"update\",\"data\":[{\"symbol\":\"BTC/USD\",\"bids\":[],\"asks\":[{\"price\":78528.7,\"qty\":0.15284794}],\"checksum\":1255268445,\"timestamp\":\"2026-08-26T11:56:05.350619Z\"}]}"}
{"recv_ts_ns":1787745365498994602,"payload":"{\"channel\":\"book\",\"type\":\"update\",\"data\":[{\"symbol\":\"BTC/USD\",\"bids\":[{\"price\":78490.0,\"qty\":0.04048246}],\"asks\":[],\"checksum\":1255268445,\"timestamp\":\"2026-08-26T11:56:05.351406Z\"}]}"}
{"recv_ts_ns":1787745365530477748,"payload":"{\"channel\":\"book\",\"type\":\"update\",\"data\":[{\"symbol\":\"BTC/USD\",\"bids\":[{\"price\":78493.8,\"qty\":1.27399360}],\"asks\":[],\"checksum\":1255268445,\"timestamp\":\"2026-08-26T11:56:05.382376Z\"}]}"}
{"recv_ts_ns":1787745365530636187,"payload":"{\"channel\":\"book\",\"type\":\"update\",\"data\":[{\"symbol\":\"BTC/USD\",\"bids\":[],\"asks\":[{\"price\":78528.7,\"qty\":0.00000000},{\"price\":78535.1,\"qty\":0.00005000},{\"price\":78528.6,\"qty\":0.24993706}],\"checksum\":1255268445,\"timestamp\":\"2026-08-26T11:56:05.383822Z\"}]}"}
{"recv_ts_ns":1787745365530783937,"payload":"{\"channel\":\"book\",\"type\":\"update\",\"data\":[{\"symbol\":\"BTC/USD\",\"bids\":[{\"price\":78493.7,\"qty\":0.00000000},{\"price\":78484.7,\"qty\":0.05060000}],\"asks\":[],\"checksum\":1255268445,\"timestamp\":\"2026-08-26T11:56:05.384013Z\"}]}"}
{"recv_ts_ns":1787745365530844455,"payload":"{\"channel\":\"book\",\"type\":\"update\",\"data\":[{\"symbol\":\"BTC/USD\",\"bids\":[{\"price\":78493.9,\"qty\":0.51480641}],\"asks\":[],\"checksum\":1255268445,\"timestamp\":\"2026-08-26T11:56:05.384025Z\"}]}"}
{"recv_ts_ns":1787745365530893463,"payload":"{\"channel\":\"book\",\"type\":\"update\",\"data\":[{\"symbol\":\"BTC/USD\",\"bids\":[],\"asks\":[{\"price\":78528.8,\"qty\":0.00000000},{\"price\":78535.2,\"qty\":0.63665790},{\"price\":78528.5,\"qty\":0.04603180}],\"checksum\":1255268445,\"timestamp\":\"2026-08-26T11:56:05.384202Z\"}]}"}
{"recv_ts_ns":1787745365531138102,"payload":"{\"channel\":\"book\",\"type\":\"update\",\"data\":[{\"symbol\":\"BTC/USD\",\"bids\":[],\"asks\":[{\"price\":78528.6,\"qty\":0.15284794}],\"checksum\":1255268445,\"timestamp\":\"2026-08-26T11:56:05.385904Z\"}]}"}
{"recv_ts_ns":1787745365532081340,"payload":"{\"channel\":\"book\",\"type\":\"update\",\"data\":[{\"symbol\":\"BTC/USD\",\"bids\":[],\"asks\":[{\"price\":78534.3,\"qty\":0.50284782}],\"checksum\":1255268445,\"timestamp\":\"2026-08-26T11:56:05.386747Z\"}]}"}
{"recv_ts_ns":1787745365538872410,"payload":"{\"channel\":\"book\",\"type\":\"update\",\"data\":[{\"symbol\":\"BTC/USD\",\"bids\":[],\"asks\":[{\"price\":78528.5,\"qty\":0.14312092}],\"checksum\":1255268445,\"timestamp\":\"2026-08-26T11:56:05.392098Z\"}]}"}
{"recv_ts_ns":1787745365556694594,"payload":"{\"channel\":\"book\",\"type\":\"update\",\"data\":[{\"symbol\":\"BTC/USD\",\"bids\":[{\"price\":78500.6,\"qty\":5.45846365}],\"asks\":[],\"checksum\":2718232341,\"timestamp\":\"2026-08-26T11:56:05.410805Z\"}]}"}
{"recv_ts_ns":1787745365557935969,"payload":"{\"channel\":\"book\",\"type\":\"update\",\"data\":[{\"symbol\":\"BTC/USD\",\"bids\":[],\"asks\":[{\"price\":78528.6,\"qty\":0.00000000},{\"price\":78535.2,\"qty\":0.63665790},{\"price\":78528.5,\"qty\":0.29596886}],\"checksum\":2718232341,\"timestamp\":\"2026-08-26T11:56:05.412418Z\"}]}"}
{"recv_ts_ns":1787745365561465500,"payload":"{\"channel\":\"book\",\"type\":\"update\",\"data\":[{\"symbol\":\"BTC/USD\",\"bids\":[],\"asks\":[{\"price\":78534.3,\"qty\":1.37775704}],\"checksum\":2718232341,\"timestamp\":\"2026-08-26T11:56:05.416080Z\"}]}"}
{"recv_ts_ns":1787745365562172102,"payload":"{\"channel\":\"book\",\"type\":\"update\",\"data\":[{\"symbol\":\"BTC/USD\",\"bids\":[],\"asks\":[{\"price\":78528.5,\"qty\":0.19887974}],\"checksum\":2718232341,\"timestamp\":\"2026-08-26T11:56:05.416285Z\"}]}"}
{"recv_ts_ns":1787745365565026384,"payload":"{\"channel\":\"book\",\"type\":\"update\",\"data\":[{\"symbol\":\"BTC/USD\",\"bids\":[],\"asks\":[{\"price\":78528.4,\"qty\":0.09708912}],\"checksum\":2718232341,\"timestamp\":\"2026-08-26T11:56:05.416602Z\"}]}"}
{"recv_ts_ns":1787745365574416100,"payload":"{\"channel\":\"book\",\"type\":\"update\",\"data\":[{\"symbol\":\"BTC/USD\",\"bids\":[],\"asks\":[{\"price\":78531.3,\"qty\":0.11005500}],\"checksum\":2718232341,\"timestamp\":\"2026-08-26T11:56:05.427356Z\"}]}"}
{"recv_ts_ns":1787745365583068192,"payload":"{\"channel\":\"book\",\"type\":\"update\",\"data\":[{\"symbol\":\"BTC/USD\",\"bids\":[],\"asks\":[{\"price\":78523.5,\"qty\":0.85606579}],\"checksum\":2718232341,\"timestamp\":\"2026-08-26T11:56:05.436609Z\"}]}"}
{"recv_ts_ns":1787745365583206782,"payload":"{\"channel\":\"book\",\"type\":\"update\",\"data\":[{\"symbol\":\"BTC/USD\",\"bids\":[],\"asks\":[{\"price\":78521.7,\"qty\":0.00000000},{\"price\":78534.3,\"qty\":1.37775704}],\"checksum\":2718232341,\"timestamp\":\"2026-08-26T11:56:05.436662Z\"}]}"}
{"recv_ts_ns":1787745365583290072,"payload":"{\"channel\":\"book\",\"type\":\"update\",\"data\":[{\"symbol\":\"BTC/USD\",\"bids\":[],\"asks\":[{\"price\":78528.5,\"qty\":0.04603180},{\"price\":78528.2,\"qty\":0.20344794}],\"checksum\":2718232341,\"timestamp\":\"2026-08-26T11:56:05.437960Z\"}]}"}
{"recv_ts_ns":1787745365583344833,"payload":"{\"channel\":\"book\",\"type\":\"update\",\"data\":[{\"symbol\":\"BTC/USD\",\"bids\":[],\"asks\":[{\"price\":78523.4,\"qty\":0.26035160}],\"checksum\":2718232341,\"timestamp\":\"2026-08-26T11:56:05.438136Z\"}]}"}
{"recv_ts_ns":1787745365586069083,"payload":"{\"channel\":\"book\",\"type\":\"update\",\"data\":[{\"symbol\":\"BTC/USD\",\"bids\":[],\"asks\":[{\"price\":78521.6,\"qty\":0.00000000},{\"price\":78534.3,\"qty\":1.37775704}],\"checksum\":2955405564,\"timestamp\":\"2026-08-26T11:56:05.438584Z\"}]}"}
{"recv_ts_ns":1787745365586245944,"payload":"{\"channel\":\"book\",\"type\":\"update\",\"data\":[{\"symbol\":\"BTC/USD\",\"bids\":[],\"asks\":[{\"price\":78528.4,\"qty\":0.00000000},{\"price\":78535.1,\"qty\":0.00005000}],\"checksum\":2955405564,\"timestamp\":\"2026-08-26T11:56:05.439538Z\"}]}"}
{"recv_ts_ns":1787745365586334966,"payload":"{\"channel\":\"book\",\"type\":\"update\",\"data\":[{\"symbol\":\"BTC/USD\",\"bids\":[],\"asks\":[{\"price\":78528.1,\"qty\":0.11219322}],\"checksum\":2955405564,\"timestamp\":\"2026-08-26T11:56:05.439578Z\"}]}"}
{"recv_ts_ns":1787745365599834879,"payload":"{\"channel\":\"book\",\"type\":\"update\",\"data\":[{\"symbol\":\"BTC/USD\",\"bids\":[],\"asks\":[{\"price\":78530.3,\"qty\":1.27365829}],\"checksum\":2955405564,\"timestamp\":\"2026-08-26T11:56:05.452165Z\"}]}"}
{"recv_ts_ns":1787745365599966813,"payload":"{\"channel\":\"book\",\"type\":\"update\",\"data\":[{\"symbol\":\"BTC/USD\",\"bids\":[{\"price\":78490.5,\"qty\":1.27365829}],\"asks\":[],\"checksum\":2955405564,\"timestamp\":\"2026-08-26T11:56:05.452225Z\"}]}"}
{"recv_ts_ns":1787745365600028232,"payload":"{\"channel\":\"book\",\"type\":\"update\",\"data\":[{\"symbol\":\"BTC/USD\",\"bids\":[],\"asks\":[{\"price\":78528.1,\"qty\":0.47803653}],\"checksum\":2955405564,\"timestamp\":\"2026-08-26T11:56:05.453883Z\"}]}"}
{"recv_ts_ns":1787745365616328550,"payload":"{\"channel\":\"book\",\"type\":\"update\",\"data\":[{\"symbol\":\"BTC/USD\",\"bids\":[],\"asks\":[{\"price\":78521.6,\"qty\":0.95543056}],\"checksum\":2313349574,\"timestamp\":\"2026-08-26T11:56:05.470618Z\"}]}"}
{"recv_ts_ns":1787745365618231173,"payload":"{\"channel\":\"book\",\"type\":\"update\",\"data\":[{\"symbol\":\"BTC/USD\",\"bids\":[],\"asks\":[{\"price\":78528.2,\"qty\":0.05060000},{\"price\":78528.0,\"qty\":0.15284794}],\"checksum\":2313349574,\"timestamp\":\"2026-08-26T11:56:05.472014Z\"}]}"}
{"recv_ts_ns":1787745365619318128,"payload":"{\"channel\":\"book\",\"type\":\"update\",\"data\":[{\"symbol\":\"BTC/USD\",\"bids\":[],\"asks\":[{\"price\":78521.5,\"qty\":0.28519602}],\"checksum\":2823127626,\"timestamp\":\"2026-08-26T11:56:05.472592Z\"}]}"}
{"recv_ts_ns":1787745365672087286,"payload":"{\"channel\":\"book\",\"type\":\"update\",\"data\":[{\"symbol\":\"BTC/USD\",\"bids\":[],\"asks\":[{\"price\":78521.6,\"qty\":0.00000000},{\"price\":78532.0,\"qty\":0.33467767}],\"checksum\":2823127626,\"timestamp\":\"2026-08-26T11:56:05.525279Z\"}]}"}
{"recv_ts_ns":1787745365672239441,"payload":"{\"channel\":\"book\",\"type\":\"update\",\"data\":[{\"symbol\":\"BTC/USD\",\"bids\":[],\"asks\":[{\"price\":78521.5,\"qty\":0.00000000},{\"price\":78532.5,\"qty\":0.02292044}],\"checksum\":2955405564,\"timestamp\":\"2026-08-26T11:56:05.526486Z\"}]}"}
{"recv_ts_ns":1787745365687330262,"payload":"{\"channel\":\"book\",\"type\":\"update\",\"data\":[{\"symbol\":\"BTC/USD\",\"bids\":[],\"asks\":[{\"price\":78528.0,\"qty\":0.00000000},{\"price\":78532.8,\"qty\":0.00254670},{\"price\":78525.7,\"qty\":0.15605709}],\"checksum\":2955405564,\"timestamp\":\"2026-08-26T11:56:05.526498Z\"}]}"}
{"recv_ts_ns":1787745365687461377,"payload":"{\"channel\":\"book\",\"type\":\"update\",\"data\":[{\"symbol\":\"BTC/USD\",\"bids\":[],\"asks\":[{\"price\":78528.5,\"qty\":0.00000000},{\"price\":78534.3,\"qty\":1.37775704},{\"price\":78528.8,\"qty\":0.04603180}],\"checksum\":2955405564,\"timestamp\":\"2026-08-26T11:56:05.526583Z\"}]}"}
{"recv_ts_ns":1787745365720475760,"payload":"{\"channel\":\"book\",\"type\":\"update\",\"data\":[{\"symbol\":\"BTC/USD\",\"bids\":[],\"asks\":[{\"price\":78520.8,\"qty\":0.95543056}],\"checksum\":4197248552,\"timestamp\":\"2026-08-26T11:56:05.571005Z\"}]}"}
{"recv_ts_ns":1787745365720655076,"payload":"{\"channel\":\"book\",\"type\":\"update\",\"data\":[{\"symbol\":\"BTC/USD\",\"bids\":[],\"asks\":[{\"price\":78532.0,\"qty\":0.00000000},{\"price\":78532.8,\"qty\":0.00254670}],\"checksum\":4197248552,\"timestamp\":\"2026-08-26T11:56:05.571289Z\"}]}"}
{"recv_ts_ns":1787745365720793838,"payload":"{\"channel\":\"book\",\"type\":\"update\",\"data\":[{\"symbol\":\"BTC/USD\",\"bids\":[],\"asks\":[{\"price\":78520.2,\"qty\":0.00000000},{\"price\":78534.3,\"qty\":1.37775704}],\"checksum\":77108629,\"timestamp\":\"2026-08-26T11:56:05.571446Z\"}]}"}
{"recv_ts_ns":1787745365720884269,"payload":"{\"channel\":\"book\",\"type\":\"update\",\"data\":[{\"symbol\":\"BTC/USD\",\"bids\":[],\"asks\":[{\"price\":78525.7,\"qty\":0.00320915},{\"price\":78528.0,\"qty\":0.15284794}],\"checksum\":77108629,\"timestamp\":\"2026-08-26T11:56:05.572253Z\"}]}"}
{"recv_ts_ns":1787745365725496307,"payload":"{\"channel\":\"book\",\"type\":\"update\",\"data\":[{\"symbol\":\"BTC/USD\",\"bids\":[],\"asks\":[{\"price\":78520.7,\"qty\":0.28519602}],\"checksum\":1518803698,\"timestamp\":\"2026-08-26T11:56:05.577189Z\"}]}"}
{"recv_ts_ns":1787745365733263845,"payload":"{\"channel\":\"book\",\"type\":\"update\",\"data\":[{\"symbol\":\"BTC/USD\",\"bids\":[],\"asks\":[{\"price\":78520.7,\"qty\":0.00000000},{\"price\":78532.8,\"qty\":0.00254670}],\"checksum\":77108629,\"timestamp\":\"2026-08-26T11:56:05.588078Z\"}]}"}
{"recv_ts_ns":1787745365793987640,"payload":"{\"channel\":\"book\",\"type\":\"update\",\"data\":[{\"symbol\":\"BTC/USD\",\"bids\":[],\"asks\":[{\"price\":78520.8,\"qty\":0.00000000},{\"price\":78534.3,\"qty\":1.37775704}],\"checksum\":2368775477,\"timestamp\":\"2026-08-26T11:56:05.648112Z\"}]}"}
{"recv_ts_ns":1787745365808818442,"payload":"{\"channel\":\"book\",\"type\":\"update\",\"data\":[{\"symbol\":\"BTC/USD\",\"bids\":[],\"asks\":[{\"price\":78530.6,\"qty\":0.00000000},{\"price\":78535.1,\"qty\":0.00005000}],\"checksum\":2368775477,\"timestamp\":\"2026-08-26T11:56:05.663303Z\"}]}"}
{"recv_ts_ns":1787745365809898846,"payload":"{\"channel\":\"book\",\"type\":\"update\",\"data\":[{\"symbol\":\"BTC/USD\",\"bids\":[],\"asks\":[{\"price\":78530.5,\"qty\":0.48069519}],\"checksum\":2368775477,\"timestamp\":\"2026-08-26T11:56:05.664699Z\"}]}"}
{"recv_ts_ns":1787745365812638193,"payload":"{\"channel\":\"book\",\"type\":\"update\",\"data\":[{\"symbol\":\"BTC/USD\",\"bids\":[],\"asks\":[{\"price\":78530.5,\"qty\":0.12065448}],\"checksum\":2368775477,\"timestamp\":\"2026-08-26T11:56:05.664835Z\"}]}"}
{"recv_ts_ns":1787745365812795546,"payload":"{\"channel\":\"book\",\"type\":\"update\",\"data\":[{\"symbol\":\"BTC/USD\",\"bids\":[],\"asks\":[{\"price\":78526.3,\"qty\":0.63673013}],\"checksum\":2368775477,\"timestamp\":\"2026-08-26T11:56:05.664868Z\"}]}"}
{"recv_ts_ns":1787745365812861374,"payload":"{\"channel\":\"book\",\"type\":\"update\",\"data\":[{\"symbol\":\"BTC/USD\",\"bids\":[],\"asks\":[{\"price\":78523.4,\"qty\":0.41713011}],\"checksum\":3039218975,\"timestamp\":\"2026-08-26T11:56:05.666600Z\"}]}"}
{"recv_ts_ns":1787745365815971929,"payload":"{\"channel\":\"book\",\"type\":\"update\",\"data\":[{\"symbol\":\"BTC/USD\",\"bids\":[],\"asks\":[{\"price\":78521.6,\"qty\":0.95543056}],\"checksum\":1412474259,\"timestamp\":\"2026-08-26T11:56:05.670606Z\"}]}"}
{"recv_ts_ns":1787745365816828198,"payload":"{\"channel\":\"book\",\"type\":\"update\",\"data\":[{\"symbol\":\"BTC/USD\",\"bids\":[],\"asks\":[{\"price\":78528.0,\"qty\":0.00000000},{\"price\":78534.3,\"qty\":1.37775704},{\"price\":78526.2,\"qty\":0.15284794}],\"checksum\":1412474259,\"timestamp\":\"2026-08-26T11:56:05.671987Z\"}]}"}
{"recv_ts_ns":1787745365819279884,"payload":"{\"channel\":\"book\",\"type\":\"update\",\"data\":[{\"symbol\":\"BTC/USD\",\"bids\":[],\"asks\":[{\"price\":78521.5,\"qty\":0.28519602}],\"checksum\":1368297202,\"timestamp\":\"2026-08-26T11:56:05.672648Z\"}]}"}
{"recv_ts_ns":1787745365860524975,"payload":"{\"channel\":\"book\",\"type\":\"update\",\"data\":[{\"symbol\":\"BTC/USD\",\"bids\":[{\"price\":78493.0,\"qty\":0.00010100}],\"asks\":[],\"checksum\":1368297202,\"timestamp\":\"2026-08-26T11:56:05.715473Z\"}]}"}
{"recv_ts_ns":1787745365864118915,"payload":"{\"channel\":\"book\",\"type\":\"update\",\"data\":[{\"symbol\":\"BTC/USD\",\"bids\":[],\"asks\":[{\"price\":78526.2,\"qty\":0.00000000},{\"price\":78532.8,\"qty\":0.00254670},{\"price\":78525.7,\"qty\":0.15605709}],\"checksum\":1368297202,\"timestamp\":\"2026-08-26T11:56:05.716790Z\"}]}"}
{"recv_ts_ns":1787745365864209495,"payload":"{\"channel\":\"book\",\"type\":\"update\",\"data\":[{\"symbol\":\"BTC/USD\",\"bids\":[],\"asks\":[{\"price\":78528.8,\"qty\":0.00000000},{\"price\":78534.3,\"qty\":1.37775704},{\"price\":78528.0,\"qty\":0.04603180}],\"checksum\":1368297202,\"timestamp\":\"2026-08-26T11:56:05.716883Z\"}]}"}
{"recv_ts_ns":1787745365872365253,"payload":"{\"channel\":\"book\",\"type\":\"update\",\"data\":[{\"symbol\":\"BTC/USD\",\"bids\":[],\"asks\":[{\"price\":78530.5,\"qty\":0.00000000},{\"price\":78534.3,\"qty\":1.10907657}],\"checksum\":1368297202,\"timestamp\":\"2026-08-26T11:56:05.727933Z\"}]}"}
{"recv_ts_ns":1787745365875221664,"payload":"{\"channel\":\"book\",\"type\":\"update\",\"data\":[{\"symbol\":\"BTC/USD\",\"bids\":[],\"asks\":[{\"price\":78531.2,\"qty\":0.04045336}],\"checksum\":1368297202,\"timestamp\":\"2026-08-26T11:56:05.730428Z\"}]}"}
{"recv_ts_ns":1787745365928509076,"payload":"{\"channel\":\"heartbeat\"}"}
{"recv_ts_ns":1787745365958568400,"payload":"{\"channel\":\"book\",\"type\":\"update\",\"data\":[{\"symbol\":\"BTC/USD\",\"bids\":[],\"asks\":[{\"price\":78530.3,\"qty\":0.00000000},{\"price\":78534.3,\"qty\":1.10907657},{\"price\":78534.2,\"qty\":1.27365770}],\"checksum\":1368297202,\"timestamp\":\"2026-08-26T11:56:05.812679Z\"}]}"}
{"recv_ts_ns":1787745365958789614,"payload":"{\"channel\":\"book\",\"type\":\"update\",\"data\":[{\"symbol\":\"BTC/USD\",\"bids\":[],\"asks\":[{\"price\":78528.1,\"qty\":0.36584331}],\"checksum\":1368297202,\"timestamp\":\"2026-08-26T11:56:05.813936Z\"}]}"}
{"recv_ts_ns":1787745365959286109,"payload":"{\"channel\":\"book\",\"type\":\"update\",\"data\":[{\"symbol\":\"BTC/USD\",\"bids\":[],\"asks\":[{\"price\":78528.1,\"qty\":0.00000000},{\"price\":78534.3,\"qty\":1.10907657}],\"checksum\":1368297202,\"timestamp\":\"2026-08-26T11:56:05.814174Z\"}]}"}
{"recv_ts_ns":1787745365960261359,"payload":"{\"channel\":\"book\",\"type\":\"update\",\"data\":[{\"symbol\":\"BTC/USD\",\"bids\":[],\"asks\":[{\"price\":78527.9,\"qty\":0.06656811}],\"checksum\":1368297202,\"timestamp\":\"2026-08-26T11:56:05.815317Z\"}]}"}
{"recv_ts_ns":1787745366005965331,"payload":"{\"channel\":\"book\",\"type\":\"update\",\"data\":[{\"symbol\":\"BTC/USD\",\"bids\":[],\"asks\":[{\"price\":78526.3,\"qty\":0.00000000},{\"price\":78534.3,\"qty\":1.10907657}],\"checksum\":1368297202,\"timestamp\":\"2026-08-26T11:56:05.859432Z\"}]}"}
{"recv_ts_ns":1787745366006389440,"payload":"{\"channel\":\"book\",\"type\":\"update\",\"data\":[{\"symbol\":\"BTC/USD\",\"bids\":[],\"asks\":[{\"price\":78523.4,\"qty\":0.26035160}],\"checksum\":1368297202,\"timestamp\":\"2026-08-26T11:56:05.860846Z\"}]}"}
{"recv_ts_ns":1787745366006453844,"payload":"{\"channel\":\"book\",\"type\":\"update\",\"data\":[{\"symbol\":\"BTC/USD\",\"bids\":[],\"asks\":[{\"price\":78525.7,\"qty\":0.00320915},{\"price\":78527.9,\"qty\":0.21941605}],\"checksum\":1368297202,\"timestamp\":\"2026-08-26T11:56:05.860964Z\"}]}"}
{"recv_ts_ns":1787745366010187319,"payload":"{\"channel\":\"book\",\"type\":\"update\",\"data\":[{\"symbol\":\"BTC/USD\",\"bids\":[],\"asks\":[{\"price\":78525.3,\"qty\":0.63673824}],\"checksum\":1368297202,\"timestamp\":\"2026-08-26T11:56:05.861256Z\"}]}"}
{"recv_ts_ns":1787745366010380373,"payload":"{\"channel\":\"book\",\"type\":\"update\",\"data\":[{\"symbol\":\"BTC/USD\",\"bids\":[],\"asks\":[{\"price\":78527.9,\"qty\":0.15284794}],\"checksum\":1368297202,\"timestamp\":\"2026-08-26T11:56:05.862173Z\"}]}"}
{"recv_ts_ns":1787745366010458583,"payload":"{\"channel\":\"book\",\"type\":\"update\",\"data\":[{\"symbol\":\"BTC/USD\",\"bids\":[],\"asks\":[{\"price\":78527.8,\"qty\":0.11219322}],\"checksum\":1368297202,\"timestamp\":\"2026-08-26T11:56:05.862490Z\"}]}"}
