{"recv_ts_ns":1787745366010536560,"payload":"{\"channel\":\"book\",\"type\":\"update\",\"data\":[{\"symbol\":\"BTC/USD\",\"bids\":[],\"asks\":[{\"price\":78523.4,\"qty\":0.41713253}],\"checksum\":1368297202,\"timestamp\":\"2026-08-26T11:56:05.862926Z\"}]}"}
{"recv_ts_ns":1787745366029066647,"payload":"{\"channel\":\"book\",\"type\":\"update\",\"data\":[{\"symbol\":\"BTC/USD\",\"bids\":[],\"asks\":[{\"price\":78528.0,\"qty\":0.00000000},{\"price\":78534.2,\"qty\":1.27365770},{\"price\":78527.8,\"qty\":0.15822502}],\"checksum\":1368297202,\"timestamp\":\"2026-08-26T11:56:05.879423Z\"}]}"}
{"recv_ts_ns":1787745366032468532,"payload":"{\"channel\":\"book\",\"type\":\"update\",\"data\":[{\"symbol\":\"BTC/USD\",\"bids\":[],\"asks\":[{\"price\":78531.3,\"qty\":0.00000000},{\"price\":78534.3,\"qty\":1.10907657}],\"checksum\":1368297202,\"timestamp\":\"2026-08-26T11:56:05.883363Z\"}]}"}
{"recv_ts_ns":1787745366032764898,"payload":"{\"channel\":\"book\",\"type\":\"update\",\"data\":[{\"symbol\":\"BTC/USD\",\"bids\":[],\"asks\":[{\"price\":78527.9,\"qty\":0.00000000},{\"price\":78535.1,\"qty\":0.00005000},{\"price\":78523.3,\"qty\":0.15284794}],\"checksum\":1368297202,\"timestamp\":\"2026-08-26T11:56:05.884594Z\"}]}"}
{"recv_ts_ns":1787745366032912419,"payload":"{\"channel\":\"book\",\"type\":\"update\",\"data\":[{\"symbol\":\"BTC/USD\",\"bids\":[],\"asks\":[{\"price\":78531.2,\"qty\":0.38261688}],\"checksum\":1368297202,\"timestamp\":\"2026-08-26T11:56:05.884994Z\"}]}"}
{"recv_ts_ns":1787745366033001107,"payload":"{\"channel\":\"book\",\"type\":\"update\",\"data\":[{\"symbol\":\"BTC/USD\",\"bids\":[],\"asks\":[{\"price\":78527.8,\"qty\":0.04603180}],\"checksum\":1368297202,\"timestamp\":\"2026-08-26T11:56:05.886442Z\"}]}"}
{"recv_ts_ns":1787745366034644866,"payload":"{\"channel\":\"book\",\"type\":\"update\",\"data\":[{\"symbol\":\"BTC/USD\",\"bids\":[],\"asks\":[{\"price\":78527.7,\"qty\":0.06656811}],\"checksum\":1368297202,\"timestamp\":\"2026-08-26T11:56:05.888110Z\"}]}"}
{"recv_ts_ns":1787745366131485754,"payload":"{\"channel\":\"book\",\"type\":\"update\",\"data\":[{\"symbol\":\"BTC/USD\",\"bids\":[],\"asks\":[{\"price\":78521.6,\"qty\":0.00000000},{\"price\":78534.3,\"qty\":1.10907657}],\"checksum\":1833580783,\"timestamp\":\"2026-08-26T11:56:05.986289Z\"}]}"}
{"recv_ts_ns":1787745366133514545,"payload":"{\"channel\":\"book\",\"type\":\"update\",\"data\":[{\"symbol\":\"BTC/USD\",\"bids\":[],\"asks\":[{\"price\":78523.3,\"qty\":0.00000000},{\"price\":78535.1,\"qty\":0.00005000},{\"price\":78525.2,\"qty\":0.15284794}],\"checksum\":3632171720,\"timestamp\":\"2026-08-26T11:56:05.987449Z\"}]}"}
{"recv_ts_ns":1787745366133710376,"payload":"{\"channel\":\"book\",\"type\":\"update\",\"data\":[{\"symbol\":\"BTC/USD\",\"bids\":[],\"asks\":[{\"price\":78521.5,\"qty\":0.00000000},{\"price\":78535.1,\"qty\":0.00005000}],\"checksum\":1126050225,\"timestamp\":\"2026-08-26T11:56:05.987648Z\"}]}"}
{"recv_ts_ns":1787745366162876692,"payload":"{\"channel\":\"book\",\"type\":\"update\",\"data\":[{\"symbol\":\"BTC/USD\",\"bids\":[],\"asks\":[{\"price\":78525.2,\"qty\":0.00000000},{\"price\":78535.2,\"qty\":0.63665790},{\"price\":78527.7,\"qty\":0.21941605}],\"checksum\":1126050225,\"timestamp\":\"2026-08-26T11:56:06.017189Z\"}]}"}
{"recv_ts_ns":1787745366164873162,"payload":"{\"channel\":\"book\",\"type\":\"update\",\"data\":[{\"symbol\":\"BTC/USD\",\"bids\":[],\"asks\":[{\"price\":78527.7,\"qty\":0.15284794}],\"checksum\":1126050225,\"timestamp\":\"2026-08-26T11:56:06.019126Z\"}]}"}
{"recv_ts_ns":1787745366164947337,"payload":"{\"channel\":\"book\",\"type\":\"update\",\"data\":[{\"symbol\":\"BTC/USD\",\"bids\":[],\"asks\":[{\"price\":78527.6,\"qty\":0.11219322}],\"checksum\":1126050225,\"timestamp\":\"2026-08-26T11:56:06.019216Z\"}]}"}
{"recv_ts_ns":1787745366165277664,"payload":"{\"channel\":\"book\",\"type\":\"update\",\"data\":[{\"symbol\":\"BTC/USD\",\"bids\":[],\"asks\":[{\"price\":78520.9,\"qty\":0.95543056}],\"checksum\":761639066,\"timestamp\":\"2026-08-26T11:56:06.019744Z\"}]}"}
{"recv_ts_ns":1787745366188062688,"payload":"{\"channel\":\"book\",\"type\":\"update\",\"data\":[{\"symbol\":\"BTC/USD\",\"bids\":[],\"asks\":[{\"price\":78527.8,\"qty\":0.00000000},{\"price\":78535.1,\"qty\":0.00005000},{\"price\":78527.5,\"qty\":0.04603180}],\"checksum\":761639066,\"timestamp\":\"2026-08-26T11:56:06.040065Z\"}]}"}
{"recv_ts_ns":1787745366188629915,"payload":"{\"channel\":\"book\",\"type\":\"update\",\"data\":[{\"symbol\":\"BTC/USD\",\"bids\":[],\"asks\":[{\"price\":78527.7,\"qty\":0.00000000},{\"price\":78535.1,\"qty\":0.00005000},{\"price\":78527.5,\"qty\":0.19887974}],\"checksum\":761639066,\"timestamp\":\"2026-08-26T11:56:06.041164Z\"}]}"}
{"recv_ts_ns":1787745366188838739,"payload":"{\"channel\":\"book\",\"type\":\"update\",\"data\":[{\"symbol\":\"BTC/USD\",\"bids\":[],\"asks\":[{\"price\":78527.6,\"qty\":0.00000000},{\"price\":78535.2,\"qty\":0.63665790}],\"checksum\":761639066,\"timestamp\":\"2026-08-26T11:56:06.042361Z\"}]}"}
{"recv_ts_ns":1787745366188964317,"payload":"{\"channel\":\"book\",\"type\":\"update\",\"data\":[{\"symbol\":\"BTC/USD\",\"bids\":[],\"asks\":[{\"price\":78527.4,\"qty\":0.11219322}],\"checksum\":761639066,\"timestamp\":\"2026-08-26T11:56:06.042665Z\"}]}"}
{"recv_ts_ns":1787745366232618095,"payload":"{\"channel\":\"book\",\"type\":\"update\",\"data\":[{\"symbol\":\"BTC/USD\",\"bids\":[],\"asks\":[{\"price\":78527.5,\"qty\":0.04603180},{\"price\":78527.4,\"qty\":0.26504116}],\"checksum\":761639066,\"timestamp\":\"2026-08-26T11:56:06.087750Z\"}]}"}
{"recv_ts_ns":1787745366235201221,"payload":"{\"channel\":\"book\",\"type\":\"update\",\"data\":[{\"symbol\":\"BTC/USD\",\"bids\":[],\"asks\":[{\"price\":78527.3,\"qty\":0.11219322}],\"checksum\":761639066,\"timestamp\":\"2026-08-26T11:56:06.089266Z\"}]}"}
{"recv_ts_ns":1787745366235257449,"payload":"{\"channel\":\"book\",\"type\":\"update\",\"data\":[{\"symbol\":\"BTC/USD\",\"bids\":[],\"asks\":[{\"price\":78527.4,\"qty\":0.15284794}],\"checksum\":761639066,\"timestamp\":\"2026-08-26T11:56:06.089317Z\"}]}"}
{"recv_ts_ns":1787745366267776072,"payload":"{\"channel\":\"book\",\"type\":\"update\",\"data\":[{\"symbol\":\"BTC/USD\",\"bids\":[],\"asks\":[{\"price\":78533.7,\"qty\":0.10440600}],\"checksum\":761639066,\"timestamp\":\"2026-08-26T11:56:06.122535Z\"}]}"}
{"recv_ts_ns":1787745366268412845,"payload":"{\"channel\":\"book\",\"type\":\"update\",\"data\":[{\"symbol\":\"BTC/USD\",\"bids\":[],\"asks\":[{\"price\":78527.4,\"qty\":0.00000000},{\"price\":78534.3,\"qty\":1.10907657},{\"price\":78527.3,\"qty\":0.26504116}],\"checksum\":761639066,\"timestamp\":\"2026-08-26T11:56:06.123791Z\"}]}"}
{"recv_ts_ns":1787745366279455359,"payload":"{\"channel\":\"book\",\"type\":\"update\",\"data\":[{\"symbol\":\"BTC/USD\",\"bids\":[],\"asks\":[{\"price\":78527.3,\"qty\":0.15284794}],\"checksum\":761639066,\"timestamp\":\"2026-08-26T11:56:06.132014Z\"}]}"}
{"recv_ts_ns":1787745366279578644,"payload":"{\"channel\":\"book\",\"type\":\"update\",\"data\":[{\"symbol\":\"BTC/USD\",\"bids\":[],\"asks\":[{\"price\":78527.2,\"qty\":0.11219322}],\"checksum\":761639066,\"timestamp\":\"2026-08-26T11:56:06.132040Z\"}]}"}
{"recv_ts_ns":1787745366305443760,"payload":"{\"channel\":\"book\",\"type\":\"update\",\"data\":[{\"symbol\":\"BTC/USD\",\"bids\":[],\"asks\":[{\"price\":78527.3,\"qty\":0.00000000},{\"price\":78534.3,\"qty\":1.10907657},{\"price\":78527.2,\"qty\":0.26504116}],\"checksum\":761639066,\"timestamp\":\"2026-08-26T11:56:06.160126Z\"}]}"}
{"recv_ts_ns":1787745366306129088,"payload":"{\"channel\":\"book\",\"type\":\"update\",\"data\":[{\"symbol\":\"BTC/USD\",\"bids\":[],\"asks\":[{\"price\":78527.2,\"qty\":0.15284794}],\"checksum\":761639066,\"timestamp\":\"2026-08-26T11:56:06.161397Z\"}]}"}
{"recv_ts_ns":1787745366306640835,"payload":"{\"channel\":\"book\",\"type\":\"update\",\"data\":[{\"symbol\":\"BTC/USD\",\"bids\":[],\"asks\":[{\"price\":78527.1,\"qty\":0.11219322}],\"checksum\":761639066,\"timestamp\":\"2026-08-26T11:56:06.161580Z\"}]}"}
{"recv_ts_ns":1787745366318046013,"payload":"{\"channel\":\"book\",\"type\":\"update\",\"data\":[{\"symbol\":\"BTC/USD\",\"bids\":[],\"asks\":[{\"price\":78520.9,\"qty\":0.00000000},{\"price\":78534.3,\"qty\":1.10907657}],\"checksum\":1126050225,\"timestamp\":\"2026-08-26T11:56:06.171100Z\"}]}"}
{"recv_ts_ns":1787745366332909865,"payload":"{\"channel\":\"book\",\"type\":\"update\",\"data\":[{\"symbol\":\"BTC/USD\",\"bids\":[],\"asks\":[{\"price\":78527.2,\"qty\":0.00000000},{\"price\":78535.1,\"qty\":0.00005000},{\"price\":78527.0,\"qty\":0.15284794}],\"checksum\":1126050225,\"timestamp\":\"2026-08-26T11:56:06.187523Z\"}]}"}
{"recv_ts_ns":1787745366334309666,"payload":"{\"channel\":\"book\",\"type\":\"update\",\"data\":[{\"symbol\":\"BTC/USD\",\"bids\":[],\"asks\":[{\"price\":78527.1,\"qty\":0.00000000},{\"price\":78535.1,\"qty\":0.00005000}],\"checksum\":1126050225,\"timestamp\":\"2026-08-26T11:56:06.188831Z\"}]}"}
{"recv_ts_ns":1787745366334414161,"payload":"{\"channel\":\"book\",\"type\":\"update\",\"data\":[{\"symbol\":\"BTC/USD\",\"bids\":[],\"asks\":[{\"price\":78526.9,\"qty\":0.11219322}],\"checksum\":1126050225,\"timestamp\":\"2026-08-26T11:56:06.188922Z\"}]}"}
{"recv_ts_ns":1787745366338151220,"payload":"{\"channel\":\"book\",\"type\":\"update\",\"data\":[{\"symbol\":\"BTC/USD\",\"bids\":[],\"asks\":[{\"price\":78521.7,\"qty\":0.95543056}],\"checksum\":1249295477,\"timestamp\":\"2026-08-26T11:56:06.192942Z\"}]}"}
{"recv_ts_ns":1787745366355787331,"payload":"{\"channel\":\"book\",\"type\":\"update\",\"data\":[{\"symbol\":\"BTC/USD\",\"bids\":[],\"asks\":[{\"price\":78527.5,\"qty\":0.00000000},{\"price\":78534.3,\"qty\":1.10907657},{\"price\":78523.3,\"qty\":0.04603180}],\"checksum\":684907857,\"timestamp\":\"2026-08-26T11:56:06.211041Z\"}]}"}
{"recv_ts_ns":1787745366357023557,"payload":"{\"channel\":\"book\",\"type\":\"update\",\"data\":[{\"symbol\":\"BTC/USD\",\"bids\":[],\"asks\":[{\"price\":78527.0,\"qty\":0.00000000},{\"price\":78534.3,\"qty\":1.10907657},{\"price\":78526.9,\"qty\":0.26504116}],\"checksum\":684907857,\"timestamp\":\"2026-08-26T11:56:06.211149Z\"}]}"}
{"recv_ts_ns":1787745366357405709,"payload":"{\"channel\":\"book\",\"type\":\"update\",\"data\":[{\"symbol\":\"BTC/USD\",\"bids\":[],\"asks\":[{\"price\":78526.9,\"qty\":0.15284794}],\"checksum\":684907857,\"timestamp\":\"2026-08-26T11:56:06.212847Z\"}]}"}
{"recv_ts_ns":1787745366357440211,"payload":"{\"channel\":\"book\",\"type\":\"update\",\"data\":[{\"symbol\":\"BTC/USD\",\"bids\":[],\"asks\":[{\"price\":78526.8,\"qty\":0.09845272}],\"checksum\":684907857,\"timestamp\":\"2026-08-26T11:56:06.213332Z\"}]}"}
{"recv_ts_ns":1787745366391561372,"payload":"{\"channel\":\"book\",\"type\":\"update\",\"data\":[{\"symbol\":\"BTC/USD\",\"bids\":[],\"asks\":[{\"price\":78522.7,\"qty\":0.00373294}],\"checksum\":1163208223,\"timestamp\":\"2026-08-26T11:56:06.244134Z\"}]}"}
{"recv_ts_ns":1787745366391726376,"payload":"{\"channel\":\"book\",\"type\":\"update\",\"data\":[{\"symbol\":\"BTC/USD\",\"bids\":[],\"asks\":[{\"price\":78526.9,\"qty\":0.00000000},{\"price\":78534.2,\"qty\":1.27365770},{\"price\":78525.2,\"qty\":0.15284794}],\"checksum\":1163208223,\"timestamp\":\"2026-08-26T11:56:06.245342Z\"}]}"}
{"recv_ts_ns":1787745366395241429,"payload":"{\"channel\":\"book\",\"type\":\"update\",\"data\":[{\"symbol\":\"BTC/USD\",\"bids\":[],\"asks\":[{\"price\":78526.8,\"qty\":0.00000000},{\"price\":78534.2,\"qty\":1.27365770}],\"checksum\":1163208223,\"timestamp\":\"2026-08-26T11:56:06.247687Z\"}]}"}
{"recv_ts_ns":1787745366395312314,"payload":"{\"channel\":\"book\",\"type\":\"update\",\"data\":[{\"symbol\":\"BTC/USD\",\"bids\":[],\"asks\":[{\"price\":78526.8,\"qty\":0.05282761}],\"checksum\":1163208223,\"timestamp\":\"2026-08-26T11:56:06.248027Z\"}]}"}
{"recv_ts_ns":1787745366462887395,"payload":"{\"channel\":\"trade\",\"type\":\"update\",\"data\":[{\"symbol\":\"BTC/USD\",\"side\":\"buy\",\"price\":78500.7,\"qty\":0.00018828,\"ord_type\":\"limit\",\"trade_id\":105995617,\"timestamp\":\"2026-08-26T11:56:06.315458Z\"}]}"}
{"recv_ts_ns":1787745366463035391,"payload":"{\"channel\":\"book\",\"type\":\"update\",\"data\":[{\"symbol\":\"BTC/USD\",\"bids\":[],\"asks\":[{\"price\":78500.7,\"qty\":0.00207693}],\"checksum\":2406185463,\"timestamp\":\"2026-08-26T11:56:06.315458Z\"}]}"}
{"recv_ts_ns":1787745366541218440,"payload":"{\"channel\":\"book\",\"type\":\"update\",\"data\":[{\"symbol\":\"BTC/USD\",\"bids\":[],\"asks\":[{\"price\":78523.3,\"qty\":0.00000000},{\"price\":78534.2,\"qty\":1.27365770},{\"price\":78522.6,\"qty\":0.04603180}],\"checksum\":4100184540,\"timestamp\":\"2026-08-26T11:56:06.394180Z\"}]}"}
{"recv_ts_ns":1787745366673404244,"payload":"{\"channel\":\"book\",\"type\":\"update\",\"data\":[{\"symbol\":\"BTC/USD\",\"bids\":[],\"asks\":[{\"price\":78519.7,\"qty\":0.01118726}],\"checksum\":15218694,\"timestamp\":\"2026-08-26T11:56:06.525538Z\"}]}"}
{"recv_ts_ns":1787745366676192981,"payload":"{\"channel\":\"book\",\"type\":\"update\",\"data\":[{\"symbol\":\"BTC/USD\",\"bids\":[],\"asks\":[{\"price\":78523.7,\"qty\":0.01495079}],\"checksum\":15218694,\"timestamp\":\"2026-08-26T11:56:06.525981Z\"}]}"}
{"recv_ts_ns":1787745366676292740,"payload":"{\"channel\":\"book\",\"type\":\"update\",\"data\":[{\"symbol\":\"BTC/USD\",\"bids\":[],\"asks\":[{\"price\":78531.5,\"qty\":0.02626839}],\"checksum\":15218694,\"timestamp\":\"2026-08-26T11:56:06.526471Z\"}]}"}
{"recv_ts_ns":1787745366676350449,"payload":"{\"channel\":\"book\",\"type\":\"update\",\"data\":[{\"symbol\":\"BTC/USD\",\"bids\":[],\"asks\":[{\"price\":78525.2,\"qty\":0.00000000},{\"price\":78532.5,\"qty\":0.02292044},{\"price\":78523.4,\"qty\":0.56998047}],\"checksum\":15218694,\"timestamp\":\"2026-08-26T11:56:06.526611Z\"}]}"}
{"recv_ts_ns":1787745366677809404,"payload":"{\"channel\":\"book\",\"type\":\"update\",\"data\":[{\"symbol\":\"BTC/USD\",\"bids\":[],\"asks\":[{\"price\":78525.3,\"qty\":0.00000000},{\"price\":78532.8,\"qty\":0.00254670}],\"checksum\":15218694,\"timestamp\":\"2026-08-26T11:56:06.531135Z\"}]}"}
{"recv_ts_ns":1787745366678270138,"payload":"{\"channel\":\"book\",\"type\":\"update\",\"data\":[{\"symbol\":\"BTC/USD\",\"bids\":[],\"asks\":[{\"price\":78523.4,\"qty\":0.41319954}],\"checksum\":15218694,\"timestamp\":\"2026-08-26T11:56:06.533027Z\"}]}"}
{"recv_ts_ns":1787745366681958672,"payload":"{\"channel\":\"book\",\"type\":\"update\",\"data\":[{\"symbol\":\"BTC/USD\",\"bids\":[],\"asks\":[{\"price\":78524.5,\"qty\":0.63674450}],\"checksum\":15218694,\"timestamp\":\"2026-08-26T11:56:06.533289Z\"}]}"}
{"recv_ts_ns":1787745366682035813,"payload":"{\"channel\":\"book\",\"type\":\"update\",\"data\":[{\"symbol\":\"BTC/USD\",\"bids\":[],\"asks\":[{\"price\":78532.3,\"qty\":0.63668147}],\"checksum\":15218694,\"timestamp\":\"2026-08-26T11:56:06.533586Z\"}]}"}
{"recv_ts_ns":1787745366682118289,"payload":"{\"channel\":\"book\",\"type\":\"update\",\"data\":[{\"symbol\":\"BTC/USD\",\"bids\":[],\"asks\":[{\"price\":78523.4,\"qty\":0.57444515}],\"checksum\":15218694,\"timestamp\":\"2026-08-26T11:56:06.534925Z\"}]}"}
{"recv_ts_ns":1787745366682181795,"payload":"{\"channel\":\"book\",\"type\":\"update\",\"data\":[{\"symbol\":\"BTC/USD\",\"bids\":[],\"asks\":[{\"price\":78531.2,\"qty\":0.04045336}],\"checksum\":15218694,\"timestamp\":\"2026-08-26T11:56:06.535183Z\"}]}"}
{"recv_ts_ns":1787745366682238915,"payload":"{\"channel\":\"book\",\"type\":\"update\",\"data\":[{\"symbol\":\"BTC/USD\",\"bids\":[],\"asks\":[{\"price\":78531.2,\"qty\":0.00000000},{\"price\":78532.5,\"qty\":0.02292044}],\"checksum\":15218694,\"timestamp\":\"2026-08-26T11:56:06.535230Z\"}]}"}
{"recv_ts_ns":1787745366682321724,"payload":"{\"channel\":\"book\",\"type\":\"update\",\"data\":[{\"symbol\":\"BTC/USD\",\"bids\":[],\"asks\":[{\"price\":78532.2,\"qty\":0.60900337}],\"checksum\":15218694,\"timestamp\":\"2026-08-26T11:56:06.536470Z\"}]}"}
{"recv_ts_ns":1787745366693367309,"payload":"{\"channel\":\"book\",\"type\":\"update\",\"data\":[{\"symbol\":\"BTC/USD\",\"bids\":[],\"asks\":[{\"price\":78524.5,\"qty\":0.00000000},{\"price\":78532.5,\"qty\":0.02292044}],\"checksum\":15218694,\"timestamp\":\"2026-08-26T11:56:06.543705Z\"}]}"}
{"recv_ts_ns":1787745366693463909,"payload":"{\"channel\":\"book\",\"type\":\"update\",\"data\":[{\"symbol\":\"BTC/USD\",\"bids\":[],\"asks\":[{\"price\":78519.7,\"qty\":0.00000000},{\"price\":78532.8,\"qty\":0.00254670}],\"checksum\":4100184540,\"timestamp\":\"2026-08-26T11:56:06.545231Z\"}]}"}
{"recv_ts_ns":1787745366693555815,"payload":"{\"channel\":\"book\",\"type\":\"update\",\"data\":[{\"symbol\":\"BTC/USD\",\"bids\":[],\"asks\":[{\"price\":78523.4,\"qty\":0.41319954}],\"checksum\":4100184540,\"timestamp\":\"2026-08-26T11:56:06.545532Z\"}]}"}
{"recv_ts_ns":1787745366693629236,"payload":"{\"channel\":\"book\",\"type\":\"update\",\"data\":[{\"symbol\":\"BTC/USD\",\"bids\":[],\"asks\":[{\"price\":78523.7,\"qty\":0.00000000},{\"price\":78533.7,\"qty\":0.10440600}],\"checksum\":4100184540,\"timestamp\":\"2026-08-26T11:56:06.545681Z\"}]}"}
{"recv_ts_ns":1787745366693756185,"payload":"{\"channel\":\"book\",\"type\":\"update\",\"data\":[{\"symbol\":\"BTC/USD\",\"bids\":[],\"asks\":[{\"price\":78531.5,\"qty\":0.00000000},{\"price\":78534.2,\"qty\":1.27365770}],\"checksum\":4100184540,\"timestamp\":\"2026-08-26T11:56:06.546112Z\"}]}"}
{"recv_ts_ns":1787745366704699832,"payload":"{\"channel\":\"book\",\"type\":\"update\",\"data\":[{\"symbol\":\"BTC/USD\",\"bids\":[],\"asks\":[{\"price\":78522.6,\"qty\":0.00000000},{\"price\":78534.3,\"qty\":1.10907657},{\"price\":78521.6,\"qty\":0.04603180}],\"checksum\":3238500230,\"timestamp\":\"2026-08-26T11:56:06.556924Z\"}]}"}
{"recv_ts_ns":1787745366726441254,"payload":"{\"channel\":\"book\",\"type\":\"update\",\"data\":[{\"symbol\":\"BTC/USD\",\"bids\":[],\"asks\":[{\"price\":78521.7,\"qty\":0.00000000},{\"price\":78534.3,\"qty\":1.10907657}],\"checksum\":1850369144,\"timestamp\":\"2026-08-26T11:56:06.580442Z\"}]}"}
{"recv_ts_ns":1787745366726830715,"payload":"{\"channel\":\"book\",\"type\":\"update\",\"data\":[{\"symbol\":\"BTC/USD\",\"bids\":[],\"asks\":[{\"price\":78523.4,\"qty\":0.26035160},{\"price\":78526.8,\"qty\":0.20567555}],\"checksum\":1850369144,\"timestamp\":\"2026-08-26T11:56:06.581808Z\"}]}"}
{"recv_ts_ns":1787745366730739397,"payload":"{\"channel\":\"book\",\"type\":\"update\",\"data\":[{\"symbol\":\"BTC/USD\",\"bids\":[],\"asks\":[{\"price\":78526.8,\"qty\":0.15284794}],\"checksum\":1850369144,\"timestamp\":\"2026-08-26T11:56:06.582959Z\"}]}"}
{"recv_ts_ns":1787745366730816250,"payload":"{\"channel\":\"book\",\"type\":\"update\",\"data\":[{\"symbol\":\"BTC/USD\",\"bids\":[],\"asks\":[{\"price\":78526.7,\"qty\":0.09845272}],\"checksum\":1850369144,\"timestamp\":\"2026-08-26T11:56:06.583078Z\"}]}"}
{"recv_ts_ns":1787745366745696731,"payload":"{\"channel\":\"book\",\"type\":\"update\",\"data\":[{\"symbol\":\"BTC/USD\",\"bids\":[],\"asks\":[{\"price\":78529.4,\"qty\":0.63670454}],\"checksum\":1850369144,\"timestamp\":\"2026-08-26T11:56:06.600583Z\"}]}"}
{"recv_ts_ns":1787745366748470428,"payload":"{\"channel\":\"book\",\"type\":\"update\",\"data\":[{\"symbol\":\"BTC/USD\",\"bids\":[],\"asks\":[{\"price\":78526.8,\"qty\":0.00000000},{\"price\":78534.2,\"qty\":1.27365770},{\"price\":78526.7,\"qty\":0.25130066}],\"checksum\":1850369144,\"timestamp\":\"2026-08-26T11:56:06.602022Z\"}]}"}
{"recv_ts_ns":1787745366748632655,"payload":"{\"channel\":\"book\",\"type\":\"update\",\"data\":[{\"symbol\":\"BTC/USD\",\"bids\":[],\"asks\":[{\"price\":78526.7,\"qty\":0.42876998}],\"checksum\":1850369144,\"timestamp\":\"2026-08-26T11:56:06.602613Z\"}]}"}
{"recv_ts_ns":1787745366765445823,"payload":"{\"channel\":\"book\",\"type\":\"update\",\"data\":[{\"symbol\":\"BTC/USD\",\"bids\":[],\"asks\":[{\"price\":78522.5,\"qty\":0.95543056}],\"checksum\":2155294427,\"timestamp\":\"2026-08-26T11:56:06.619983Z\"}]}"}
{"recv_ts_ns":1787745366768613099,"payload":"{\"channel\":\"book\",\"type\":\"update\",\"data\":[{\"symbol\":\"BTC/USD\",\"bids\":[],\"asks\":[{\"price\":78522.4,\"qty\":0.28519602}],\"checksum\":461304066,\"timestamp\":\"2026-08-26T11:56:06.621490Z\"}]}"}
{"recv_ts_ns":1787745366768689407,"payload":"{\"channel\":\"book\",\"type\":\"update\",\"data\":[{\"symbol\":\"BTC/USD\",\"bids\":[],\"asks\":[{\"price\":78526.7,\"qty\":0.27592204},{\"price\":78522.3,\"qty\":0.15284794}],\"checksum\":2907307606,\"timestamp\":\"2026-08-26T11:56:06.622906Z\"}]}"}
{"recv_ts_ns":1787745366793187430,"payload":"{\"channel\":\"book\",\"type\":\"update\",\"data\":[{\"symbol\":\"BTC/USD\",\"bids\":[],\"asks\":[{\"price\":78522.5,\"qty\":0.00000000},{\"price\":78532.8,\"qty\":0.00254670}],\"checksum\":2907307606,\"timestamp\":\"2026-08-26T11:56:06.647922Z\"}]}"}
{"recv_ts_ns":1787745366794100276,"payload":"{\"channel\":\"book\",\"type\":\"update\",\"data\":[{\"symbol\":\"BTC/USD\",\"bids\":[],\"asks\":[{\"price\":78522.3,\"qty\":0.00000000},{\"price\":78533.7,\"qty\":0.10440600},{\"price\":78525.5,\"qty\":0.16577268}],\"checksum\":461304066,\"timestamp\":\"2026-08-26T11:56:06.649184Z\"}]}"}
{"recv_ts_ns":1787745366794945582,"payload":"{\"channel\":\"book\",\"type\":\"update\",\"data\":[{\"symbol\":\"BTC/USD\",\"bids\":[],\"asks\":[{\"price\":78522.4,\"qty\":0.00000000},{\"price\":78534.2,\"qty\":1.27365770}],\"checksum\":1850369144,\"timestamp\":\"2026-08-26T11:56:06.649313Z\"}]}"}
{"recv_ts_ns":1787745366816454947,"payload":"{\"channel\":\"book\",\"type\":\"update\",\"data\":[{\"symbol\":\"BTC/USD\",\"bids\":[],\"asks\":[{\"price\":78521.6,\"qty\":1.00146236}],\"checksum\":2581970100,\"timestamp\":\"2026-08-26T11:56:06.670807Z\"}]}"}
{"recv_ts_ns":1787745366818168846,"payload":"{\"channel\":\"book\",\"type\":\"update\",\"data\":[{\"symbol\":\"BTC/USD\",\"bids\":[],\"asks\":[{\"price\":78525.5,\"qty\":0.01292474},{\"price\":78526.6,\"qty\":0.15284794}],\"checksum\":2581970100,\"timestamp\":\"2026-08-26T11:56:06.672014Z\"}]}"}
{"recv_ts_ns":1787745366824965047,"payload":"{\"channel\":\"book\",\"type\":\"update\",\"data\":[{\"symbol\":\"BTC/USD\",\"bids\":[],\"asks\":[{\"price\":78525.8,\"qty\":0.63673391}],\"checksum\":2581970100,\"timestamp\":\"2026-08-26T11:56:06.679340Z\"}]}"}
{"recv_ts_ns":1787745366825925444,"payload":"{\"channel\":\"book\",\"type\":\"update\",\"data\":[{\"symbol\":\"BTC/USD\",\"bids\":[],\"asks\":[{\"price\":78523.4,\"qty\":0.41713124}],\"checksum\":2581970100,\"timestamp\":\"2026-08-26T11:56:06.680611Z\"}]}"}
{"recv_ts_ns":1787745366843613789,"payload":"{\"channel\":\"book\",\"type\":\"update\",\"data\":[{\"symbol\":\"BTC/USD\",\"bids\":[],\"asks\":[{\"price\":78529.4,\"qty\":0.00000000},{\"price\":78533.7,\"qty\":0.10440600}],\"checksum\":2581970100,\"timestamp\":\"2026-08-26T11:56:06.696093Z\"}]}"}
{"recv_ts_ns":1787745366843763067,"payload":"{\"channel\":\"book\",\"type\":\"update\",\"data\":[{\"symbol\":\"BTC/USD\",\"bids\":[],\"asks\":[{\"price\":78525.8,\"qty\":0.00000000},{\"price\":78534.2,\"qty\":1.27365770}],\"checksum\":2581970100,\"timestamp\":\"2026-08-26T11:56:06.696158Z\"}]}"}
{"recv_ts_ns":1787745366844270595,"payload":"{\"channel\":\"book\",\"type\":\"update\",\"data\":[{\"symbol\":\"BTC/USD\",\"bids\":[],\"asks\":[{\"price\":78526.7,\"qty\":0.09845272}],\"checksum\":2581970100,\"timestamp\":\"2026-08-26T11:56:06.697528Z\"}]}"}
{"recv_ts_ns":1787745366844356073,"payload":"{\"channel\":\"book\",\"type\":\"update\",\"data\":[{\"symbol\":\"BTC/USD\",\"bids\":[],\"asks\":[{\"price\":78523.4,\"qty\":0.26035160}],\"checksum\":2581970100,\"timestamp\":\"2026-08-26T11:56:06.697695Z\"}]}"}
{"recv_ts_ns":1787745366844396948,"payload":"{\"channel\":\"book\",\"type\":\"update\",\"data\":[{\"symbol\":\"BTC/USD\",\"bids\":[],\"asks\":[{\"price\":78526.7,\"qty\":0.00000000},{\"price\":78534.3,\"qty\":1.10907657}],\"checksum\":2581970100,\"timestamp\":\"2026-08-26T11:56:06.697835Z\"}]}"}
{"recv_ts_ns":1787745366844458409,"payload":"{\"channel\":\"book\",\"type\":\"update\",\"data\":[{\"symbol\":\"BTC/USD\",\"bids\":[],\"asks\":[{\"price\":78526.6,\"qty\":0.00000000},{\"price\":78535.1,\"qty\":0.00005000},{\"price\":78525.7,\"qty\":0.15605709}],\"checksum\":2581970100,\"timestamp\":\"2026-08-26T11:56:06.697861Z\"}]}"}
{"recv_ts_ns":1787745366844609923,"payload":"{\"channel\":\"book\",\"type\":\"update\",\"data\":[{\"symbol\":\"BTC/USD\",\"bids\":[],\"asks\":[{\"price\":78526.5,\"qty\":0.09845272}],\"checksum\":2581970100,\"timestamp\":\"2026-08-26T11:56:06.699152Z\"}]}"}
{"recv_ts_ns":1787745366844778811,"payload":"{\"channel\":\"book\",\"type\":\"update\",\"data\":[{\"symbol\":\"BTC/USD\",\"bids\":[],\"asks\":[{\"price\":78526.5,\"qty\":0.00000000},{\"price\":78535.1,\"qty\":0.00005000}],\"checksum\":2581970100,\"timestamp\":\"2026-08-26T11:56:06.699400Z\"}]}"}
{"recv_ts_ns":1787745366846351718,"payload":"{\"channel\":\"book\",\"type\":\"update\",\"data\":[{\"symbol\":\"BTC/USD\",\"bids\":[],\"asks\":[{\"price\":78526.5,\"qty\":0.05282761}],\"checksum\":2581970100,\"timestamp\":\"2026-08-26T11:56:06.699630Z\"}]}"}
{"recv_ts_ns":1787745366879115285,"payload":"{\"channel\":\"book\",\"type\":\"update\",\"data\":[{\"symbol\":\"BTC/USD\",\"bids\":[],\"asks\":[{\"price\":78525.7,\"qty\":0.00320915},{\"price\":78526.5,\"qty\":0.20567555}],\"checksum\":2581970100,\"timestamp\":\"2026-08-26T11:56:06.734004Z\"}]}"}
{"recv_ts_ns":1787745366927328861,"payload":"{\"channel\":\"heartbeat\"}"}
{"recv_ts_ns":1787745366948092557,"payload":"{\"channel\":\"book\",\"type\":\"update\",\"data\":[{\"symbol\":\"BTC/USD\",\"bids\":[],\"asks\":[{\"price\":78525.9,\"qty\":0.63673283}],\"checksum\":2581970100,\"timestamp\":\"2026-08-26T11:56:06.800271Z\"}]}"}
{"recv_ts_ns":1787745366948229580,"payload":"{\"channel\":\"book\",\"type\":\"update\",\"data\":[{\"symbol\":\"BTC/USD\",\"bids\":[],\"asks\":[{\"price\":78525.9,\"qty\":0.00000000},{\"price\":78534.3,\"qty\":1.10907657}],\"checksum\":2581970100,\"timestamp\":\"2026-08-26T11:56:06.800467Z\"}]}"}
{"recv_ts_ns":1787745366948314490,"payload":"{\"channel\":\"book\",\"type\":\"update\",\"data\":[{\"symbol\":\"BTC/USD\",\"bids\":[],\"asks\":[{\"price\":78526.5,\"qty\":0.05282761},{\"price\":78525.8,\"qty\":0.15284794}],\"checksum\":2581970100,\"timestamp\":\"2026-08-26T11:56:06.801626Z\"}]}"}
{"recv_ts_ns":1787745366948377846,"payload":"{\"channel\":\"book\",\"type\":\"update\",\"data\":[{\"symbol\":\"BTC/USD\",\"bids\":[],\"asks\":[{\"price\":78523.4,\"qty\":0.46275603}],\"checksum\":2581970100,\"timestamp\":\"2026-08-26T11:56:06.801851Z\"}]}"}
{"recv_ts_ns":1787745366948436173,"payload":"{\"channel\":\"book\",\"type\":\"update\",\"data\":[{\"symbol\":\"BTC/USD\",\"bids\":[],\"asks\":[{\"price\":78523.4,\"qty\":0.26035160}],\"checksum\":2581970100,\"timestamp\":\"2026-08-26T11:56:06.802160Z\"}]}"}
{"recv_ts_ns":1787745367033781212,"payload":"{\"channel\":\"book\",\"type\":\"update\",\"data\":[{\"symbol\":\"BTC/USD\",\"bids\":[],\"asks\":[{\"price\":78525.8,\"qty\":0.00000000},{\"price\":78534.3,\"qty\":1.10907657},{\"price\":78525.7,\"qty\":0.15605709}],\"checksum\":2581970100,\"timestamp\":\"2026-08-26T11:56:06.887835Z\"}]}"}
{"recv_ts_ns":1787745367051927377,"payload":"{\"channel\":\"book\",\"type\":\"update\",\"data\":[{\"symbol\":\"BTC/USD\",\"bids\":[],\"asks\":[{\"price\":78526.9,\"qty\":0.63672459}],\"checksum\":2581970100,\"timestamp\":\"2026-08-26T11:56:06.907087Z\"}]}"}
{"recv_ts_ns":1787745367053289377,"payload":"{\"channel\":\"book\",\"type\":\"update\",\"data\":[{\"symbol\":\"BTC/USD\",\"bids\":[],\"asks\":[{\"price\":78529.4,\"qty\":0.63670480}],\"checksum\":2581970100,\"timestamp\":\"2026-08-26T11:56:06.907106Z\"}]}"}
{"recv_ts_ns":1787745367053858582,"payload":"{\"channel\":\"book\",\"type\":\"update\",\"data\":[{\"symbol\":\"BTC/USD\",\"bids\":[],\"asks\":[{\"price\":78525.7,\"qty\":0.00320915},{\"price\":78526.5,\"qty\":0.20567555}],\"checksum\":2581970100,\"timestamp\":\"2026-08-26T11:56:06.908541Z\"}]}"}
{"recv_ts_ns":1787745367055610296,"payload":"{\"channel\":\"book\",\"type\":\"update\",\"data\":[{\"symbol\":\"BTC/USD\",\"bids\":[],\"asks\":[{\"price\":78526.5,\"qty\":0.38898394}],\"checksum\":2581970100,\"timestamp\":\"2026-08-26T11:56:06.909098Z\"}]}"}
{"recv_ts_ns":1787745367055624697,"payload":"{\"channel\":\"book\",\"type\":\"update\",\"data\":[{\"symbol\":\"BTC/USD\",\"bids\":[],\"asks\":[{\"price\":78526.5,\"qty\":0.20567555}],\"checksum\":2581970100,\"timestamp\":\"2026-08-26T11:56:06.909116Z\"}]}"}
{"recv_ts_ns":1787745367055633296,"payload":"{\"channel\":\"book\",\"type\":\"update\",\"data\":[{\"symbol\":\"BTC/USD\",\"bids\":[],\"asks\":[{\"price\":78526.5,\"qty\":0.60843231}],\"checksum\":2581970100,\"timestamp\":\"2026-08-26T11:56:06.909123Z\"}]}"}
{"recv_ts_ns":1787745367055644621,"payload":"{\"channel\":\"book\",\"type\":\"update\",\"data\":[{\"symbol\":\"BTC/USD\",\"bids\":[],\"asks\":[{\"price\":78526.5,\"qty\":0.55560470}],\"checksum\":2581970100,\"timestamp\":\"2026-08-26T11:56:06.909402Z\"}]}"}
{"recv_ts_ns":1787745367135097623,"payload":"{\"channel\":\"book\",\"type\":\"update\",\"data\":[{\"symbol\":\"BTC/USD\",\"bids\":[],\"asks\":[{\"price\":78521.6,\"qty\":0.04603180}],\"checksum\":1850369144,\"timestamp\":\"2026-08-26T11:56:06.988875Z\"}]}"}
{"recv_ts_ns":1787745367135612147,"payload":"{\"channel\":\"book\",\"type\":\"update\",\"data\":[{\"symbol\":\"BTC/USD\",\"bids\":[],\"asks\":[{\"price\":78521.6,\"qty\":0.00000000},{\"price\":78534.2,\"qty\":1.27365770},{\"price\":78522.6,\"qty\":0.04603180}],\"checksum\":1605606458,\"timestamp\":\"2026-08-26T11:56:06.990151Z\"}]}"}
{"recv_ts_ns":1787745367159942331,"payload":"{\"channel\":\"book\",\"type\":\"update\",\"data\":[{\"symbol\":\"BTC/USD\",\"bids\":[],\"asks\":[{\"price\":78522.6,\"qty\":1.00146236}],\"checksum\":3905739492,\"timestamp\":\"2026-08-26T11:56:07.014600Z\"}]}"}
{"recv_ts_ns":1787745367164512334,"payload":"{\"channel\":\"book\",\"type\":\"update\",\"data\":[{\"symbol\":\"BTC/USD\",\"bids\":[],\"asks\":[{\"price\":78522.5,\"qty\":0.29893651}],\"checksum\":2569079067,\"timestamp\":\"2026-08-26T11:56:07.016210Z\"}]}"}
{"recv_ts_ns":1787745367164560020,"payload":"{\"channel\":\"book\",\"type\":\"update\",\"data\":[{\"symbol\":\"BTC/USD\",\"bids\":[],\"asks\":[{\"price\":78526.5,\"qty\":0.40275676}],\"checksum\":2569079067,\"timestamp\":\"2026-08-26T11:56:07.017332Z\"}]}"}
{"recv_ts_ns":1787745367266218160,"payload":"{\"channel\":\"book\",\"type\":\"update\",\"data\":[{\"symbol\":\"BTC/USD\",\"bids\":[],\"asks\":[{\"price\":78526.9,\"qty\":0.00000000},{\"price\":78533.7,\"qty\":0.10440600}],\"checksum\":2569079067,\"timestamp\":\"2026-08-26T11:56:07.120459Z\"}]}"}
{"recv_ts_ns":1787745367267215414,"payload":"{\"channel\":\"book\",\"type\":\"update\",\"data\":[{\"symbol\":\"BTC/USD\",\"bids\":[],\"asks\":[{\"price\":78526.5,\"qty\":0.00000000},{\"price\":78534.2,\"qty\":1.27365770}],\"checksum\":2569079067,\"timestamp\":\"2026-08-26T11:56:07.122011Z\"}]}"}
{"recv_ts_ns":1787745367267906089,"payload":"{\"channel\":\"book\",\"type\":\"update\",\"data\":[{\"symbol\":\"BTC/USD\",\"bids\":[],\"asks\":[{\"price\":78526.5,\"qty\":0.24288400}],\"checksum\":2569079067,\"timestamp\":\"2026-08-26T11:56:07.122121Z\"}]}"}
{"recv_ts_ns":1787745367268026714,"payload":"{\"channel\":\"book\",\"type\":\"update\",\"data\":[{\"symbol\":\"BTC/USD\",\"bids\":[],\"asks\":[{\"price\":78526.1,\"qty\":0.63673110}],\"checksum\":2569079067,\"timestamp\":\"2026-08-26T11:56:07.122646Z\"}]}"}
{"recv_ts_ns":1787745367269950853,"payload":"{\"channel\":\"book\",\"type\":\"update\",\"data\":[{\"symbol\":\"BTC/USD\",\"bids\":[],\"asks\":[{\"price\":78523.4,\"qty\":0.41713040}],\"checksum\":2569079067,\"timestamp\":\"2026-08-26T11:56:07.124275Z\"}]}"}
{"recv_ts_ns":1787745367301194460,"payload":"{\"channel\":\"book\",\"type\":\"update\",\"data\":[{\"symbol\":\"BTC/USD\",\"bids\":[],\"asks\":[{\"price\":78522.6,\"qty\":0.04603180}],\"checksum\":1108206200,\"timestamp\":\"2026-08-26T11:56:07.156125Z\"}]}"}
{"recv_ts_ns":1787745367303771443,"payload":"{\"channel\":\"book\",\"type\":\"update\",\"data\":[{\"symbol\":\"BTC/USD\",\"bids\":[],\"asks\":[{\"price\":78522.6,\"qty\":0.00000000},{\"price\":78533.7,\"qty\":0.10440600},{\"price\":78522.4,\"qty\":0.04603180}],\"checksum\":3819190107,\"timestamp\":\"2026-08-26T11:56:07.157514Z\"}]}"}
{"recv_ts_ns":1787745367303948719,"payload":"{\"channel\":\"book\",\"type\":\"update\",\"data\":[{\"symbol\":\"BTC/USD\",\"bids\":[],\"asks\":[{\"price\":78522.5,\"qty\":0.00000000},{\"price\":78533.7,\"qty\":0.10440600}],\"checksum\":3122091278,\"timestamp\":\"2026-08-26T11:56:07.157651Z\"}]}"}
{"recv_ts_ns":1787745367317196136,"payload":"{\"channel\":\"book\",\"type\":\"update\",\"data\":[{\"symbol\":\"BTC/USD\",\"bids\":[],\"asks\":[{\"price\":78521.8,\"qty\":0.95543056}],\"checksum\":471744447,\"timestamp\":\"2026-08-26T11:56:07.171407Z\"}]}"}
{"recv_ts_ns":1787745367320295048,"payload":"{\"channel\":\"book\",\"type\":\"update\",\"data\":[{\"symbol\":\"BTC/USD\",\"bids\":[],\"asks\":[{\"price\":78521.7,\"qty\":0.29893651}],\"checksum\":1873310174,\"timestamp\":\"2026-08-26T11:56:07.173196Z\"}]}"}
{"recv_ts_ns":1787745367439995549,"payload":"{\"channel\":\"book\",\"type\":\"update\",\"data\":[{\"symbol\":\"BTC/USD\",\"bids\":[{\"price\":78494.6,\"qty\":0.00000000},{\"price\":78484.9,\"qty\":0.00900000}],\"asks\":[],\"checksum\":1873310174,\"timestamp\":\"2026-08-26T11:56:07.294615Z\"}]}"}
{"recv_ts_ns":1787745367593959539,"payload":"{\"channel\":\"book\",\"type\":\"update\",\"data\":[{\"symbol\":\"BTC/USD\",\"bids\":[],\"asks\":[{\"price\":78522.4,\"qty\":0.00000000},{\"price\":78532.8,\"qty\":0.00254670},{\"price\":78519.9,\"qty\":0.04603180}],\"checksum\":600528202,\"timestamp\":\"2026-08-26T11:56:07.447131Z\"}]}"}
{"recv_ts_ns":1787745367929770071,"payload":"{\"channel\":\"heartbeat\"}"}
{"recv_ts_ns":1787745367934006908,"payload":"{\"channel\":\"book\",\"type\":\"update\",\"data\":[{\"symbol\":\"BTC/USD\",\"bids\":[{\"price\":78500.0,\"qty\":0.13781402}],\"asks\":[],\"checksum\":2909613126,\"timestamp\":\"2026-08-26T11:56:07.777437Z\"}]}"}
{"recv_ts_ns":1787745367934144072,"payload":"{\"channel\":\"book\",\"type\":\"update\",\"data\":[{\"symbol\":\"BTC/USD\",\"bids\":[],\"asks\":[{\"price\":78525.7,\"qty\":0.15605709}],\"checksum\":2909613126,\"timestamp\":\"2026-08-26T11:56:07.787588Z\"}]}"}
{"recv_ts_ns":1787745367951629461,"payload":"{\"channel\":\"book\",\"type\":\"update\",\"data\":[{\"symbol\":\"BTC/USD\",\"bids\":[{\"price\":78493.0,\"qty\":0.00000000},{\"price\":78484.8,\"qty\":0.00005100},{\"price\":78492.2,\"qty\":0.40010100}],\"asks\":[],\"checksum\":2909613126,\"timestamp\":\"2026-08-26T11:56:07.805036Z\"}]}"}
{"recv_ts_ns":1787745368191343702,"payload":"{\"channel\":\"book\",\"type\":\"update\",\"data\":[{\"symbol\":\"BTC/USD\",\"bids\":[{\"price\":78487.0,\"qty\":0.34238799}],\"asks\":[],\"checksum\":2909613126,\"timestamp\":\"2026-08-26T11:56:08.043884Z\"}]}"}
{"recv_ts_ns":1787745368191548695,"payload":"{\"channel\":\"book\",\"type\":\"update\",\"data\":[{\"symbol\":\"BTC/USD\",\"bids\":[{\"price\":78485.0,\"qty\":0.00000000},{\"price\":78484.8,\"qty\":0.00005100}],\"asks\":[],\"checksum\":2909613126,\"timestamp\":\"2026-08-26T11:56:08.045040Z\"}]}"}
{"recv_ts_ns":1787745368191706899,"payload":"{\"channel\":\"book\",\"type\":\"update\",\"data\":[{\"symbol\":\"BTC/USD\",\"bids\":[{\"price\":78487.1,\"qty\":0.12000864}],\"asks\":[],\"checksum\":2909613126,\"timestamp\":\"2026-08-26T11:56:08.046437Z\"}]}"}
{"recv_ts_ns":1787745368317463012,"payload":"{\"channel\":\"book\",\"type\":\"update\",\"data\":[{\"symbol\":\"BTC/USD\",\"bids\":[],\"asks\":[{\"price\":78520.4,\"qty\":0.01113138}],\"checksum\":1933267353,\"timestamp\":\"2026-08-26T11:56:08.166768Z\"}]}"}
{"recv_ts_ns":1787745368317875666,"payload":"{\"channel\":\"book\",\"type\":\"update\",\"data\":[{\"symbol\":\"BTC/USD\",\"bids\":[],\"asks\":[{\"price\":78532.1,\"qty\":0.02606386}],\"checksum\":1933267353,\"timestamp\":\"2026-08-26T11:56:08.167720Z\"}]}"}
{"recv_ts_ns":1787745368318001159,"payload":"{\"channel\":\"book\",\"type\":\"update\",\"data\":[{\"symbol\":\"BTC/USD\",\"bids\":[],\"asks\":[{\"price\":78524.3,\"qty\":0.01512865}],\"checksum\":1933267353,\"timestamp\":\"2026-08-26T11:56:08.168031Z\"}]}"}
{"recv_ts_ns":1787745368318073123,"payload":"{\"channel\":\"book\",\"type\":\"update\",\"data\":[{\"symbol\":\"BTC/USD\",\"bids\":[],\"asks\":[{\"price\":78525.7,\"qty\":0.00320915},{\"price\":78525.5,\"qty\":0.16577268}],\"checksum\":1933267353,\"timestamp\":\"2026-08-26T11:56:08.168227Z\"}]}"}
{"recv_ts_ns":1787745368339365493,"payload":"{\"channel\":\"book\",\"type\":\"update\",\"data\":[{\"symbol\":\"BTC/USD\",\"bids\":[],\"asks\":[{\"price\":78521.8,\"qty\":0.00000000},{\"price\":78532.2,\"qty\":0.60900337}],\"checksum\":1933267353,\"timestamp\":\"2026-08-26T11:56:08.192950Z\"}]}"}
{"recv_ts_ns":1787745368340142760,"payload":"{\"channel\":\"book\",\"type\":\"update\",\"data\":[{\"symbol\":\"BTC/USD\",\"bids\":[],\"asks\":[{\"price\":78521.7,\"qty\":0.00000000},{\"price\":78532.3,\"qty\":0.63668147}],\"checksum\":1933267353,\"timestamp\":\"2026-08-26T11:56:08.194385Z\"}]}"}
{"recv_ts_ns":1787745368367251165,"payload":"{\"channel\":\"book\",\"type\":\"update\",\"data\":[{\"symbol\":\"BTC/USD\",\"bids\":[],\"asks\":[{\"price\":78521.7,\"qty\":0.95543056}],\"checksum\":1933267353,\"timestamp\":\"2026-08-26T11:56:08.220002Z\"}]}"}
{"recv_ts_ns":1787745368367440450,"payload":"{\"channel\":\"book\",\"type\":\"update\",\"data\":[{\"symbol\":\"BTC/USD\",\"bids\":[],\"asks\":[{\"price\":78521.6,\"qty\":0.28519602}],\"checksum\":1933267353,\"timestamp\":\"2026-08-26T11:56:08.221513Z\"}]}"}
{"recv_ts_ns":1787745368368022446,"payload":"{\"channel\":\"book\",\"type\":\"update\",\"data\":[{\"symbol\":\"BTC/USD\",\"bids\":[],\"asks\":[{\"price\":78525.5,\"qty\":0.01292474},{\"price\":78523.4,\"qty\":0.56997834}],\"checksum\":1933267353,\"timestamp\":\"2026-08-26T11:56:08.222673Z\"}]}"}
{"recv_ts_ns":1787745368461202367,"payload":"{\"channel\":\"book\",\"type\":\"update\",\"data\":[{\"symbol\":\"BTC/USD\",\"bids\":[],\"asks\":[{\"price\":78529.4,\"qty\":0.00000000},{\"price\":78532.2,\"qty\":0.60900337}],\"checksum\":1933267353,\"timestamp\":\"2026-08-26T11:56:08.314760Z\"}]}"}
{"recv_ts_ns":1787745368462275310,"payload":"{\"channel\":\"book\",\"type\":\"update\",\"data\":[{\"symbol\":\"BTC/USD\",\"bids\":[],\"asks\":[{\"price\":78526.1,\"qty\":0.00000000},{\"price\":78532.3,\"qty\":0.63668147}],\"checksum\":1933267353,\"timestamp\":\"2026-08-26T11:56:08.315389Z\"}]}"}
{"recv_ts_ns":1787745368462305842,"payload":"{\"channel\":\"book\",\"type\":\"update\",\"data\":[{\"symbol\":\"BTC/USD\",\"bids\":[],\"asks\":[{\"price\":78526.5,\"qty\":0.00000000},{\"price\":78532.5,\"qty\":0.02292044}],\"checksum\":1933267353,\"timestamp\":\"2026-08-26T11:56:08.316454Z\"}]}"}
{"recv_ts_ns":1787745368462328639,"payload":"{\"channel\":\"book\",\"type\":\"update\",\"data\":[{\"symbol\":\"BTC/USD\",\"bids\":[],\"asks\":[{\"price\":78519.9,\"qty\":0.00000000},{\"price\":78532.8,\"qty\":0.00254670},{\"price\":78516.1,\"qty\":0.04603180}],\"checksum\":3613788790,\"timestamp\":\"2026-08-26T11:56:08.316511Z\"}]}"}
{"recv_ts_ns":1787745368467944254,"payload":"{\"channel\":\"book\",\"type\":\"update\",\"data\":[{\"symbol\":\"BTC/USD\",\"bids\":[],\"asks\":[{\"price\":78523.4,\"qty\":0.41319954}],\"checksum\":3613788790,\"timestamp\":\"2026-08-26T11:56:08.317091Z\"}]}"}
{"recv_ts_ns":1787745368467984550,"payload":"{\"channel\":\"book\",\"type\":\"update\",\"data\":[{\"symbol\":\"BTC/USD\",\"bids\":[],\"asks\":[{\"price\":78525.2,\"qty\":0.63673838}],\"checksum\":3613788790,\"timestamp\":\"2026-08-26T11:56:08.317475Z\"}]}"}
{"recv_ts_ns":1787745368468007611,"payload":"{\"channel\":\"book\",\"type\":\"update\",\"data\":[{\"symbol\":\"BTC/USD\",\"bids\":[],\"asks\":[{\"price\":78528.1,\"qty\":0.63671493}],\"checksum\":3613788790,\"timestamp\":\"2026-08-26T11:56:08.317885Z\"}]}"}
{"recv_ts_ns":1787745368468032395,"payload":"{\"channel\":\"book\",\"type\":\"update\",\"data\":[{\"symbol\":\"BTC/USD\",\"bids\":[],\"asks\":[{\"price\":78528.1,\"qty\":0.68954254}],\"checksum\":3613788790,\"timestamp\":\"2026-08-26T11:56:08.318010Z\"}]}"}
{"recv_ts_ns":1787745368468056895,"payload":"{\"channel\":\"book\",\"type\":\"update\",\"data\":[{\"symbol\":\"BTC/USD\",\"bids\":[],\"asks\":[{\"price\":78523.4,\"qty\":0.57449641}],\"checksum\":3613788790,\"timestamp\":\"2026-08-26T11:56:08.319502Z\"}]}"}
{"recv_ts_ns":1787745368468079020,"payload":"{\"channel\":\"book\",\"type\":\"update\",\"data\":[{\"symbol\":\"BTC/USD\",\"bids\":[],\"asks\":[{\"price\":78528.1,\"qty\":0.63671493}],\"checksum\":3613788790,\"timestamp\":\"2026-08-26T11:56:08.319887Z\"}]}"}
{"recv_ts_ns":1787745368468103632,"payload":"{\"channel\":\"book\",\"type\":\"update\",\"data\":[{\"symbol\":\"BTC/USD\",\"bids\":[],\"asks\":[{\"price\":78528.0,\"qty\":0.24288702}],\"checksum\":3613788790,\"timestamp\":\"2026-08-26T11:56:08.321346Z\"}]}"}
{"recv_ts_ns":1787745368476023214,"payload":"{\"channel\":\"book\",\"type\":\"update\",\"data\":[{\"symbol\":\"BTC/USD\",\"bids\":[{\"price\":78484.9,\"qty\":0.00000000},{\"price\":78484.8,\"qty\":0.00005100},{\"price\":78500.6,\"qty\":5.46746365}],\"asks\":[],\"checksum\":1094731805,\"timestamp\":\"2026-08-26T11:56:08.331029Z\"}]}"}
{"recv_ts_ns":1787745368505374855,"payload":"{\"channel\":\"book\",\"type\":\"update\",\"data\":[{\"symbol\":\"BTC/USD\",\"bids\":[],\"asks\":[{\"price\":78521.7,\"qty\":0.00000000},{\"price\":78532.2,\"qty\":0.60900337}],\"checksum\":1094731805,\"timestamp\":\"2026-08-26T11:56:08.360237Z\"}]}"}
{"recv_ts_ns":1787745368510401359,"payload":"{\"channel\":\"book\",\"type\":\"update\",\"data\":[{\"symbol\":\"BTC/USD\",\"bids\":[],\"asks\":[{\"price\":78521.6,\"qty\":0.00000000},{\"price\":78532.3,\"qty\":0.63668147}],\"checksum\":1094731805,\"timestamp\":\"2026-08-26T11:56:08.361499Z\"}]}"}
{"recv_ts_ns":1787745368517211715,"payload":"{\"channel\":\"book\",\"type\":\"update\",\"data\":[{\"symbol\":\"BTC/USD\",\"bids\":[],\"asks\":[{\"price\":78523.2,\"qty\":0.95543056}],\"checksum\":1094731805,\"timestamp\":\"2026-08-26T11:56:08.371036Z\"}]}"}
{"recv_ts_ns":1787745368519447218,"payload":"{\"channel\":\"book\",\"type\":\"update\",\"data\":[{\"symbol\":\"BTC/USD\",\"bids\":[],\"asks\":[{\"price\":78523.4,\"qty\":0.42164847}],\"checksum\":1094731805,\"timestamp\":\"2026-08-26T11:56:08.372506Z\"}]}"}
{"recv_ts_ns":1787745368519624545,"payload":"{\"channel\":\"book\",\"type\":\"update\",\"data\":[{\"symbol\":\"BTC/USD\",\"bids\":[],\"asks\":[{\"price\":78523.4,\"qty\":0.26035160}],\"checksum\":1094731805,\"timestamp\":\"2026-08-26T11:56:08.372555Z\"}]}"}
{"recv_ts_ns":1787745368519770021,"payload":"{\"channel\":\"book\",\"type\":\"update\",\"data\":[{\"symbol\":\"BTC/USD\",\"bids\":[],\"asks\":[{\"price\":78523.4,\"qty\":0.00000000},{\"price\":78532.3,\"qty\":0.63668147}],\"checksum\":1094731805,\"timestamp\":\"2026-08-26T11:56:08.372599Z\"}]}"}
{"recv_ts_ns":1787745368519868088,"payload":"{\"channel\":\"book\",\"type\":\"update\",\"data\":[{\"symbol\":\"BTC/USD\",\"bids\":[],\"asks\":[{\"price\":78523.1,\"qty\":0.68091210}],\"checksum\":1094731805,\"timestamp\":\"2026-08-26T11:56:08.372896Z\"}]}"}
{"recv_ts_ns":1787745368568421396,"payload":"{\"channel\":\"book\",\"type\":\"update\",\"data\":[{\"symbol\":\"BTC/USD\",\"bids\":[],\"asks\":[{\"price\":78525.2,\"qty\":0.00000000},{\"price\":78532.3,\"qty\":0.63668147}],\"checksum\":1094731805,\"timestamp\":\"2026-08-26T11:56:08.423222Z\"}]}"}
{"recv_ts_ns":1787745368568940103,"payload":"{\"channel\":\"book\",\"type\":\"update\",\"data\":[{\"symbol\":\"BTC/USD\",\"bids\":[],\"asks\":[{\"price\":78526.0,\"qty\":0.63673198}],\"checksum\":1094731805,\"timestamp\":\"2026-08-26T11:56:08.424567Z\"}]}"}
{"recv_ts_ns":1787745368579583774,"payload":"{\"channel\":\"book\",\"type\":\"update\",\"data\":[{\"symbol\":\"BTC/USD\",\"bids\":[],\"asks\":[{\"price\":78508.3,\"qty\":0.00000000},{\"price\":78532.3,\"qty\":0.63668147}],\"checksum\":4053121675,\"timestamp\":\"2026-08-26T11:56:08.434755Z\"}]}"}
{"recv_ts_ns":1787745368644387479,"payload":"{\"channel\":\"book\",\"type\":\"update\",\"data\":[{\"symbol\":\"BTC/USD\",\"bids\":[],\"asks\":[{\"price\":78526.0,\"qty\":0.00000000},{\"price\":78532.5,\"qty\":0.02292044}],\"checksum\":4053121675,\"timestamp\":\"2026-08-26T11:56:08.495229Z\"}]}"}
{"recv_ts_ns":1787745368716122347,"payload":"{\"channel\":\"book\",\"type\":\"update\",\"data\":[{\"symbol\":\"BTC/USD\",\"bids\":[],\"asks\":[{\"price\":78523.0,\"qty\":0.15284794}],\"checksum\":4053121675,\"timestamp\":\"2026-08-26T11:56:08.570976Z\"}]}"}
{"recv_ts_ns":1787745368725120991,"payload":"{\"channel\":\"book\",\"type\":\"update\",\"data\":[{\"symbol\":\"BTC/USD\",\"bids\":[],\"asks\":[{\"price\":78523.2,\"qty\":0.00000000},{\"price\":78532.5,\"qty\":0.02292044}],\"checksum\":4053121675,\"timestamp\":\"2026-08-26T11:56:08.580682Z\"}]}"}
{"recv_ts_ns":1787745368726991658,"payload":"{\"channel\":\"book\",\"type\":\"update\",\"data\":[{\"symbol\":\"BTC/USD\",\"bids\":[],\"asks\":[{\"price\":78523.1,\"qty\":0.94577961}],\"checksum\":4053121675,\"timestamp\":\"2026-08-26T11:56:08.581865Z\"}]}"}
{"recv_ts_ns":1787745368727090653,"payload":"{\"channel\":\"book\",\"type\":\"update\",\"data\":[{\"symbol\":\"BTC/USD\",\"bids\":[],\"asks\":[{\"price\":78523.1,\"qty\":0.26486751}],\"checksum\":4053121675,\"timestamp\":\"2026-08-26T11:56:08.582333Z\"}]}"}
{"recv_ts_ns":1787745368730286004,"payload":"{\"channel\":\"book\",\"type\":\"update\",\"data\":[{\"symbol\":\"BTC/USD\",\"bids\":[],\"asks\":[{\"price\":78526.0,\"qty\":0.63673183}],\"checksum\":4053121675,\"timestamp\":\"2026-08-26T11:56:08.584177Z\"}]}"}
{"recv_ts_ns":1787745368730459656,"payload":"{\"channel\":\"book\",\"type\":\"update\",\"data\":[{\"symbol\":\"BTC/USD\",\"bids\":[],\"asks\":[{\"price\":78523.1,\"qty\":0.42106917}],\"checksum\":4053121675,\"timestamp\":\"2026-08-26T11:56:08.585475Z\"}]}"}
{"recv_ts_ns":1787745368764275030,"payload":"{\"channel\":\"book\",\"type\":\"update\",\"data\":[{\"symbol\":\"BTC/USD\",\"bids\":[],\"asks\":[{\"price\":78522.4,\"qty\":0.95543056}],\"checksum\":527036910,\"timestamp\":\"2026-08-26T11:56:08.620080Z\"}]}"}
{"recv_ts_ns":1787745368795019430,"payload":"{\"channel\":\"book\",\"type\":\"update\",\"data\":[{\"symbol\":\"BTC/USD\",\"bids\":[],\"asks\":[{\"price\":78522.4,\"qty\":0.00000000},{\"price\":78532.3,\"qty\":0.63668147}],\"checksum\":4053121675,\"timestamp\":\"2026-08-26T11:56:08.647967Z\"}]}"}
{"recv_ts_ns":1787745368820727562,"payload":"{\"channel\":\"book\",\"type\":\"update\",\"data\":[{\"symbol\":\"BTC/USD\",\"bids\":[],\"asks\":[{\"price\":78522.3,\"qty\":0.95543056}],\"checksum\":2396513377,\"timestamp\":\"2026-08-26T11:56:08.675110Z\"}]}"}
{"recv_ts_ns":1787745368928374592,"payload":"{\"channel\":\"heartbeat\"}"}
{"recv_ts_ns":1787745369005237691,"payload":"{\"channel\":\"book\",\"type\":\"update\",\"data\":[{\"symbol\":\"BTC/USD\",\"bids\":[],\"asks\":[{\"price\":78526.0,\"qty\":0.00000000},{\"price\":78532.3,\"qty\":0.63668147}],\"checksum\":2396513377,\"timestamp\":\"2026-08-26T11:56:08.858689Z\"}]}"}
{"recv_ts_ns":1787745369005413380,"payload":"{\"channel\":\"book\",\"type\":\"update\",\"data\":[{\"symbol\":\"BTC/USD\",\"bids\":[],\"asks\":[{\"price\":78523.1,\"qty\":0.26486751}],\"checksum\":2396513377,\"timestamp\":\"2026-08-26T11:56:08.860114Z\"}]}"}
{"recv_ts_ns":1787745369005494642,"payload":"{\"channel\":\"book\",\"type\":\"update\",\"data\":[{\"symbol\":\"BTC/USD\",\"bids\":[],\"asks\":[{\"price\":78525.3,\"qty\":0.63673804}],\"checksum\":2396513377,\"timestamp\":\"2026-08-26T11:56:08.860127Z\"}]}"}
{"recv_ts_ns":1787745369007848703,"payload":"{\"channel\":\"book\",\"type\":\"update\",\"data\":[{\"symbol\":\"BTC/USD\",\"bids\":[],\"asks\":[{\"price\":78522.2,\"qty\":0.28519602}],\"checksum\":3846279674,\"timestamp\":\"2026-08-26T11:56:08.861367Z\"}]}"}
{"recv_ts_ns":1787745369072888279,"payload":"{\"channel\":\"book\",\"type\":\"update\",\"data\":[{\"symbol\":\"BTC/USD\",\"bids\":[],\"asks\":[{\"price\":78508.3,\"qty\":0.00005100}],\"checksum\":1094731805,\"timestamp\":\"2026-08-26T11:56:08.928231Z\"}]}"}
{"recv_ts_ns":1787745369196721135,"payload":"{\"channel\":\"book\",\"type\":\"update\",\"data\":[{\"symbol\":\"BTC/USD\",\"bids\":[],\"asks\":[{\"price\":78523.1,\"qty\":0.42107102}],\"checksum\":1094731805,\"timestamp\":\"2026-08-26T11:56:09.049539Z\"}]}"}
{"recv_ts_ns":1787745369200169362,"payload":"{\"channel\":\"book\",\"type\":\"update\",\"data\":[{\"symbol\":\"BTC/USD\",\"bids\":[],\"asks\":[{\"price\":78525.3,\"qty\":0.00000000},{\"price\":78532.1,\"qty\":0.02606386}],\"checksum\":1094731805,\"timestamp\":\"2026-08-26T11:56:09.053117Z\"}]}"}
{"recv_ts_ns":1787745369200265151,"payload":"{\"channel\":\"book\",\"type\":\"update\",\"data\":[{\"symbol\":\"BTC/USD\",\"bids\":[],\"asks\":[{\"price\":78523.1,\"qty\":0.26486751}],\"checksum\":1094731805,\"timestamp\":\"2026-08-26T11:56:09.054304Z\"}]}"}
{"recv_ts_ns":1787745369201493719,"payload":"{\"channel\":\"book\",\"type\":\"update\",\"data\":[{\"symbol\":\"BTC/USD\",\"bids\":[],\"asks\":[{\"price\":78526.2,\"qty\":0.63673035}],\"checksum\":1094731805,\"timestamp\":\"2026-08-26T11:56:09.054729Z\"}]}"}
{"recv_ts_ns":1787745369204143792,"payload":"{\"channel\":\"book\",\"type\":\"update\",\"data\":[{\"symbol\":\"BTC/USD\",\"bids\":[],\"asks\":[{\"price\":78523.1,\"qty\":0.42106873}],\"checksum\":1094731805,\"timestamp\":\"2026-08-26T11:56:09.056495Z\"}]}"}
{"recv_ts_ns":1787745369210911774,"payload":"{\"channel\":\"book\",\"type\":\"update\",\"data\":[{\"symbol\":\"BTC/USD\",\"bids\":[],\"asks\":[{\"price\":78528.1,\"qty\":0.00000000},{\"price\":78532.1,\"qty\":0.02606386}],\"checksum\":1094731805,\"timestamp\":\"2026-08-26T11:56:09.064467Z\"}]}"}
{"recv_ts_ns":1787745369211137888,"payload":"{\"channel\":\"book\",\"type\":\"update\",\"data\":[{\"symbol\":\"BTC/USD\",\"bids\":[],\"asks\":[{\"price\":78528.0,\"qty\":0.00000000},{\"price\":78532.2,\"qty\":0.60900337}],\"checksum\":1094731805,\"timestamp\":\"2026-08-26T11:56:09.065976Z\"}]}"}
{"recv_ts_ns":1787745369211201906,"payload":"{\"channel\":\"book\",\"type\":\"update\",\"data\":[{\"symbol\":\"BTC/USD\",\"bids\":[],\"asks\":[{\"price\":78529.6,\"qty\":0.63670330}],\"checksum\":1094731805,\"timestamp\":\"2026-08-26T11:56:09.066149Z\"}]}"}
{"recv_ts_ns":1787745369212633544,"payload":"{\"channel\":\"book\",\"type\":\"update\",\"data\":[{\"symbol\":\"BTC/USD\",\"bids\":[],\"asks\":[{\"price\":78528.1,\"qty\":0.05282761}],\"checksum\":1094731805,\"timestamp\":\"2026-08-26T11:56:09.067350Z\"}]}"}
{"recv_ts_ns":1787745369929487409,"payload":"{\"channel\":\"heartbeat\"}"}
{"recv_ts_ns":1787745369962564521,"payload":"{\"channel\":\"book\",\"type\":\"update\",\"data\":[{\"symbol\":\"BTC/USD\",\"bids\":[],\"asks\":[{\"price\":78526.2,\"qty\":0.00000000},{\"price\":78532.1,\"qty\":0.02606386}],\"checksum\":1094731805,\"timestamp\":\"2026-08-26T11:56:09.814754Z\"}]}"}
{"recv_ts_ns":1787745369962775768,"payload":"{\"channel\":\"book\",\"type\":\"update\",\"data\":[{\"symbol\":\"BTC/USD\",\"bids\":[],\"asks\":[{\"price\":78529.6,\"qty\":0.00000000},{\"price\":78532.2,\"qty\":0.60900337}],\"checksum\":1094731805,\"timestamp\":\"2026-08-26T11:56:09.814787Z\"}]}"}
{"recv_ts_ns":1787745369969175742,"payload":"{\"channel\":\"book\",\"type\":\"update\",\"data\":[{\"symbol\":\"BTC/USD\",\"bids\":[],\"asks\":[{\"price\":78525.4,\"qty\":0.63673694}],\"checksum\":1094731805,\"timestamp\":\"2026-08-26T11:56:09.817790Z\"}]}"}
{"recv_ts_ns":1787745369969338906,"payload":"{\"channel\":\"book\",\"type\":\"update\",\"data\":[{\"symbol\":\"BTC/USD\",\"bids\":[],\"asks\":[{\"price\":78528.1,\"qty\":0.68954295}],\"checksum\":1094731805,\"timestamp\":\"2026-08-26T11:56:09.817976Z\"}]}"}
{"recv_ts_ns":1787745369976760206,"payload":"{\"channel\":\"book\",\"type\":\"update\",\"data\":[{\"symbol\":\"BTC/USD\",\"bids\":[{\"price\":78493.8,\"qty\":0.00000000},{\"price\":78484.7,\"qty\":0.05060000},{\"price\":78490.6,\"qty\":1.27404554}],\"asks\":[],\"checksum\":1094731805,\"timestamp\":\"2026-08-26T11:56:09.818223Z\"}]}"}
{"recv_ts_ns":1787745369976893930,"payload":"{\"channel\":\"book\",\"type\":\"update\",\"data\":[{\"symbol\":\"BTC/USD\",\"bids\":[],\"asks\":[{\"price\":78523.1,\"qty\":0.26486751}],\"checksum\":1094731805,\"timestamp\":\"2026-08-26T11:56:09.818277Z\"}]}"}
{"recv_ts_ns":1787745369976968863,"payload":"{\"channel\":\"book\",\"type\":\"update\",\"data\":[{\"symbol\":\"BTC/USD\",\"bids\":[{\"price\":78500.6,\"qty\":4.51203309}],\"asks\":[],\"checksum\":4111592872,\"timestamp\":\"2026-08-26T11:56:09.819988Z\"}]}"}
{"recv_ts_ns":1787745369977034794,"payload":"{\"channel\":\"book\",\"type\":\"update\",\"data\":[{\"symbol\":\"BTC/USD\",\"bids\":[{\"price\":78500.6,\"qty\":3.65596730}],\"asks\":[],\"checksum\":2588379851,\"timestamp\":\"2026-08-26T11:56:09.820168Z\"}]}"}
{"recv_ts_ns":1787745369977092868,"payload":"{\"channel\":\"book\",\"type\":\"update\",\"data\":[{\"symbol\":\"BTC/USD\",\"bids\":[],\"asks\":[{\"price\":78525.4,\"qty\":0.00000000},{\"price\":78532.2,\"qty\":0.60900337}],\"checksum\":2588379851,\"timestamp\":\"2026-08-26T11:56:09.820311Z\"}]}"}
{"recv_ts_ns":1787745369977162859,"payload":"{\"channel\":\"book\",\"type\":\"update\",\"data\":[{\"symbol\":\"BTC/USD\",\"bids\":[],\"asks\":[{\"price\":78528.1,\"qty\":0.05282761}],\"checksum\":2588379851,\"timestamp\":\"2026-08-26T11:56:09.820847Z\"}]}"}
{"recv_ts_ns":1787745369977234585,"payload":"{\"channel\":\"book\",\"type\":\"update\",\"data\":[{\"symbol\":\"BTC/USD\",\"bids\":[{\"price\":78490.4,\"qty\":0.00000000},{\"price\":78484.7,\"qty\":0.05060000}],\"asks\":[],\"checksum\":2588379851,\"timestamp\":\"2026-08-26T11:56:09.822162Z\"}]}"}
{"recv_ts_ns":1787745369982898221,"payload":"{\"channel\":\"book\",\"type\":\"update\",\"data\":[{\"symbol\":\"BTC/USD\",\"bids\":[],\"asks\":[{\"price\":78528.1,\"qty\":0.00000000},{\"price\":78532.3,\"qty\":0.63668147}],\"checksum\":2588379851,\"timestamp\":\"2026-08-26T11:56:09.822875Z\"}]}"}
{"recv_ts_ns":1787745369983008891,"payload":"{\"channel\":\"book\",\"type\":\"update\",\"data\":[{\"symbol\":\"BTC/USD\",\"bids\":[{\"price\":78493.9,\"qty\":0.00000000},{\"price\":78482.7,\"qty\":0.00005000}],\"asks\":[],\"checksum\":2588379851,\"timestamp\":\"2026-08-26T11:56:09.824173Z\"}]}"}
{"recv_ts_ns":1787745369983069262,"payload":"{\"channel\":\"book\",\"type\":\"update\",\"data\":[{\"symbol\":\"BTC/USD\",\"bids\":[],\"asks\":[{\"price\":78523.1,\"qty\":0.42107069}],\"checksum\":2588379851,\"timestamp\":\"2026-08-26T11:56:09.824254Z\"}]}"}
{"recv_ts_ns":1787745369983118688,"payload":"{\"channel\":\"book\",\"type\":\"update\",\"data\":[{\"symbol\":\"BTC/USD\",\"bids\":[],\"asks\":[{\"price\":78529.5,\"qty\":1.27368782}],\"checksum\":2588379851,\"timestamp\":\"2026-08-26T11:56:09.824780Z\"}]}"}
{"recv_ts_ns":1787745369983180040,"payload":"{\"channel\":\"book\",\"type\":\"update\",\"data\":[{\"symbol\":\"BTC/USD\",\"bids\":[{\"price\":78492.3,\"qty\":0.11943015}],\"asks\":[],\"checksum\":2588379851,\"timestamp\":\"2026-08-26T11:56:09.824808Z\"}]}"}
{"recv_ts_ns":1787745369983251116,"payload":"{\"channel\":\"book\",\"type\":\"update\",\"data\":[{\"symbol\":\"BTC/USD\",\"bids\":[],\"asks\":[{\"price\":78523.1,\"qty\":0.26486751}],\"checksum\":2588379851,\"timestamp\":\"2026-08-26T11:56:09.825518Z\"}]}"}
{"recv_ts_ns":1787745369983303093,"payload":"{\"channel\":\"book\",\"type\":\"update\",\"data\":[{\"symbol\":\"BTC/USD\",\"bids\":[],\"asks\":[{\"price\":78528.1,\"qty\":0.05282761}],\"checksum\":2588379851,\"timestamp\":\"2026-08-26T11:56:09.826127Z\"}]}"}
{"recv_ts_ns":1787745369983373584,"payload":"{\"channel\":\"book\",\"type\":\"update\",\"data\":[{\"symbol\":\"BTC/USD\",\"bids\":[{\"price\":78490.6,\"qty\":0.00000000},{\"price\":78482.7,\"qty\":0.00005000}],\"asks\":[],\"checksum\":2588379851,\"timestamp\":\"2026-08-26T11:56:09.831457Z\"}]}"}
{"recv_ts_ns":1787745369983454087,"payload":"{\"channel\":\"book\",\"type\":\"update\",\"data\":[{\"symbol\":\"BTC/USD\",\"bids\":[],\"asks\":[{\"price\":78528.1,\"qty\":0.42626952}],\"checksum\":2588379851,\"timestamp\":\"2026-08-26T11:56:09.831800Z\"}]}"}
{"recv_ts_ns":1787745369986039052,"payload":"{\"channel\":\"book\",\"type\":\"update\",\"data\":[{\"symbol\":\"BTC/USD\",\"bids\":[],\"asks\":[{\"price\":78516.0,\"qty\":0.01375572}],\"checksum\":2495373134,\"timestamp\":\"2026-08-26T11:56:09.835092Z\"}]}"}
{"recv_ts_ns":1787745369989006148,"payload":"{\"channel\":\"book\",\"type\":\"update\",\"data\":[{\"symbol\":\"BTC/USD\",\"bids\":[{\"price\":78500.2,\"qty\":0.00000000},{\"price\":78482.5,\"qty\":0.01163107}],\"asks\":[],\"checksum\":3399329851,\"timestamp\":\"2026-08-26T11:56:09.836909Z\"}]}"}
{"recv_ts_ns":1787745369989110768,"payload":"{\"channel\":\"book\",\"type\":\"update\",\"data\":[{\"symbol\":\"BTC/USD\",\"bids\":[],\"asks\":[{\"price\":78523.0,\"qty\":0.00000000},{\"price\":78532.1,\"qty\":0.02606386},{\"price\":78522.1,\"qty\":0.15284794}],\"checksum\":3399329851,\"timestamp\":\"2026-08-26T11:56:09.838078Z\"}]}"}
{"recv_ts_ns":1787745369989192935,"payload":"{\"channel\":\"book\",\"type\":\"update\",\"data\":[{\"symbol\":\"BTC/USD\",\"bids\":[{\"price\":78500.4,\"qty\":0.00000000},{\"price\":78481.8,\"qty\":1.81916627}],\"asks\":[],\"checksum\":820812825,\"timestamp\":\"2026-08-26T11:56:09.838131Z\"}]}"}
{"recv_ts_ns":1787745369989278038,"payload":"{\"channel\":\"book\",\"type\":\"update\",\"data\":[{\"symbol\":\"BTC/USD\",\"bids\":[],\"asks\":[{\"price\":78522.3,\"qty\":0.00000000},{\"price\":78532.1,\"qty\":0.02606386}],\"checksum\":820812825,\"timestamp\":\"2026-08-26T11:56:09.838306Z\"}]}"}
{"recv_ts_ns":1787745369993400043,"payload":"{\"channel\":\"book\",\"type\":\"update\",\"data\":[{\"symbol\":\"BTC/USD\",\"bids\":[{\"price\":78493.5,\"qty\":0.04310600}],\"asks\":[],\"checksum\":2024954729,\"timestamp\":\"2026-08-26T11:56:09.839425Z\"}]}"}
{"recv_ts_ns":1787745369996911300,"payload":"{\"channel\":\"book\",\"type\":\"update\",\"data\":[{\"symbol\":\"BTC/USD\",\"bids\":[],\"asks\":[{\"price\":78516.1,\"qty\":0.00000000},{\"price\":78532.5,\"qty\":0.02292044},{\"price\":78515.9,\"qty\":0.04603180}],\"checksum\":1267421704,\"timestamp\":\"2026-08-26T11:56:09.841828Z\"}]}"}
{"recv_ts_ns":1787745369997037078,"payload":"{\"channel\":\"book\",\"type\":\"update\",\"data\":[{\"symbol\":\"BTC/USD\",\"bids\":[],\"asks\":[{\"price\":78529.4,\"qty\":0.63670491}],\"checksum\":1267421704,\"timestamp\":\"2026-08-26T11:56:09.843933Z\"}]}"}
{"recv_ts_ns":1787745369997083232,"payload":"{\"channel\":\"book\",\"type\":\"update\",\"data\":[{\"symbol\":\"BTC/USD\",\"bids\":[],\"asks\":[{\"price\":78522.2,\"qty\":0.00000000},{\"price\":78532.1,\"qty\":0.02606386}],\"checksum\":1267421704,\"timestamp\":\"2026-08-26T11:56:09.844606Z\"}]}"}
{"recv_ts_ns":1787745369997145928,"payload":"{\"channel\":\"book\",\"type\":\"update\",\"data\":[{\"symbol\":\"BTC/USD\",\"bids\":[],\"asks\":[{\"price\":78523.5,\"qty\":0.00000000},{\"price\":78532.5,\"qty\":0.02292044}],\"checksum\":1267421704,\"timestamp\":\"2026-08-26T11:56:09.845033Z\"}]}"}
{"recv_ts_ns":1787745370002612372,"payload":"{\"channel\":\"book\",\"type\":\"update\",\"data\":[{\"symbol\":\"BTC/USD\",\"bids\":[],\"asks\":[{\"price\":78532.4,\"qty\":0.03876713}],\"checksum\":1267421704,\"timestamp\":\"2026-08-26T11:56:09.847349Z\"}]}"}
{"recv_ts_ns":1787745370003612396,"payload":"{\"channel\":\"book\",\"type\":\"update\",\"data\":[{\"symbol\":\"BTC/USD\",\"bids\":[],\"asks\":[{\"price\":78516.0,\"qty\":0.00000000},{\"price\":78532.5,\"qty\":0.02292044}],\"checksum\":3329979070,\"timestamp\":\"2026-08-26T11:56:09.848421Z\"}]}"}
{"recv_ts_ns":1787745370006047114,"payload":"{\"channel\":\"book\",\"type\":\"update\",\"data\":[{\"symbol\":\"BTC/USD\",\"bids\":[],\"asks\":[{\"price\":78522.0,\"qty\":0.04562511}],\"checksum\":3329979070,\"timestamp\":\"2026-08-26T11:56:09.852858Z\"}]}"}
{"recv_ts_ns":1787745370009767458,"payload":"{\"channel\":\"book\",\"type\":\"update\",\"data\":[{\"symbol\":\"BTC/USD\",\"bids\":[],\"asks\":[{\"price\":78523.1,\"qty\":0.00000000},{\"price\":78532.5,\"qty\":0.02292044}],\"checksum\":3329979070,\"timestamp\":\"2026-08-26T11:56:09.853113Z\"}]}"}
{"recv_ts_ns":1787745370009923408,"payload":"{\"channel\":\"book\",\"type\":\"update\",\"data\":[{\"symbol\":\"BTC/USD\",\"bids\":[],\"asks\":[{\"price\":78515.8,\"qty\":0.01375572}],\"checksum\":1673531877,\"timestamp\":\"2026-08-26T11:56:09.853284Z\"}]}"}
{"recv_ts_ns":1787745370011456637,"payload":"{\"channel\":\"book\",\"type\":\"update\",\"data\":[{\"symbol\":\"BTC/USD\",\"bids\":[],\"asks\":[{\"price\":78506.7,\"qty\":0.00000000},{\"price\":78532.5,\"qty\":0.02292044}],\"checksum\":4089845269,\"timestamp\":\"2026-08-26T11:56:09.855365Z\"}]}"}
{"recv_ts_ns":1787745370011563782,"payload":"{\"channel\":\"book\",\"type\":\"update\",\"data\":[{\"symbol\":\"BTC/USD\",\"bids\":[],\"asks\":[{\"price\":78504.6,\"qty\":0.01565551}],\"checksum\":298920774,\"timestamp\":\"2026-08-26T11:56:09.855499Z\"}]}"}
{"recv_ts_ns":1787745370021015652,"payload":"{\"channel\":\"book\",\"type\":\"update\",\"data\":[{\"symbol\":\"BTC/USD\",\"bids\":[],\"asks\":[{\"price\":78529.4,\"qty\":0.00000000},{\"price\":78532.5,\"qty\":0.02292044}],\"checksum\":298920774,\"timestamp\":\"2026-08-26T11:56:09.866164Z\"}]}"}
{"recv_ts_ns":1787745370021129615,"payload":"{\"channel\":\"book\",\"type\":\"update\",\"data\":[{\"symbol\":\"BTC/USD\",\"bids\":[{\"price\":78500.6,\"qty\":0.62465388},{\"price\":78498.8,\"qty\":3.03148619}],\"asks\":[],\"checksum\":1908206335,\"timestamp\":\"2026-08-26T11:56:09.866501Z\"}]}"}
{"recv_ts_ns":1787745370021217067,"payload":"{\"channel\":\"book\",\"type\":\"update\",\"data\":[{\"symbol\":\"BTC/USD\",\"bids\":[],\"asks\":[{\"price\":78522.1,\"qty\":0.00000000},{\"price\":78532.8,\"qty\":0.00254670},{\"price\":78524.3,\"qty\":0.16797659}],\"checksum\":1908206335,\"timestamp\":\"2026-08-26T11:56:09.867354Z\"}]}"}
{"recv_ts_ns":1787745370021303220,"payload":"{\"channel\":\"book\",\"type\":\"update\",\"data\":[{\"symbol\":\"BTC/USD\",\"bids\":[],\"asks\":[{\"price\":78515.9,\"qty\":1.00146236}],\"checksum\":2420539128,\"timestamp\":\"2026-08-26T11:56:09.868818Z\"}]}"}
{"recv_ts_ns":1787745370028132317,"payload":"{\"channel\":\"book\",\"type\":\"update\",\"data\":[{\"symbol\":\"BTC/USD\",\"bids\":[],\"asks\":[{\"price\":78524.2,\"qty\":0.05495698}],\"checksum\":2420539128,\"timestamp\":\"2026-08-26T11:56:09.871364Z\"}]}"}
{"recv_ts_ns":1787745370028263475,"payload":"{\"channel\":\"book\",\"type\":\"update\",\"data\":[{\"symbol\":\"BTC/USD\",\"bids\":[],\"asks\":[{\"price\":78515.8,\"qty\":0.29719310}],\"checksum\":1837018956,\"timestamp\":\"2026-08-26T11:56:09.871584Z\"}]}"}
{"recv_ts_ns":1787745370028342313,"payload":"{\"channel\":\"book\",\"type\":\"update\",\"data\":[{\"symbol\":\"BTC/USD\",\"bids\":[{\"price\":78500.6,\"qty\":1.22620611}],\"asks\":[],\"checksum\":2787488034,\"timestamp\":\"2026-08-26T11:56:09.871698Z\"}]}"}
{"recv_ts_ns":1787745370028451481,"payload":"{\"channel\":\"book\",\"type\":\"update\",\"data\":[{\"symbol\":\"BTC/USD\",\"bids\":[],\"asks\":[{\"price\":78522.0,\"qty\":0.00000000},{\"price\":78532.8,\"qty\":0.00254670}],\"checksum\":2787488034,\"timestamp\":\"2026-08-26T11:56:09.871739Z\"}]}"}
{"recv_ts_ns":1787745370028539587,"payload":"{\"channel\":\"book\",\"type\":\"update\",\"data\":[{\"symbol\":\"BTC/USD\",\"bids\":[{\"price\":78490.6,\"qty\":0.77260883}],\"asks\":[],\"checksum\":2787488034,\"timestamp\":\"2026-08-26T11:56:09.874708Z\"}]}"}
{"recv_ts_ns":1787745370038199748,"payload":"{\"channel\":\"book\",\"type\":\"update\",\"data\":[{\"symbol\":\"BTC/USD\",\"bids\":[{\"price\":78498.8,\"qty\":0.00000000},{\"price\":78482.7,\"qty\":0.00005000},{\"price\":78495.8,\"qty\":3.03154505}],\"asks\":[],\"checksum\":1021343061,\"timestamp\":\"2026-08-26T11:56:09.891878Z\"}]}"}
{"recv_ts_ns":1787745370038354966,"payload":"{\"channel\":\"book\",\"type\":\"update\",\"data\":[{\"symbol\":\"BTC/USD\",\"bids\":[{\"price\":78492.2,\"qty\":0.40000000},{\"price\":78493.3,\"qty\":0.00010100}],\"asks\":[],\"checksum\":1021343061,\"timestamp\":\"2026-08-26T11:56:09.892528Z\"}]}"}
{"recv_ts_ns":1787745370040070868,"payload":"{\"channel\":\"book\",\"type\":\"update\",\"data\":[{\"symbol\":\"BTC/USD\",\"bids\":[],\"asks\":[{\"price\":78524.3,\"qty\":0.01512865},{\"price\":78525.5,\"qty\":0.16577268}],\"checksum\":1021343061,\"timestamp\":\"2026-08-26T11:56:09.893316Z\"}]}"}
{"recv_ts_ns":1787745370045190543,"payload":"{\"channel\":\"book\",\"type\":\"update\",\"data\":[{\"symbol\":\"BTC/USD\",\"bids\":[{\"price\":78490.0,\"qty\":0.00000000},{\"price\":78484.7,\"qty\":0.05060000}],\"asks\":[],\"checksum\":1021343061,\"timestamp\":\"2026-08-26T11:56:09.899294Z\"}]}"}
{"recv_ts_ns":1787745370057892203,"payload":"{\"channel\":\"book\",\"type\":\"update\",\"data\":[{\"symbol\":\"BTC/USD\",\"bids\":[{\"price\":78495.8,\"qty\":0.00000000},{\"price\":78482.7,\"qty\":0.00005000},{\"price\":78498.8,\"qty\":3.03148501}],\"asks\":[],\"checksum\":325930592,\"timestamp\":\"2026-08-26T11:56:09.911806Z\"}]}"}
{"recv_ts_ns":1787745370093434187,"payload":"{\"channel\":\"book\",\"type\":\"update\",\"data\":[{\"symbol\":\"BTC/USD\",\"bids\":[{\"price\":78500.6,\"qty\":2.18163667}],\"asks\":[],\"checksum\":2572728272,\"timestamp\":\"2026-08-26T11:56:09.948308Z\"}]}"}
{"recv_ts_ns":1787745370111565625,"payload":"{\"channel\":\"book\",\"type\":\"update\",\"data\":[{\"symbol\":\"BTC/USD\",\"bids\":[],\"asks\":[{\"price\":78529.5,\"qty\":0.00000000},{\"price\":78533.7,\"qty\":0.10440600},{\"price\":78532.1,\"qty\":1.29981707}],\"checksum\":2572728272,\"timestamp\":\"2026-08-26T11:56:09.965656Z\"}]}"}
{"recv_ts_ns":1787745370111609316,"payload":"{\"channel\":\"book\",\"type\":\"update\",\"data\":[{\"symbol\":\"BTC/USD\",\"bids\":[{\"price\":78498.9,\"qty\":0.33248162}],\"asks\":[],\"checksum\":3290567429,\"timestamp\":\"2026-08-26T11:56:09.967007Z\"}]}"}
{"recv_ts_ns":1787745370113110142,"payload":"{\"channel\":\"book\",\"type\":\"update\",\"data\":[{\"symbol\":\"BTC/USD\",\"bids\":[],\"asks\":[{\"price\":78528.1,\"qty\":0.05282761}],\"checksum\":3290567429,\"timestamp\":\"2026-08-26T11:56:09.967057Z\"}]}"}
{"recv_ts_ns":1787745370162126073,"payload":"{\"channel\":\"book\",\"type\":\"update\",\"data\":[{\"symbol\":\"BTC/USD\",\"bids\":[],\"asks\":[{\"price\":78532.1,\"qty\":0.02606386}],\"checksum\":3290567429,\"timestamp\":\"2026-08-26T11:56:10.013973Z\"}]}"}
{"recv_ts_ns":1787745370162293070,"payload":"{\"channel\":\"book\",\"type\":\"update\",\"data\":[{\"symbol\":\"BTC/USD\",\"bids\":[],\"asks\":[{\"price\":78515.9,\"qty\":0.95543056},{\"price\":78515.7,\"qty\":0.04603180}],\"checksum\":2233690758,\"timestamp\":\"2026-08-26T11:56:10.015562Z\"}]}"}
{"recv_ts_ns":1787745370162634644,"payload":"{\"channel\":\"book\",\"type\":\"update\",\"data\":[{\"symbol\":\"BTC/USD\",\"bids\":[],\"asks\":[{\"price\":78525.5,\"qty\":0.01292474},{\"price\":78524.3,\"qty\":0.16797659}],\"checksum\":2233690758,\"timestamp\":\"2026-08-26T11:56:10.016678Z\"}]}"}
{"recv_ts_ns":1787745370178446153,"payload":"{\"channel\":\"book\",\"type\":\"update\",\"data\":[{\"symbol\":\"BTC/USD\",\"bids\":[{\"price\":78498.8,\"qty\":0.00000000},{\"price\":78484.7,\"qty\":0.05060000},{\"price\":78495.8,\"qty\":3.03153327}],\"asks\":[],\"checksum\":2123096717,\"timestamp\":\"2026-08-26T11:56:10.032208Z\"}]}"}
{"recv_ts_ns":1787745370204585775,"payload":"{\"channel\":\"book\",\"type\":\"update\",\"data\":[{\"symbol\":\"BTC/USD\",\"bids\":[],\"asks\":[{\"price\":78516.9,\"qty\":0.85606579}],\"checksum\":1605891810,\"timestamp\":\"2026-08-26T11:56:10.059265Z\"}]}"}
{"recv_ts_ns":1787745370206271667,"payload":"{\"channel\":\"book\",\"type\":\"update\",\"data\":[{\"symbol\":\"BTC/USD\",\"bids\":[],\"asks\":[{\"price\":78524.3,\"qty\":0.01512865},{\"price\":78524.2,\"qty\":0.20780492}],\"checksum\":1605891810,\"timestamp\":\"2026-08-26T11:56:10.060490Z\"}]}"}
{"recv_ts_ns":1787745370210816766,"payload":"{\"channel\":\"book\",\"type\":\"update\",\"data\":[{\"symbol\":\"BTC/USD\",\"bids\":[],\"asks\":[{\"price\":78515.8,\"qty\":0.28343738}],\"checksum\":1448708632,\"timestamp\":\"2026-08-26T11:56:10.060711Z\"}]}"}
{"recv_ts_ns":1787745370210949495,"payload":"{\"channel\":\"book\",\"type\":\"update\",\"data\":[{\"symbol\":\"BTC/USD\",\"bids\":[],\"asks\":[{\"price\":78532.4,\"qty\":0.41402636}],\"checksum\":1448708632,\"timestamp\":\"2026-08-26T11:56:10.060754Z\"}]}"}
{"recv_ts_ns":1787745370211019627,"payload":"{\"channel\":\"book\",\"type\":\"update\",\"data\":[{\"symbol\":\"BTC/USD\",\"bids\":[],\"asks\":[{\"price\":78515.8,\"qty\":0.00000000},{\"price\":78532.8,\"qty\":0.00254670}],\"checksum\":1861105480,\"timestamp\":\"2026-08-26T11:56:10.061094Z\"}]}"}
{"recv_ts_ns":1787745370213608753,"payload":"{\"channel\":\"book\",\"type\":\"update\",\"data\":[{\"symbol\":\"BTC/USD\",\"bids\":[],\"asks\":[{\"price\":78524.2,\"qty\":0.15284794}],\"checksum\":1861105480,\"timestamp\":\"2026-08-26T11:56:10.063085Z\"}]}"}
{"recv_ts_ns":1787745370213783471,"payload":"{\"channel\":\"book\",\"type\":\"update\",\"data\":[{\"symbol\":\"BTC/USD\",\"bids\":[],\"asks\":[{\"price\":78515.8,\"qty\":0.54074688}],\"checksum\":3309496842,\"timestamp\":\"2026-08-26T11:56:10.063553Z\"}]}"}
{"recv_ts_ns":1787745370213847763,"payload":"{\"channel\":\"book\",\"type\":\"update\",\"data\":[{\"symbol\":\"BTC/USD\",\"bids\":[],\"asks\":[{\"price\":78524.1,\"qty\":0.05495698}],\"checksum\":3309496842,\"timestamp\":\"2026-08-26T11:56:10.063727Z\"}]}"}
{"recv_ts_ns":1787745370215539646,"payload":"{\"channel\":\"book\",\"type\":\"update\",\"data\":[{\"symbol\":\"BTC/USD\",\"bids\":[{\"price\":78487.1,\"qty\":1.39411100}],\"asks\":[],\"checksum\":3309496842,\"timestamp\":\"2026-08-26T11:56:10.068071Z\"}]}"}
{"recv_ts_ns":1787745370219030459,"payload":"{\"channel\":\"book\",\"type\":\"update\",\"data\":[{\"symbol\":\"BTC/USD\",\"bids\":[],\"asks\":[{\"price\":78520.8,\"qty\":0.63677431}],\"checksum\":3309496842,\"timestamp\":\"2026-08-26T11:56:10.072891Z\"}]}"}
{"recv_ts_ns":1787745370220994409,"payload":"{\"channel\":\"book\",\"type\":\"update\",\"data\":[{\"symbol\":\"BTC/USD\",\"bids\":[{\"price\":78495.8,\"qty\":0.00000000},{\"price\":78484.7,\"qty\":0.05060000},{\"price\":78500.6,\"qty\":5.21308462}],\"asks\":[],\"checksum\":2405444324,\"timestamp\":\"2026-08-26T11:56:10.073475Z\"}]}"}
{"recv_ts_ns":1787745370222289328,"payload":"{\"channel\":\"book\",\"type\":\"update\",\"data\":[{\"symbol\":\"BTC/USD\",\"bids\":[],\"asks\":[{\"price\":78520.7,\"qty\":0.19007713}],\"checksum\":2405444324,\"timestamp\":\"2026-08-26T11:56:10.075045Z\"}]}"}
{"recv_ts_ns":1787745370222392036,"payload":"{\"channel\":\"book\",\"type\":\"update\",\"data\":[{\"symbol\":\"BTC/USD\",\"bids\":[{\"price\":78500.6,\"qty\":5.13508462}],\"asks\":[],\"checksum\":943544148,\"timestamp\":\"2026-08-26T11:56:10.075632Z\"}]}"}
{"recv_ts_ns":1787745370232756406,"payload":"{\"channel\":\"book\",\"type\":\"update\",\"data\":[{\"symbol\":\"BTC/USD\",\"bids\":[],\"asks\":[{\"price\":78524.2,\"qty\":0.00000000},{\"price\":78532.1,\"qty\":0.02606386},{\"price\":78519.7,\"qty\":0.15284794}],\"checksum\":943544148,\"timestamp\":\"2026-08-26T11:56:10.087785Z\"}]}"}
{"recv_ts_ns":1787745370234017636,"payload":"{\"channel\":\"book\",\"type\":\"update\",\"data\":[{\"symbol\":\"BTC/USD\",\"bids\":[],\"asks\":[{\"price\":78524.1,\"qty\":0.00000000},{\"price\":78532.1,\"qty\":0.02606386}],\"checksum\":943544148,\"timestamp\":\"2026-08-26T11:56:10.089025Z\"}]}"}
{"recv_ts_ns":1787745370248542623,"payload":"{\"channel\":\"book\",\"type\":\"update\",\"data\":[{\"symbol\":\"BTC/USD\",\"bids\":[],\"asks\":[{\"price\":78515.8,\"qty\":0.00000000},{\"price\":78532.4,\"qty\":0.41402636}],\"checksum\":2747979996,\"timestamp\":\"2026-08-26T11:56:10.102837Z\"}]}"}
{"recv_ts_ns":1787745370274481353,"payload":"{\"channel\":\"book\",\"type\":\"update\",\"data\":[{\"symbol\":\"BTC/USD\",\"bids\":[],\"asks\":[{\"price\":78519.7,\"qty\":0.00000000},{\"price\":78532.5,\"qty\":0.02292044}],\"checksum\":3753429467,\"timestamp\":\"2026-08-26T11:56:10.129350Z\"}]}"}
{"recv_ts_ns":1787745370280797022,"payload":"{\"channel\":\"book\",\"type\":\"update\",\"data\":[{\"symbol\":\"BTC/USD\",\"bids\":[{\"price\":78500.6,\"qty\":2.10363667},{\"price\":78495.8,\"qty\":3.03153696}],\"asks\":[],\"checksum\":2505854859,\"timestamp\":\"2026-08-26T11:56:10.133507Z\"}]}"}
{"recv_ts_ns":1787745370282370588,"payload":"{\"channel\":\"book\",\"type\":\"update\",\"data\":[{\"symbol\":\"BTC/USD\",\"bids\":[{\"price\":78500.6,\"qty\":2.18163667}],\"asks\":[],\"checksum\":2842430387,\"timestamp\":\"2026-08-26T11:56:10.135307Z\"}]}"}
{"recv_ts_ns":1787745370293625255,"payload":"{\"channel\":\"book\",\"type\":\"update\",\"data\":[{\"symbol\":\"BTC/USD\",\"bids\":[{\"price\":78495.8,\"qty\":0.00000000},{\"price\":78484.7,\"qty\":0.05060000},{\"price\":78498.8,\"qty\":3.03153148}],\"asks\":[],\"checksum\":1730479410,\"timestamp\":\"2026-08-26T11:56:10.148244Z\"}]}"}
{"recv_ts_ns":1787745370294836276,"payload":"{\"channel\":\"book\",\"type\":\"update\",\"data\":[{\"symbol\":\"BTC/USD\",\"bids\":[],\"asks\":[{\"price\":78515.7,\"qty\":0.00000000},{\"price\":78532.8,\"qty\":0.00254670},{\"price\":78515.8,\"qty\":0.04603180}],\"checksum\":426244175,\"timestamp\":\"2026-08-26T11:56:10.149427Z\"}]}"}
{"recv_ts_ns":1787745370296858107,"payload":"{\"channel\":\"book\",\"type\":\"update\",\"data\":[{\"symbol\":\"BTC/USD\",\"bids\":[{\"price\":78499.5,\"qty\":0.85606579}],\"asks\":[],\"checksum\":1797343038,\"timestamp\":\"2026-08-26T11:56:10.151845Z\"}]}"}
{"recv_ts_ns":1787745370296933799,"payload":"{\"channel\":\"book\",\"type\":\"update\",\"data\":[{\"symbol\":\"BTC/USD\",\"bids\":[],\"asks\":[{\"price\":78532.5,\"qty\":0.87898623}],\"checksum\":1797343038,\"timestamp\":\"2026-08-26T11:56:10.151915Z\"}]}"}
{"recv_ts_ns":1787745370300055614,"payload":"{\"channel\":\"book\",\"type\":\"update\",\"data\":[{\"symbol\":\"BTC/USD\",\"bids\":[],\"asks\":[{\"price\":78532.4,\"qty\":0.37525923}],\"checksum\":1797343038,\"timestamp\":\"2026-08-26T11:56:10.153880Z\"}]}"}
{"recv_ts_ns":1787745370300153119,"payload":"{\"channel\":\"book\",\"type\":\"update\",\"data\":[{\"symbol\":\"BTC/USD\",\"bids\":[],\"asks\":[{\"price\":78532.4,\"qty\":0.99684508}],\"checksum\":1797343038,\"timestamp\":\"2026-08-26T11:56:10.154019Z\"}]}"}
{"recv_ts_ns":1787745370300203644,"payload":"{\"channel\":\"book\",\"type\":\"update\",\"data\":[{\"symbol\":\"BTC/USD\",\"bids\":[],\"asks\":[{\"price\":78532.4,\"qty\":0.62158585}],\"checksum\":1797343038,\"timestamp\":\"2026-08-26T11:56:10.154052Z\"}]}"}
{"recv_ts_ns":1787745370435065461,"payload":"{\"channel\":\"book\",\"type\":\"update\",\"data\":[{\"symbol\":\"BTC/USD\",\"bids\":[],\"asks\":[{\"price\":78515.8,\"qty\":0.58677868}],\"checksum\":1163168763,\"timestamp\":\"2026-08-26T11:56:10.289381Z\"}]}"}
{"recv_ts_ns":1787745370556847586,"payload":"{\"channel\":\"book\",\"type\":\"update\",\"data\":[{\"symbol\":\"BTC/USD\",\"bids\":[{\"price\":78493.5,\"qty\":0.00000000},{\"price\":78484.8,\"qty\":0.00005100}],\"asks\":[],\"checksum\":1163168763,\"timestamp\":\"2026-08-26T11:56:10.408671Z\"}]}"}
{"recv_ts_ns":1787745370556993008,"payload":"{\"channel\":\"book\",\"type\":\"update\",\"data\":[{\"symbol\":\"BTC/USD\",\"bids\":[{\"price\":78500.6,\"qty\":2.22485267}],\"asks\":[],\"checksum\":1230880245,\"timestamp\":\"2026-08-26T11:56:10.410159Z\"}]}"}
{"recv_ts_ns":1787745370557035433,"payload":"{\"channel\":\"book\",\"type\":\"update\",\"data\":[{\"symbol\":\"BTC/USD\",\"bids\":[],\"asks\":[{\"price\":78515.8,\"qty\":0.54074688},{\"price\":78515.7,\"qty\":0.04603180}],\"checksum\":3516641837,\"timestamp\":\"2026-08-26T11:56:10.410178Z\"}]}"}
{"recv_ts_ns":1787745370727303578,"payload":"{\"channel\":\"book\",\"type\":\"update\",\"data\":[{\"symbol\":\"BTC/USD\",\"bids\":[],\"asks\":[{\"price\":78515.9,\"qty\":0.00000000},{\"price\":78532.5,\"qty\":0.87898623}],\"checksum\":786969441,\"timestamp\":\"2026-08-26T11:56:10.580749Z\"}]}"}
{"recv_ts_ns":1787745370728134920,"payload":"{\"channel\":\"book\",\"type\":\"update\",\"data\":[{\"symbol\":\"BTC/USD\",\"bids\":[],\"asks\":[{\"price\":78515.8,\"qty\":0.00000000},{\"price\":78532.8,\"qty\":0.00254670}],\"checksum\":2602086462,\"timestamp\":\"2026-08-26T11:56:10.582120Z\"}]}"}
{"recv_ts_ns":1787745370728259846,"payload":"{\"channel\":\"book\",\"type\":\"update\",\"data\":[{\"symbol\":\"BTC/USD\",\"bids\":[],\"asks\":[{\"price\":78515.7,\"qty\":0.00000000},{\"price\":78533.7,\"qty\":0.10440600},{\"price\":78516.1,\"qty\":0.04603180}],\"checksum\":2889779152,\"timestamp\":\"2026-08-26T11:56:10.583445Z\"}]}"}
{"recv_ts_ns":1787745370728360284,"payload":"{\"channel\":\"book\",\"type\":\"update\",\"data\":[{\"symbol\":\"BTC/USD\",\"bids\":[],\"asks\":[{\"price\":78516.8,\"qty\":0.25553564}],\"checksum\":3768393593,\"timestamp\":\"2026-08-26T11:56:10.583837Z\"}]}"}
{"recv_ts_ns":1787745370764954029,"payload":"{\"channel\":\"book\",\"type\":\"update\",\"data\":[{\"symbol\":\"BTC/USD\",\"bids\":[],\"asks\":[{\"price\":78516.9,\"qty\":1.81149635}],\"checksum\":3135745324,\"timestamp\":\"2026-08-26T11:56:10.619780Z\"}]}"}
{"recv_ts_ns":1787745370796489526,"payload":"{\"channel\":\"book\",\"type\":\"update\",\"data\":[{\"symbol\":\"BTC/USD\",\"bids\":[],\"asks\":[{\"price\":78516.9,\"qty\":0.85606579}],\"checksum\":3768393593,\"timestamp\":\"2026-08-26T11:56:10.648584Z\"}]}"}
{"recv_ts_ns":1787745370817241924,"payload":"{\"channel\":\"book\",\"type\":\"update\",\"data\":[{\"symbol\":\"BTC/USD\",\"bids\":[],\"asks\":[{\"price\":78517.0,\"qty\":0.95543056}],\"checksum\":3277292727,\"timestamp\":\"2026-08-26T11:56:10.670121Z\"}]}"}
{"recv_ts_ns":1787745370838204033,"payload":"{\"channel\":\"book\",\"type\":\"update\",\"data\":[{\"symbol\":\"BTC/USD\",\"bids\":[{\"price\":78498.8,\"qty\":0.00000000},{\"price\":78484.7,\"qty\":0.05060000},{\"price\":78500.6,\"qty\":5.25629532}],\"asks\":[],\"checksum\":528397804,\"timestamp\":\"2026-08-26T11:56:10.691737Z\"}]}"}
{"recv_ts_ns":1787745370865644601,"payload":"{\"channel\":\"book\",\"type\":\"update\",\"data\":[{\"symbol\":\"BTC/USD\",\"bids\":[{\"price\":78500.6,\"qty\":2.22485267},{\"price\":78499.0,\"qty\":3.03152346}],\"asks\":[],\"checksum\":2936907690,\"timestamp\":\"2026-08-26T11:56:10.720725Z\"}]}"}
{"recv_ts_ns":1787745370878143049,"payload":"{\"channel\":\"book\",\"type\":\"update\",\"data\":[{\"symbol\":\"BTC/USD\",\"bids\":[{\"price\":78500.6,\"qty\":2.25033018}],\"asks\":[],\"checksum\":3252703780,\"timestamp\":\"2026-08-26T11:56:10.732193Z\"}]}"}
{"recv_ts_ns":1787745370927315949,"payload":"{\"channel\":\"heartbeat\"}"}
{"recv_ts_ns":1787745371121840883,"payload":"{\"channel\":\"book\",\"type\":\"update\",\"data\":[{\"symbol\":\"BTC/USD\",\"bids\":[],\"asks\":[{\"price\":78522.4,\"qty\":0.63676101}],\"checksum\":3252703780,\"timestamp\":\"2026-08-26T11:56:10.907132Z\"}]}"}
{"recv_ts_ns":1787745371121951071,"payload":"{\"channel\":\"book\",\"type\":\"update\",\"data\":[{\"symbol\":\"BTC/USD\",\"bids\":[],\"asks\":[{\"price\":78526.6,\"qty\":0.63672749}],\"checksum\":3252703780,\"timestamp\":\"2026-08-26T11:56:10.907415Z\"}]}"}
{"recv_ts_ns":1787745371121982962,"payload":"{\"channel\":\"book\",\"type\":\"update\",\"data\":[{\"symbol\":\"BTC/USD\",\"bids\":[],\"asks\":[{\"price\":78528.1,\"qty\":0.00000000},{\"price\":78532.1,\"qty\":0.02606386}],\"checksum\":3252703780,\"timestamp\":\"2026-08-26T11:56:10.909780Z\"}]}"}
{"recv_ts_ns":1787745371122008785,"payload":"{\"channel\":\"book\",\"type\":\"update\",\"data\":[{\"symbol\":\"BTC/USD\",\"bids\":[],\"asks\":[{\"price\":78516.8,\"qty\":0.50806193}],\"checksum\":2925306542,\"timestamp\":\"2026-08-26T11:56:10.911917Z\"}]}"}
{"recv_ts_ns":1787745371122041734,"payload":"{\"channel\":\"book\",\"type\":\"update\",\"data\":[{\"symbol\":\"BTC/USD\",\"bids\":[],\"asks\":[{\"price\":78531.5,\"qty\":0.02547148}],\"checksum\":2925306542,\"timestamp\":\"2026-08-26T11:56:10.959871Z\"}]}"}
{"recv_ts_ns":1787745371122086370,"payload":"{\"channel\":\"book\",\"type\":\"update\",\"data\":[{\"symbol\":\"BTC/USD\",\"bids\":[],\"asks\":[{\"price\":78517.0,\"qty\":0.00000000},{\"price\":78532.1,\"qty\":0.02606386}],\"checksum\":4004356668,\"timestamp\":\"2026-08-26T11:56:10.966024Z\"}]}"}
{"recv_ts_ns":1787745371151043919,"payload":"{\"channel\":\"book\",\"type\":\"update\",\"data\":[{\"symbol\":\"BTC/USD\",\"bids\":[],\"asks\":[{\"price\":78516.8,\"qty\":0.25553564}],\"checksum\":3794455018,\"timestamp\":\"2026-08-26T11:56:10.967576Z\"}]}"}
{"recv_ts_ns":1787745371151202542,"payload":"{\"channel\":\"book\",\"type\":\"update\",\"data\":[{\"symbol\":\"BTC/USD\",\"bids\":[],\"asks\":[{\"price\":78520.7,\"qty\":0.35584931}],\"checksum\":3794455018,\"timestamp\":\"2026-08-26T11:56:10.968889Z\"}]}"}
{"recv_ts_ns":1787745371151244062,"payload":"{\"channel\":\"book\",\"type\":\"update\",\"data\":[{\"symbol\":\"BTC/USD\",\"bids\":[],\"asks\":[{\"price\":78517.8,\"qty\":0.95543056}],\"checksum\":791229837,\"timestamp\":\"2026-08-26T11:56:10.970697Z\"}]}"}
{"recv_ts_ns":1787745371151277163,"payload":"{\"channel\":\"book\",\"type\":\"update\",\"data\":[{\"symbol\":\"BTC/USD\",\"bids\":[],\"asks\":[{\"price\":78516.8,\"qty\":0.50806193}],\"checksum\":1083557127,\"timestamp\":\"2026-08-26T11:56:10.972644Z\"}]}"}
{"recv_ts_ns":1787745371302167179,"payload":"{\"channel\":\"book\",\"type\":\"update\",\"data\":[{\"symbol\":\"BTC/USD\",\"bids\":[{\"price\":78500.6,\"qty\":2.22485267}],\"asks\":[],\"checksum\":779628681,\"timestamp\":\"2026-08-26T11:56:11.156733Z\"}]}"}
{"recv_ts_ns":1787745371302447601,"payload":"{\"channel\":\"book\",\"type\":\"update\",\"data\":[{\"symbol\":\"BTC/USD\",\"bids\":[],\"asks\":[{\"price\":78519.7,\"qty\":0.15284794}],\"checksum\":779628681,\"timestamp\":\"2026-08-26T11:56:11.158067Z\"}]}"}
{"recv_ts_ns":1787745371436106349,"payload":"{\"channel\":\"book\",\"type\":\"update\",\"data\":[{\"symbol\":\"BTC/USD\",\"bids\":[{\"price\":78487.1,\"qty\":0.12000864}],\"asks\":[],\"checksum\":779628681,\"timestamp\":\"2026-08-26T11:56:11.163423Z\"}]}"}
{"recv_ts_ns":1787745371436260302,"payload":"{\"channel\":\"book\",\"type\":\"update\",\"data\":[{\"symbol\":\"BTC/USD\",\"bids\":[],\"asks\":[{\"price\":78520.8,\"qty\":0.00000000},{\"price\":78531.5,\"qty\":0.02547148}],\"checksum\":779628681,\"timestamp\":\"2026-08-26T11:56:11.279298Z\"}]}"}
{"recv_ts_ns":1787745371436309886,"payload":"{\"channel\":\"book\",\"type\":\"update\",\"data\":[{\"symbol\":\"BTC/USD\",\"bids\":[],\"asks\":[{\"price\":78520.7,\"qty\":0.19007713}],\"checksum\":779628681,\"timestamp\":\"2026-08-26T11:56:11.280480Z\"}]}"}
{"recv_ts_ns":1787745371436347528,"payload":"{\"channel\":\"book\",\"type\":\"update\",\"data\":[{\"symbol\":\"BTC/USD\",\"bids\":[],\"asks\":[{\"price\":78520.0,\"qty\":0.65872674}],\"checksum\":779628681,\"timestamp\":\"2026-08-26T11:56:11.280715Z\"}]}"}
{"recv_ts_ns":1787745371436415485,"payload":"{\"channel\":\"book\",\"type\":\"update\",\"data\":[{\"symbol\":\"BTC/USD\",\"bids\":[],\"asks\":[{\"price\":78519.9,\"qty\":0.39004103}],\"checksum\":779628681,\"timestamp\":\"2026-08-26T11:56:11.281998Z\"}]}"}
{"recv_ts_ns":1787745371436477785,"payload":"{\"channel\":\"book\",\"type\":\"update\",\"data\":[{\"symbol\":\"BTC/USD\",\"bids\":[],\"asks\":[{\"price\":78520.7,\"qty\":0.00000000},{\"price\":78531.5,\"qty\":0.02547148}],\"checksum\":779628681,\"timestamp\":\"2026-08-26T11:56:11.282034Z\"}]}"}
{"recv_ts_ns":1787745371436549633,"payload":"{\"channel\":\"book\",\"type\":\"update\",\"data\":[{\"symbol\":\"BTC/USD\",\"bids\":[],\"asks\":[{\"price\":78519.7,\"qty\":0.00000000},{\"price\":78532.1,\"qty\":0.02606386},{\"price\":78522.3,\"qty\":0.15284794}],\"checksum\":779628681,\"timestamp\":\"2026-08-26T11:56:11.283166Z\"}]}"}
{"recv_ts_ns":1787745371549718593,"payload":"{\"channel\":\"book\",\"type\":\"update\",\"data\":[{\"symbol\":\"BTC/USD\",\"bids\":[],\"asks\":[{\"price\":78526.5,\"qty\":0.24289077}],\"checksum\":779628681,\"timestamp\":\"2026-08-26T11:56:11.403201Z\"}]}"}
{"recv_ts_ns":1787745371565520722,"payload":"{\"channel\":\"book\",\"type\":\"update\",\"data\":[{\"symbol\":\"BTC/USD\",\"bids\":[],\"asks\":[{\"price\":78520.0,\"qty\":0.02194573}],\"checksum\":779628681,\"timestamp\":\"2026-08-26T11:56:11.419307Z\"}]}"}
{"recv_ts_ns":1787745371565640507,"payload":"{\"channel\":\"book\",\"type\":\"update\",\"data\":[{\"symbol\":\"BTC/USD\",\"bids\":[],\"asks\":[{\"price\":78522.4,\"qty\":0.00000000},{\"price\":78531.5,\"qty\":0.02547148}],\"checksum\":779628681,\"timestamp\":\"2026-08-26T11:56:11.419909Z\"}]}"}
{"recv_ts_ns":1787745371567856258,"payload":"{\"channel\":\"book\",\"type\":\"update\",\"data\":[{\"symbol\":\"BTC/USD\",\"bids\":[],\"asks\":[{\"price\":78519.9,\"qty\":0.00000000},{\"price\":78532.1,\"qty\":0.02606386}],\"checksum\":779628681,\"timestamp\":\"2026-08-26T11:56:11.420764Z\"}]}"}
{"recv_ts_ns":1787745371567949208,"payload":"{\"channel\":\"book\",\"type\":\"update\",\"data\":[{\"symbol\":\"BTC/USD\",\"bids\":[],\"asks\":[{\"price\":78520.8,\"qty\":0.63677419}],\"checksum\":779628681,\"timestamp\":\"2026-08-26T11:56:11.421490Z\"}]}"}
{"recv_ts_ns":1787745371568016890,"payload":"{\"channel\":\"book\",\"type\":\"update\",\"data\":[{\"symbol\":\"BTC/USD\",\"bids\":[],\"asks\":[{\"price\":78523.8,\"qty\":0.63674999}],\"checksum\":779628681,\"timestamp\":\"2026-08-26T11:56:11.421734Z\"}]}"}
{"recv_ts_ns":1787745371568074897,"payload":"{\"channel\":\"book\",\"type\":\"update\",\"data\":[{\"symbol\":\"BTC/USD\",\"bids\":[],\"asks\":[{\"price\":78522.2,\"qty\":0.04562511}],\"checksum\":779628681,\"timestamp\":\"2026-08-26T11:56:11.422103Z\"}]}"}
{"recv_ts_ns":1787745371570417932,"payload":"{\"channel\":\"book\",\"type\":\"update\",\"data\":[{\"symbol\":\"BTC/USD\",\"bids\":[],\"asks\":[{\"price\":78522.2,\"qty\":0.00000000},{\"price\":78529.3,\"qty\":0.11364277}],\"checksum\":779628681,\"timestamp\":\"2026-08-26T11:56:11.422764Z\"}]}"}
{"recv_ts_ns":1787745371570512864,"payload":"{\"channel\":\"book\",\"type\":\"update\",\"data\":[{\"symbol\":\"BTC/USD\",\"bids\":[],\"asks\":[{\"price\":78517.8,\"qty\":0.00000000},{\"price\":78531.5,\"qty\":0.02547148}],\"checksum\":2151700402,\"timestamp\":\"2026-08-26T11:56:11.423011Z\"}]}"}
{"recv_ts_ns":1787745371570567051,"payload":"{\"channel\":\"book\",\"type\":\"update\",\"data\":[{\"symbol\":\"BTC/USD\",\"bids\":[],\"asks\":[{\"price\":78522.3,\"qty\":0.00000000},{\"price\":78532.1,\"qty\":0.02606386}],\"checksum\":2151700402,\"timestamp\":\"2026-08-26T11:56:11.423063Z\"}]}"}
{"recv_ts_ns":1787745371571009587,"payload":"{\"channel\":\"book\",\"type\":\"update\",\"data\":[{\"symbol\":\"BTC/USD\",\"bids\":[],\"asks\":[{\"price\":78520.7,\"qty\":0.23570221}],\"checksum\":2151700402,\"timestamp\":\"2026-08-26T11:56:11.424224Z\"}]}"}
{"recv_ts_ns":1787745371571110207,"payload":"{\"channel\":\"book\",\"type\":\"update\",\"data\":[{\"symbol\":\"BTC/USD\",\"bids\":[{\"price\":78499.0,\"qty\":0.00000000},{\"price\":78484.7,\"qty\":0.05060000},{\"price\":78500.6,\"qty\":5.25628437}],\"asks\":[],\"checksum\":4088167899,\"timestamp\":\"2026-08-26T11:56:11.424253Z\"}]}"}
{"recv_ts_ns":1787745371581003970,"payload":"{\"channel\":\"book\",\"type\":\"update\",\"data\":[{\"symbol\":\"BTC/USD\",\"bids\":[],\"asks\":[{\"price\":78516.8,\"qty\":0.25553564}],\"checksum\":3989592437,\"timestamp\":\"2026-08-26T11:56:11.424673Z\"}]}"}
{"recv_ts_ns":1787745371581148674,"payload":"{\"channel\":\"book\",\"type\":\"update\",\"data\":[{\"symbol\":\"BTC/USD\",\"bids\":[],\"asks\":[{\"price\":78523.7,\"qty\":0.19940174}],\"checksum\":3989592437,\"timestamp\":\"2026-08-26T11:56:11.433378Z\"}]}"}
{"recv_ts_ns":1787745371613757860,"payload":"{\"channel\":\"book\",\"type\":\"update\",\"data\":[{\"symbol\":\"BTC/USD\",\"bids\":[],\"asks\":[{\"price\":78516.9,\"qty\":0.00000000},{\"price\":78531.5,\"qty\":0.02547148}],\"checksum\":4069921558,\"timestamp\":\"2026-08-26T11:56:11.466081Z\"}]}"}
{"recv_ts_ns":1787745371613899886,"payload":"{\"channel\":\"book\",\"type\":\"update\",\"data\":[{\"symbol\":\"BTC/USD\",\"bids\":[],\"asks\":[{\"price\":78516.8,\"qty\":0.00000000},{\"price\":78532.1,\"qty\":0.02606386}],\"checksum\":1708938974,\"timestamp\":\"2026-08-26T11:56:11.467449Z\"}]}"}
{"recv_ts_ns":1787745371617733216,"payload":"{\"channel\":\"book\",\"type\":\"update\",\"data\":[{\"symbol\":\"BTC/USD\",\"bids\":[],\"asks\":[{\"price\":78518.0,\"qty\":0.95543056}],\"checksum\":2510850693,\"timestamp\":\"2026-08-26T11:56:11.470640Z\"}]}"}
{"recv_ts_ns":1787745371621902248,"payload":"{\"channel\":\"book\",\"type\":\"update\",\"data\":[{\"symbol\":\"BTC/USD\",\"bids\":[],\"asks\":[{\"price\":78517.9,\"qty\":0.28519602}],\"checksum\":416145306,\"timestamp\":\"2026-08-26T11:56:11.472217Z\"}]}"}
{"recv_ts_ns":1787745371624809986,"payload":"{\"channel\":\"book\",\"type\":\"update\",\"data\":[{\"symbol\":\"BTC/USD\",\"bids\":[{\"price\":78487.1,\"qty\":1.39411100}],\"asks\":[],\"checksum\":416145306,\"timestamp\":\"2026-08-26T11:56:11.479434Z\"}]}"}
{"recv_ts_ns":1787745371628272968,"payload":"{\"channel\":\"book\",\"type\":\"update\",\"data\":[{\"symbol\":\"BTC/USD\",\"bids\":[{\"price\":78500.6,\"qty\":2.22485267},{\"price\":78499.6,\"qty\":3.03148514}],\"asks\":[],\"checksum\":1981888442,\"timestamp\":\"2026-08-26T11:56:11.483549Z\"}]}"}
{"recv_ts_ns":1787745371719443195,"payload":"{\"channel\":\"book\",\"type\":\"update\",\"data\":[{\"symbol\":\"BTC/USD\",\"bids\":[{\"price\":78487.1,\"qty\":0.12000864}],\"asks\":[],\"checksum\":1981888442,\"timestamp\":\"2026-08-26T11:56:11.571005Z\"}]}"}
{"recv_ts_ns":1787745371794196590,"payload":"{\"channel\":\"book\",\"type\":\"update\",\"data\":[{\"symbol\":\"BTC/USD\",\"bids\":[],\"asks\":[{\"price\":78518.0,\"qty\":0.00000000},{\"price\":78531.5,\"qty\":0.02547148}],\"checksum\":4113269218,\"timestamp\":\"2026-08-26T11:56:11.648531Z\"}]}"}
{"recv_ts_ns":1787745371795952641,"payload":"{\"channel\":\"book\",\"type\":\"update\",\"data\":[{\"symbol\":\"BTC/USD\",\"bids\":[],\"asks\":[{\"price\":78517.9,\"qty\":0.00000000},{\"price\":78532.1,\"qty\":0.02606386}],\"checksum\":1985018670,\"timestamp\":\"2026-08-26T11:56:11.650794Z\"}]}"}
{"recv_ts_ns":1787745371815912097,"payload":"{\"channel\":\"book\",\"type\":\"update\",\"data\":[{\"symbol\":\"BTC/USD\",\"bids\":[],\"asks\":[{\"price\":78518.1,\"qty\":0.95543056}],\"checksum\":3292448670,\"timestamp\":\"2026-08-26T11:56:11.670720Z\"}]}"}
{"recv_ts_ns":1787745371818581586,"payload":"{\"channel\":\"book\",\"type\":\"update\",\"data\":[{\"symbol\":\"BTC/USD\",\"bids\":[],\"asks\":[{\"price\":78518.0,\"qty\":0.28519602}],\"checksum\":2953924488,\"timestamp\":\"2026-08-26T11:56:11.672374Z\"}]}"}
{"recv_ts_ns":1787745371884510903,"payload":"{\"channel\":\"book\",\"type\":\"update\",\"data\":[{\"symbol\":\"BTC/USD\",\"bids\":[{\"price\":78500.6,\"qty\":2.21585267}],\"asks\":[],\"checksum\":1057432101,\"timestamp\":\"2026-08-26T11:56:11.738301Z\"}]}"}
{"recv_ts_ns":1787745371929586434,"payload":"{\"channel\":\"heartbeat\"}"}
{"recv_ts_ns":1787745371941053783,"payload":"{\"channel\":\"book\",\"type\":\"update\",\"data\":[{\"symbol\":\"BTC/USD\",\"bids\":[{\"price\":78500.6,\"qty\":2.24133018}],\"asks\":[],\"checksum\":1934261552,\"timestamp\":\"2026-08-26T11:56:11.796338Z\"}]}"}
{"recv_ts_ns":1787745372052937434,"payload":"{\"channel\":\"book\",\"type\":\"update\",\"data\":[{\"symbol\":\"BTC/USD\",\"bids\":[{\"price\":78499.6,\"qty\":0.00000000},{\"price\":78484.7,\"qty\":0.05060000},{\"price\":78500.6,\"qty\":5.27278495}],\"asks\":[],\"checksum\":330445589,\"timestamp\":\"2026-08-26T11:56:11.906036Z\"}]}"}
{"recv_ts_ns":1787745372060102517,"payload":"{\"channel\":\"book\",\"type\":\"update\",\"data\":[{\"symbol\":\"BTC/USD\",\"bids\":[],\"asks\":[{\"price\":78520.8,\"qty\":0.00000000},{\"price\":78531.5,\"qty\":0.02547148}],\"checksum\":330445589,\"timestamp\":\"2026-08-26T11:56:11.915070Z\"}]}"}
{"recv_ts_ns":1787745372061239571,"payload":"{\"channel\":\"book\",\"type\":\"update\",\"data\":[{\"symbol\":\"BTC/USD\",\"bids\":[],\"asks\":[{\"price\":78526.6,\"qty\":0.00000000},{\"price\":78532.1,\"qty\":0.02606386}],\"checksum\":330445589,\"timestamp\":\"2026-08-26T11:56:11.915487Z\"}]}"}
{"recv_ts_ns":1787745372061268535,"payload":"{\"channel\":\"book\",\"type\":\"update\",\"data\":[{\"symbol\":\"BTC/USD\",\"bids\":[],\"asks\":[{\"price\":78523.8,\"qty\":0.00000000},{\"price\":78532.2,\"qty\":0.06367870}],\"checksum\":330445589,\"timestamp\":\"2026-08-26T11:56:11.915811Z\"}]}"}
{"recv_ts_ns":1787745372066172001,"payload":"{\"channel\":\"book\",\"type\":\"update\",\"data\":[{\"symbol\":\"BTC/USD\",\"bids\":[],\"asks\":[{\"price\":78520.7,\"qty\":0.00000000},{\"price\":78532.5,\"qty\":0.02292044}],\"checksum\":330445589,\"timestamp\":\"2026-08-26T11:56:11.917639Z\"}]}"}
{"recv_ts_ns":1787745372066224964,"payload":"{\"channel\":\"book\",\"type\":\"update\",\"data\":[{\"symbol\":\"BTC/USD\",\"bids\":[],\"asks\":[{\"price\":78526.5,\"qty\":0.00000000},{\"price\":78532.8,\"qty\":0.00254670}],\"checksum\":330445589,\"timestamp\":\"2026-08-26T11:56:11.917683Z\"}]}"}
{"recv_ts_ns":1787745372066256523,"payload":"{\"channel\":\"book\",\"type\":\"update\",\"data\":[{\"symbol\":\"BTC/USD\",\"bids\":[],\"asks\":[{\"price\":78523.9,\"qty\":0.63674922}],\"checksum\":330445589,\"timestamp\":\"2026-08-26T11:56:11.917854Z\"}]}"}
{"recv_ts_ns":1787745372066290769,"payload":"{\"channel\":\"book\",\"type\":\"update\",\"data\":[{\"symbol\":\"BTC/USD\",\"bids\":[],\"asks\":[{\"price\":78525.3,\"qty\":0.63673746}],\"checksum\":330445589,\"timestamp\":\"2026-08-26T11:56:11.918134Z\"}]}"}
{"recv_ts_ns":1787745372066319185,"payload":"{\"channel\":\"book\",\"type\":\"update\",\"data\":[{\"symbol\":\"BTC/USD\",\"bids\":[],\"asks\":[{\"price\":78523.7,\"qty\":0.00000000},{\"price\":78532.5,\"qty\":0.02292044}],\"checksum\":330445589,\"timestamp\":\"2026-08-26T11:56:11.918344Z\"}]}"}
{"recv_ts_ns":1787745372066361450,"payload":"{\"channel\":\"book\",\"type\":\"update\",\"data\":[{\"symbol\":\"BTC/USD\",\"bids\":[],\"asks\":[{\"price\":78529.7,\"qty\":0.63670220}],\"checksum\":330445589,\"timestamp\":\"2026-08-26T11:56:11.918454Z\"}]}"}
{"recv_ts_ns":1787745372066403454,"payload":"{\"channel\":\"book\",\"type\":\"update\",\"data\":[{\"symbol\":\"BTC/USD\",\"bids\":[],\"asks\":[{\"price\":78528.1,\"qty\":0.05282761}],\"checksum\":330445589,\"timestamp\":\"2026-08-26T11:56:11.919867Z\"}]}"}
{"recv_ts_ns":1787745372066430765,"payload":"{\"channel\":\"book\",\"type\":\"update\",\"data\":[{\"symbol\":\"BTC/USD\",\"bids\":[],\"asks\":[{\"price\":78523.8,\"qty\":0.19940151}],\"checksum\":330445589,\"timestamp\":\"2026-08-26T11:56:11.920307Z\"}]}"}
{"recv_ts_ns":1787745372069764267,"payload":"{\"channel\":\"book\",\"type\":\"update\",\"data\":[{\"symbol\":\"BTC/USD\",\"bids\":[],\"asks\":[{\"price\":78523.8,\"qty\":0.36397455}],\"checksum\":330445589,\"timestamp\":\"2026-08-26T11:56:11.920374Z\"}]}"}
{"recv_ts_ns":1787745372069811456,"payload":"{\"channel\":\"book\",\"type\":\"update\",\"data\":[{\"symbol\":\"BTC/USD\",\"bids\":[],\"asks\":[{\"price\":78528.1,\"qty\":0.23612931}],\"checksum\":330445589,\"timestamp\":\"2026-08-26T11:56:11.920754Z\"}]}"}
{"recv_ts_ns":1787745372096375882,"payload":"{\"channel\":\"book\",\"type\":\"update\",\"data\":[{\"symbol\":\"BTC/USD\",\"bids\":[{\"price\":78500.6,\"qty\":5.24730744}],\"asks\":[],\"checksum\":2550598625,\"timestamp\":\"2026-08-26T11:56:11.950777Z\"}]}"}
{"recv_ts_ns":1787745372117557742,"payload":"{\"channel\":\"book\",\"type\":\"update\",\"data\":[{\"symbol\":\"BTC/USD\",\"bids\":[],\"asks\":[{\"price\":78518.1,\"qty\":0.00000000},{\"price\":78532.1,\"qty\":0.02606386}],\"checksum\":713252406,\"timestamp\":\"2026-08-26T11:56:11.972196Z\"}]}"}
{"recv_ts_ns":1787745372119226149,"payload":"{\"channel\":\"book\",\"type\":\"update\",\"data\":[{\"symbol\":\"BTC/USD\",\"bids\":[],\"asks\":[{\"price\":78518.0,\"qty\":0.00000000},{\"price\":78532.2,\"qty\":0.06367870}],\"checksum\":1198680449,\"timestamp\":\"2026-08-26T11:56:11.973603Z\"}]}"}
{"recv_ts_ns":1787745372148371071,"payload":"{\"channel\":\"book\",\"type\":\"update\",\"data\":[{\"symbol\":\"BTC/USD\",\"bids\":[{\"price\":78487.1,\"qty\":1.39411100}],\"asks\":[],\"checksum\":1198680449,\"timestamp\":\"2026-08-26T11:56:12.003311Z\"}]}"}
{"recv_ts_ns":1787745372150718708,"payload":"{\"channel\":\"book\",\"type\":\"update\",\"data\":[{\"symbol\":\"BTC/USD\",\"bids\":[{\"price\":78487.1,\"qty\":1.27410236}],\"asks\":[],\"checksum\":1198680449,\"timestamp\":\"2026-08-26T11:56:12.004866Z\"}]}"}
{"recv_ts_ns":1787745372150867945,"payload":"{\"channel\":\"book\",\"type\":\"update\",\"data\":[{\"symbol\":\"BTC/USD\",\"bids\":[{\"price\":78487.2,\"qty\":0.49764169}],\"asks\":[],\"checksum\":1198680449,\"timestamp\":\"2026-08-26T11:56:12.005108Z\"}]}"}
{"recv_ts_ns":1787745372163168415,"payload":"{\"channel\":\"book\",\"type\":\"update\",\"data\":[{\"symbol\":\"BTC/USD\",\"bids\":[],\"asks\":[{\"price\":78520.1,\"qty\":0.95548156}],\"checksum\":112792588,\"timestamp\":\"2026-08-26T11:56:12.017917Z\"}]}"}
{"recv_ts_ns":1787745372166799471,"payload":"{\"channel\":\"book\",\"type\":\"update\",\"data\":[{\"symbol\":\"BTC/USD\",\"bids\":[],\"asks\":[{\"price\":78520.0,\"qty\":0.31047969}],\"checksum\":1873244487,\"timestamp\":\"2026-08-26T11:56:12.020101Z\"}]}"}
{"recv_ts_ns":1787745372167935074,"payload":"{\"channel\":\"book\",\"type\":\"update\",\"data\":[{\"symbol\":\"BTC/USD\",\"bids\":[],\"asks\":[{\"price\":78523.9,\"qty\":0.00000000},{\"price\":78532.5,\"qty\":0.02292044}],\"checksum\":1873244487,\"timestamp\":\"2026-08-26T11:56:12.022603Z\"}]}"}
{"recv_ts_ns":1787745372168027796,"payload":"{\"channel\":\"book\",\"type\":\"update\",\"data\":[{\"symbol\":\"BTC/USD\",\"bids\":[],\"asks\":[{\"price\":78529.7,\"qty\":0.00000000},{\"price\":78532.8,\"qty\":0.00254670}],\"checksum\":1873244487,\"timestamp\":\"2026-08-26T11:56:12.022861Z\"}]}"}
{"recv_ts_ns":1787745372170906626,"payload":"{\"channel\":\"book\",\"type\":\"update\",\"data\":[{\"symbol\":\"BTC/USD\",\"bids\":[],\"asks\":[{\"price\":78525.3,\"qty\":0.00000000},{\"price\":78533.7,\"qty\":0.10440600}],\"checksum\":1873244487,\"timestamp\":\"2026-08-26T11:56:12.023642Z\"}]}"}
{"recv_ts_ns":1787745372173653989,"payload":"{\"channel\":\"book\",\"type\":\"update\",\"data\":[{\"symbol\":\"BTC/USD\",\"bids\":[],\"asks\":[{\"price\":78526.3,\"qty\":0.63673009}],\"checksum\":1873244487,\"timestamp\":\"2026-08-26T11:56:12.025367Z\"}]}"}
{"recv_ts_ns":1787745372173840758,"payload":"{\"channel\":\"book\",\"type\":\"update\",\"data\":[{\"symbol\":\"BTC/USD\",\"bids\":[],\"asks\":[{\"price\":78523.8,\"qty\":0.16457304}],\"checksum\":1873244487,\"timestamp\":\"2026-08-26T11:56:12.027600Z\"}]}"}
{"recv_ts_ns":1787745372173939939,"payload":"{\"channel\":\"book\",\"type\":\"update\",\"data\":[{\"symbol\":\"BTC/USD\",\"bids\":[{\"price\":78498.9,\"qty\":0.00000000},{\"price\":78484.7,\"qty\":0.05060000}],\"asks\":[],\"checksum\":4130767675,\"timestamp\":\"2026-08-26T11:56:12.027615Z\"}]}"}
{"recv_ts_ns":1787745372174035088,"payload":"{\"channel\":\"book\",\"type\":\"update\",\"data\":[{\"symbol\":\"BTC/USD\",\"bids\":[],\"asks\":[{\"price\":78523.8,\"qty\":0.00000000},{\"price\":78533.7,\"qty\":0.10440600}],\"checksum\":4130767675,\"timestamp\":\"2026-08-26T11:56:12.027840Z\"}]}"}
{"recv_ts_ns":1787745372175827082,"payload":"{\"channel\":\"book\",\"type\":\"update\",\"data\":[{\"symbol\":\"BTC/USD\",\"bids\":[],\"asks\":[{\"price\":78528.1,\"qty\":0.05282761}],\"checksum\":4130767675,\"timestamp\":\"2026-08-26T11:56:12.027937Z\"}]}"}
{"recv_ts_ns":1787745372175943125,"payload":"{\"channel\":\"book\",\"type\":\"update\",\"data\":[{\"symbol\":\"BTC/USD\",\"bids\":[],\"asks\":[{\"price\":78526.2,\"qty\":0.19006393}],\"checksum\":4130767675,\"timestamp\":\"2026-08-26T11:56:12.029266Z\"}]}"}
{"recv_ts_ns":1787745372176037504,"payload":"{\"channel\":\"book\",\"type\":\"update\",\"data\":[{\"symbol\":\"BTC/USD\",\"bids\":[{\"price\":78500.4,\"qty\":0.84076501}],\"asks\":[],\"checksum\":106548353,\"timestamp\":\"2026-08-26T11:56:12.029281Z\"}]}"}
{"recv_ts_ns":1787745372178035657,"payload":"{\"channel\":\"book\",\"type\":\"update\",\"data\":[{\"symbol\":\"BTC/USD\",\"bids\":[{\"price\":78500.6,\"qty\":5.26360742}],\"asks\":[],\"checksum\":1946627102,\"timestamp\":\"2026-08-26T11:56:12.031854Z\"}]}"}
{"recv_ts_ns":1787745372178187112,"payload":"{\"channel\":\"book\",\"type\":\"update\",\"data\":[{\"symbol\":\"BTC/USD\",\"bids\":[],\"asks\":[{\"price\":78526.3,\"qty\":0.00000000},{\"price\":78533.7,\"qty\":0.10440600}],\"checksum\":1946627102,\"timestamp\":\"2026-08-26T11:56:12.032821Z\"}]}"}
{"recv_ts_ns":1787745372180742062,"payload":"{\"channel\":\"book\",\"type\":\"update\",\"data\":[{\"symbol\":\"BTC/USD\",\"bids\":[],\"asks\":[{\"price\":78526.2,\"qty\":0.00000000},{\"price\":78534.1,\"qty\":0.38021553}],\"checksum\":1946627102,\"timestamp\":\"2026-08-26T11:56:12.034952Z\"}]}"}
{"recv_ts_ns":1787745372183372859,"payload":"{\"channel\":\"book\",\"type\":\"update\",\"data\":[{\"symbol\":\"BTC/USD\",\"bids\":[],\"asks\":[{\"price\":78523.4,\"qty\":0.85606579}],\"checksum\":1946627102,\"timestamp\":\"2026-08-26T11:56:12.036403Z\"}]}"}
{"recv_ts_ns":1787745372183469876,"payload":"{\"channel\":\"book\",\"type\":\"update\",\"data\":[{\"symbol\":\"BTC/USD\",\"bids\":[],\"asks\":[{\"price\":78520.1,\"qty\":0.00005100}],\"checksum\":3236376800,\"timestamp\":\"2026-08-26T11:56:12.036632Z\"}]}"}
{"recv_ts_ns":1787745372183533720,"payload":"{\"channel\":\"book\",\"type\":\"update\",\"data\":[{\"symbol\":\"BTC/USD\",\"bids\":[],\"asks\":[{\"price\":78520.0,\"qty\":0.02194573}],\"checksum\":1557279960,\"timestamp\":\"2026-08-26T11:56:12.037878Z\"}]}"}
{"recv_ts_ns":1787745372186929627,"payload":"{\"channel\":\"book\",\"type\":\"update\",\"data\":[{\"symbol\":\"BTC/USD\",\"bids\":[],\"asks\":[{\"price\":78523.3,\"qty\":0.26486751}],\"checksum\":1557279960,\"timestamp\":\"2026-08-26T11:56:12.038906Z\"}]}"}
{"recv_ts_ns":1787745372194160758,"payload":"{\"channel\":\"book\",\"type\":\"update\",\"data\":[{\"symbol\":\"BTC/USD\",\"bids\":[{\"price\":78487.5,\"qty\":0.01149380}],\"asks\":[],\"checksum\":1557279960,\"timestamp\":\"2026-08-26T11:56:12.049330Z\"}]}"}
{"recv_ts_ns":1787745372196862866,"payload":"{\"channel\":\"book\",\"type\":\"update\",\"data\":[{\"symbol\":\"BTC/USD\",\"bids\":[],\"asks\":[{\"price\":78525.5,\"qty\":0.16577268}],\"checksum\":1557279960,\"timestamp\":\"2026-08-26T11:56:12.051696Z\"}]}"}
{"recv_ts_ns":1787745372212082332,"payload":"{\"channel\":\"book\",\"type\":\"update\",\"data\":[{\"symbol\":\"BTC/USD\",\"bids\":[],\"asks\":[{\"price\":78529.6,\"qty\":1.27367436}],\"checksum\":1557279960,\"timestamp\":\"2026-08-26T11:56:12.066630Z\"}]}"}
{"recv_ts_ns":1787745372212452930,"payload":"{\"channel\":\"book\",\"type\":\"update\",\"data\":[{\"symbol\":\"BTC/USD\",\"bids\":[],\"asks\":[{\"price\":78528.1,\"qty\":0.42626550}],\"checksum\":1557279960,\"timestamp\":\"2026-08-26T11:56:12.068040Z\"}]}"}
{"recv_ts_ns":1787745372217000692,"payload":"{\"channel\":\"book\",\"type\":\"update\",\"data\":[{\"symbol\":\"BTC/USD\",\"bids\":[],\"asks\":[{\"price\":78532.0,\"qty\":0.06555529}],\"checksum\":1557279960,\"timestamp\":\"2026-08-26T11:56:12.069557Z\"}]}"}
{"recv_ts_ns":1787745372217169178,"payload":"{\"channel\":\"book\",\"type\":\"update\",\"data\":[{\"symbol\":\"BTC/USD\",\"bids\":[],\"asks\":[{\"price\":78521.8,\"qty\":0.95543056}],\"checksum\":1557279960,\"timestamp\":\"2026-08-26T11:56:12.069946Z\"}]}"}
{"recv_ts_ns":1787745372219727037,"payload":"{\"channel\":\"book\",\"type\":\"update\",\"data\":[{\"symbol\":\"BTC/USD\",\"bids\":[],\"asks\":[{\"price\":78521.7,\"qty\":0.28519602}],\"checksum\":1557279960,\"timestamp\":\"2026-08-26T11:56:12.073235Z\"}]}"}
{"recv_ts_ns":1787745372222178870,"payload":"{\"channel\":\"book\",\"type\":\"update\",\"data\":[{\"symbol\":\"BTC/USD\",\"bids\":[],\"asks\":[{\"price\":78525.5,\"qty\":0.01292474},{\"price\":78523.3,\"qty\":0.41771545}],\"checksum\":1557279960,\"timestamp\":\"2026-08-26T11:56:12.074607Z\"}]}"}
{"recv_ts_ns":1787745372249136648,"payload":"{\"channel\":\"book\",\"type\":\"update\",\"data\":[{\"symbol\":\"BTC/USD\",\"bids\":[],\"asks\":[{\"price\":78531.5,\"qty\":0.00000000},{\"price\":78532.1,\"qty\":0.02606386}],\"checksum\":1557279960,\"timestamp\":\"2026-08-26T11:56:12.103982Z\"}]}"}
{"recv_ts_ns":1787745372255001401,"payload":"{\"channel\":\"book\",\"type\":\"update\",\"data\":[{\"symbol\":\"BTC/USD\",\"bids\":[],\"asks\":[{\"price\":78504.6,\"qty\":0.00000000},{\"price\":78532.2,\"qty\":0.06367870}],\"checksum\":1104819948,\"timestamp\":\"2026-08-26T11:56:12.108653Z\"}]}"}
{"recv_ts_ns":1787745372257449832,"payload":"{\"channel\":\"book\",\"type\":\"update\",\"data\":[{\"symbol\":\"BTC/USD\",\"bids\":[],\"asks\":[{\"price\":78507.7,\"qty\":0.01565551}],\"checksum\":3410831331,\"timestamp\":\"2026-08-26T11:56:12.111751Z\"}]}"}
{"recv_ts_ns":1787745372292896969,"payload":"{\"channel\":\"book\",\"type\":\"update\",\"data\":[{\"symbol\":\"BTC/USD\",\"bids\":[{\"price\":78490.0,\"qty\":0.03372252}],\"asks\":[],\"checksum\":3410831331,\"timestamp\":\"2026-08-26T11:56:12.147833Z\"}]}"}
{"recv_ts_ns":1787745372302056501,"payload":"{\"channel\":\"book\",\"type\":\"update\",\"data\":[{\"symbol\":\"BTC/USD\",\"bids\":[],\"asks\":[{\"price\":78521.8,\"qty\":0.00000000},{\"price\":78532.2,\"qty\":0.06367870}],\"checksum\":3410831331,\"timestamp\":\"2026-08-26T11:56:12.156715Z\"}]}"}
{"recv_ts_ns":1787745372303501871,"payload":"{\"channel\":\"book\",\"type\":\"update\",\"data\":[{\"symbol\":\"BTC/USD\",\"bids\":[],\"asks\":[{\"price\":78521.7,\"qty\":0.00000000},{\"price\":78532.5,\"qty\":0.02292044}],\"checksum\":3410831331,\"timestamp\":\"2026-08-26T11:56:12.158305Z\"}]}"}
{"recv_ts_ns":1787745372304136579,"payload":"{\"channel\":\"book\",\"type\":\"update\",\"data\":[{\"symbol\":\"BTC/USD\",\"bids\":[],\"asks\":[{\"price\":78523.3,\"qty\":0.26486751},{\"price\":78525.5,\"qty\":0.16577268}],\"checksum\":3410831331,\"timestamp\":\"2026-08-26T11:56:12.159647Z\"}]}"}
{"recv_ts_ns":1787745372317481903,"payload":"{\"channel\":\"book\",\"type\":\"update\",\"data\":[{\"symbol\":\"BTC/USD\",\"bids\":[],\"asks\":[{\"price\":78529.6,\"qty\":0.00000000},{\"price\":78532.8,\"qty\":0.00254670}],\"checksum\":3410831331,\"timestamp\":\"2026-08-26T11:56:12.171345Z\"}]}"}
{"recv_ts_ns":1787745372317607379,"payload":"{\"channel\":\"book\",\"type\":\"update\",\"data\":[{\"symbol\":\"BTC/USD\",\"bids\":[],\"asks\":[{\"price\":78521.9,\"qty\":0.95543056}],\"checksum\":3410831331,\"timestamp\":\"2026-08-26T11:56:12.171394Z\"}]}"}
{"recv_ts_ns":1787745372317698459,"payload":"{\"channel\":\"book\",\"type\":\"update\",\"data\":[{\"symbol\":\"BTC/USD\",\"bids\":[],\"asks\":[{\"price\":78528.1,\"qty\":0.05282761}],\"checksum\":3410831331,\"timestamp\":\"2026-08-26T11:56:12.172758Z\"}]}"}
{"recv_ts_ns":1787745372317796870,"payload":"{\"channel\":\"book\",\"type\":\"update\",\"data\":[{\"symbol\":\"BTC/USD\",\"bids\":[],\"asks\":[{\"price\":78532.0,\"qty\":0.43736850}],\"checksum\":3410831331,\"timestamp\":\"2026-08-26T11:56:12.173018Z\"}]}"}
{"recv_ts_ns":1787745372319561927,"payload":"{\"channel\":\"book\",\"type\":\"update\",\"data\":[{\"symbol\":\"BTC/USD\",\"bids\":[],\"asks\":[{\"price\":78521.8,\"qty\":0.28519602}],\"checksum\":3410831331,\"timestamp\":\"2026-08-26T11:56:12.174249Z\"}]}"}
{"recv_ts_ns":1787745372332302932,"payload":"{\"channel\":\"book\",\"type\":\"update\",\"data\":[{\"symbol\":\"BTC/USD\",\"bids\":[],\"asks\":[{\"price\":78525.5,\"qty\":0.01292474}],\"checksum\":3410831331,\"timestamp\":\"2026-08-26T11:56:12.187356Z\"}]}"}
{"recv_ts_ns":1787745372387888055,"payload":"{\"channel\":\"book\",\"type\":\"update\",\"data\":[{\"symbol\":\"BTC/USD\",\"bids\":[{\"price\":78500.1,\"qty\":0.01000000}],\"asks\":[],\"checksum\":4038184729,\"timestamp\":\"2026-08-26T11:56:12.242735Z\"}]}"}
{"recv_ts_ns":1787745372488161617,"payload":"{\"channel\":\"book\",\"type\":\"update\",\"data\":[{\"symbol\":\"BTC/USD\",\"bids\":[{\"price\":78487.2,\"qty\":0.00000000},{\"price\":78487.0,\"qty\":0.34238799}],\"asks\":[],\"checksum\":4038184729,\"timestamp\":\"2026-08-26T11:56:12.342312Z\"}]}"}
{"recv_ts_ns":1787745372541498021,"payload":"{\"channel\":\"book\",\"type\":\"update\",\"data\":[{\"symbol\":\"BTC/USD\",\"bids\":[{\"price\":78490.2,\"qty\":1.27405203}],\"asks\":[],\"checksum\":4038184729,\"timestamp\":\"2026-08-26T11:56:12.393341Z\"}]}"}
{"recv_ts_ns":1787745372569102625,"payload":"{\"channel\":\"book\",\"type\":\"update\",\"data\":[{\"symbol\":\"BTC/USD\",\"bids\":[],\"asks\":[{\"price\":78521.9,\"qty\":0.00000000},{\"price\":78532.5,\"qty\":0.02292044}],\"checksum\":4038184729,\"timestamp\":\"2026-08-26T11:56:12.422362Z\"}]}"}
{"recv_ts_ns":1787745372569269273,"payload":"{\"channel\":\"book\",\"type\":\"update\",\"data\":[{\"symbol\":\"BTC/USD\",\"bids\":[],\"asks\":[{\"price\":78521.8,\"qty\":0.00000000},{\"price\":78532.8,\"qty\":0.00254670}],\"checksum\":4038184729,\"timestamp\":\"2026-08-26T11:56:12.423702Z\"}]}"}
{"recv_ts_ns":1787745372620047539,"payload":"{\"channel\":\"book\",\"type\":\"update\",\"data\":[{\"symbol\":\"BTC/USD\",\"bids\":[],\"asks\":[{\"price\":78520.9,\"qty\":0.95543056}],\"checksum\":4038184729,\"timestamp\":\"2026-08-26T11:56:12.471200Z\"}]}"}
{"recv_ts_ns":1787745372620196877,"payload":"{\"channel\":\"book\",\"type\":\"update\",\"data\":[{\"symbol\":\"BTC/USD\",\"bids\":[],\"asks\":[{\"price\":78520.8,\"qty\":0.28519602}],\"checksum\":4038184729,\"timestamp\":\"2026-08-26T11:56:12.472806Z\"}]}"}
{"recv_ts_ns":1787745372725190512,"payload":"{\"channel\":\"book\",\"type\":\"update\",\"data\":[{\"symbol\":\"BTC/USD\",\"bids\":[],\"asks\":[{\"price\":78520.9,\"qty\":0.00000000},{\"price\":78532.5,\"qty\":0.02292044}],\"checksum\":4038184729,\"timestamp\":\"2026-08-26T11:56:12.580840Z\"}]}"}
{"recv_ts_ns":1787745372726402307,"payload":"{\"channel\":\"book\",\"type\":\"update\",\"data\":[{\"symbol\":\"BTC/USD\",\"bids\":[],\"asks\":[{\"price\":78520.8,\"qty\":0.00000000},{\"price\":78532.8,\"qty\":0.00254670}],\"checksum\":4038184729,\"timestamp\":\"2026-08-26T11:56:12.582332Z\"}]}"}
{"recv_ts_ns":1787745372766184364,"payload":"{\"channel\":\"book\",\"type\":\"update\",\"data\":[{\"symbol\":\"BTC/USD\",\"bids\":[],\"asks\":[{\"price\":78521.0,\"qty\":0.95543056}],\"checksum\":4038184729,\"timestamp\":\"2026-08-26T11:56:12.620686Z\"}]}"}
{"recv_ts_ns":1787745372766965495,"payload":"{\"channel\":\"book\",\"type\":\"update\",\"data\":[{\"symbol\":\"BTC/USD\",\"bids\":[],\"asks\":[{\"price\":78520.9,\"qty\":0.28519602}],\"checksum\":4038184729,\"timestamp\":\"2026-08-26T11:56:12.622153Z\"}]}"}
{"recv_ts_ns":1787745372927399768,"payload":"{\"channel\":\"heartbeat\"}"}
{"recv_ts_ns":1787745372942098778,"payload":"{\"channel\":\"book\",\"type\":\"update\",\"data\":[{\"symbol\":\"BTC/USD\",\"bids\":[],\"asks\":[{\"price\":78520.9,\"qty\":0.00000000},{\"price\":78532.5,\"qty\":0.02292044}],\"checksum\":4038184729,\"timestamp\":\"2026-08-26T11:56:12.796355Z\"}]}"}
{"recv_ts_ns":1787745373008716103,"payload":"{\"channel\":\"book\",\"type\":\"update\",\"data\":[{\"symbol\":\"BTC/USD\",\"bids\":[{\"price\":78500.6,\"qty\":5.28908493}],\"asks\":[],\"checksum\":2046502418,\"timestamp\":\"2026-08-26T11:56:12.858649Z\"}]}"}
{"recv_ts_ns":1787745373014167501,"payload":"{\"channel\":\"book\",\"type\":\"update\",\"data\":[{\"symbol\":\"BTC/USD\",\"bids\":[],\"asks\":[{\"price\":78532.1,\"qty\":0.00000000},{\"price\":78532.8,\"qty\":0.00254670}],\"checksum\":2046502418,\"timestamp\":\"2026-08-26T11:56:12.869103Z\"}]}"}
{"recv_ts_ns":1787745373014276907,"payload":"{\"channel\":\"book\",\"type\":\"update\",\"data\":[{\"symbol\":\"BTC/USD\",\"bids\":[],\"asks\":[{\"price\":78524.3,\"qty\":0.00000000},{\"price\":78533.7,\"qty\":0.10440600}],\"checksum\":2046502418,\"timestamp\":\"2026-08-26T11:56:12.869326Z\"}]}"}
{"recv_ts_ns":1787745373022377206,"payload":"{\"channel\":\"book\",\"type\":\"update\",\"data\":[{\"symbol\":\"BTC/USD\",\"bids\":[],\"asks\":[{\"price\":78533.7,\"qty\":0.00000000},{\"price\":78534.0,\"qty\":1.27368283}],\"checksum\":2046502418,\"timestamp\":\"2026-08-26T11:56:12.876377Z\"}]}"}
{"recv_ts_ns":1787745373053336048,"payload":"{\"channel\":\"book\",\"type\":\"update\",\"data\":[{\"symbol\":\"BTC/USD\",\"bids\":[],\"asks\":[{\"price\":78524.6,\"qty\":0.63674329}],\"checksum\":2046502418,\"timestamp\":\"2026-08-26T11:56:12.906880Z\"}]}"}
{"recv_ts_ns":1787745373053476059,"payload":"{\"channel\":\"book\",\"type\":\"update\",\"data\":[{\"symbol\":\"BTC/USD\",\"bids\":[],\"asks\":[{\"price\":78527.7,\"qty\":0.63671869}],\"checksum\":2046502418,\"timestamp\":\"2026-08-26T11:56:12.907211Z\"}]}"}
{"recv_ts_ns":1787745373056347446,"payload":"{\"channel\":\"book\",\"type\":\"update\",\"data\":[{\"symbol\":\"BTC/USD\",\"bids\":[],\"asks\":[{\"price\":78523.3,\"qty\":0.41655669}],\"checksum\":2046502418,\"timestamp\":\"2026-08-26T11:56:12.909963Z\"}]}"}
{"recv_ts_ns":1787745373056517882,"payload":"{\"channel\":\"book\",\"type\":\"update\",\"data\":[{\"symbol\":\"BTC/USD\",\"bids\":[],\"asks\":[{\"price\":78528.1,\"qty\":0.00000000},{\"price\":78532.6,\"qty\":0.63667876}],\"checksum\":2046502418,\"timestamp\":\"2026-08-26T11:56:12.910130Z\"}]}"}
{"recv_ts_ns":1787745373057922773,"payload":"{\"channel\":\"book\",\"type\":\"update\",\"data\":[{\"symbol\":\"BTC/USD\",\"bids\":[],\"asks\":[{\"price\":78527.6,\"qty\":0.24288814}],\"checksum\":2046502418,\"timestamp\":\"2026-08-26T11:56:12.912998Z\"}]}"}
{"recv_ts_ns":1787745373060994785,"payload":"{\"channel\":\"book\",\"type\":\"update\",\"data\":[{\"symbol\":\"BTC/USD\",\"bids\":[],\"asks\":[{\"price\":78507.7,\"qty\":0.00000000},{\"price\":78532.6,\"qty\":0.63667876}],\"checksum\":3202030743,\"timestamp\":\"2026-08-26T11:56:12.915361Z\"}]}"}
{"recv_ts_ns":1787745373062392479,"payload":"{\"channel\":\"book\",\"type\":\"update\",\"data\":[{\"symbol\":\"BTC/USD\",\"bids\":[],\"asks\":[{\"price\":78505.6,\"qty\":0.01565551}],\"checksum\":3506899362,\"timestamp\":\"2026-08-26T11:56:12.916146Z\"}]}"}
{"recv_ts_ns":1787745373113253203,"payload":"{\"channel\":\"book\",\"type\":\"update\",\"data\":[{\"symbol\":\"BTC/USD\",\"bids\":[],\"asks\":[{\"price\":78521.0,\"qty\":0.00000000},{\"price\":78532.6,\"qty\":0.63667876}],\"checksum\":3506899362,\"timestamp\":\"2026-08-26T11:56:12.965881Z\"}]}"}
{"recv_ts_ns":1787745373113298051,"payload":"{\"channel\":\"book\",\"type\":\"update\",\"data\":[{\"symbol\":\"BTC/USD\",\"bids\":[],\"asks\":[{\"price\":78525.5,\"qty\":0.16577268}],\"checksum\":3506899362,\"timestamp\":\"2026-08-26T11:56:12.967050Z\"}]}"}
{"recv_ts_ns":1787745373118380986,"payload":"{\"channel\":\"book\",\"type\":\"update\",\"data\":[{\"symbol\":\"BTC/USD\",\"bids\":[],\"asks\":[{\"price\":78522.3,\"qty\":0.95543056}],\"checksum\":3506899362,\"timestamp\":\"2026-08-26T11:56:12.971255Z\"}]}"}
{"recv_ts_ns":1787745373147984946,"payload":"{\"channel\":\"book\",\"type\":\"update\",\"data\":[{\"symbol\":\"BTC/USD\",\"bids\":[{\"price\":78500.6,\"qty\":5.26360742}],\"asks\":[],\"checksum\":1481498793,\"timestamp\":\"2026-08-26T11:56:13.002185Z\"}]}"}
{"recv_ts_ns":1787745373150065887,"payload":"{\"channel\":\"book\",\"type\":\"update\",\"data\":[{\"symbol\":\"BTC/USD\",\"bids\":[],\"asks\":[{\"price\":78529.3,\"qty\":0.00000000},{\"price\":78532.6,\"qty\":0.63667876}],\"checksum\":1481498793,\"timestamp\":\"2026-08-26T11:56:13.003252Z\"}]}"}
{"recv_ts_ns":1787745373150203390,"payload":"{\"channel\":\"book\",\"type\":\"update\",\"data\":[{\"symbol\":\"BTC/USD\",\"bids\":[],\"asks\":[{\"price\":78525.5,\"qty\":0.01292474},{\"price\":78523.2,\"qty\":0.15284794}],\"checksum\":1481498793,\"timestamp\":\"2026-08-26T11:56:13.003430Z\"}]}"}
{"recv_ts_ns":1787745373267884342,"payload":"{\"channel\":\"book\",\"type\":\"update\",\"data\":[{\"symbol\":\"BTC/USD\",\"bids\":[{\"price\":78490.2,\"qty\":0.00000000},{\"price\":78487.0,\"qty\":0.34238799},{\"price\":78487.1,\"qty\":1.27410236}],\"asks\":[],\"checksum\":1481498793,\"timestamp\":\"2026-08-26T11:56:13.122968Z\"}]}"}
{"recv_ts_ns":1787745373513943982,"payload":"{\"channel\":\"book\",\"type\":\"update\",\"data\":[{\"symbol\":\"BTC/USD\",\"bids\":[],\"asks\":[{\"price\":78532.2,\"qty\":0.08994686}],\"checksum\":1481498793,\"timestamp\":\"2026-08-26T11:56:13.369185Z\"}]}"}
{"recv_ts_ns":1787745373514039667,"payload":"{\"channel\":\"book\",\"type\":\"update\",\"data\":[{\"symbol\":\"BTC/USD\",\"bids\":[],\"asks\":[{\"price\":78524.4,\"qty\":0.01494613}],\"checksum\":1481498793,\"timestamp\":\"2026-08-26T11:56:13.369279Z\"}]}"}
{"recv_ts_ns":1787745373927788550,"payload":"{\"channel\":\"heartbeat\"}"}
{"recv_ts_ns":1787745373953112174,"payload":"{\"channel\":\"book\",\"type\":\"update\",\"data\":[{\"symbol\":\"BTC/USD\",\"bids\":[],\"asks\":[{\"price\":78532.2,\"qty\":0.02626816}],\"checksum\":1481498793,\"timestamp\":\"2026-08-26T11:56:13.805216Z\"}]}"}
{"recv_ts_ns":1787745374165204304,"payload":"{\"channel\":\"book\",\"type\":\"update\",\"data\":[{\"symbol\":\"BTC/USD\",\"bids\":[{\"price\":78500.6,\"qty\":5.28908493}],\"asks\":[],\"checksum\":3506899362,\"timestamp\":\"2026-08-26T11:56:14.019519Z\"}]}"}
{"recv_ts_ns":1787745374181374198,"payload":"{\"channel\":\"book\",\"type\":\"update\",\"data\":[{\"symbol\":\"BTC/USD\",\"bids\":[],\"asks\":[{\"price\":78520.4,\"qty\":0.00000000},{\"price\":78532.5,\"qty\":0.02292044}],\"checksum\":3075502156,\"timestamp\":\"2026-08-26T11:56:14.035725Z\"}]}"}
{"recv_ts_ns":1787745374311062502,"payload":"{\"channel\":\"book\",\"type\":\"update\",\"data\":[{\"symbol\":\"BTC/USD\",\"bids\":[{\"price\":78500.6,\"qty\":5.26360742}],\"asks\":[],\"checksum\":1041930567,\"timestamp\":\"2026-08-26T11:56:14.165411Z\"}]}"}
{"recv_ts_ns":1787745374532335480,"payload":"{\"channel\":\"book\",\"type\":\"update\",\"data\":[{\"symbol\":\"BTC/USD\",\"bids\":[],\"asks\":[{\"price\":78528.5,\"qty\":0.00254684}],\"checksum\":1041930567,\"timestamp\":\"2026-08-26T11:56:14.386824Z\"}]}"}
{"recv_ts_ns":1787745374576289016,"payload":"{\"channel\":\"book\",\"type\":\"update\",\"data\":[{\"symbol\":\"BTC/USD\",\"bids\":[],\"asks\":[{\"price\":78528.3,\"qty\":0.02292167}],\"checksum\":1041930567,\"timestamp\":\"2026-08-26T11:56:14.430616Z\"}]}"}
{"recv_ts_ns":1787745374680235065,"payload":"{\"channel\":\"book\",\"type\":\"update\",\"data\":[{\"symbol\":\"BTC/USD\",\"bids\":[{\"price\":78487.9,\"qty\":0.02049402}],\"asks\":[],\"checksum\":1041930567,\"timestamp\":\"2026-08-26T11:56:14.534141Z\"}]}"}
{"recv_ts_ns":1787745374683265804,"payload":"{\"channel\":\"book\",\"type\":\"update\",\"data\":[{\"symbol\":\"BTC/USD\",\"bids\":[],\"asks\":[{\"price\":78519.4,\"qty\":0.02039597}],\"checksum\":855316461,\"timestamp\":\"2026-08-26T11:56:14.535066Z\"}]}"}
{"recv_ts_ns":1787745374683415495,"payload":"{\"channel\":\"book\",\"type\":\"update\",\"data\":[{\"symbol\":\"BTC/USD\",\"bids\":[],\"asks\":[{\"price\":78520.5,\"qty\":0.01152884}],\"checksum\":855316461,\"timestamp\":\"2026-08-26T11:56:14.535531Z\"}]}"}
{"recv_ts_ns":1787745374836455065,"payload":"{\"channel\":\"book\",\"type\":\"update\",\"data\":[{\"symbol\":\"BTC/USD\",\"bids\":[],\"asks\":[{\"price\":78505.6,\"qty\":0.00000000},{\"price\":78528.9,\"qty\":0.01273416}],\"checksum\":4115844836,\"timestamp\":\"2026-08-26T11:56:14.690541Z\"}]}"}
{"recv_ts_ns":1787745374841228974,"payload":"{\"channel\":\"book\",\"type\":\"update\",\"data\":[{\"symbol\":\"BTC/USD\",\"bids\":[],\"asks\":[{\"price\":78508.6,\"qty\":0.01565551}],\"checksum\":4240881594,\"timestamp\":\"2026-08-26T11:56:14.693314Z\"}]}"}
{"recv_ts_ns":1787745374843952034,"payload":"{\"channel\":\"book\",\"type\":\"update\",\"data\":[{\"symbol\":\"BTC/USD\",\"bids\":[],\"asks\":[{\"price\":78524.4,\"qty\":0.00000000},{\"price\":78528.9,\"qty\":0.01273416}],\"checksum\":4240881594,\"timestamp\":\"2026-08-26T11:56:14.697894Z\"}]}"}
{"recv_ts_ns":1787745374844093861,"payload":"{\"channel\":\"book\",\"type\":\"update\",\"data\":[{\"symbol\":\"BTC/USD\",\"bids\":[],\"asks\":[{\"price\":78520.5,\"qty\":0.00000000},{\"price\":78532.0,\"qty\":0.43736850}],\"checksum\":4240881594,\"timestamp\":\"2026-08-26T11:56:14.698216Z\"}]}"}
{"recv_ts_ns":1787745374928820522,"payload":"{\"channel\":\"heartbeat\"}"}
{"recv_ts_ns":1787745375061923310,"payload":"{\"channel\":\"book\",\"type\":\"update\",\"data\":[{\"symbol\":\"BTC/USD\",\"bids\":[],\"asks\":[{\"price\":78508.6,\"qty\":0.00000000},{\"price\":78532.6,\"qty\":0.63667876}],\"checksum\":1799105516,\"timestamp\":\"2026-08-26T11:56:14.914103Z\"}]}"}
{"recv_ts_ns":1787745375062102666,"payload":"{\"channel\":\"book\",\"type\":\"update\",\"data\":[{\"symbol\":\"BTC/USD\",\"bids\":[],\"asks\":[{\"price\":78506.6,\"qty\":0.01565551}],\"checksum\":1935561328,\"timestamp\":\"2026-08-26T11:56:14.914221Z\"}]}"}
{"recv_ts_ns":1787745375162051581,"payload":"{\"channel\":\"book\",\"type\":\"update\",\"data\":[{\"symbol\":\"BTC/USD\",\"bids\":[],\"asks\":[{\"price\":78522.3,\"qty\":0.00000000},{\"price\":78532.6,\"qty\":0.63667876}],\"checksum\":1935561328,\"timestamp\":\"2026-08-26T11:56:15.014686Z\"}]}"}
{"recv_ts_ns":1787745375167825961,"payload":"{\"channel\":\"book\",\"type\":\"update\",\"data\":[{\"symbol\":\"BTC/USD\",\"bids\":[],\"asks\":[{\"price\":78522.2,\"qty\":0.95543056}],\"checksum\":1935561328,\"timestamp\":\"2026-08-26T11:56:15.020057Z\"}]}"}
{"recv_ts_ns":1787745375214520084,"payload":"{\"channel\":\"trade\",\"type\":\"update\",\"data\":[{\"symbol\":\"BTC/USD\",\"side\":\"buy\",\"price\":78500.7,\"qty\":0.00028943,\"ord_type\":\"limit\",\"trade_id\":105995618,\"timestamp\":\"2026-08-26T11:56:15.068110Z\"},{\"symbol\":\"BTC/USD\",\"side\":\"buy\",\"price\":78500.7,\"qty\":0.00008341,\"ord_type\":\"limit\",\"trade_id\":105995619,\"timestamp\":\"2026-08-26T11:56:15.068110Z\"}]}"}
{"recv_ts_ns":1787745375216547458,"payload":"{\"channel\":\"book\",\"type\":\"update\",\"data\":[{\"symbol\":\"BTC/USD\",\"bids\":[],\"asks\":[{\"price\":78500.7,\"qty\":0.00178750},{\"price\":78500.7,\"qty\":0.00170409}],\"checksum\":1458627279,\"timestamp\":\"2026-08-26T11:56:15.068110Z\"}]}"}
{"recv_ts_ns":1787745375237436809,"payload":"{\"channel\":\"book\",\"type\":\"update\",\"data\":[{\"symbol\":\"BTC/USD\",\"bids\":[{\"price\":78500.6,\"qty\":5.28908493}],\"asks\":[],\"checksum\":3753511876,\"timestamp\":\"2026-08-26T11:56:15.088176Z\"}]}"}
{"recv_ts_ns":1787745375287669449,"payload":"{\"channel\":\"book\",\"type\":\"update\",\"data\":[{\"symbol\":\"BTC/USD\",\"bids\":[],\"asks\":[{\"price\":78524.6,\"qty\":0.00000000},{\"price\":78532.6,\"qty\":0.63667876}],\"checksum\":3753511876,\"timestamp\":\"2026-08-26T11:56:15.136555Z\"}]}"}
{"recv_ts_ns":1787745375287895216,"payload":"{\"channel\":\"book\",\"type\":\"update\",\"data\":[{\"symbol\":\"BTC/USD\",\"bids\":[],\"asks\":[{\"price\":78527.7,\"qty\":0.00000000},{\"price\":78534.0,\"qty\":1.27368283}],\"checksum\":3753511876,\"timestamp\":\"2026-08-26T11:56:15.136711Z\"}]}"}
{"recv_ts_ns":1787745375288002843,"payload":"{\"channel\":\"book\",\"type\":\"update\",\"data\":[{\"symbol\":\"BTC/USD\",\"bids\":[],\"asks\":[{\"price\":78523.8,\"qty\":0.63675020}],\"checksum\":3753511876,\"timestamp\":\"2026-08-26T11:56:15.138481Z\"}]}"}
{"recv_ts_ns":1787745375288091248,"payload":"{\"channel\":\"book\",\"type\":\"update\",\"data\":[{\"symbol\":\"BTC/USD\",\"bids\":[],\"asks\":[{\"price\":78526.4,\"qty\":0.63672923}],\"checksum\":3753511876,\"timestamp\":\"2026-08-26T11:56:15.138815Z\"}]}"}
{"recv_ts_ns":1787745375288206812,"payload":"{\"channel\":\"book\",\"type\":\"update\",\"data\":[{\"symbol\":\"BTC/USD\",\"bids\":[],\"asks\":[{\"price\":78523.3,\"qty\":0.26486751}],\"checksum\":3753511876,\"timestamp\":\"2026-08-26T11:56:15.140418Z\"}]}"}
{"recv_ts_ns":1787745375288299864,"payload":"{\"channel\":\"book\",\"type\":\"update\",\"data\":[{\"symbol\":\"BTC/USD\",\"bids\":[],\"asks\":[{\"price\":78527.6,\"qty\":0.00000000},{\"price\":78532.6,\"qty\":0.63667876}],\"checksum\":3753511876,\"timestamp\":\"2026-08-26T11:56:15.140651Z\"}]}"}
{"recv_ts_ns":1787745375288571795,"payload":"{\"channel\":\"book\",\"type\":\"update\",\"data\":[{\"symbol\":\"BTC/USD\",\"bids\":[],\"asks\":[{\"price\":78522.1,\"qty\":0.28519602}],\"checksum\":3753511876,\"timestamp\":\"2026-08-26T11:56:15.141912Z\"}]}"}
{"recv_ts_ns":1787745375289560892,"payload":"{\"channel\":\"book\",\"type\":\"update\",\"data\":[{\"symbol\":\"BTC/USD\",\"bids\":[],\"asks\":[{\"price\":78523.3,\"qty\":0.60662243}],\"checksum\":3753511876,\"timestamp\":\"2026-08-26T11:56:15.142533Z\"}]}"}
{"recv_ts_ns":1787745375344424938,"payload":"{\"channel\":\"book\",\"type\":\"update\",\"data\":[{\"symbol\":\"BTC/USD\",\"bids\":[],\"asks\":[{\"price\":78520.9,\"qty\":0.01117684}],\"checksum\":3753511876,\"timestamp\":\"2026-08-26T11:56:15.198546Z\"}]}"}
{"recv_ts_ns":1787745375344525650,"payload":"{\"channel\":\"book\",\"type\":\"update\",\"data\":[{\"symbol\":\"BTC/USD\",\"bids\":[],\"asks\":[{\"price\":78524.9,\"qty\":0.01508777}],\"checksum\":3753511876,\"timestamp\":\"2026-08-26T11:56:15.198796Z\"}]}"}
{"recv_ts_ns":1787745375347013550,"payload":"{\"channel\":\"book\",\"type\":\"update\",\"data\":[{\"symbol\":\"BTC/USD\",\"bids\":[],\"asks\":[{\"price\":78523.2,\"qty\":0.00000000},{\"price\":78528.9,\"qty\":0.01273416},{\"price\":78522.0,\"qty\":0.15284794}],\"checksum\":3753511876,\"timestamp\":\"2026-08-26T11:56:15.200054Z\"}]}"}
{"recv_ts_ns":1787745375366386398,"payload":"{\"channel\":\"book\",\"type\":\"update\",\"data\":[{\"symbol\":\"BTC/USD\",\"bids\":[],\"asks\":[{\"price\":78500.7,\"qty\":0.00218180}],\"checksum\":240000239,\"timestamp\":\"2026-08-26T11:56:15.219792Z\"}]}"}
{"recv_ts_ns":1787745375380209077,"payload":"{\"channel\":\"book\",\"type\":\"update\",\"data\":[{\"symbol\":\"BTC/USD\",\"bids\":[{\"price\":78500.6,\"qty\":5.26360742}],\"asks\":[],\"checksum\":2265249252,\"timestamp\":\"2026-08-26T11:56:15.233605Z\"}]}"}
{"recv_ts_ns":1787745375420752085,"payload":"{\"channel\":\"book\",\"type\":\"update\",\"data\":[{\"symbol\":\"BTC/USD\",\"bids\":[],\"asks\":[{\"price\":78500.7,\"qty\":0.00265951}],\"checksum\":2226163159,\"timestamp\":\"2026-08-26T11:56:15.273699Z\"}]}"}
{"recv_ts_ns":1787745375474590692,"payload":"{\"channel\":\"book\",\"type\":\"update\",\"data\":[{\"symbol\":\"BTC/USD\",\"bids\":[],\"asks\":[{\"price\":78500.7,\"qty\":0.00313722}],\"checksum\":1226480278,\"timestamp\":\"2026-08-26T11:56:15.328140Z\"}]}"}
{"recv_ts_ns":1787745375482944366,"payload":"{\"channel\":\"book\",\"type\":\"update\",\"data\":[{\"symbol\":\"BTC/USD\",\"bids\":[],\"asks\":[{\"price\":78500.7,\"qty\":0.00265951}],\"checksum\":2226163159,\"timestamp\":\"2026-08-26T11:56:15.336566Z\"}]}"}
{"recv_ts_ns":1787745375545750035,"payload":"{\"channel\":\"book\",\"type\":\"update\",\"data\":[{\"symbol\":\"BTC/USD\",\"bids\":[],\"asks\":[{\"price\":78500.7,\"qty\":0.00218180}],\"checksum\":2265249252,\"timestamp\":\"2026-08-26T11:56:15.399060Z\"}]}"}
{"recv_ts_ns":1787745375885273425,"payload":"{\"channel\":\"book\",\"type\":\"update\",\"data\":[{\"symbol\":\"BTC/USD\",\"bids\":[],\"asks\":[{\"price\":78522.2,\"qty\":0.00000000},{\"price\":78528.9,\"qty\":0.01273416}],\"checksum\":2265249252,\"timestamp\":\"2026-08-26T11:56:15.739461Z\"}]}"}
{"recv_ts_ns":1787745375886867688,"payload":"{\"channel\":\"book\",\"type\":\"update\",\"data\":[{\"symbol\":\"BTC/USD\",\"bids\":[],\"asks\":[{\"price\":78522.0,\"qty\":0.00000000},{\"price\":78532.0,\"qty\":0.43736850},{\"price\":78523.2,\"qty\":0.15284794}],\"checksum\":2265249252,\"timestamp\":\"2026-08-26T11:56:15.740762Z\"}]}"}
{"recv_ts_ns":1787745375887456866,"payload":"{\"channel\":\"book\",\"type\":\"update\",\"data\":[{\"symbol\":\"BTC/USD\",\"bids\":[],\"asks\":[{\"price\":78522.1,\"qty\":0.00000000},{\"price\":78532.0,\"qty\":0.43736850}],\"checksum\":2265249252,\"timestamp\":\"2026-08-26T11:56:15.740831Z\"}]}"}
{"recv_ts_ns":1787745375918384695,"payload":"{\"channel\":\"book\",\"type\":\"update\",\"data\":[{\"symbol\":\"BTC/USD\",\"bids\":[],\"asks\":[{\"price\":78522.1,\"qty\":0.95543056}],\"checksum\":2265249252,\"timestamp\":\"2026-08-26T11:56:15.770949Z\"}]}"}
{"recv_ts_ns":1787745375921230365,"payload":"{\"channel\":\"book\",\"type\":\"update\",\"data\":[{\"symbol\":\"BTC/USD\",\"bids\":[],\"asks\":[{\"price\":78522.0,\"qty\":0.28519602}],\"checksum\":2265249252,\"timestamp\":\"2026-08-26T11:56:15.774336Z\"}]}"}
{"recv_ts_ns":1787745375923883287,"payload":"{\"channel\":\"book\",\"type\":\"update\",\"data\":[{\"symbol\":\"BTC/USD\",\"bids\":[],\"asks\":[{\"price\":78523.2,\"qty\":0.00000000},{\"price\":78528.9,\"qty\":0.01273416},{\"price\":78521.9,\"qty\":0.15284794}],\"checksum\":2265249252,\"timestamp\":\"2026-08-26T11:56:15.775583Z\"}]}"}
{"recv_ts_ns":1787745375929697203,"payload":"{\"channel\":\"heartbeat\"}"}
